************************************************************/
2016-12-02 23:02:54,302 INFO org.apache.hadoop.yarn.server.resourcemanager.ResourceManager: STARTUP_MSG: 
/************************************************************
STARTUP_MSG: Starting ResourceManager
STARTUP_MSG:   host = NameNode/10.0.0.4
STARTUP_MSG:   args = []
STARTUP_MSG:   version = 2.7.3
STARTUP_MSG:   classpath = /opt/yarn/hadoop/etc/hadoop:/opt/yarn/hadoop/etc/hadoop:/opt/yarn/hadoop/etc/hadoop:/opt/yarn/hadoop/share/hadoop/common/lib/curator-framework-2.7.1.jar:/opt/yarn/hadoop/share/hadoop/common/lib/junit-4.11.jar:/opt/yarn/hadoop/share/hadoop/common/lib/commons-codec-1.4.jar:/opt/yarn/hadoop/share/hadoop/common/lib/jetty-6.1.26.jar:/opt/yarn/hadoop/share/hadoop/common/lib/java-xmlbuilder-0.4.jar:/opt/yarn/hadoop/share/hadoop/common/lib/hadoop-auth-2.7.3.jar:/opt/yarn/hadoop/share/hadoop/common/lib/mockito-all-1.8.5.jar:/opt/yarn/hadoop/share/hadoop/common/lib/curator-recipes-2.7.1.jar:/opt/yarn/hadoop/share/hadoop/common/lib/jsr305-3.0.0.jar:/opt/yarn/hadoop/share/hadoop/common/lib/httpclient-4.2.5.jar:/opt/yarn/hadoop/share/hadoop/common/lib/api-asn1-api-1.0.0-M20.jar:/opt/yarn/hadoop/share/hadoop/common/lib/servlet-api-2.5.jar:/opt/yarn/hadoop/share/hadoop/common/lib/commons-configuration-1.6.jar:/opt/yarn/hadoop/share/hadoop/common/lib/jsch-0.1.42.jar:/opt/yarn/hadoop/share/hadoop/common/lib/jsp-api-2.1.jar:/opt/yarn/hadoop/share/hadoop/common/lib/jackson-xc-1.9.13.jar:/opt/yarn/hadoop/share/hadoop/common/lib/curator-client-2.7.1.jar:/opt/yarn/hadoop/share/hadoop/common/lib/xz-1.0.jar:/opt/yarn/hadoop/share/hadoop/common/lib/commons-collections-3.2.2.jar:/opt/yarn/hadoop/share/hadoop/common/lib/commons-lang-2.6.jar:/opt/yarn/hadoop/share/hadoop/common/lib/jackson-mapper-asl-1.9.13.jar:/opt/yarn/hadoop/share/hadoop/common/lib/jackson-jaxrs-1.9.13.jar:/opt/yarn/hadoop/share/hadoop/common/lib/apacheds-i18n-2.0.0-M15.jar:/opt/yarn/hadoop/share/hadoop/common/lib/paranamer-2.3.jar:/opt/yarn/hadoop/share/hadoop/common/lib/jersey-json-1.9.jar:/opt/yarn/hadoop/share/hadoop/common/lib/jaxb-api-2.2.2.jar:/opt/yarn/hadoop/share/hadoop/common/lib/log4j-1.2.17.jar:/opt/yarn/hadoop/share/hadoop/common/lib/protobuf-java-2.5.0.jar:/opt/yarn/hadoop/share/hadoop/common/lib/stax-api-1.0-2.jar:/opt/yarn/hadoop/share/hadoop/common/lib/jetty-util-6.1.26.jar:/opt/yarn/hadoop/share/hadoop/common/lib/commons-httpclient-3.1.jar:/opt/yarn/hadoop/share/hadoop/common/lib/netty-3.6.2.Final.jar:/opt/yarn/hadoop/share/hadoop/common/lib/snappy-java-1.0.4.1.jar:/opt/yarn/hadoop/share/hadoop/common/lib/commons-cli-1.2.jar:/opt/yarn/hadoop/share/hadoop/common/lib/commons-beanutils-1.7.0.jar:/opt/yarn/hadoop/share/hadoop/common/lib/gson-2.2.4.jar:/opt/yarn/hadoop/share/hadoop/common/lib/commons-logging-1.1.3.jar:/opt/yarn/hadoop/share/hadoop/common/lib/zookeeper-3.4.6.jar:/opt/yarn/hadoop/share/hadoop/common/lib/asm-3.2.jar:/opt/yarn/hadoop/share/hadoop/common/lib/hadoop-annotations-2.7.3.jar:/opt/yarn/hadoop/share/hadoop/common/lib/hamcrest-core-1.3.jar:/opt/yarn/hadoop/share/hadoop/common/lib/slf4j-log4j12-1.7.10.jar:/opt/yarn/hadoop/share/hadoop/common/lib/commons-io-2.4.jar:/opt/yarn/hadoop/share/hadoop/common/lib/activation-1.1.jar:/opt/yarn/hadoop/share/hadoop/common/lib/commons-net-3.1.jar:/opt/yarn/hadoop/share/hadoop/common/lib/htrace-core-3.1.0-incubating.jar:/opt/yarn/hadoop/share/hadoop/common/lib/commons-compress-1.4.1.jar:/opt/yarn/hadoop/share/hadoop/common/lib/avro-1.7.4.jar:/opt/yarn/hadoop/share/hadoop/common/lib/commons-digester-1.8.jar:/opt/yarn/hadoop/share/hadoop/common/lib/httpcore-4.2.5.jar:/opt/yarn/hadoop/share/hadoop/common/lib/xmlenc-0.52.jar:/opt/yarn/hadoop/share/hadoop/common/lib/jets3t-0.9.0.jar:/opt/yarn/hadoop/share/hadoop/common/lib/commons-beanutils-core-1.8.0.jar:/opt/yarn/hadoop/share/hadoop/common/lib/slf4j-api-1.7.10.jar:/opt/yarn/hadoop/share/hadoop/common/lib/apacheds-kerberos-codec-2.0.0-M15.jar:/opt/yarn/hadoop/share/hadoop/common/lib/jersey-server-1.9.jar:/opt/yarn/hadoop/share/hadoop/common/lib/jettison-1.1.jar:/opt/yarn/hadoop/share/hadoop/common/lib/jersey-core-1.9.jar:/opt/yarn/hadoop/share/hadoop/common/lib/jaxb-impl-2.2.3-1.jar:/opt/yarn/hadoop/share/hadoop/common/lib/api-util-1.0.0-M20.jar:/opt/yarn/hadoop/share/hadoop/common/lib/commons-math3-3.1.1.jar:/opt/yarn/hadoop/share/hadoop/common/lib/jackson-core-asl-1.9.13.jar:/opt/yarn/hadoop/share/hadoop/common/lib/guava-11.0.2.jar:/
opt/yarn/hadoop/share/hadoop/common/hadoop-nfs-2.7.3.jar:/opt/yarn/hadoop/share/hadoop/common/hadoop-common-2.7.3.jar:/opt/yarn/hadoop/share/hadoop/common/hadoop-common-2.7.3-tests.jar:/opt/yarn/hadoop/share/hadoop/hdfs:/opt/yarn/hadoop/share/hadoop/hdfs/lib/commons-codec-1.4.jar:/opt/yarn/hadoop/share/hadoop/hdfs/lib/jetty-6.1.26.jar:/opt/yarn/hadoop/share/hadoop/hdfs/lib/commons-daemon-1.0.13.jar:/opt/yarn/hadoop/share/hadoop/hdfs/lib/leveldbjni-all-1.8.jar:/opt/yarn/hadoop/share/hadoop/hdfs/lib/jsr305-3.0.0.jar:/opt/yarn/hadoop/share/hadoop/hdfs/lib/servlet-api-2.5.jar:/opt/yarn/hadoop/share/hadoop/hdfs/lib/commons-lang-2.6.jar:/opt/yarn/hadoop/share/hadoop/hdfs/lib/jackson-mapper-asl-1.9.13.jar:/opt/yarn/hadoop/share/hadoop/hdfs/lib/log4j-1.2.17.jar:/opt/yarn/hadoop/share/hadoop/hdfs/lib/protobuf-java-2.5.0.jar:/opt/yarn/hadoop/share/hadoop/hdfs/lib/jetty-util-6.1.26.jar:/opt/yarn/hadoop/share/hadoop/hdfs/lib/netty-3.6.2.Final.jar:/opt/yarn/hadoop/share/hadoop/hdfs/lib/xercesImpl-2.9.1.jar:/opt/yarn/hadoop/share/hadoop/hdfs/lib/commons-cli-1.2.jar:/opt/yarn/hadoop/share/hadoop/hdfs/lib/commons-logging-1.1.3.jar:/opt/yarn/hadoop/share/hadoop/hdfs/lib/asm-3.2.jar:/opt/yarn/hadoop/share/hadoop/hdfs/lib/xml-apis-1.3.04.jar:/opt/yarn/hadoop/share/hadoop/hdfs/lib/netty-all-4.0.23.Final.jar:/opt/yarn/hadoop/share/hadoop/hdfs/lib/commons-io-2.4.jar:/opt/yarn/hadoop/share/hadoop/hdfs/lib/htrace-core-3.1.0-incubating.jar:/opt/yarn/hadoop/share/hadoop/hdfs/lib/xmlenc-0.52.jar:/opt/yarn/hadoop/share/hadoop/hdfs/lib/jersey-server-1.9.jar:/opt/yarn/hadoop/share/hadoop/hdfs/lib/jersey-core-1.9.jar:/opt/yarn/hadoop/share/hadoop/hdfs/lib/jackson-core-asl-1.9.13.jar:/opt/yarn/hadoop/share/hadoop/hdfs/lib/guava-11.0.2.jar:/opt/yarn/hadoop/share/hadoop/hdfs/hadoop-hdfs-nfs-2.7.3.jar:/opt/yarn/hadoop/share/hadoop/hdfs/hadoop-hdfs-2.7.3-tests.jar:/opt/yarn/hadoop/share/hadoop/hdfs/hadoop-hdfs-2.7.3.jar:/opt/yarn/hadoop/share/hadoop/yarn/lib/commons-codec-1.4.jar:/opt/yarn/hadoop/share/hadoop/yarn/lib/jetty-6.1.26.jar:/opt/yarn/hadoop/share/hadoop/yarn/lib/leveldbjni-all-1.8.jar:/opt/yarn/hadoop/share/hadoop/yarn/lib/jsr305-3.0.0.jar:/opt/yarn/hadoop/share/hadoop/yarn/lib/servlet-api-2.5.jar:/opt/yarn/hadoop/share/hadoop/yarn/lib/guice-3.0.jar:/opt/yarn/hadoop/share/hadoop/yarn/lib/jackson-xc-1.9.13.jar:/opt/yarn/hadoop/share/hadoop/yarn/lib/jersey-client-1.9.jar:/opt/yarn/hadoop/share/hadoop/yarn/lib/xz-1.0.jar:/opt/yarn/hadoop/share/hadoop/yarn/lib/commons-collections-3.2.2.jar:/opt/yarn/hadoop/share/hadoop/yarn/lib/commons-lang-2.6.jar:/opt/yarn/hadoop/share/hadoop/yarn/lib/jackson-mapper-asl-1.9.13.jar:/opt/yarn/hadoop/share/hadoop/yarn/lib/jackson-jaxrs-1.9.13.jar:/opt/yarn/hadoop/share/hadoop/yarn/lib/guice-servlet-3.0.jar:/opt/yarn/hadoop/share/hadoop/yarn/lib/jersey-json-1.9.jar:/opt/yarn/hadoop/share/hadoop/yarn/lib/jaxb-api-2.2.2.jar:/opt/yarn/hadoop/share/hadoop/yarn/lib/log4j-1.2.17.jar:/opt/yarn/hadoop/share/hadoop/yarn/lib/protobuf-java-2.5.0.jar:/opt/yarn/hadoop/share/hadoop/yarn/lib/stax-api-1.0-2.jar:/opt/yarn/hadoop/share/hadoop/yarn/lib/jetty-util-6.1.26.jar:/opt/yarn/hadoop/share/hadoop/yarn/lib/netty-3.6.2.Final.jar:/opt/yarn/hadoop/share/hadoop/yarn/lib/commons-cli-1.2.jar:/opt/yarn/hadoop/share/hadoop/yarn/lib/commons-logging-1.1.3.jar:/opt/yarn/hadoop/share/hadoop/yarn/lib/zookeeper-3.4.6.jar:/opt/yarn/hadoop/share/hadoop/yarn/lib/asm-3.2.jar:/opt/yarn/hadoop/share/hadoop/yarn/lib/commons-io-2.4.jar:/opt/yarn/hadoop/share/hadoop/yarn/lib/javax.inject-1.jar:/opt/yarn/hadoop/share/hadoop/yarn/lib/activation-1.1.jar:/opt/yarn/hadoop/share/hadoop/yarn/lib/commons-compress-1.4.1.jar:/opt/yarn/hadoop/share/hadoop/yarn/lib/aopalliance-1.0.jar:/opt/yarn/hadoop/share/hadoop/yarn/lib/jersey-server-1.9.jar:/opt/yarn/hadoop/share/hadoop/yarn/lib/jettison-1.1.jar:/opt/yarn/hadoop/share/hadoop/yarn/lib/jersey-core-1.9.jar:/opt/yarn/hadoop/share/hadoop/yarn/lib/zookeeper-3.4.6-tests.jar:/opt/yarn/hadoop/share/hadoop/yarn/lib/jaxb-impl-2.2.3-1.jar:/opt/yarn/hadoop/share/hadoop/yarn/lib/jackson-core-asl-1.9.13.jar:/opt/yarn/hadoop/
share/hadoop/yarn/lib/jersey-guice-1.9.jar:/opt/yarn/hadoop/share/hadoop/yarn/lib/guava-11.0.2.jar:/opt/yarn/hadoop/share/hadoop/yarn/hadoop-yarn-server-nodemanager-2.7.3.jar:/opt/yarn/hadoop/share/hadoop/yarn/hadoop-yarn-server-tests-2.7.3.jar:/opt/yarn/hadoop/share/hadoop/yarn/hadoop-yarn-applications-distributedshell-2.7.3.jar:/opt/yarn/hadoop/share/hadoop/yarn/hadoop-yarn-registry-2.7.3.jar:/opt/yarn/hadoop/share/hadoop/yarn/hadoop-yarn-server-sharedcachemanager-2.7.3.jar:/opt/yarn/hadoop/share/hadoop/yarn/hadoop-yarn-applications-unmanaged-am-launcher-2.7.3.jar:/opt/yarn/hadoop/share/hadoop/yarn/hadoop-yarn-client-2.7.3.jar:/opt/yarn/hadoop/share/hadoop/yarn/hadoop-yarn-server-applicationhistoryservice-2.7.3.jar:/opt/yarn/hadoop/share/hadoop/yarn/hadoop-yarn-common-2.7.3.jar:/opt/yarn/hadoop/share/hadoop/yarn/hadoop-yarn-api-2.7.3.jar:/opt/yarn/hadoop/share/hadoop/yarn/hadoop-yarn-server-common-2.7.3.jar:/opt/yarn/hadoop/share/hadoop/yarn/hadoop-yarn-server-web-proxy-2.7.3.jar:/opt/yarn/hadoop/share/hadoop/yarn/hadoop-yarn-server-resourcemanager-2.7.3.jar:/opt/yarn/hadoop/share/hadoop/mapreduce/lib/junit-4.11.jar:/opt/yarn/hadoop/share/hadoop/mapreduce/lib/leveldbjni-all-1.8.jar:/opt/yarn/hadoop/share/hadoop/mapreduce/lib/guice-3.0.jar:/opt/yarn/hadoop/share/hadoop/mapreduce/lib/xz-1.0.jar:/opt/yarn/hadoop/share/hadoop/mapreduce/lib/jackson-mapper-asl-1.9.13.jar:/opt/yarn/hadoop/share/hadoop/mapreduce/lib/paranamer-2.3.jar:/opt/yarn/hadoop/share/hadoop/mapreduce/lib/guice-servlet-3.0.jar:/opt/yarn/hadoop/share/hadoop/mapreduce/lib/log4j-1.2.17.jar:/opt/yarn/hadoop/share/hadoop/mapreduce/lib/protobuf-java-2.5.0.jar:/opt/yarn/hadoop/share/hadoop/mapreduce/lib/netty-3.6.2.Final.jar:/opt/yarn/hadoop/share/hadoop/mapreduce/lib/snappy-java-1.0.4.1.jar:/opt/yarn/hadoop/share/hadoop/mapreduce/lib/asm-3.2.jar:/opt/yarn/hadoop/share/hadoop/mapreduce/lib/hadoop-annotations-2.7.3.jar:/opt/yarn/hadoop/share/hadoop/mapreduce/lib/hamcrest-core-1.3.jar:/opt/yarn/hadoop/share/hadoop/mapreduce/lib/commons-io-2.4.jar:/opt/yarn/hadoop/share/hadoop/mapreduce/lib/javax.inject-1.jar:/opt/yarn/hadoop/share/hadoop/mapreduce/lib/commons-compress-1.4.1.jar:/opt/yarn/hadoop/share/hadoop/mapreduce/lib/aopalliance-1.0.jar:/opt/yarn/hadoop/share/hadoop/mapreduce/lib/avro-1.7.4.jar:/opt/yarn/hadoop/share/hadoop/mapreduce/lib/jersey-server-1.9.jar:/opt/yarn/hadoop/share/hadoop/mapreduce/lib/jersey-core-1.9.jar:/opt/yarn/hadoop/share/hadoop/mapreduce/lib/jackson-core-asl-1.9.13.jar:/opt/yarn/hadoop/share/hadoop/mapreduce/lib/jersey-guice-1.9.jar:/opt/yarn/hadoop/share/hadoop/mapreduce/hadoop-mapreduce-client-jobclient-2.7.3.jar:/opt/yarn/hadoop/share/hadoop/mapreduce/hadoop-mapreduce-client-hs-plugins-2.7.3.jar:/opt/yarn/hadoop/share/hadoop/mapreduce/hadoop-mapreduce-client-app-2.7.3.jar:/opt/yarn/hadoop/share/hadoop/mapreduce/hadoop-mapreduce-client-common-2.7.3.jar:/opt/yarn/hadoop/share/hadoop/mapreduce/hadoop-mapreduce-client-jobclient-2.7.3-tests.jar:/opt/yarn/hadoop/share/hadoop/mapreduce/hadoop-mapreduce-client-hs-2.7.3.jar:/opt/yarn/hadoop/share/hadoop/mapreduce/hadoop-mapreduce-client-core-2.7.3.jar:/opt/yarn/hadoop/share/hadoop/mapreduce/hadoop-mapreduce-client-shuffle-2.7.3.jar:/opt/yarn/hadoop/share/hadoop/mapreduce/hadoop-mapreduce-examples-2.7.3.jar:/opt/yarn/hadoop/etc/hadoop:/opt/yarn/hadoop/share/hadoop/common/lib/curator-framework-2.7.1.jar:/opt/yarn/hadoop/share/hadoop/common/lib/junit-4.11.jar:/opt/yarn/hadoop/share/hadoop/common/lib/commons-codec-1.4.jar:/opt/yarn/hadoop/share/hadoop/common/lib/jetty-6.1.26.jar:/opt/yarn/hadoop/share/hadoop/common/lib/java-xmlbuilder-0.4.jar:/opt/yarn/hadoop/share/hadoop/common/lib/hadoop-auth-2.7.3.jar:/opt/yarn/hadoop/share/hadoop/common/lib/mockito-all-1.8.5.jar:/opt/yarn/hadoop/share/hadoop/common/lib/curator-recipes-2.7.1.jar:/opt/yarn/hadoop/share/hadoop/common/lib/jsr305-3.0.0.jar:/opt/yarn/hadoop/share/hadoop/common/lib/httpclient-4.2.5.jar:/opt/yarn/hadoop/share/hadoop/common/lib/api-asn1-api-1.0.0-M20.jar:/opt/yarn/hadoop/share/hadoop/common/lib/servlet-api-2.5.jar:/opt/yarn/hadoop/
share/hadoop/common/lib/commons-configuration-1.6.jar:/opt/yarn/hadoop/share/hadoop/common/lib/jsch-0.1.42.jar:/opt/yarn/hadoop/share/hadoop/common/lib/jsp-api-2.1.jar:/opt/yarn/hadoop/share/hadoop/common/lib/jackson-xc-1.9.13.jar:/opt/yarn/hadoop/share/hadoop/common/lib/curator-client-2.7.1.jar:/opt/yarn/hadoop/share/hadoop/common/lib/xz-1.0.jar:/opt/yarn/hadoop/share/hadoop/common/lib/commons-collections-3.2.2.jar:/opt/yarn/hadoop/share/hadoop/common/lib/commons-lang-2.6.jar:/opt/yarn/hadoop/share/hadoop/common/lib/jackson-mapper-asl-1.9.13.jar:/opt/yarn/hadoop/share/hadoop/common/lib/jackson-jaxrs-1.9.13.jar:/opt/yarn/hadoop/share/hadoop/common/lib/apacheds-i18n-2.0.0-M15.jar:/opt/yarn/hadoop/share/hadoop/common/lib/paranamer-2.3.jar:/opt/yarn/hadoop/share/hadoop/common/lib/jersey-json-1.9.jar:/opt/yarn/hadoop/share/hadoop/common/lib/jaxb-api-2.2.2.jar:/opt/yarn/hadoop/share/hadoop/common/lib/log4j-1.2.17.jar:/opt/yarn/hadoop/share/hadoop/common/lib/protobuf-java-2.5.0.jar:/opt/yarn/hadoop/share/hadoop/common/lib/stax-api-1.0-2.jar:/opt/yarn/hadoop/share/hadoop/common/lib/jetty-util-6.1.26.jar:/opt/yarn/hadoop/share/hadoop/common/lib/commons-httpclient-3.1.jar:/opt/yarn/hadoop/share/hadoop/common/lib/netty-3.6.2.Final.jar:/opt/yarn/hadoop/share/hadoop/common/lib/snappy-java-1.0.4.1.jar:/opt/yarn/hadoop/share/hadoop/common/lib/commons-cli-1.2.jar:/opt/yarn/hadoop/share/hadoop/common/lib/commons-beanutils-1.7.0.jar:/opt/yarn/hadoop/share/hadoop/common/lib/gson-2.2.4.jar:/opt/yarn/hadoop/share/hadoop/common/lib/commons-logging-1.1.3.jar:/opt/yarn/hadoop/share/hadoop/common/lib/zookeeper-3.4.6.jar:/opt/yarn/hadoop/share/hadoop/common/lib/asm-3.2.jar:/opt/yarn/hadoop/share/hadoop/common/lib/hadoop-annotations-2.7.3.jar:/opt/yarn/hadoop/share/hadoop/common/lib/hamcrest-core-1.3.jar:/opt/yarn/hadoop/share/hadoop/common/lib/slf4j-log4j12-1.7.10.jar:/opt/yarn/hadoop/share/hadoop/common/lib/commons-io-2.4.jar:/opt/yarn/hadoop/share/hadoop/common/lib/activation-1.1.jar:/opt/yarn/hadoop/share/hadoop/common/lib/commons-net-3.1.jar:/opt/yarn/hadoop/share/hadoop/common/lib/htrace-core-3.1.0-incubating.jar:/opt/yarn/hadoop/share/hadoop/common/lib/commons-compress-1.4.1.jar:/opt/yarn/hadoop/share/hadoop/common/lib/avro-1.7.4.jar:/opt/yarn/hadoop/share/hadoop/common/lib/commons-digester-1.8.jar:/opt/yarn/hadoop/share/hadoop/common/lib/httpcore-4.2.5.jar:/opt/yarn/hadoop/share/hadoop/common/lib/xmlenc-0.52.jar:/opt/yarn/hadoop/share/hadoop/common/lib/jets3t-0.9.0.jar:/opt/yarn/hadoop/share/hadoop/common/lib/commons-beanutils-core-1.8.0.jar:/opt/yarn/hadoop/share/hadoop/common/lib/slf4j-api-1.7.10.jar:/opt/yarn/hadoop/share/hadoop/common/lib/apacheds-kerberos-codec-2.0.0-M15.jar:/opt/yarn/hadoop/share/hadoop/common/lib/jersey-server-1.9.jar:/opt/yarn/hadoop/share/hadoop/common/lib/jettison-1.1.jar:/opt/yarn/hadoop/share/hadoop/common/lib/jersey-core-1.9.jar:/opt/yarn/hadoop/share/hadoop/common/lib/jaxb-impl-2.2.3-1.jar:/opt/yarn/hadoop/share/hadoop/common/lib/api-util-1.0.0-M20.jar:/opt/yarn/hadoop/share/hadoop/common/lib/commons-math3-3.1.1.jar:/opt/yarn/hadoop/share/hadoop/common/lib/jackson-core-asl-1.9.13.jar:/opt/yarn/hadoop/share/hadoop/common/lib/guava-11.0.2.jar:/opt/yarn/hadoop/share/hadoop/common/hadoop-nfs-2.7.3.jar:/opt/yarn/hadoop/share/hadoop/common/hadoop-common-2.7.3.jar:/opt/yarn/hadoop/share/hadoop/common/hadoop-common-2.7.3-tests.jar:/opt/yarn/hadoop/share/hadoop/hdfs:/opt/yarn/hadoop/share/hadoop/hdfs/lib/commons-codec-1.4.jar:/opt/yarn/hadoop/share/hadoop/hdfs/lib/jetty-6.1.26.jar:/opt/yarn/hadoop/share/hadoop/hdfs/lib/commons-daemon-1.0.13.jar:/opt/yarn/hadoop/share/hadoop/hdfs/lib/leveldbjni-all-1.8.jar:/opt/yarn/hadoop/share/hadoop/hdfs/lib/jsr305-3.0.0.jar:/opt/yarn/hadoop/share/hadoop/hdfs/lib/servlet-api-2.5.jar:/opt/yarn/hadoop/share/hadoop/hdfs/lib/commons-lang-2.6.jar:/opt/yarn/hadoop/share/hadoop/hdfs/lib/jackson-mapper-asl-1.9.13.jar:/opt/yarn/hadoop/share/hadoop/hdfs/lib/log4j-1.2.17.jar:/opt/yarn/hadoop/share/hadoop/hdfs/lib/protobuf-java-2.5.0.jar:/opt/yarn/hadoop/share/hadoop/hdfs/lib/jetty-util-6.1.
26.jar:/opt/yarn/hadoop/share/hadoop/hdfs/lib/netty-3.6.2.Final.jar:/opt/yarn/hadoop/share/hadoop/hdfs/lib/xercesImpl-2.9.1.jar:/opt/yarn/hadoop/share/hadoop/hdfs/lib/commons-cli-1.2.jar:/opt/yarn/hadoop/share/hadoop/hdfs/lib/commons-logging-1.1.3.jar:/opt/yarn/hadoop/share/hadoop/hdfs/lib/asm-3.2.jar:/opt/yarn/hadoop/share/hadoop/hdfs/lib/xml-apis-1.3.04.jar:/opt/yarn/hadoop/share/hadoop/hdfs/lib/netty-all-4.0.23.Final.jar:/opt/yarn/hadoop/share/hadoop/hdfs/lib/commons-io-2.4.jar:/opt/yarn/hadoop/share/hadoop/hdfs/lib/htrace-core-3.1.0-incubating.jar:/opt/yarn/hadoop/share/hadoop/hdfs/lib/xmlenc-0.52.jar:/opt/yarn/hadoop/share/hadoop/hdfs/lib/jersey-server-1.9.jar:/opt/yarn/hadoop/share/hadoop/hdfs/lib/jersey-core-1.9.jar:/opt/yarn/hadoop/share/hadoop/hdfs/lib/jackson-core-asl-1.9.13.jar:/opt/yarn/hadoop/share/hadoop/hdfs/lib/guava-11.0.2.jar:/opt/yarn/hadoop/share/hadoop/hdfs/hadoop-hdfs-nfs-2.7.3.jar:/opt/yarn/hadoop/share/hadoop/hdfs/hadoop-hdfs-2.7.3-tests.jar:/opt/yarn/hadoop/share/hadoop/hdfs/hadoop-hdfs-2.7.3.jar:/opt/yarn/hadoop/share/hadoop/yarn/lib/commons-codec-1.4.jar:/opt/yarn/hadoop/share/hadoop/yarn/lib/jetty-6.1.26.jar:/opt/yarn/hadoop/share/hadoop/yarn/lib/leveldbjni-all-1.8.jar:/opt/yarn/hadoop/share/hadoop/yarn/lib/jsr305-3.0.0.jar:/opt/yarn/hadoop/share/hadoop/yarn/lib/servlet-api-2.5.jar:/opt/yarn/hadoop/share/hadoop/yarn/lib/guice-3.0.jar:/opt/yarn/hadoop/share/hadoop/yarn/lib/jackson-xc-1.9.13.jar:/opt/yarn/hadoop/share/hadoop/yarn/lib/jersey-client-1.9.jar:/opt/yarn/hadoop/share/hadoop/yarn/lib/xz-1.0.jar:/opt/yarn/hadoop/share/hadoop/yarn/lib/commons-collections-3.2.2.jar:/opt/yarn/hadoop/share/hadoop/yarn/lib/commons-lang-2.6.jar:/opt/yarn/hadoop/share/hadoop/yarn/lib/jackson-mapper-asl-1.9.13.jar:/opt/yarn/hadoop/share/hadoop/yarn/lib/jackson-jaxrs-1.9.13.jar:/opt/yarn/hadoop/share/hadoop/yarn/lib/guice-servlet-3.0.jar:/opt/yarn/hadoop/share/hadoop/yarn/lib/jersey-json-1.9.jar:/opt/yarn/hadoop/share/hadoop/yarn/lib/jaxb-api-2.2.2.jar:/opt/yarn/hadoop/share/hadoop/yarn/lib/log4j-1.2.17.jar:/opt/yarn/hadoop/share/hadoop/yarn/lib/protobuf-java-2.5.0.jar:/opt/yarn/hadoop/share/hadoop/yarn/lib/stax-api-1.0-2.jar:/opt/yarn/hadoop/share/hadoop/yarn/lib/jetty-util-6.1.26.jar:/opt/yarn/hadoop/share/hadoop/yarn/lib/netty-3.6.2.Final.jar:/opt/yarn/hadoop/share/hadoop/yarn/lib/commons-cli-1.2.jar:/opt/yarn/hadoop/share/hadoop/yarn/lib/commons-logging-1.1.3.jar:/opt/yarn/hadoop/share/hadoop/yarn/lib/zookeeper-3.4.6.jar:/opt/yarn/hadoop/share/hadoop/yarn/lib/asm-3.2.jar:/opt/yarn/hadoop/share/hadoop/yarn/lib/commons-io-2.4.jar:/opt/yarn/hadoop/share/hadoop/yarn/lib/javax.inject-1.jar:/opt/yarn/hadoop/share/hadoop/yarn/lib/activation-1.1.jar:/opt/yarn/hadoop/share/hadoop/yarn/lib/commons-compress-1.4.1.jar:/opt/yarn/hadoop/share/hadoop/yarn/lib/aopalliance-1.0.jar:/opt/yarn/hadoop/share/hadoop/yarn/lib/jersey-server-1.9.jar:/opt/yarn/hadoop/share/hadoop/yarn/lib/jettison-1.1.jar:/opt/yarn/hadoop/share/hadoop/yarn/lib/jersey-core-1.9.jar:/opt/yarn/hadoop/share/hadoop/yarn/lib/zookeeper-3.4.6-tests.jar:/opt/yarn/hadoop/share/hadoop/yarn/lib/jaxb-impl-2.2.3-1.jar:/opt/yarn/hadoop/share/hadoop/yarn/lib/jackson-core-asl-1.9.13.jar:/opt/yarn/hadoop/share/hadoop/yarn/lib/jersey-guice-1.9.jar:/opt/yarn/hadoop/share/hadoop/yarn/lib/guava-11.0.2.jar:/opt/yarn/hadoop/share/hadoop/yarn/hadoop-yarn-server-nodemanager-2.7.3.jar:/opt/yarn/hadoop/share/hadoop/yarn/hadoop-yarn-server-tests-2.7.3.jar:/opt/yarn/hadoop/share/hadoop/yarn/hadoop-yarn-applications-distributedshell-2.7.3.jar:/opt/yarn/hadoop/share/hadoop/yarn/hadoop-yarn-registry-2.7.3.jar:/opt/yarn/hadoop/share/hadoop/yarn/hadoop-yarn-server-sharedcachemanager-2.7.3.jar:/opt/yarn/hadoop/share/hadoop/yarn/hadoop-yarn-applications-unmanaged-am-launcher-2.7.3.jar:/opt/yarn/hadoop/share/hadoop/yarn/hadoop-yarn-client-2.7.3.jar:/opt/yarn/hadoop/share/hadoop/yarn/hadoop-yarn-server-applicationhistoryservice-2.7.3.jar:/opt/yarn/hadoop/share/hadoop/yarn/hadoop-yarn-common-2.7.3.jar:/opt/yarn/hadoop/share/hadoop/yarn/hadoop-yarn-api-2.7.3.jar:/opt/yarn/hadoop/share/hadoop/
yarn/hadoop-yarn-server-common-2.7.3.jar:/opt/yarn/hadoop/share/hadoop/yarn/hadoop-yarn-server-web-proxy-2.7.3.jar:/opt/yarn/hadoop/share/hadoop/yarn/hadoop-yarn-server-resourcemanager-2.7.3.jar:/opt/yarn/hadoop/share/hadoop/mapreduce/lib/junit-4.11.jar:/opt/yarn/hadoop/share/hadoop/mapreduce/lib/leveldbjni-all-1.8.jar:/opt/yarn/hadoop/share/hadoop/mapreduce/lib/guice-3.0.jar:/opt/yarn/hadoop/share/hadoop/mapreduce/lib/xz-1.0.jar:/opt/yarn/hadoop/share/hadoop/mapreduce/lib/jackson-mapper-asl-1.9.13.jar:/opt/yarn/hadoop/share/hadoop/mapreduce/lib/paranamer-2.3.jar:/opt/yarn/hadoop/share/hadoop/mapreduce/lib/guice-servlet-3.0.jar:/opt/yarn/hadoop/share/hadoop/mapreduce/lib/log4j-1.2.17.jar:/opt/yarn/hadoop/share/hadoop/mapreduce/lib/protobuf-java-2.5.0.jar:/opt/yarn/hadoop/share/hadoop/mapreduce/lib/netty-3.6.2.Final.jar:/opt/yarn/hadoop/share/hadoop/mapreduce/lib/snappy-java-1.0.4.1.jar:/opt/yarn/hadoop/share/hadoop/mapreduce/lib/asm-3.2.jar:/opt/yarn/hadoop/share/hadoop/mapreduce/lib/hadoop-annotations-2.7.3.jar:/opt/yarn/hadoop/share/hadoop/mapreduce/lib/hamcrest-core-1.3.jar:/opt/yarn/hadoop/share/hadoop/mapreduce/lib/commons-io-2.4.jar:/opt/yarn/hadoop/share/hadoop/mapreduce/lib/javax.inject-1.jar:/opt/yarn/hadoop/share/hadoop/mapreduce/lib/commons-compress-1.4.1.jar:/opt/yarn/hadoop/share/hadoop/mapreduce/lib/aopalliance-1.0.jar:/opt/yarn/hadoop/share/hadoop/mapreduce/lib/avro-1.7.4.jar:/opt/yarn/hadoop/share/hadoop/mapreduce/lib/jersey-server-1.9.jar:/opt/yarn/hadoop/share/hadoop/mapreduce/lib/jersey-core-1.9.jar:/opt/yarn/hadoop/share/hadoop/mapreduce/lib/jackson-core-asl-1.9.13.jar:/opt/yarn/hadoop/share/hadoop/mapreduce/lib/jersey-guice-1.9.jar:/opt/yarn/hadoop/share/hadoop/mapreduce/hadoop-mapreduce-client-jobclient-2.7.3.jar:/opt/yarn/hadoop/share/hadoop/mapreduce/hadoop-mapreduce-client-hs-plugins-2.7.3.jar:/opt/yarn/hadoop/share/hadoop/mapreduce/hadoop-mapreduce-client-app-2.7.3.jar:/opt/yarn/hadoop/share/hadoop/mapreduce/hadoop-mapreduce-client-common-2.7.3.jar:/opt/yarn/hadoop/share/hadoop/mapreduce/hadoop-mapreduce-client-jobclient-2.7.3-tests.jar:/opt/yarn/hadoop/share/hadoop/mapreduce/hadoop-mapreduce-client-hs-2.7.3.jar:/opt/yarn/hadoop/share/hadoop/mapreduce/hadoop-mapreduce-client-core-2.7.3.jar:/opt/yarn/hadoop/share/hadoop/mapreduce/hadoop-mapreduce-client-shuffle-2.7.3.jar:/opt/yarn/hadoop/share/hadoop/mapreduce/hadoop-mapreduce-examples-2.7.3.jar:/contrib/capacity-scheduler/*.jar:.:/contrib/capacity-scheduler/*.jar:/contrib/capacity-scheduler/*.jar:/opt/yarn/hadoop/share/hadoop/yarn/hadoop-yarn-server-nodemanager-2.7.3.jar:/opt/yarn/hadoop/share/hadoop/yarn/hadoop-yarn-server-tests-2.7.3.jar:/opt/yarn/hadoop/share/hadoop/yarn/hadoop-yarn-applications-distributedshell-2.7.3.jar:/opt/yarn/hadoop/share/hadoop/yarn/hadoop-yarn-registry-2.7.3.jar:/opt/yarn/hadoop/share/hadoop/yarn/hadoop-yarn-server-sharedcachemanager-2.7.3.jar:/opt/yarn/hadoop/share/hadoop/yarn/hadoop-yarn-applications-unmanaged-am-launcher-2.7.3.jar:/opt/yarn/hadoop/share/hadoop/yarn/hadoop-yarn-client-2.7.3.jar:/opt/yarn/hadoop/share/hadoop/yarn/hadoop-yarn-server-applicationhistoryservice-2.7.3.jar:/opt/yarn/hadoop/share/hadoop/yarn/hadoop-yarn-common-2.7.3.jar:/opt/yarn/hadoop/share/hadoop/yarn/hadoop-yarn-api-2.7.3.jar:/opt/yarn/hadoop/share/hadoop/yarn/hadoop-yarn-server-common-2.7.3.jar:/opt/yarn/hadoop/share/hadoop/yarn/hadoop-yarn-server-web-proxy-2.7.3.jar:/opt/yarn/hadoop/share/hadoop/yarn/hadoop-yarn-server-resourcemanager-2.7.3.jar:/opt/yarn/hadoop/share/hadoop/yarn/lib/commons-codec-1.4.jar:/opt/yarn/hadoop/share/hadoop/yarn/lib/jetty-6.1.26.jar:/opt/yarn/hadoop/share/hadoop/yarn/lib/leveldbjni-all-1.8.jar:/opt/yarn/hadoop/share/hadoop/yarn/lib/jsr305-3.0.0.jar:/opt/yarn/hadoop/share/hadoop/yarn/lib/servlet-api-2.5.jar:/opt/yarn/hadoop/share/hadoop/yarn/lib/guice-3.0.jar:/opt/yarn/hadoop/share/hadoop/yarn/lib/jackson-xc-1.9.13.jar:/opt/yarn/hadoop/share/hadoop/yarn/lib/jersey-client-1.9.jar:/opt/yarn/hadoop/share/hadoop/yarn/lib/xz-1.0.jar:/opt/yarn/hadoop/share/hadoop/yarn/lib/commons-collections-3.2.2.jar:/opt/yarn/
hadoop/share/hadoop/yarn/lib/commons-lang-2.6.jar:/opt/yarn/hadoop/share/hadoop/yarn/lib/jackson-mapper-asl-1.9.13.jar:/opt/yarn/hadoop/share/hadoop/yarn/lib/jackson-jaxrs-1.9.13.jar:/opt/yarn/hadoop/share/hadoop/yarn/lib/guice-servlet-3.0.jar:/opt/yarn/hadoop/share/hadoop/yarn/lib/jersey-json-1.9.jar:/opt/yarn/hadoop/share/hadoop/yarn/lib/jaxb-api-2.2.2.jar:/opt/yarn/hadoop/share/hadoop/yarn/lib/log4j-1.2.17.jar:/opt/yarn/hadoop/share/hadoop/yarn/lib/protobuf-java-2.5.0.jar:/opt/yarn/hadoop/share/hadoop/yarn/lib/stax-api-1.0-2.jar:/opt/yarn/hadoop/share/hadoop/yarn/lib/jetty-util-6.1.26.jar:/opt/yarn/hadoop/share/hadoop/yarn/lib/netty-3.6.2.Final.jar:/opt/yarn/hadoop/share/hadoop/yarn/lib/commons-cli-1.2.jar:/opt/yarn/hadoop/share/hadoop/yarn/lib/commons-logging-1.1.3.jar:/opt/yarn/hadoop/share/hadoop/yarn/lib/zookeeper-3.4.6.jar:/opt/yarn/hadoop/share/hadoop/yarn/lib/asm-3.2.jar:/opt/yarn/hadoop/share/hadoop/yarn/lib/commons-io-2.4.jar:/opt/yarn/hadoop/share/hadoop/yarn/lib/javax.inject-1.jar:/opt/yarn/hadoop/share/hadoop/yarn/lib/activation-1.1.jar:/opt/yarn/hadoop/share/hadoop/yarn/lib/commons-compress-1.4.1.jar:/opt/yarn/hadoop/share/hadoop/yarn/lib/aopalliance-1.0.jar:/opt/yarn/hadoop/share/hadoop/yarn/lib/jersey-server-1.9.jar:/opt/yarn/hadoop/share/hadoop/yarn/lib/jettison-1.1.jar:/opt/yarn/hadoop/share/hadoop/yarn/lib/jersey-core-1.9.jar:/opt/yarn/hadoop/share/hadoop/yarn/lib/zookeeper-3.4.6-tests.jar:/opt/yarn/hadoop/share/hadoop/yarn/lib/jaxb-impl-2.2.3-1.jar:/opt/yarn/hadoop/share/hadoop/yarn/lib/jackson-core-asl-1.9.13.jar:/opt/yarn/hadoop/share/hadoop/yarn/lib/jersey-guice-1.9.jar:/opt/yarn/hadoop/share/hadoop/yarn/lib/guava-11.0.2.jar:/opt/yarn/hadoop/etc/hadoop/rm-config/log4j.properties
STARTUP_MSG:   build = https://git-wip-us.apache.org/repos/asf/hadoop.git -r baa91f7c6bc9cb92be5982de4719c1c8af91ccff; compiled by 'root' on 2016-08-18T01:41Z
STARTUP_MSG:   java = 1.8.0_102
************************************************************/
2016-12-02 23:02:54,375 INFO org.apache.hadoop.yarn.server.resourcemanager.ResourceManager: registered UNIX signal handlers for [TERM, HUP, INT]
2016-12-02 23:02:55,563 INFO org.apache.hadoop.conf.Configuration: found resource core-site.xml at file:/opt/yarn/hadoop-2.7.3/etc/hadoop/core-site.xml
2016-12-02 23:02:55,685 WARN org.apache.hadoop.conf.Configuration: java.io.BufferedInputStream@2df32bf7:an attempt to override final parameter: fs.defaultFS;  Ignoring.
2016-12-02 23:02:55,685 WARN org.apache.hadoop.conf.Configuration: java.io.BufferedInputStream@2df32bf7:an attempt to override final parameter: hadoop.tmp.dir;  Ignoring.
2016-12-02 23:02:55,685 WARN org.apache.hadoop.conf.Configuration: java.io.BufferedInputStream@2df32bf7:an attempt to override final parameter: hadoop.http.staticuser.user;  Ignoring.
2016-12-02 23:02:55,780 INFO org.apache.hadoop.security.Groups: clearing userToGroupsMap cache
2016-12-02 23:02:55,960 INFO org.apache.hadoop.conf.Configuration: found resource yarn-site.xml at file:/opt/yarn/hadoop-2.7.3/etc/hadoop/yarn-site.xml
2016-12-02 23:02:56,012 WARN org.apache.hadoop.conf.Configuration: java.io.BufferedInputStream@6ab7a896:an attempt to override final parameter: yarn.resourcemanager.hostname;  Ignoring.
2016-12-02 23:02:56,012 WARN org.apache.hadoop.conf.Configuration: java.io.BufferedInputStream@6ab7a896:an attempt to override final parameter: yarn.nodemanager.aux-services;  Ignoring.
2016-12-02 23:02:56,012 WARN org.apache.hadoop.conf.Configuration: java.io.BufferedInputStream@6ab7a896:an attempt to override final parameter: yarn.nodemanager.aux-services.mapreduce_shuffle.class;  Ignoring.
2016-12-02 23:02:56,012 WARN org.apache.hadoop.conf.Configuration: java.io.BufferedInputStream@6ab7a896:an attempt to override final parameter: yarn.nodemanager.resource.cpu-vcores;  Ignoring.
2016-12-02 23:02:56,012 WARN org.apache.hadoop.conf.Configuration: java.io.BufferedInputStream@6ab7a896:an attempt to override final parameter: yarn.nodemanager.resource.memory-mb;  Ignoring.
2016-12-02 23:02:56,012 WARN org.apache.hadoop.conf.Configuration: java.io.BufferedInputStream@6ab7a896:an attempt to override final parameter: yarn.nodemanager.vmem-pmem-ratio;  Ignoring.
2016-12-02 23:02:56,012 WARN org.apache.hadoop.conf.Configuration: java.io.BufferedInputStream@6ab7a896:an attempt to override final parameter: yarn.scheduler.maximum-allocation-vcores;  Ignoring.
2016-12-02 23:02:56,012 WARN org.apache.hadoop.conf.Configuration: java.io.BufferedInputStream@6ab7a896:an attempt to override final parameter: yarn.scheduler.minimum-allocation-mb;  Ignoring.
2016-12-02 23:02:56,012 WARN org.apache.hadoop.conf.Configuration: java.io.BufferedInputStream@6ab7a896:an attempt to override final parameter: yarn.scheduler.maximum-allocation-mb;  Ignoring.
2016-12-02 23:02:56,655 INFO org.apache.hadoop.yarn.event.AsyncDispatcher: Registering class org.apache.hadoop.yarn.server.resourcemanager.RMFatalEventType for class org.apache.hadoop.yarn.server.resourcemanager.ResourceManager$RMFatalEventDispatcher
2016-12-02 23:02:57,022 INFO org.apache.hadoop.yarn.server.resourcemanager.security.NMTokenSecretManagerInRM: NMTokenKeyRollingInterval: 86400000ms and NMTokenKeyActivationDelay: 900000ms
2016-12-02 23:02:57,058 INFO org.apache.hadoop.yarn.server.resourcemanager.security.RMContainerTokenSecretManager: ContainerTokenKeyRollingInterval: 86400000ms and ContainerTokenKeyActivationDelay: 900000ms
2016-12-02 23:02:57,070 INFO org.apache.hadoop.yarn.server.resourcemanager.security.AMRMTokenSecretManager: AMRMTokenKeyRollingInterval: 86400000ms and AMRMTokenKeyActivationDelay: 900000 ms
2016-12-02 23:02:57,176 INFO org.apache.hadoop.yarn.event.AsyncDispatcher: Registering class org.apache.hadoop.yarn.server.resourcemanager.recovery.RMStateStoreEventType for class org.apache.hadoop.yarn.server.resourcemanager.recovery.RMStateStore$ForwardingEventHandler
2016-12-02 23:02:57,182 INFO org.apache.hadoop.yarn.event.AsyncDispatcher: Registering class org.apache.hadoop.yarn.server.resourcemanager.NodesListManagerEventType for class org.apache.hadoop.yarn.server.resourcemanager.NodesListManager
2016-12-02 23:02:57,182 INFO org.apache.hadoop.yarn.server.resourcemanager.ResourceManager: Using Scheduler: org.apache.hadoop.yarn.server.resourcemanager.scheduler.capacity.CapacityScheduler
2016-12-02 23:02:57,227 INFO org.apache.hadoop.yarn.event.AsyncDispatcher: Registering class org.apache.hadoop.yarn.server.resourcemanager.scheduler.event.SchedulerEventType for class org.apache.hadoop.yarn.server.resourcemanager.ResourceManager$SchedulerEventDispatcher
2016-12-02 23:02:57,228 INFO org.apache.hadoop.yarn.event.AsyncDispatcher: Registering class org.apache.hadoop.yarn.server.resourcemanager.rmapp.RMAppEventType for class org.apache.hadoop.yarn.server.resourcemanager.ResourceManager$ApplicationEventDispatcher
2016-12-02 23:02:57,228 INFO org.apache.hadoop.yarn.event.AsyncDispatcher: Registering class org.apache.hadoop.yarn.server.resourcemanager.rmapp.attempt.RMAppAttemptEventType for class org.apache.hadoop.yarn.server.resourcemanager.ResourceManager$ApplicationAttemptEventDispatcher
2016-12-02 23:02:57,230 INFO org.apache.hadoop.yarn.event.AsyncDispatcher: Registering class org.apache.hadoop.yarn.server.resourcemanager.rmnode.RMNodeEventType for class org.apache.hadoop.yarn.server.resourcemanager.ResourceManager$NodeEventDispatcher
2016-12-02 23:02:57,319 INFO org.apache.hadoop.metrics2.impl.MetricsConfig: loaded properties from hadoop-metrics2.properties
2016-12-02 23:02:57,403 INFO org.apache.hadoop.metrics2.impl.MetricsSystemImpl: Scheduled snapshot period at 10 second(s).
2016-12-02 23:02:57,404 INFO org.apache.hadoop.metrics2.impl.MetricsSystemImpl: ResourceManager metrics system started
2016-12-02 23:02:57,423 INFO org.apache.hadoop.yarn.event.AsyncDispatcher: Registering class org.apache.hadoop.yarn.server.resourcemanager.RMAppManagerEventType for class org.apache.hadoop.yarn.server.resourcemanager.RMAppManager
2016-12-02 23:02:57,436 INFO org.apache.hadoop.yarn.event.AsyncDispatcher: Registering class org.apache.hadoop.yarn.server.resourcemanager.amlauncher.AMLauncherEventType for class org.apache.hadoop.yarn.server.resourcemanager.amlauncher.ApplicationMasterLauncher
2016-12-02 23:02:57,438 INFO org.apache.hadoop.yarn.server.resourcemanager.RMNMInfo: Registered RMNMInfo MBean
2016-12-02 23:02:57,439 INFO org.apache.hadoop.yarn.security.YarnAuthorizationProvider: org.apache.hadoop.yarn.security.ConfiguredYarnAuthorizer is instiantiated.
2016-12-02 23:02:57,467 INFO org.apache.hadoop.util.HostsFileReader: Refreshing hosts (include/exclude) list
2016-12-02 23:02:57,490 INFO org.apache.hadoop.util.HostsFileReader: Adding datanode1 to the list of included hosts from /opt/yarn/hadoop/etc/hadoop/yarn-include
2016-12-02 23:02:57,490 INFO org.apache.hadoop.util.HostsFileReader: Adding datanode2 to the list of included hosts from /opt/yarn/hadoop/etc/hadoop/yarn-include
2016-12-02 23:02:57,490 INFO org.apache.hadoop.util.HostsFileReader: Adding datanode3 to the list of included hosts from /opt/yarn/hadoop/etc/hadoop/yarn-include
2016-12-02 23:02:57,491 INFO org.apache.hadoop.util.HostsFileReader: Adding datanode4 to the list of included hosts from /opt/yarn/hadoop/etc/hadoop/yarn-include
2016-12-02 23:02:57,492 INFO org.apache.hadoop.conf.Configuration: found resource capacity-scheduler.xml at file:/opt/yarn/hadoop-2.7.3/etc/hadoop/capacity-scheduler.xml
2016-12-02 23:02:57,580 INFO org.apache.hadoop.yarn.server.resourcemanager.scheduler.capacity.CapacitySchedulerConfiguration: max alloc mb per queue for root is undefined
2016-12-02 23:02:57,580 INFO org.apache.hadoop.yarn.server.resourcemanager.scheduler.capacity.CapacitySchedulerConfiguration: max alloc vcore per queue for root is undefined
2016-12-02 23:02:57,588 INFO org.apache.hadoop.yarn.server.resourcemanager.scheduler.capacity.ParentQueue: root, capacity=1.0, asboluteCapacity=1.0, maxCapacity=1.0, asboluteMaxCapacity=1.0, state=RUNNING, acls=SUBMIT_APP:*ADMINISTER_QUEUE:*, labels=*,
, reservationsContinueLooking=true
2016-12-02 23:02:57,588 INFO org.apache.hadoop.yarn.server.resourcemanager.scheduler.capacity.ParentQueue: Initialized parent-queue root name=root, fullname=root
2016-12-02 23:02:57,609 INFO org.apache.hadoop.yarn.server.resourcemanager.scheduler.capacity.CapacitySchedulerConfiguration: max alloc mb per queue for root.default is undefined
2016-12-02 23:02:57,609 INFO org.apache.hadoop.yarn.server.resourcemanager.scheduler.capacity.CapacitySchedulerConfiguration: max alloc vcore per queue for root.default is undefined
2016-12-02 23:02:57,610 INFO org.apache.hadoop.yarn.server.resourcemanager.scheduler.capacity.LeafQueue: Initializing default
capacity = 1.0 [= (float) configuredCapacity / 100 ]
asboluteCapacity = 1.0 [= parentAbsoluteCapacity * capacity ]
maxCapacity = 1.0 [= configuredMaxCapacity ]
absoluteMaxCapacity = 1.0 [= 1.0 maximumCapacity undefined, (parentAbsoluteMaxCapacity * maximumCapacity) / 100 otherwise ]
userLimit = 100 [= configuredUserLimit ]
userLimitFactor = 1.0 [= configuredUserLimitFactor ]
maxApplications = 10000 [= configuredMaximumSystemApplicationsPerQueue or (int)(configuredMaximumSystemApplications * absoluteCapacity)]
maxApplicationsPerUser = 10000 [= (int)(maxApplications * (userLimit / 100.0f) * userLimitFactor) ]
usedCapacity = 0.0 [= usedResourcesMemory / (clusterResourceMemory * absoluteCapacity)]
absoluteUsedCapacity = 0.0 [= usedResourcesMemory / clusterResourceMemory]
maxAMResourcePerQueuePercent = 0.1 [= configuredMaximumAMResourcePercent ]
minimumAllocationFactor = 0.6666667 [= (float)(maximumAllocationMemory - minimumAllocationMemory) / maximumAllocationMemory ]
maximumAllocation = <memory:3072, vCores:1> [= configuredMaxAllocation ]
numContainers = 0 [= currentNumContainers ]
state = RUNNING [= configuredState ]
acls = SUBMIT_APP:*ADMINISTER_QUEUE:* [= configuredAcls ]
nodeLocalityDelay = 40
labels=*,
nodeLocalityDelay = 40
reservationsContinueLooking = true
preemptionDisabled = true

2016-12-02 23:02:57,611 INFO org.apache.hadoop.yarn.server.resourcemanager.scheduler.capacity.CapacityScheduler: Initialized queue: default: capacity=1.0, absoluteCapacity=1.0, usedResources=<memory:0, vCores:0>, usedCapacity=0.0, absoluteUsedCapacity=0.0, numApps=0, numContainers=0
2016-12-02 23:02:57,611 INFO org.apache.hadoop.yarn.server.resourcemanager.scheduler.capacity.CapacityScheduler: Initialized queue: root: numChildQueue= 1, capacity=1.0, absoluteCapacity=1.0, usedResources=<memory:0, vCores:0>usedCapacity=0.0, numApps=0, numContainers=0
2016-12-02 23:02:57,611 INFO org.apache.hadoop.yarn.server.resourcemanager.scheduler.capacity.CapacityScheduler: Initialized root queue root: numChildQueue= 1, capacity=1.0, absoluteCapacity=1.0, usedResources=<memory:0, vCores:0>usedCapacity=0.0, numApps=0, numContainers=0
2016-12-02 23:02:57,611 INFO org.apache.hadoop.yarn.server.resourcemanager.scheduler.capacity.CapacityScheduler: Initialized queue mappings, override: false
2016-12-02 23:02:57,612 INFO org.apache.hadoop.yarn.server.resourcemanager.scheduler.capacity.CapacityScheduler: Initialized CapacityScheduler with calculator=class org.apache.hadoop.yarn.util.resource.DefaultResourceCalculator, minimumAllocation=<<memory:1024, vCores:1>>, maximumAllocation=<<memory:3072, vCores:1>>, asynchronousScheduling=false, asyncScheduleInterval=5ms
2016-12-02 23:02:57,694 INFO org.apache.hadoop.yarn.server.resourcemanager.metrics.SystemMetricsPublisher: YARN system metrics publishing service is not enabled
2016-12-02 23:02:57,694 INFO org.apache.hadoop.yarn.server.resourcemanager.ResourceManager: Transitioning to active state
2016-12-02 23:02:57,737 INFO org.apache.hadoop.yarn.server.resourcemanager.recovery.RMStateStore: Updating AMRMToken
2016-12-02 23:02:57,738 INFO org.apache.hadoop.yarn.server.resourcemanager.security.RMContainerTokenSecretManager: Rolling master-key for container-tokens
2016-12-02 23:02:57,738 INFO org.apache.hadoop.yarn.server.resourcemanager.security.NMTokenSecretManagerInRM: Rolling master-key for nm-tokens
2016-12-02 23:02:57,739 INFO org.apache.hadoop.security.token.delegation.AbstractDelegationTokenSecretManager: Updating the current master key for generating delegation tokens
2016-12-02 23:02:57,740 INFO org.apache.hadoop.yarn.server.resourcemanager.security.RMDelegationTokenSecretManager: storing master key with keyID 1
2016-12-02 23:02:57,740 INFO org.apache.hadoop.yarn.server.resourcemanager.recovery.RMStateStore: Storing RMDTMasterKey.
2016-12-02 23:02:57,758 INFO org.apache.hadoop.security.token.delegation.AbstractDelegationTokenSecretManager: Starting expired delegation token remover thread, tokenRemoverScanInterval=60 min(s)
2016-12-02 23:02:57,759 INFO org.apache.hadoop.security.token.delegation.AbstractDelegationTokenSecretManager: Updating the current master key for generating delegation tokens
2016-12-02 23:02:57,759 INFO org.apache.hadoop.yarn.server.resourcemanager.security.RMDelegationTokenSecretManager: storing master key with keyID 2
2016-12-02 23:02:57,759 INFO org.apache.hadoop.yarn.server.resourcemanager.recovery.RMStateStore: Storing RMDTMasterKey.
2016-12-02 23:02:57,767 INFO org.apache.hadoop.yarn.event.AsyncDispatcher: Registering class org.apache.hadoop.yarn.nodelabels.event.NodeLabelsStoreEventType for class org.apache.hadoop.yarn.nodelabels.CommonNodeLabelsManager$ForwardingEventHandler
2016-12-02 23:02:57,804 INFO org.apache.hadoop.ipc.CallQueueManager: Using callQueue class java.util.concurrent.LinkedBlockingQueue
2016-12-02 23:02:57,895 INFO org.apache.hadoop.ipc.Server: Starting Socket Reader #1 for port 8031
2016-12-02 23:02:57,948 INFO org.apache.hadoop.yarn.factories.impl.pb.RpcServerFactoryPBImpl: Adding protocol org.apache.hadoop.yarn.server.api.ResourceTrackerPB to the server
2016-12-02 23:02:57,949 INFO org.apache.hadoop.ipc.Server: IPC Server Responder: starting
2016-12-02 23:02:57,950 INFO org.apache.hadoop.ipc.Server: IPC Server listener on 8031: starting
2016-12-02 23:02:58,019 INFO org.apache.hadoop.ipc.CallQueueManager: Using callQueue class java.util.concurrent.LinkedBlockingQueue
2016-12-02 23:02:58,031 INFO org.apache.hadoop.ipc.Server: Starting Socket Reader #1 for port 8030
2016-12-02 23:02:58,089 INFO org.apache.hadoop.yarn.factories.impl.pb.RpcServerFactoryPBImpl: Adding protocol org.apache.hadoop.yarn.api.ApplicationMasterProtocolPB to the server
2016-12-02 23:02:58,094 INFO org.apache.hadoop.ipc.Server: IPC Server listener on 8030: starting
2016-12-02 23:02:58,110 INFO org.apache.hadoop.ipc.Server: IPC Server Responder: starting
2016-12-02 23:02:58,322 INFO org.apache.hadoop.ipc.CallQueueManager: Using callQueue class java.util.concurrent.LinkedBlockingQueue
2016-12-02 23:02:58,323 INFO org.apache.hadoop.ipc.Server: Starting Socket Reader #1 for port 8032
2016-12-02 23:02:58,324 INFO org.apache.hadoop.yarn.factories.impl.pb.RpcServerFactoryPBImpl: Adding protocol org.apache.hadoop.yarn.api.ApplicationClientProtocolPB to the server
2016-12-02 23:02:58,327 INFO org.apache.hadoop.ipc.Server: IPC Server Responder: starting
2016-12-02 23:02:58,327 INFO org.apache.hadoop.ipc.Server: IPC Server listener on 8032: starting
2016-12-02 23:02:58,346 INFO org.apache.hadoop.yarn.server.resourcemanager.ResourceManager: Transitioned to active state
2016-12-02 23:02:58,445 INFO org.mortbay.log: Logging to org.slf4j.impl.Log4jLoggerAdapter(org.mortbay.log) via org.mortbay.log.Slf4jLog
2016-12-02 23:02:58,451 INFO org.apache.hadoop.security.authentication.server.AuthenticationFilter: Unable to initialize FileSignerSecretProvider, falling back to use random secrets.
2016-12-02 23:02:58,456 INFO org.apache.hadoop.http.HttpRequestLog: Http request log for http.requests.resourcemanager is not defined
2016-12-02 23:02:58,463 INFO org.apache.hadoop.http.HttpServer2: Added global filter 'safety' (class=org.apache.hadoop.http.HttpServer2$QuotingInputFilter)
2016-12-02 23:02:58,467 INFO org.apache.hadoop.http.HttpServer2: Added filter RMAuthenticationFilter (class=org.apache.hadoop.yarn.server.security.http.RMAuthenticationFilter) to context cluster
2016-12-02 23:02:58,467 INFO org.apache.hadoop.http.HttpServer2: Added filter RMAuthenticationFilter (class=org.apache.hadoop.yarn.server.security.http.RMAuthenticationFilter) to context logs
2016-12-02 23:02:58,467 INFO org.apache.hadoop.http.HttpServer2: Added filter RMAuthenticationFilter (class=org.apache.hadoop.yarn.server.security.http.RMAuthenticationFilter) to context static
2016-12-02 23:02:58,468 INFO org.apache.hadoop.http.HttpServer2: Added filter static_user_filter (class=org.apache.hadoop.http.lib.StaticUserWebFilter$StaticUserFilter) to context cluster
2016-12-02 23:02:58,468 INFO org.apache.hadoop.http.HttpServer2: Added filter static_user_filter (class=org.apache.hadoop.http.lib.StaticUserWebFilter$StaticUserFilter) to context logs
2016-12-02 23:02:58,468 INFO org.apache.hadoop.http.HttpServer2: Added filter static_user_filter (class=org.apache.hadoop.http.lib.StaticUserWebFilter$StaticUserFilter) to context static
2016-12-02 23:02:58,472 INFO org.apache.hadoop.http.HttpServer2: adding path spec: /cluster/*
2016-12-02 23:02:58,472 INFO org.apache.hadoop.http.HttpServer2: adding path spec: /ws/*
2016-12-02 23:02:59,211 INFO org.apache.hadoop.yarn.webapp.WebApps: Registered webapp guice modules
2016-12-02 23:02:59,216 INFO org.apache.hadoop.http.HttpServer2: Jetty bound to port 8088
2016-12-02 23:02:59,217 INFO org.mortbay.log: jetty-6.1.26
2016-12-02 23:02:59,248 INFO org.mortbay.log: Extract jar:file:/opt/yarn/hadoop-2.7.3/share/hadoop/yarn/hadoop-yarn-common-2.7.3.jar!/webapps/cluster to /tmp/Jetty_resourcemanager_8088_cluster____.cnqfat/webapp
2016-12-02 23:02:59,575 INFO org.apache.hadoop.security.token.delegation.AbstractDelegationTokenSecretManager: Updating the current master key for generating delegation tokens
2016-12-02 23:02:59,589 INFO org.apache.hadoop.security.token.delegation.AbstractDelegationTokenSecretManager: Starting expired delegation token remover thread, tokenRemoverScanInterval=60 min(s)
2016-12-02 23:02:59,593 INFO org.apache.hadoop.security.token.delegation.AbstractDelegationTokenSecretManager: Updating the current master key for generating delegation tokens
2016-12-02 23:03:01,426 INFO org.mortbay.log: Started HttpServer2$SelectChannelConnectorWithSafeStartup@resourcemanager:8088
2016-12-02 23:03:01,427 INFO org.apache.hadoop.yarn.webapp.WebApps: Web app cluster started at 8088
2016-12-02 23:03:01,452 INFO org.apache.hadoop.ipc.CallQueueManager: Using callQueue class java.util.concurrent.LinkedBlockingQueue
2016-12-02 23:03:01,452 INFO org.apache.hadoop.ipc.Server: Starting Socket Reader #1 for port 8033
2016-12-02 23:03:01,454 INFO org.apache.hadoop.yarn.factories.impl.pb.RpcServerFactoryPBImpl: Adding protocol org.apache.hadoop.yarn.server.api.ResourceManagerAdministrationProtocolPB to the server
2016-12-02 23:03:01,464 INFO org.apache.hadoop.ipc.Server: IPC Server listener on 8033: starting
2016-12-02 23:03:01,464 INFO org.apache.hadoop.ipc.Server: IPC Server Responder: starting
2016-12-02 23:03:11,543 INFO org.apache.hadoop.yarn.util.RackResolver: Resolved datanode3 to /rack2
2016-12-02 23:03:11,547 INFO org.apache.hadoop.yarn.server.resourcemanager.ResourceTrackerService: NodeManager from node datanode3(cmPort: 60932 httpPort: 8042) registered with capability: <memory:3072, vCores:1>, assigned nodeId datanode3:60932
2016-12-02 23:03:11,556 INFO org.apache.hadoop.yarn.server.resourcemanager.rmnode.RMNodeImpl: datanode3:60932 Node Transitioned from NEW to RUNNING
2016-12-02 23:03:11,567 INFO org.apache.hadoop.yarn.server.resourcemanager.scheduler.capacity.CapacityScheduler: Added node datanode3:60932 clusterResource: <memory:3072, vCores:1>
2016-12-02 23:03:12,003 INFO org.apache.hadoop.yarn.util.RackResolver: Resolved datanode4 to /rack2
2016-12-02 23:03:12,003 INFO org.apache.hadoop.yarn.server.resourcemanager.rmnode.RMNodeImpl: datanode4:45290 Node Transitioned from NEW to RUNNING
2016-12-02 23:03:12,004 INFO org.apache.hadoop.yarn.server.resourcemanager.scheduler.capacity.CapacityScheduler: Added node datanode4:45290 clusterResource: <memory:6144, vCores:2>
2016-12-02 23:03:12,004 INFO org.apache.hadoop.yarn.server.resourcemanager.ResourceTrackerService: NodeManager from node datanode4(cmPort: 45290 httpPort: 8042) registered with capability: <memory:3072, vCores:1>, assigned nodeId datanode4:45290
2016-12-02 23:03:15,206 INFO org.apache.hadoop.yarn.util.RackResolver: Resolved datanode2 to /rack1
2016-12-02 23:03:15,210 INFO org.apache.hadoop.yarn.server.resourcemanager.rmnode.RMNodeImpl: datanode2:60334 Node Transitioned from NEW to RUNNING
2016-12-02 23:03:15,211 INFO org.apache.hadoop.yarn.server.resourcemanager.scheduler.capacity.CapacityScheduler: Added node datanode2:60334 clusterResource: <memory:9216, vCores:3>
2016-12-02 23:03:15,207 INFO org.apache.hadoop.yarn.server.resourcemanager.ResourceTrackerService: NodeManager from node datanode2(cmPort: 60334 httpPort: 8042) registered with capability: <memory:3072, vCores:1>, assigned nodeId datanode2:60334
2016-12-02 23:03:18,041 INFO org.apache.hadoop.yarn.util.RackResolver: Resolved datanode1 to /rack1
2016-12-02 23:03:18,041 INFO org.apache.hadoop.yarn.server.resourcemanager.ResourceTrackerService: NodeManager from node datanode1(cmPort: 50178 httpPort: 8042) registered with capability: <memory:3072, vCores:1>, assigned nodeId datanode1:50178
2016-12-02 23:03:18,041 INFO org.apache.hadoop.yarn.server.resourcemanager.rmnode.RMNodeImpl: datanode1:50178 Node Transitioned from NEW to RUNNING
2016-12-02 23:03:18,041 INFO org.apache.hadoop.yarn.server.resourcemanager.scheduler.capacity.CapacityScheduler: Added node datanode1:50178 clusterResource: <memory:12288, vCores:4>
2016-12-02 23:03:34,340 INFO org.apache.hadoop.yarn.server.resourcemanager.ClientRMService: Allocated new applicationId: 1
2016-12-02 23:04:10,762 INFO org.apache.hadoop.yarn.server.resourcemanager.ClientRMService: Allocated new applicationId: 2
2016-12-02 23:06:30,431 INFO org.apache.hadoop.yarn.server.resourcemanager.ClientRMService: Allocated new applicationId: 3
2016-12-02 23:06:32,913 INFO org.apache.hadoop.yarn.server.resourcemanager.rmapp.RMAppImpl: Storing application with id application_1480719777699_0003
2016-12-02 23:06:32,914 INFO org.apache.hadoop.yarn.server.resourcemanager.ClientRMService: Application with id 3 submitted by user hdmaster
2016-12-02 23:06:32,918 INFO org.apache.hadoop.yarn.server.resourcemanager.RMAuditLogger: USER=hdmaster	IP=10.0.0.4	OPERATION=Submit Application Request	TARGET=ClientRMService	RESULT=SUCCESS	APPID=application_1480719777699_0003
2016-12-02 23:06:32,921 INFO org.apache.hadoop.yarn.server.resourcemanager.recovery.RMStateStore: Storing info for app: application_1480719777699_0003
2016-12-02 23:06:32,921 INFO org.apache.hadoop.yarn.server.resourcemanager.rmapp.RMAppImpl: application_1480719777699_0003 State change from NEW to NEW_SAVING
2016-12-02 23:06:32,923 INFO org.apache.hadoop.yarn.server.resourcemanager.rmapp.RMAppImpl: application_1480719777699_0003 State change from NEW_SAVING to SUBMITTED
2016-12-02 23:06:32,928 INFO org.apache.hadoop.yarn.server.resourcemanager.scheduler.capacity.ParentQueue: Application added - appId: application_1480719777699_0003 user: hdmaster leaf-queue of parent: root #applications: 1
2016-12-02 23:06:32,929 INFO org.apache.hadoop.yarn.server.resourcemanager.scheduler.capacity.CapacityScheduler: Accepted application application_1480719777699_0003 from user: hdmaster, in queue: default
2016-12-02 23:06:32,955 INFO org.apache.hadoop.yarn.server.resourcemanager.rmapp.RMAppImpl: application_1480719777699_0003 State change from SUBMITTED to ACCEPTED
2016-12-02 23:06:33,012 INFO org.apache.hadoop.yarn.server.resourcemanager.ApplicationMasterService: Registering app attempt : appattempt_1480719777699_0003_000001
2016-12-02 23:06:33,013 INFO org.apache.hadoop.yarn.server.resourcemanager.rmapp.attempt.RMAppAttemptImpl: appattempt_1480719777699_0003_000001 State change from NEW to SUBMITTED
2016-12-02 23:06:33,033 INFO org.apache.hadoop.yarn.server.resourcemanager.scheduler.capacity.LeafQueue: Application application_1480719777699_0003 from user: hdmaster activated in queue: default
2016-12-02 23:06:33,033 INFO org.apache.hadoop.yarn.server.resourcemanager.scheduler.capacity.LeafQueue: Application added - appId: application_1480719777699_0003 user: org.apache.hadoop.yarn.server.resourcemanager.scheduler.capacity.LeafQueue$User@22293684, leaf-queue: default #user-pending-applications: 0 #user-active-applications: 1 #queue-pending-applications: 0 #queue-active-applications: 1
2016-12-02 23:06:33,034 INFO org.apache.hadoop.yarn.server.resourcemanager.scheduler.capacity.CapacityScheduler: Added Application Attempt appattempt_1480719777699_0003_000001 to scheduler from user hdmaster in queue default
2016-12-02 23:06:33,039 INFO org.apache.hadoop.yarn.server.resourcemanager.rmapp.attempt.RMAppAttemptImpl: appattempt_1480719777699_0003_000001 State change from SUBMITTED to SCHEDULED
2016-12-02 23:06:33,214 INFO org.apache.hadoop.yarn.server.resourcemanager.rmcontainer.RMContainerImpl: container_1480719777699_0003_01_000001 Container Transitioned from NEW to ALLOCATED
2016-12-02 23:06:33,214 INFO org.apache.hadoop.yarn.server.resourcemanager.RMAuditLogger: USER=hdmaster	OPERATION=AM Allocated Container	TARGET=SchedulerApp	RESULT=SUCCESS	APPID=application_1480719777699_0003	CONTAINERID=container_1480719777699_0003_01_000001
2016-12-02 23:06:33,215 INFO org.apache.hadoop.yarn.server.resourcemanager.scheduler.SchedulerNode: Assigned container container_1480719777699_0003_01_000001 of capacity <memory:2048, vCores:1> on host datanode3:60932, which has 1 containers, <memory:2048, vCores:1> used and <memory:1024, vCores:0> available after allocation
2016-12-02 23:06:33,215 INFO org.apache.hadoop.yarn.server.resourcemanager.scheduler.capacity.LeafQueue: assignedContainer application attempt=appattempt_1480719777699_0003_000001 container=Container: [ContainerId: container_1480719777699_0003_01_000001, NodeId: datanode3:60932, NodeHttpAddress: datanode3:8042, Resource: <memory:2048, vCores:1>, Priority: 0, Token: null, ] queue=default: capacity=1.0, absoluteCapacity=1.0, usedResources=<memory:0, vCores:0>, usedCapacity=0.0, absoluteUsedCapacity=0.0, numApps=1, numContainers=0 clusterResource=<memory:12288, vCores:4> type=OFF_SWITCH
2016-12-02 23:06:33,222 INFO org.apache.hadoop.yarn.server.resourcemanager.scheduler.capacity.ParentQueue: Re-sorting assigned queue: root.default stats: default: capacity=1.0, absoluteCapacity=1.0, usedResources=<memory:2048, vCores:1>, usedCapacity=0.16666667, absoluteUsedCapacity=0.16666667, numApps=1, numContainers=1
2016-12-02 23:06:33,222 INFO org.apache.hadoop.yarn.server.resourcemanager.scheduler.capacity.ParentQueue: assignedContainer queue=root usedCapacity=0.16666667 absoluteUsedCapacity=0.16666667 used=<memory:2048, vCores:1> cluster=<memory:12288, vCores:4>
2016-12-02 23:06:33,284 INFO org.apache.hadoop.yarn.server.resourcemanager.security.NMTokenSecretManagerInRM: Sending NMToken for nodeId : datanode3:60932 for container : container_1480719777699_0003_01_000001
2016-12-02 23:06:33,292 INFO org.apache.hadoop.yarn.server.resourcemanager.rmcontainer.RMContainerImpl: container_1480719777699_0003_01_000001 Container Transitioned from ALLOCATED to ACQUIRED
2016-12-02 23:06:33,292 INFO org.apache.hadoop.yarn.server.resourcemanager.security.NMTokenSecretManagerInRM: Clear node set for appattempt_1480719777699_0003_000001
2016-12-02 23:06:33,294 INFO org.apache.hadoop.yarn.server.resourcemanager.rmapp.attempt.RMAppAttemptImpl: Storing attempt: AppId: application_1480719777699_0003 AttemptId: appattempt_1480719777699_0003_000001 MasterContainer: Container: [ContainerId: container_1480719777699_0003_01_000001, NodeId: datanode3:60932, NodeHttpAddress: datanode3:8042, Resource: <memory:2048, vCores:1>, Priority: 0, Token: Token { kind: ContainerToken, service: 10.0.0.8:60932 }, ]
2016-12-02 23:06:33,304 INFO org.apache.hadoop.yarn.server.resourcemanager.rmapp.attempt.RMAppAttemptImpl: appattempt_1480719777699_0003_000001 State change from SCHEDULED to ALLOCATED_SAVING
2016-12-02 23:06:33,307 INFO org.apache.hadoop.yarn.server.resourcemanager.rmapp.attempt.RMAppAttemptImpl: appattempt_1480719777699_0003_000001 State change from ALLOCATED_SAVING to ALLOCATED
2016-12-02 23:06:33,311 INFO org.apache.hadoop.yarn.server.resourcemanager.amlauncher.AMLauncher: Launching masterappattempt_1480719777699_0003_000001
2016-12-02 23:06:33,356 INFO org.apache.hadoop.yarn.server.resourcemanager.amlauncher.AMLauncher: Setting up container Container: [ContainerId: container_1480719777699_0003_01_000001, NodeId: datanode3:60932, NodeHttpAddress: datanode3:8042, Resource: <memory:2048, vCores:1>, Priority: 0, Token: Token { kind: ContainerToken, service: 10.0.0.8:60932 }, ] for AM appattempt_1480719777699_0003_000001
2016-12-02 23:06:33,356 INFO org.apache.hadoop.yarn.server.resourcemanager.amlauncher.AMLauncher: Command to launch container container_1480719777699_0003_01_000001 : $JAVA_HOME/bin/java -Djava.io.tmpdir=$PWD/tmp -Dlog4j.configuration=container-log4j.properties -Dyarn.app.container.log.dir=<LOG_DIR> -Dyarn.app.container.log.filesize=0 -Dhadoop.root.logger=INFO,CLA -Dhadoop.root.logfile=syslog  -Xmx1024m org.apache.hadoop.mapreduce.v2.app.MRAppMaster 1><LOG_DIR>/stdout 2><LOG_DIR>/stderr 
2016-12-02 23:06:33,367 INFO org.apache.hadoop.yarn.server.resourcemanager.security.AMRMTokenSecretManager: Create AMRMToken for ApplicationAttempt: appattempt_1480719777699_0003_000001
2016-12-02 23:06:33,370 INFO org.apache.hadoop.yarn.server.resourcemanager.security.AMRMTokenSecretManager: Creating password for appattempt_1480719777699_0003_000001
2016-12-02 23:06:34,410 INFO org.apache.hadoop.yarn.server.resourcemanager.amlauncher.AMLauncher: Done launching container Container: [ContainerId: container_1480719777699_0003_01_000001, NodeId: datanode3:60932, NodeHttpAddress: datanode3:8042, Resource: <memory:2048, vCores:1>, Priority: 0, Token: Token { kind: ContainerToken, service: 10.0.0.8:60932 }, ] for AM appattempt_1480719777699_0003_000001
2016-12-02 23:06:34,410 INFO org.apache.hadoop.yarn.server.resourcemanager.rmapp.attempt.RMAppAttemptImpl: appattempt_1480719777699_0003_000001 State change from ALLOCATED to LAUNCHED
2016-12-02 23:06:35,213 INFO org.apache.hadoop.yarn.server.resourcemanager.rmcontainer.RMContainerImpl: container_1480719777699_0003_01_000001 Container Transitioned from ACQUIRED to RUNNING
2016-12-02 23:06:48,953 INFO SecurityLogger.org.apache.hadoop.ipc.Server: Auth successful for appattempt_1480719777699_0003_000001 (auth:SIMPLE)
2016-12-02 23:06:48,975 INFO org.apache.hadoop.yarn.server.resourcemanager.ApplicationMasterService: AM registration appattempt_1480719777699_0003_000001
2016-12-02 23:06:48,976 INFO org.apache.hadoop.yarn.server.resourcemanager.rmapp.attempt.RMAppAttemptImpl: appattempt_1480719777699_0003_000001 State change from LAUNCHED to RUNNING
2016-12-02 23:06:48,976 INFO org.apache.hadoop.yarn.server.resourcemanager.rmapp.RMAppImpl: application_1480719777699_0003 State change from ACCEPTED to RUNNING
2016-12-02 23:06:48,976 INFO org.apache.hadoop.yarn.server.resourcemanager.RMAuditLogger: USER=hdmaster	IP=10.0.0.8	OPERATION=Register App Master	TARGET=ApplicationMasterService	RESULT=SUCCESS	APPID=application_1480719777699_0003	APPATTEMPTID=appattempt_1480719777699_0003_000001
2016-12-02 23:06:53,263 INFO org.apache.hadoop.yarn.server.resourcemanager.rmcontainer.RMContainerImpl: container_1480719777699_0003_01_000002 Container Transitioned from NEW to RESERVED
2016-12-02 23:06:53,263 INFO org.apache.hadoop.yarn.server.resourcemanager.scheduler.capacity.LeafQueue: Reserved container  application=application_1480719777699_0003 resource=<memory:2048, vCores:1> queue=default: capacity=1.0, absoluteCapacity=1.0, usedResources=<memory:2048, vCores:1>, usedCapacity=0.16666667, absoluteUsedCapacity=0.16666667, numApps=1, numContainers=1 usedCapacity=0.16666667 absoluteUsedCapacity=0.16666667 used=<memory:2048, vCores:1> cluster=<memory:12288, vCores:4>
2016-12-02 23:06:53,264 INFO org.apache.hadoop.yarn.server.resourcemanager.scheduler.capacity.ParentQueue: Re-sorting assigned queue: root.default stats: default: capacity=1.0, absoluteCapacity=1.0, usedResources=<memory:4096, vCores:2>, usedCapacity=0.33333334, absoluteUsedCapacity=0.33333334, numApps=1, numContainers=2
2016-12-02 23:06:53,264 INFO org.apache.hadoop.yarn.server.resourcemanager.scheduler.capacity.ParentQueue: assignedContainer queue=root usedCapacity=0.33333334 absoluteUsedCapacity=0.33333334 used=<memory:4096, vCores:2> cluster=<memory:12288, vCores:4>
2016-12-02 23:06:53,666 INFO org.apache.hadoop.yarn.server.resourcemanager.rmcontainer.RMContainerImpl: container_1480719777699_0003_01_000003 Container Transitioned from NEW to ALLOCATED
2016-12-02 23:06:53,666 INFO org.apache.hadoop.yarn.server.resourcemanager.RMAuditLogger: USER=hdmaster	OPERATION=AM Allocated Container	TARGET=SchedulerApp	RESULT=SUCCESS	APPID=application_1480719777699_0003	CONTAINERID=container_1480719777699_0003_01_000003
2016-12-02 23:06:53,666 INFO org.apache.hadoop.yarn.server.resourcemanager.scheduler.SchedulerNode: Assigned container container_1480719777699_0003_01_000003 of capacity <memory:2048, vCores:1> on host datanode4:45290, which has 1 containers, <memory:2048, vCores:1> used and <memory:1024, vCores:0> available after allocation
2016-12-02 23:06:53,666 INFO org.apache.hadoop.yarn.server.resourcemanager.scheduler.capacity.LeafQueue: assignedContainer application attempt=appattempt_1480719777699_0003_000001 container=Container: [ContainerId: container_1480719777699_0003_01_000003, NodeId: datanode4:45290, NodeHttpAddress: datanode4:8042, Resource: <memory:2048, vCores:1>, Priority: 20, Token: null, ] queue=default: capacity=1.0, absoluteCapacity=1.0, usedResources=<memory:4096, vCores:2>, usedCapacity=0.33333334, absoluteUsedCapacity=0.33333334, numApps=1, numContainers=2 clusterResource=<memory:12288, vCores:4> type=OFF_SWITCH
2016-12-02 23:06:53,667 INFO org.apache.hadoop.yarn.server.resourcemanager.scheduler.capacity.ParentQueue: Re-sorting assigned queue: root.default stats: default: capacity=1.0, absoluteCapacity=1.0, usedResources=<memory:6144, vCores:3>, usedCapacity=0.5, absoluteUsedCapacity=0.5, numApps=1, numContainers=3
2016-12-02 23:06:53,667 INFO org.apache.hadoop.yarn.server.resourcemanager.scheduler.capacity.ParentQueue: assignedContainer queue=root usedCapacity=0.5 absoluteUsedCapacity=0.5 used=<memory:6144, vCores:3> cluster=<memory:12288, vCores:4>
2016-12-02 23:06:53,766 INFO org.apache.hadoop.yarn.server.resourcemanager.rmcontainer.RMContainerImpl: container_1480719777699_0003_01_000004 Container Transitioned from NEW to ALLOCATED
2016-12-02 23:06:53,766 INFO org.apache.hadoop.yarn.server.resourcemanager.RMAuditLogger: USER=hdmaster	OPERATION=AM Allocated Container	TARGET=SchedulerApp	RESULT=SUCCESS	APPID=application_1480719777699_0003	CONTAINERID=container_1480719777699_0003_01_000004
2016-12-02 23:06:53,766 INFO org.apache.hadoop.yarn.server.resourcemanager.scheduler.SchedulerNode: Assigned container container_1480719777699_0003_01_000004 of capacity <memory:2048, vCores:1> on host datanode1:50178, which has 1 containers, <memory:2048, vCores:1> used and <memory:1024, vCores:0> available after allocation
2016-12-02 23:06:53,767 INFO org.apache.hadoop.yarn.server.resourcemanager.scheduler.capacity.LeafQueue: assignedContainer application attempt=appattempt_1480719777699_0003_000001 container=Container: [ContainerId: container_1480719777699_0003_01_000004, NodeId: datanode1:50178, NodeHttpAddress: datanode1:8042, Resource: <memory:2048, vCores:1>, Priority: 20, Token: null, ] queue=default: capacity=1.0, absoluteCapacity=1.0, usedResources=<memory:6144, vCores:3>, usedCapacity=0.5, absoluteUsedCapacity=0.5, numApps=1, numContainers=3 clusterResource=<memory:12288, vCores:4> type=OFF_SWITCH
2016-12-02 23:06:53,767 INFO org.apache.hadoop.yarn.server.resourcemanager.scheduler.capacity.ParentQueue: Re-sorting assigned queue: root.default stats: default: capacity=1.0, absoluteCapacity=1.0, usedResources=<memory:8192, vCores:4>, usedCapacity=0.6666667, absoluteUsedCapacity=0.6666667, numApps=1, numContainers=4
2016-12-02 23:06:53,767 INFO org.apache.hadoop.yarn.server.resourcemanager.scheduler.capacity.ParentQueue: assignedContainer queue=root usedCapacity=0.6666667 absoluteUsedCapacity=0.6666667 used=<memory:8192, vCores:4> cluster=<memory:12288, vCores:4>
2016-12-02 23:06:53,844 INFO org.apache.hadoop.yarn.server.resourcemanager.rmcontainer.RMContainerImpl: container_1480719777699_0003_01_000005 Container Transitioned from NEW to ALLOCATED
2016-12-02 23:06:53,844 INFO org.apache.hadoop.yarn.server.resourcemanager.RMAuditLogger: USER=hdmaster	OPERATION=AM Allocated Container	TARGET=SchedulerApp	RESULT=SUCCESS	APPID=application_1480719777699_0003	CONTAINERID=container_1480719777699_0003_01_000005
2016-12-02 23:06:53,844 INFO org.apache.hadoop.yarn.server.resourcemanager.scheduler.SchedulerNode: Assigned container container_1480719777699_0003_01_000005 of capacity <memory:2048, vCores:1> on host datanode2:60334, which has 1 containers, <memory:2048, vCores:1> used and <memory:1024, vCores:0> available after allocation
2016-12-02 23:06:53,844 INFO org.apache.hadoop.yarn.server.resourcemanager.scheduler.capacity.LeafQueue: assignedContainer application attempt=appattempt_1480719777699_0003_000001 container=Container: [ContainerId: container_1480719777699_0003_01_000005, NodeId: datanode2:60334, NodeHttpAddress: datanode2:8042, Resource: <memory:2048, vCores:1>, Priority: 20, Token: null, ] queue=default: capacity=1.0, absoluteCapacity=1.0, usedResources=<memory:8192, vCores:4>, usedCapacity=0.6666667, absoluteUsedCapacity=0.6666667, numApps=1, numContainers=4 clusterResource=<memory:12288, vCores:4> type=OFF_SWITCH
2016-12-02 23:06:53,844 INFO org.apache.hadoop.yarn.server.resourcemanager.scheduler.capacity.ParentQueue: Re-sorting assigned queue: root.default stats: default: capacity=1.0, absoluteCapacity=1.0, usedResources=<memory:10240, vCores:5>, usedCapacity=0.8333333, absoluteUsedCapacity=0.8333333, numApps=1, numContainers=5
2016-12-02 23:06:53,844 INFO org.apache.hadoop.yarn.server.resourcemanager.scheduler.capacity.ParentQueue: assignedContainer queue=root usedCapacity=0.8333333 absoluteUsedCapacity=0.8333333 used=<memory:10240, vCores:5> cluster=<memory:12288, vCores:4>
2016-12-02 23:06:54,070 INFO org.apache.hadoop.yarn.server.resourcemanager.security.NMTokenSecretManagerInRM: Sending NMToken for nodeId : datanode4:45290 for container : container_1480719777699_0003_01_000003
2016-12-02 23:06:54,072 INFO org.apache.hadoop.yarn.server.resourcemanager.rmcontainer.RMContainerImpl: container_1480719777699_0003_01_000003 Container Transitioned from ALLOCATED to ACQUIRED
2016-12-02 23:06:54,072 INFO org.apache.hadoop.yarn.server.resourcemanager.security.NMTokenSecretManagerInRM: Sending NMToken for nodeId : datanode1:50178 for container : container_1480719777699_0003_01_000004
2016-12-02 23:06:54,073 INFO org.apache.hadoop.yarn.server.resourcemanager.rmcontainer.RMContainerImpl: container_1480719777699_0003_01_000004 Container Transitioned from ALLOCATED to ACQUIRED
2016-12-02 23:06:54,075 INFO org.apache.hadoop.yarn.server.resourcemanager.security.NMTokenSecretManagerInRM: Sending NMToken for nodeId : datanode2:60334 for container : container_1480719777699_0003_01_000005
2016-12-02 23:06:54,076 INFO org.apache.hadoop.yarn.server.resourcemanager.rmcontainer.RMContainerImpl: container_1480719777699_0003_01_000005 Container Transitioned from ALLOCATED to ACQUIRED
2016-12-02 23:06:54,267 INFO org.apache.hadoop.yarn.server.resourcemanager.scheduler.capacity.CapacityScheduler: Trying to fulfill reservation for application application_1480719777699_0003 on node: datanode3:60932
2016-12-02 23:06:54,268 INFO org.apache.hadoop.yarn.server.resourcemanager.scheduler.capacity.LeafQueue: Reserved container  application=application_1480719777699_0003 resource=<memory:2048, vCores:1> queue=default: capacity=1.0, absoluteCapacity=1.0, usedResources=<memory:10240, vCores:5>, usedCapacity=0.8333333, absoluteUsedCapacity=0.8333333, numApps=1, numContainers=5 usedCapacity=0.8333333 absoluteUsedCapacity=0.8333333 used=<memory:10240, vCores:5> cluster=<memory:12288, vCores:4>
2016-12-02 23:06:54,268 INFO org.apache.hadoop.yarn.server.resourcemanager.scheduler.capacity.CapacityScheduler: Skipping scheduling since node datanode3:60932 is reserved by application appattempt_1480719777699_0003_000001
2016-12-02 23:06:55,269 INFO org.apache.hadoop.yarn.server.resourcemanager.scheduler.capacity.CapacityScheduler: Trying to fulfill reservation for application application_1480719777699_0003 on node: datanode3:60932
2016-12-02 23:06:55,270 INFO org.apache.hadoop.yarn.server.resourcemanager.scheduler.capacity.LeafQueue: Reserved container  application=application_1480719777699_0003 resource=<memory:2048, vCores:1> queue=default: capacity=1.0, absoluteCapacity=1.0, usedResources=<memory:10240, vCores:5>, usedCapacity=0.8333333, absoluteUsedCapacity=0.8333333, numApps=1, numContainers=5 usedCapacity=0.8333333 absoluteUsedCapacity=0.8333333 used=<memory:10240, vCores:5> cluster=<memory:12288, vCores:4>
2016-12-02 23:06:55,270 INFO org.apache.hadoop.yarn.server.resourcemanager.scheduler.capacity.CapacityScheduler: Skipping scheduling since node datanode3:60932 is reserved by application appattempt_1480719777699_0003_000001
2016-12-02 23:06:55,689 INFO org.apache.hadoop.yarn.server.resourcemanager.rmcontainer.RMContainerImpl: container_1480719777699_0003_01_000003 Container Transitioned from ACQUIRED to RUNNING
2016-12-02 23:06:55,790 INFO org.apache.hadoop.yarn.server.resourcemanager.rmcontainer.RMContainerImpl: container_1480719777699_0003_01_000004 Container Transitioned from ACQUIRED to RUNNING
2016-12-02 23:06:55,869 INFO org.apache.hadoop.yarn.server.resourcemanager.rmcontainer.RMContainerImpl: container_1480719777699_0003_01_000005 Container Transitioned from ACQUIRED to RUNNING
2016-12-02 23:06:56,273 INFO org.apache.hadoop.yarn.server.resourcemanager.scheduler.capacity.CapacityScheduler: Trying to fulfill reservation for application application_1480719777699_0003 on node: datanode3:60932
2016-12-02 23:06:56,273 INFO org.apache.hadoop.yarn.server.resourcemanager.scheduler.capacity.LeafQueue: Reserved container  application=application_1480719777699_0003 resource=<memory:2048, vCores:1> queue=default: capacity=1.0, absoluteCapacity=1.0, usedResources=<memory:10240, vCores:5>, usedCapacity=0.8333333, absoluteUsedCapacity=0.8333333, numApps=1, numContainers=5 usedCapacity=0.8333333 absoluteUsedCapacity=0.8333333 used=<memory:10240, vCores:5> cluster=<memory:12288, vCores:4>
2016-12-02 23:06:56,274 INFO org.apache.hadoop.yarn.server.resourcemanager.scheduler.capacity.CapacityScheduler: Skipping scheduling since node datanode3:60932 is reserved by application appattempt_1480719777699_0003_000001
2016-12-02 23:06:57,279 INFO org.apache.hadoop.yarn.server.resourcemanager.scheduler.capacity.CapacityScheduler: Trying to fulfill reservation for application application_1480719777699_0003 on node: datanode3:60932
2016-12-02 23:06:57,280 INFO org.apache.hadoop.yarn.server.resourcemanager.scheduler.capacity.LeafQueue: Reserved container  application=application_1480719777699_0003 resource=<memory:2048, vCores:1> queue=default: capacity=1.0, absoluteCapacity=1.0, usedResources=<memory:10240, vCores:5>, usedCapacity=0.8333333, absoluteUsedCapacity=0.8333333, numApps=1, numContainers=5 usedCapacity=0.8333333 absoluteUsedCapacity=0.8333333 used=<memory:10240, vCores:5> cluster=<memory:12288, vCores:4>
2016-12-02 23:06:57,280 INFO org.apache.hadoop.yarn.server.resourcemanager.scheduler.capacity.CapacityScheduler: Skipping scheduling since node datanode3:60932 is reserved by application appattempt_1480719777699_0003_000001
2016-12-02 23:06:57,694 INFO org.apache.hadoop.yarn.server.resourcemanager.rmcontainer.RMContainerImpl: container_1480719777699_0003_01_000015 Container Transitioned from NEW to RESERVED
2016-12-02 23:06:57,695 INFO org.apache.hadoop.yarn.server.resourcemanager.scheduler.capacity.LeafQueue: Reserved container  application=application_1480719777699_0003 resource=<memory:2048, vCores:1> queue=default: capacity=1.0, absoluteCapacity=1.0, usedResources=<memory:10240, vCores:5>, usedCapacity=0.8333333, absoluteUsedCapacity=0.8333333, numApps=1, numContainers=5 usedCapacity=0.8333333 absoluteUsedCapacity=0.8333333 used=<memory:10240, vCores:5> cluster=<memory:12288, vCores:4>
2016-12-02 23:06:57,695 INFO org.apache.hadoop.yarn.server.resourcemanager.scheduler.capacity.ParentQueue: Re-sorting assigned queue: root.default stats: default: capacity=1.0, absoluteCapacity=1.0, usedResources=<memory:12288, vCores:6>, usedCapacity=1.0, absoluteUsedCapacity=1.0, numApps=1, numContainers=6
2016-12-02 23:06:57,695 INFO org.apache.hadoop.yarn.server.resourcemanager.scheduler.capacity.ParentQueue: assignedContainer queue=root usedCapacity=1.0 absoluteUsedCapacity=1.0 used=<memory:12288, vCores:6> cluster=<memory:12288, vCores:4>
2016-12-02 23:06:58,286 INFO org.apache.hadoop.yarn.server.resourcemanager.scheduler.capacity.CapacityScheduler: Trying to fulfill reservation for application application_1480719777699_0003 on node: datanode3:60932
2016-12-02 23:06:58,287 INFO org.apache.hadoop.yarn.server.resourcemanager.scheduler.capacity.LeafQueue: Reserved container  application=application_1480719777699_0003 resource=<memory:2048, vCores:1> queue=default: capacity=1.0, absoluteCapacity=1.0, usedResources=<memory:12288, vCores:6>, usedCapacity=1.0, absoluteUsedCapacity=1.0, numApps=1, numContainers=6 usedCapacity=1.0 absoluteUsedCapacity=1.0 used=<memory:12288, vCores:6> cluster=<memory:12288, vCores:4>
2016-12-02 23:06:58,287 INFO org.apache.hadoop.yarn.server.resourcemanager.scheduler.capacity.CapacityScheduler: Skipping scheduling since node datanode3:60932 is reserved by application appattempt_1480719777699_0003_000001
2016-12-02 23:06:58,698 INFO org.apache.hadoop.yarn.server.resourcemanager.scheduler.capacity.CapacityScheduler: Trying to fulfill reservation for application application_1480719777699_0003 on node: datanode4:45290
2016-12-02 23:06:58,698 INFO org.apache.hadoop.yarn.server.resourcemanager.scheduler.capacity.LeafQueue: Reserved container  application=application_1480719777699_0003 resource=<memory:2048, vCores:1> queue=default: capacity=1.0, absoluteCapacity=1.0, usedResources=<memory:12288, vCores:6>, usedCapacity=1.0, absoluteUsedCapacity=1.0, numApps=1, numContainers=6 usedCapacity=1.0 absoluteUsedCapacity=1.0 used=<memory:12288, vCores:6> cluster=<memory:12288, vCores:4>
2016-12-02 23:06:58,698 INFO org.apache.hadoop.yarn.server.resourcemanager.scheduler.capacity.CapacityScheduler: Skipping scheduling since node datanode4:45290 is reserved by application appattempt_1480719777699_0003_000001
2016-12-02 23:06:59,284 INFO org.apache.hadoop.yarn.server.resourcemanager.scheduler.capacity.CapacityScheduler: Trying to fulfill reservation for application application_1480719777699_0003 on node: datanode3:60932
2016-12-02 23:06:59,285 INFO org.apache.hadoop.yarn.server.resourcemanager.scheduler.capacity.LeafQueue: Reserved container  application=application_1480719777699_0003 resource=<memory:2048, vCores:1> queue=default: capacity=1.0, absoluteCapacity=1.0, usedResources=<memory:12288, vCores:6>, usedCapacity=1.0, absoluteUsedCapacity=1.0, numApps=1, numContainers=6 usedCapacity=1.0 absoluteUsedCapacity=1.0 used=<memory:12288, vCores:6> cluster=<memory:12288, vCores:4>
2016-12-02 23:06:59,285 INFO org.apache.hadoop.yarn.server.resourcemanager.scheduler.capacity.CapacityScheduler: Skipping scheduling since node datanode3:60932 is reserved by application appattempt_1480719777699_0003_000001
2016-12-02 23:06:59,700 INFO org.apache.hadoop.yarn.server.resourcemanager.scheduler.capacity.CapacityScheduler: Trying to fulfill reservation for application application_1480719777699_0003 on node: datanode4:45290
2016-12-02 23:06:59,700 INFO org.apache.hadoop.yarn.server.resourcemanager.scheduler.capacity.LeafQueue: Reserved container  application=application_1480719777699_0003 resource=<memory:2048, vCores:1> queue=default: capacity=1.0, absoluteCapacity=1.0, usedResources=<memory:12288, vCores:6>, usedCapacity=1.0, absoluteUsedCapacity=1.0, numApps=1, numContainers=6 usedCapacity=1.0 absoluteUsedCapacity=1.0 used=<memory:12288, vCores:6> cluster=<memory:12288, vCores:4>
2016-12-02 23:06:59,700 INFO org.apache.hadoop.yarn.server.resourcemanager.scheduler.capacity.CapacityScheduler: Skipping scheduling since node datanode4:45290 is reserved by application appattempt_1480719777699_0003_000001
2016-12-02 23:07:00,288 INFO org.apache.hadoop.yarn.server.resourcemanager.scheduler.capacity.CapacityScheduler: Trying to fulfill reservation for application application_1480719777699_0003 on node: datanode3:60932
2016-12-02 23:07:00,288 INFO org.apache.hadoop.yarn.server.resourcemanager.scheduler.capacity.LeafQueue: Reserved container  application=application_1480719777699_0003 resource=<memory:2048, vCores:1> queue=default: capacity=1.0, absoluteCapacity=1.0, usedResources=<memory:12288, vCores:6>, usedCapacity=1.0, absoluteUsedCapacity=1.0, numApps=1, numContainers=6 usedCapacity=1.0 absoluteUsedCapacity=1.0 used=<memory:12288, vCores:6> cluster=<memory:12288, vCores:4>
2016-12-02 23:07:00,288 INFO org.apache.hadoop.yarn.server.resourcemanager.scheduler.capacity.CapacityScheduler: Skipping scheduling since node datanode3:60932 is reserved by application appattempt_1480719777699_0003_000001
2016-12-02 23:07:00,702 INFO org.apache.hadoop.yarn.server.resourcemanager.scheduler.capacity.CapacityScheduler: Trying to fulfill reservation for application application_1480719777699_0003 on node: datanode4:45290
2016-12-02 23:07:00,702 INFO org.apache.hadoop.yarn.server.resourcemanager.scheduler.capacity.LeafQueue: Reserved container  application=application_1480719777699_0003 resource=<memory:2048, vCores:1> queue=default: capacity=1.0, absoluteCapacity=1.0, usedResources=<memory:12288, vCores:6>, usedCapacity=1.0, absoluteUsedCapacity=1.0, numApps=1, numContainers=6 usedCapacity=1.0 absoluteUsedCapacity=1.0 used=<memory:12288, vCores:6> cluster=<memory:12288, vCores:4>
2016-12-02 23:07:00,702 INFO org.apache.hadoop.yarn.server.resourcemanager.scheduler.capacity.CapacityScheduler: Skipping scheduling since node datanode4:45290 is reserved by application appattempt_1480719777699_0003_000001
2016-12-02 23:07:01,290 INFO org.apache.hadoop.yarn.server.resourcemanager.scheduler.capacity.CapacityScheduler: Trying to fulfill reservation for application application_1480719777699_0003 on node: datanode3:60932
2016-12-02 23:07:01,290 INFO org.apache.hadoop.yarn.server.resourcemanager.scheduler.capacity.LeafQueue: Reserved container  application=application_1480719777699_0003 resource=<memory:2048, vCores:1> queue=default: capacity=1.0, absoluteCapacity=1.0, usedResources=<memory:12288, vCores:6>, usedCapacity=1.0, absoluteUsedCapacity=1.0, numApps=1, numContainers=6 usedCapacity=1.0 absoluteUsedCapacity=1.0 used=<memory:12288, vCores:6> cluster=<memory:12288, vCores:4>
2016-12-02 23:07:01,290 INFO org.apache.hadoop.yarn.server.resourcemanager.scheduler.capacity.CapacityScheduler: Skipping scheduling since node datanode3:60932 is reserved by application appattempt_1480719777699_0003_000001
2016-12-02 23:07:01,421 INFO org.apache.hadoop.yarn.server.resourcemanager.rmcontainer.RMContainerImpl: container_1480719777699_0003_01_000003 Container Transitioned from RUNNING to COMPLETED
2016-12-02 23:07:01,421 INFO org.apache.hadoop.yarn.server.resourcemanager.scheduler.common.fica.FiCaSchedulerApp: Completed container: container_1480719777699_0003_01_000003 in state: COMPLETED event:FINISHED
2016-12-02 23:07:01,421 INFO org.apache.hadoop.yarn.server.resourcemanager.RMAuditLogger: USER=hdmaster	OPERATION=AM Released Container	TARGET=SchedulerApp	RESULT=SUCCESS	APPID=application_1480719777699_0003	CONTAINERID=container_1480719777699_0003_01_000003
2016-12-02 23:07:01,421 INFO org.apache.hadoop.yarn.server.resourcemanager.scheduler.SchedulerNode: Released container container_1480719777699_0003_01_000003 of capacity <memory:2048, vCores:1> on host datanode4:45290, which currently has 0 containers, <memory:0, vCores:0> used and <memory:3072, vCores:1> available, release resources=true
2016-12-02 23:07:01,421 INFO org.apache.hadoop.yarn.server.resourcemanager.scheduler.capacity.LeafQueue: default used=<memory:10240, vCores:5> numContainers=5 user=hdmaster user-resources=<memory:10240, vCores:5>
2016-12-02 23:07:01,425 INFO org.apache.hadoop.yarn.server.resourcemanager.scheduler.capacity.LeafQueue: completedContainer container=Container: [ContainerId: container_1480719777699_0003_01_000003, NodeId: datanode4:45290, NodeHttpAddress: datanode4:8042, Resource: <memory:2048, vCores:1>, Priority: 20, Token: Token { kind: ContainerToken, service: 10.0.0.9:45290 }, ] queue=default: capacity=1.0, absoluteCapacity=1.0, usedResources=<memory:10240, vCores:5>, usedCapacity=0.8333333, absoluteUsedCapacity=0.8333333, numApps=1, numContainers=5 cluster=<memory:12288, vCores:4>
2016-12-02 23:07:01,425 INFO org.apache.hadoop.yarn.server.resourcemanager.scheduler.capacity.ParentQueue: completedContainer queue=root usedCapacity=0.8333333 absoluteUsedCapacity=0.8333333 used=<memory:10240, vCores:5> cluster=<memory:12288, vCores:4>
2016-12-02 23:07:01,425 INFO org.apache.hadoop.yarn.server.resourcemanager.scheduler.capacity.ParentQueue: Re-sorting completed queue: root.default stats: default: capacity=1.0, absoluteCapacity=1.0, usedResources=<memory:10240, vCores:5>, usedCapacity=0.8333333, absoluteUsedCapacity=0.8333333, numApps=1, numContainers=5
2016-12-02 23:07:01,425 INFO org.apache.hadoop.yarn.server.resourcemanager.scheduler.capacity.CapacityScheduler: Application attempt appattempt_1480719777699_0003_000001 released container container_1480719777699_0003_01_000003 on node: host: datanode4:45290 #containers=0 available=<memory:3072, vCores:1> used=<memory:0, vCores:0> with event: FINISHED
2016-12-02 23:07:01,425 INFO org.apache.hadoop.yarn.server.resourcemanager.scheduler.capacity.CapacityScheduler: Trying to fulfill reservation for application application_1480719777699_0003 on node: datanode4:45290
2016-12-02 23:07:01,425 INFO org.apache.hadoop.yarn.server.resourcemanager.scheduler.common.fica.FiCaSchedulerApp: Application application_1480719777699_0003 unreserved  on node host: datanode4:45290 #containers=0 available=<memory:3072, vCores:1> used=<memory:0, vCores:0>, currently has 1 at priority 20; currentReservation <memory:2048, vCores:1>
2016-12-02 23:07:01,425 INFO org.apache.hadoop.yarn.server.resourcemanager.rmcontainer.RMContainerImpl: container_1480719777699_0003_01_000015 Container Transitioned from NEW to ALLOCATED
2016-12-02 23:07:01,425 INFO org.apache.hadoop.yarn.server.resourcemanager.RMAuditLogger: USER=hdmaster	OPERATION=AM Allocated Container	TARGET=SchedulerApp	RESULT=SUCCESS	APPID=application_1480719777699_0003	CONTAINERID=container_1480719777699_0003_01_000015
2016-12-02 23:07:01,425 INFO org.apache.hadoop.yarn.server.resourcemanager.scheduler.SchedulerNode: Assigned container container_1480719777699_0003_01_000015 of capacity <memory:2048, vCores:1> on host datanode4:45290, which has 1 containers, <memory:2048, vCores:1> used and <memory:1024, vCores:0> available after allocation
2016-12-02 23:07:01,426 INFO org.apache.hadoop.yarn.server.resourcemanager.scheduler.capacity.LeafQueue: assignedContainer application attempt=appattempt_1480719777699_0003_000001 container=Container: [ContainerId: container_1480719777699_0003_01_000015, NodeId: datanode4:45290, NodeHttpAddress: datanode4:8042, Resource: <memory:2048, vCores:1>, Priority: 20, Token: null, ] queue=default: capacity=1.0, absoluteCapacity=1.0, usedResources=<memory:10240, vCores:5>, usedCapacity=0.8333333, absoluteUsedCapacity=0.8333333, numApps=1, numContainers=5 clusterResource=<memory:12288, vCores:4> type=OFF_SWITCH
2016-12-02 23:07:02,129 INFO org.apache.hadoop.yarn.server.resourcemanager.rmcontainer.RMContainerImpl: container_1480719777699_0003_01_000015 Container Transitioned from ALLOCATED to ACQUIRED
2016-12-02 23:07:02,292 INFO org.apache.hadoop.yarn.server.resourcemanager.scheduler.capacity.CapacityScheduler: Trying to fulfill reservation for application application_1480719777699_0003 on node: datanode3:60932
2016-12-02 23:07:02,293 INFO org.apache.hadoop.yarn.server.resourcemanager.scheduler.common.fica.FiCaSchedulerApp: Application application_1480719777699_0003 unreserved  on node host: datanode3:60932 #containers=1 available=<memory:1024, vCores:0> used=<memory:2048, vCores:1>, currently has 0 at priority 20; currentReservation <memory:0, vCores:0>
2016-12-02 23:07:02,293 INFO org.apache.hadoop.yarn.server.resourcemanager.scheduler.capacity.LeafQueue: default used=<memory:8192, vCores:4> numContainers=4 user=hdmaster user-resources=<memory:8192, vCores:4>
2016-12-02 23:07:02,293 INFO org.apache.hadoop.yarn.server.resourcemanager.scheduler.capacity.LeafQueue: completedContainer container=Container: [ContainerId: container_1480719777699_0003_01_000002, NodeId: datanode3:60932, NodeHttpAddress: datanode3:8042, Resource: <memory:2048, vCores:1>, Priority: 20, Token: null, ] queue=default: capacity=1.0, absoluteCapacity=1.0, usedResources=<memory:8192, vCores:4>, usedCapacity=0.6666667, absoluteUsedCapacity=0.6666667, numApps=1, numContainers=4 cluster=<memory:12288, vCores:4>
2016-12-02 23:07:02,293 INFO org.apache.hadoop.yarn.server.resourcemanager.scheduler.capacity.ParentQueue: completedContainer queue=root usedCapacity=0.6666667 absoluteUsedCapacity=0.6666667 used=<memory:8192, vCores:4> cluster=<memory:12288, vCores:4>
2016-12-02 23:07:02,293 INFO org.apache.hadoop.yarn.server.resourcemanager.scheduler.capacity.ParentQueue: Re-sorting completed queue: root.default stats: default: capacity=1.0, absoluteCapacity=1.0, usedResources=<memory:8192, vCores:4>, usedCapacity=0.6666667, absoluteUsedCapacity=0.6666667, numApps=1, numContainers=4
2016-12-02 23:07:02,294 INFO org.apache.hadoop.yarn.server.resourcemanager.rmcontainer.RMContainerImpl: container_1480719777699_0003_01_000024 Container Transitioned from NEW to RESERVED
2016-12-02 23:07:02,294 INFO org.apache.hadoop.yarn.server.resourcemanager.scheduler.capacity.LeafQueue: Reserved container  application=application_1480719777699_0003 resource=<memory:2048, vCores:1> queue=default: capacity=1.0, absoluteCapacity=1.0, usedResources=<memory:8192, vCores:4>, usedCapacity=0.6666667, absoluteUsedCapacity=0.6666667, numApps=1, numContainers=4 usedCapacity=0.6666667 absoluteUsedCapacity=0.6666667 used=<memory:8192, vCores:4> cluster=<memory:12288, vCores:4>
2016-12-02 23:07:02,294 INFO org.apache.hadoop.yarn.server.resourcemanager.scheduler.capacity.ParentQueue: Re-sorting assigned queue: root.default stats: default: capacity=1.0, absoluteCapacity=1.0, usedResources=<memory:10240, vCores:5>, usedCapacity=0.8333333, absoluteUsedCapacity=0.8333333, numApps=1, numContainers=5
2016-12-02 23:07:02,295 INFO org.apache.hadoop.yarn.server.resourcemanager.scheduler.capacity.ParentQueue: assignedContainer queue=root usedCapacity=0.8333333 absoluteUsedCapacity=0.8333333 used=<memory:10240, vCores:5> cluster=<memory:12288, vCores:4>
2016-12-02 23:07:02,424 INFO org.apache.hadoop.yarn.server.resourcemanager.rmcontainer.RMContainerImpl: container_1480719777699_0003_01_000015 Container Transitioned from ACQUIRED to RUNNING
2016-12-02 23:07:02,808 INFO org.apache.hadoop.yarn.server.resourcemanager.rmcontainer.RMContainerImpl: container_1480719777699_0003_01_000005 Container Transitioned from RUNNING to COMPLETED
2016-12-02 23:07:02,808 INFO org.apache.hadoop.yarn.server.resourcemanager.scheduler.common.fica.FiCaSchedulerApp: Completed container: container_1480719777699_0003_01_000005 in state: COMPLETED event:FINISHED
2016-12-02 23:07:02,808 INFO org.apache.hadoop.yarn.server.resourcemanager.RMAuditLogger: USER=hdmaster	OPERATION=AM Released Container	TARGET=SchedulerApp	RESULT=SUCCESS	APPID=application_1480719777699_0003	CONTAINERID=container_1480719777699_0003_01_000005
2016-12-02 23:07:02,808 INFO org.apache.hadoop.yarn.server.resourcemanager.scheduler.SchedulerNode: Released container container_1480719777699_0003_01_000005 of capacity <memory:2048, vCores:1> on host datanode2:60334, which currently has 0 containers, <memory:0, vCores:0> used and <memory:3072, vCores:1> available, release resources=true
2016-12-02 23:07:02,808 INFO org.apache.hadoop.yarn.server.resourcemanager.scheduler.capacity.LeafQueue: default used=<memory:8192, vCores:4> numContainers=4 user=hdmaster user-resources=<memory:8192, vCores:4>
2016-12-02 23:07:02,809 INFO org.apache.hadoop.yarn.server.resourcemanager.scheduler.capacity.LeafQueue: completedContainer container=Container: [ContainerId: container_1480719777699_0003_01_000005, NodeId: datanode2:60334, NodeHttpAddress: datanode2:8042, Resource: <memory:2048, vCores:1>, Priority: 20, Token: Token { kind: ContainerToken, service: 10.0.0.7:60334 }, ] queue=default: capacity=1.0, absoluteCapacity=1.0, usedResources=<memory:8192, vCores:4>, usedCapacity=0.6666667, absoluteUsedCapacity=0.6666667, numApps=1, numContainers=4 cluster=<memory:12288, vCores:4>
2016-12-02 23:07:02,809 INFO org.apache.hadoop.yarn.server.resourcemanager.scheduler.capacity.ParentQueue: completedContainer queue=root usedCapacity=0.6666667 absoluteUsedCapacity=0.6666667 used=<memory:8192, vCores:4> cluster=<memory:12288, vCores:4>
2016-12-02 23:07:02,809 INFO org.apache.hadoop.yarn.server.resourcemanager.scheduler.capacity.ParentQueue: Re-sorting completed queue: root.default stats: default: capacity=1.0, absoluteCapacity=1.0, usedResources=<memory:8192, vCores:4>, usedCapacity=0.6666667, absoluteUsedCapacity=0.6666667, numApps=1, numContainers=4
2016-12-02 23:07:02,809 INFO org.apache.hadoop.yarn.server.resourcemanager.scheduler.capacity.CapacityScheduler: Application attempt appattempt_1480719777699_0003_000001 released container container_1480719777699_0003_01_000005 on node: host: datanode2:60334 #containers=0 available=<memory:3072, vCores:1> used=<memory:0, vCores:0> with event: FINISHED
2016-12-02 23:07:02,809 INFO org.apache.hadoop.yarn.server.resourcemanager.scheduler.common.fica.FiCaSchedulerApp: Application application_1480719777699_0003 unreserved  on node host: datanode3:60932 #containers=1 available=<memory:1024, vCores:0> used=<memory:2048, vCores:1>, currently has 0 at priority 5; currentReservation <memory:0, vCores:0>
2016-12-02 23:07:02,809 INFO org.apache.hadoop.yarn.server.resourcemanager.scheduler.capacity.LeafQueue: default used=<memory:6144, vCores:3> numContainers=3 user=hdmaster user-resources=<memory:6144, vCores:3>
2016-12-02 23:07:02,809 INFO org.apache.hadoop.yarn.server.resourcemanager.scheduler.capacity.LeafQueue: completedContainer container=Container: [ContainerId: container_1480719777699_0003_01_000024, NodeId: datanode3:60932, NodeHttpAddress: datanode3:8042, Resource: <memory:2048, vCores:1>, Priority: 5, Token: null, ] queue=default: capacity=1.0, absoluteCapacity=1.0, usedResources=<memory:6144, vCores:3>, usedCapacity=0.5, absoluteUsedCapacity=0.5, numApps=1, numContainers=3 cluster=<memory:12288, vCores:4>
2016-12-02 23:07:02,809 INFO org.apache.hadoop.yarn.server.resourcemanager.scheduler.capacity.ParentQueue: completedContainer queue=root usedCapacity=0.5 absoluteUsedCapacity=0.5 used=<memory:6144, vCores:3> cluster=<memory:12288, vCores:4>
2016-12-02 23:07:02,810 INFO org.apache.hadoop.yarn.server.resourcemanager.rmcontainer.RMContainerImpl: container_1480719777699_0003_01_000026 Container Transitioned from NEW to ALLOCATED
2016-12-02 23:07:02,810 INFO org.apache.hadoop.yarn.server.resourcemanager.RMAuditLogger: USER=hdmaster	OPERATION=AM Allocated Container	TARGET=SchedulerApp	RESULT=SUCCESS	APPID=application_1480719777699_0003	CONTAINERID=container_1480719777699_0003_01_000026
2016-12-02 23:07:02,810 INFO org.apache.hadoop.yarn.server.resourcemanager.scheduler.SchedulerNode: Assigned container container_1480719777699_0003_01_000026 of capacity <memory:2048, vCores:1> on host datanode2:60334, which has 1 containers, <memory:2048, vCores:1> used and <memory:1024, vCores:0> available after allocation
2016-12-02 23:07:02,810 INFO org.apache.hadoop.yarn.server.resourcemanager.scheduler.capacity.LeafQueue: assignedContainer application attempt=appattempt_1480719777699_0003_000001 container=Container: [ContainerId: container_1480719777699_0003_01_000026, NodeId: datanode2:60334, NodeHttpAddress: datanode2:8042, Resource: <memory:2048, vCores:1>, Priority: 5, Token: null, ] queue=default: capacity=1.0, absoluteCapacity=1.0, usedResources=<memory:6144, vCores:3>, usedCapacity=0.5, absoluteUsedCapacity=0.5, numApps=1, numContainers=3 clusterResource=<memory:12288, vCores:4> type=OFF_SWITCH
2016-12-02 23:07:02,810 INFO org.apache.hadoop.yarn.server.resourcemanager.scheduler.capacity.ParentQueue: Re-sorting assigned queue: root.default stats: default: capacity=1.0, absoluteCapacity=1.0, usedResources=<memory:8192, vCores:4>, usedCapacity=0.6666667, absoluteUsedCapacity=0.6666667, numApps=1, numContainers=4
2016-12-02 23:07:02,810 INFO org.apache.hadoop.yarn.server.resourcemanager.scheduler.capacity.ParentQueue: assignedContainer queue=root usedCapacity=0.6666667 absoluteUsedCapacity=0.6666667 used=<memory:8192, vCores:4> cluster=<memory:12288, vCores:4>
2016-12-02 23:07:03,139 INFO org.apache.hadoop.yarn.server.resourcemanager.scheduler.AppSchedulingInfo: checking for deactivate of application :application_1480719777699_0003
2016-12-02 23:07:03,144 INFO org.apache.hadoop.yarn.server.resourcemanager.rmcontainer.RMContainerImpl: container_1480719777699_0003_01_000026 Container Transitioned from ALLOCATED to ACQUIRED
2016-12-02 23:07:03,297 INFO org.apache.hadoop.yarn.server.resourcemanager.rmcontainer.RMContainerImpl: container_1480719777699_0003_01_000027 Container Transitioned from NEW to RESERVED
2016-12-02 23:07:03,297 INFO org.apache.hadoop.yarn.server.resourcemanager.scheduler.capacity.LeafQueue: Reserved container  application=application_1480719777699_0003 resource=<memory:2048, vCores:1> queue=default: capacity=1.0, absoluteCapacity=1.0, usedResources=<memory:8192, vCores:4>, usedCapacity=0.6666667, absoluteUsedCapacity=0.6666667, numApps=1, numContainers=4 usedCapacity=0.6666667 absoluteUsedCapacity=0.6666667 used=<memory:8192, vCores:4> cluster=<memory:12288, vCores:4>
2016-12-02 23:07:03,297 INFO org.apache.hadoop.yarn.server.resourcemanager.scheduler.capacity.ParentQueue: Re-sorting assigned queue: root.default stats: default: capacity=1.0, absoluteCapacity=1.0, usedResources=<memory:10240, vCores:5>, usedCapacity=0.8333333, absoluteUsedCapacity=0.8333333, numApps=1, numContainers=5
2016-12-02 23:07:03,297 INFO org.apache.hadoop.yarn.server.resourcemanager.scheduler.capacity.ParentQueue: assignedContainer queue=root usedCapacity=0.8333333 absoluteUsedCapacity=0.8333333 used=<memory:10240, vCores:5> cluster=<memory:12288, vCores:4>
2016-12-02 23:07:03,428 INFO org.apache.hadoop.yarn.server.resourcemanager.rmcontainer.RMContainerImpl: container_1480719777699_0003_01_000028 Container Transitioned from NEW to RESERVED
2016-12-02 23:07:03,428 INFO org.apache.hadoop.yarn.server.resourcemanager.scheduler.capacity.LeafQueue: Reserved container  application=application_1480719777699_0003 resource=<memory:2048, vCores:1> queue=default: capacity=1.0, absoluteCapacity=1.0, usedResources=<memory:10240, vCores:5>, usedCapacity=0.8333333, absoluteUsedCapacity=0.8333333, numApps=1, numContainers=5 usedCapacity=0.8333333 absoluteUsedCapacity=0.8333333 used=<memory:10240, vCores:5> cluster=<memory:12288, vCores:4>
2016-12-02 23:07:03,428 INFO org.apache.hadoop.yarn.server.resourcemanager.scheduler.capacity.ParentQueue: Re-sorting assigned queue: root.default stats: default: capacity=1.0, absoluteCapacity=1.0, usedResources=<memory:12288, vCores:6>, usedCapacity=1.0, absoluteUsedCapacity=1.0, numApps=1, numContainers=6
2016-12-02 23:07:03,428 INFO org.apache.hadoop.yarn.server.resourcemanager.scheduler.capacity.ParentQueue: assignedContainer queue=root usedCapacity=1.0 absoluteUsedCapacity=1.0 used=<memory:12288, vCores:6> cluster=<memory:12288, vCores:4>
2016-12-02 23:07:03,811 INFO org.apache.hadoop.yarn.server.resourcemanager.rmcontainer.RMContainerImpl: container_1480719777699_0003_01_000026 Container Transitioned from ACQUIRED to RUNNING
2016-12-02 23:07:04,299 INFO org.apache.hadoop.yarn.server.resourcemanager.scheduler.capacity.CapacityScheduler: Trying to fulfill reservation for application application_1480719777699_0003 on node: datanode3:60932
2016-12-02 23:07:04,299 INFO org.apache.hadoop.yarn.server.resourcemanager.scheduler.capacity.LeafQueue: Reserved container  application=application_1480719777699_0003 resource=<memory:2048, vCores:1> queue=default: capacity=1.0, absoluteCapacity=1.0, usedResources=<memory:12288, vCores:6>, usedCapacity=1.0, absoluteUsedCapacity=1.0, numApps=1, numContainers=6 usedCapacity=1.0 absoluteUsedCapacity=1.0 used=<memory:12288, vCores:6> cluster=<memory:12288, vCores:4>
2016-12-02 23:07:04,299 INFO org.apache.hadoop.yarn.server.resourcemanager.scheduler.capacity.CapacityScheduler: Skipping scheduling since node datanode3:60932 is reserved by application appattempt_1480719777699_0003_000001
2016-12-02 23:07:04,430 INFO org.apache.hadoop.yarn.server.resourcemanager.scheduler.capacity.CapacityScheduler: Trying to fulfill reservation for application application_1480719777699_0003 on node: datanode4:45290
2016-12-02 23:07:04,430 INFO org.apache.hadoop.yarn.server.resourcemanager.scheduler.capacity.LeafQueue: Reserved container  application=application_1480719777699_0003 resource=<memory:2048, vCores:1> queue=default: capacity=1.0, absoluteCapacity=1.0, usedResources=<memory:12288, vCores:6>, usedCapacity=1.0, absoluteUsedCapacity=1.0, numApps=1, numContainers=6 usedCapacity=1.0 absoluteUsedCapacity=1.0 used=<memory:12288, vCores:6> cluster=<memory:12288, vCores:4>
2016-12-02 23:07:04,431 INFO org.apache.hadoop.yarn.server.resourcemanager.scheduler.capacity.CapacityScheduler: Skipping scheduling since node datanode4:45290 is reserved by application appattempt_1480719777699_0003_000001
2016-12-02 23:07:05,301 INFO org.apache.hadoop.yarn.server.resourcemanager.scheduler.capacity.CapacityScheduler: Trying to fulfill reservation for application application_1480719777699_0003 on node: datanode3:60932
2016-12-02 23:07:05,301 INFO org.apache.hadoop.yarn.server.resourcemanager.scheduler.capacity.LeafQueue: Reserved container  application=application_1480719777699_0003 resource=<memory:2048, vCores:1> queue=default: capacity=1.0, absoluteCapacity=1.0, usedResources=<memory:12288, vCores:6>, usedCapacity=1.0, absoluteUsedCapacity=1.0, numApps=1, numContainers=6 usedCapacity=1.0 absoluteUsedCapacity=1.0 used=<memory:12288, vCores:6> cluster=<memory:12288, vCores:4>
2016-12-02 23:07:05,301 INFO org.apache.hadoop.yarn.server.resourcemanager.scheduler.capacity.CapacityScheduler: Skipping scheduling since node datanode3:60932 is reserved by application appattempt_1480719777699_0003_000001
2016-12-02 23:07:05,433 INFO org.apache.hadoop.yarn.server.resourcemanager.scheduler.capacity.CapacityScheduler: Trying to fulfill reservation for application application_1480719777699_0003 on node: datanode4:45290
2016-12-02 23:07:05,434 INFO org.apache.hadoop.yarn.server.resourcemanager.scheduler.capacity.LeafQueue: Reserved container  application=application_1480719777699_0003 resource=<memory:2048, vCores:1> queue=default: capacity=1.0, absoluteCapacity=1.0, usedResources=<memory:12288, vCores:6>, usedCapacity=1.0, absoluteUsedCapacity=1.0, numApps=1, numContainers=6 usedCapacity=1.0 absoluteUsedCapacity=1.0 used=<memory:12288, vCores:6> cluster=<memory:12288, vCores:4>
2016-12-02 23:07:05,434 INFO org.apache.hadoop.yarn.server.resourcemanager.scheduler.capacity.CapacityScheduler: Skipping scheduling since node datanode4:45290 is reserved by application appattempt_1480719777699_0003_000001
2016-12-02 23:07:05,967 INFO org.apache.hadoop.yarn.server.resourcemanager.rmcontainer.RMContainerImpl: container_1480719777699_0003_01_000004 Container Transitioned from RUNNING to COMPLETED
2016-12-02 23:07:05,967 INFO org.apache.hadoop.yarn.server.resourcemanager.scheduler.common.fica.FiCaSchedulerApp: Completed container: container_1480719777699_0003_01_000004 in state: COMPLETED event:FINISHED
2016-12-02 23:07:05,967 INFO org.apache.hadoop.yarn.server.resourcemanager.RMAuditLogger: USER=hdmaster	OPERATION=AM Released Container	TARGET=SchedulerApp	RESULT=SUCCESS	APPID=application_1480719777699_0003	CONTAINERID=container_1480719777699_0003_01_000004
2016-12-02 23:07:05,967 INFO org.apache.hadoop.yarn.server.resourcemanager.scheduler.SchedulerNode: Released container container_1480719777699_0003_01_000004 of capacity <memory:2048, vCores:1> on host datanode1:50178, which currently has 0 containers, <memory:0, vCores:0> used and <memory:3072, vCores:1> available, release resources=true
2016-12-02 23:07:05,968 INFO org.apache.hadoop.yarn.server.resourcemanager.scheduler.capacity.LeafQueue: default used=<memory:10240, vCores:5> numContainers=5 user=hdmaster user-resources=<memory:10240, vCores:5>
2016-12-02 23:07:05,971 INFO org.apache.hadoop.yarn.server.resourcemanager.scheduler.capacity.LeafQueue: completedContainer container=Container: [ContainerId: container_1480719777699_0003_01_000004, NodeId: datanode1:50178, NodeHttpAddress: datanode1:8042, Resource: <memory:2048, vCores:1>, Priority: 20, Token: Token { kind: ContainerToken, service: 10.0.0.6:50178 }, ] queue=default: capacity=1.0, absoluteCapacity=1.0, usedResources=<memory:10240, vCores:5>, usedCapacity=0.8333333, absoluteUsedCapacity=0.8333333, numApps=1, numContainers=5 cluster=<memory:12288, vCores:4>
2016-12-02 23:07:05,971 INFO org.apache.hadoop.yarn.server.resourcemanager.scheduler.capacity.ParentQueue: completedContainer queue=root usedCapacity=0.8333333 absoluteUsedCapacity=0.8333333 used=<memory:10240, vCores:5> cluster=<memory:12288, vCores:4>
2016-12-02 23:07:05,971 INFO org.apache.hadoop.yarn.server.resourcemanager.scheduler.capacity.ParentQueue: Re-sorting completed queue: root.default stats: default: capacity=1.0, absoluteCapacity=1.0, usedResources=<memory:10240, vCores:5>, usedCapacity=0.8333333, absoluteUsedCapacity=0.8333333, numApps=1, numContainers=5
2016-12-02 23:07:05,971 INFO org.apache.hadoop.yarn.server.resourcemanager.scheduler.capacity.CapacityScheduler: Application attempt appattempt_1480719777699_0003_000001 released container container_1480719777699_0003_01_000004 on node: host: datanode1:50178 #containers=0 available=<memory:3072, vCores:1> used=<memory:0, vCores:0> with event: FINISHED
2016-12-02 23:07:05,972 INFO org.apache.hadoop.yarn.server.resourcemanager.scheduler.common.fica.FiCaSchedulerApp: Application application_1480719777699_0003 unreserved  on node host: datanode3:60932 #containers=1 available=<memory:1024, vCores:0> used=<memory:2048, vCores:1>, currently has 1 at priority 5; currentReservation <memory:2048, vCores:1>
2016-12-02 23:07:05,972 INFO org.apache.hadoop.yarn.server.resourcemanager.scheduler.capacity.LeafQueue: default used=<memory:8192, vCores:4> numContainers=4 user=hdmaster user-resources=<memory:8192, vCores:4>
2016-12-02 23:07:05,972 INFO org.apache.hadoop.yarn.server.resourcemanager.scheduler.capacity.LeafQueue: completedContainer container=Container: [ContainerId: container_1480719777699_0003_01_000027, NodeId: datanode3:60932, NodeHttpAddress: datanode3:8042, Resource: <memory:2048, vCores:1>, Priority: 5, Token: null, ] queue=default: capacity=1.0, absoluteCapacity=1.0, usedResources=<memory:8192, vCores:4>, usedCapacity=0.6666667, absoluteUsedCapacity=0.6666667, numApps=1, numContainers=4 cluster=<memory:12288, vCores:4>
2016-12-02 23:07:05,972 INFO org.apache.hadoop.yarn.server.resourcemanager.scheduler.capacity.ParentQueue: completedContainer queue=root usedCapacity=0.6666667 absoluteUsedCapacity=0.6666667 used=<memory:8192, vCores:4> cluster=<memory:12288, vCores:4>
2016-12-02 23:07:05,972 INFO org.apache.hadoop.yarn.server.resourcemanager.rmcontainer.RMContainerImpl: container_1480719777699_0003_01_000035 Container Transitioned from NEW to ALLOCATED
2016-12-02 23:07:05,972 INFO org.apache.hadoop.yarn.server.resourcemanager.RMAuditLogger: USER=hdmaster	OPERATION=AM Allocated Container	TARGET=SchedulerApp	RESULT=SUCCESS	APPID=application_1480719777699_0003	CONTAINERID=container_1480719777699_0003_01_000035
2016-12-02 23:07:05,972 INFO org.apache.hadoop.yarn.server.resourcemanager.scheduler.SchedulerNode: Assigned container container_1480719777699_0003_01_000035 of capacity <memory:2048, vCores:1> on host datanode1:50178, which has 1 containers, <memory:2048, vCores:1> used and <memory:1024, vCores:0> available after allocation
2016-12-02 23:07:05,972 INFO org.apache.hadoop.yarn.server.resourcemanager.scheduler.capacity.LeafQueue: assignedContainer application attempt=appattempt_1480719777699_0003_000001 container=Container: [ContainerId: container_1480719777699_0003_01_000035, NodeId: datanode1:50178, NodeHttpAddress: datanode1:8042, Resource: <memory:2048, vCores:1>, Priority: 5, Token: null, ] queue=default: capacity=1.0, absoluteCapacity=1.0, usedResources=<memory:8192, vCores:4>, usedCapacity=0.6666667, absoluteUsedCapacity=0.6666667, numApps=1, numContainers=4 clusterResource=<memory:12288, vCores:4> type=OFF_SWITCH
2016-12-02 23:07:05,972 INFO org.apache.hadoop.yarn.server.resourcemanager.scheduler.capacity.ParentQueue: Re-sorting assigned queue: root.default stats: default: capacity=1.0, absoluteCapacity=1.0, usedResources=<memory:10240, vCores:5>, usedCapacity=0.8333333, absoluteUsedCapacity=0.8333333, numApps=1, numContainers=5
2016-12-02 23:07:05,972 INFO org.apache.hadoop.yarn.server.resourcemanager.scheduler.capacity.ParentQueue: assignedContainer queue=root usedCapacity=0.8333333 absoluteUsedCapacity=0.8333333 used=<memory:10240, vCores:5> cluster=<memory:12288, vCores:4>
2016-12-02 23:07:06,160 INFO org.apache.hadoop.yarn.server.resourcemanager.rmcontainer.RMContainerImpl: container_1480719777699_0003_01_000035 Container Transitioned from ALLOCATED to ACQUIRED
2016-12-02 23:07:06,304 INFO org.apache.hadoop.yarn.server.resourcemanager.rmcontainer.RMContainerImpl: container_1480719777699_0003_01_000036 Container Transitioned from NEW to RESERVED
2016-12-02 23:07:06,304 INFO org.apache.hadoop.yarn.server.resourcemanager.scheduler.capacity.LeafQueue: Reserved container  application=application_1480719777699_0003 resource=<memory:2048, vCores:1> queue=default: capacity=1.0, absoluteCapacity=1.0, usedResources=<memory:10240, vCores:5>, usedCapacity=0.8333333, absoluteUsedCapacity=0.8333333, numApps=1, numContainers=5 usedCapacity=0.8333333 absoluteUsedCapacity=0.8333333 used=<memory:10240, vCores:5> cluster=<memory:12288, vCores:4>
2016-12-02 23:07:06,304 INFO org.apache.hadoop.yarn.server.resourcemanager.scheduler.capacity.ParentQueue: Re-sorting assigned queue: root.default stats: default: capacity=1.0, absoluteCapacity=1.0, usedResources=<memory:12288, vCores:6>, usedCapacity=1.0, absoluteUsedCapacity=1.0, numApps=1, numContainers=6
2016-12-02 23:07:06,304 INFO org.apache.hadoop.yarn.server.resourcemanager.scheduler.capacity.ParentQueue: assignedContainer queue=root usedCapacity=1.0 absoluteUsedCapacity=1.0 used=<memory:12288, vCores:6> cluster=<memory:12288, vCores:4>
2016-12-02 23:07:06,436 INFO org.apache.hadoop.yarn.server.resourcemanager.scheduler.capacity.CapacityScheduler: Trying to fulfill reservation for application application_1480719777699_0003 on node: datanode4:45290
2016-12-02 23:07:06,437 INFO org.apache.hadoop.yarn.server.resourcemanager.scheduler.capacity.LeafQueue: Reserved container  application=application_1480719777699_0003 resource=<memory:2048, vCores:1> queue=default: capacity=1.0, absoluteCapacity=1.0, usedResources=<memory:12288, vCores:6>, usedCapacity=1.0, absoluteUsedCapacity=1.0, numApps=1, numContainers=6 usedCapacity=1.0 absoluteUsedCapacity=1.0 used=<memory:12288, vCores:6> cluster=<memory:12288, vCores:4>
2016-12-02 23:07:06,437 INFO org.apache.hadoop.yarn.server.resourcemanager.scheduler.capacity.CapacityScheduler: Skipping scheduling since node datanode4:45290 is reserved by application appattempt_1480719777699_0003_000001
2016-12-02 23:07:06,522 INFO org.apache.hadoop.yarn.server.resourcemanager.rmcontainer.RMContainerImpl: container_1480719777699_0003_01_000015 Container Transitioned from RUNNING to COMPLETED
2016-12-02 23:07:06,522 INFO org.apache.hadoop.yarn.server.resourcemanager.scheduler.common.fica.FiCaSchedulerApp: Completed container: container_1480719777699_0003_01_000015 in state: COMPLETED event:FINISHED
2016-12-02 23:07:06,522 INFO org.apache.hadoop.yarn.server.resourcemanager.RMAuditLogger: USER=hdmaster	OPERATION=AM Released Container	TARGET=SchedulerApp	RESULT=SUCCESS	APPID=application_1480719777699_0003	CONTAINERID=container_1480719777699_0003_01_000015
2016-12-02 23:07:06,522 INFO org.apache.hadoop.yarn.server.resourcemanager.scheduler.SchedulerNode: Released container container_1480719777699_0003_01_000015 of capacity <memory:2048, vCores:1> on host datanode4:45290, which currently has 0 containers, <memory:0, vCores:0> used and <memory:3072, vCores:1> available, release resources=true
2016-12-02 23:07:06,522 INFO org.apache.hadoop.yarn.server.resourcemanager.scheduler.capacity.LeafQueue: default used=<memory:10240, vCores:5> numContainers=5 user=hdmaster user-resources=<memory:10240, vCores:5>
2016-12-02 23:07:06,522 INFO org.apache.hadoop.yarn.server.resourcemanager.scheduler.capacity.LeafQueue: completedContainer container=Container: [ContainerId: container_1480719777699_0003_01_000015, NodeId: datanode4:45290, NodeHttpAddress: datanode4:8042, Resource: <memory:2048, vCores:1>, Priority: 20, Token: Token { kind: ContainerToken, service: 10.0.0.9:45290 }, ] queue=default: capacity=1.0, absoluteCapacity=1.0, usedResources=<memory:10240, vCores:5>, usedCapacity=0.8333333, absoluteUsedCapacity=0.8333333, numApps=1, numContainers=5 cluster=<memory:12288, vCores:4>
2016-12-02 23:07:06,522 INFO org.apache.hadoop.yarn.server.resourcemanager.scheduler.capacity.ParentQueue: completedContainer queue=root usedCapacity=0.8333333 absoluteUsedCapacity=0.8333333 used=<memory:10240, vCores:5> cluster=<memory:12288, vCores:4>
2016-12-02 23:07:06,522 INFO org.apache.hadoop.yarn.server.resourcemanager.scheduler.capacity.ParentQueue: Re-sorting completed queue: root.default stats: default: capacity=1.0, absoluteCapacity=1.0, usedResources=<memory:10240, vCores:5>, usedCapacity=0.8333333, absoluteUsedCapacity=0.8333333, numApps=1, numContainers=5
2016-12-02 23:07:06,522 INFO org.apache.hadoop.yarn.server.resourcemanager.scheduler.capacity.CapacityScheduler: Application attempt appattempt_1480719777699_0003_000001 released container container_1480719777699_0003_01_000015 on node: host: datanode4:45290 #containers=0 available=<memory:3072, vCores:1> used=<memory:0, vCores:0> with event: FINISHED
2016-12-02 23:07:06,522 INFO org.apache.hadoop.yarn.server.resourcemanager.scheduler.capacity.CapacityScheduler: Trying to fulfill reservation for application application_1480719777699_0003 on node: datanode4:45290
2016-12-02 23:07:06,522 INFO org.apache.hadoop.yarn.server.resourcemanager.scheduler.common.fica.FiCaSchedulerApp: Application application_1480719777699_0003 unreserved  on node host: datanode4:45290 #containers=0 available=<memory:3072, vCores:1> used=<memory:0, vCores:0>, currently has 1 at priority 5; currentReservation <memory:2048, vCores:1>
2016-12-02 23:07:06,523 INFO org.apache.hadoop.yarn.server.resourcemanager.rmcontainer.RMContainerImpl: container_1480719777699_0003_01_000028 Container Transitioned from NEW to ALLOCATED
2016-12-02 23:07:06,523 INFO org.apache.hadoop.yarn.server.resourcemanager.RMAuditLogger: USER=hdmaster	OPERATION=AM Allocated Container	TARGET=SchedulerApp	RESULT=SUCCESS	APPID=application_1480719777699_0003	CONTAINERID=container_1480719777699_0003_01_000028
2016-12-02 23:07:06,523 INFO org.apache.hadoop.yarn.server.resourcemanager.scheduler.SchedulerNode: Assigned container container_1480719777699_0003_01_000028 of capacity <memory:2048, vCores:1> on host datanode4:45290, which has 1 containers, <memory:2048, vCores:1> used and <memory:1024, vCores:0> available after allocation
2016-12-02 23:07:06,523 INFO org.apache.hadoop.yarn.server.resourcemanager.scheduler.capacity.LeafQueue: assignedContainer application attempt=appattempt_1480719777699_0003_000001 container=Container: [ContainerId: container_1480719777699_0003_01_000028, NodeId: datanode4:45290, NodeHttpAddress: datanode4:8042, Resource: <memory:2048, vCores:1>, Priority: 5, Token: null, ] queue=default: capacity=1.0, absoluteCapacity=1.0, usedResources=<memory:10240, vCores:5>, usedCapacity=0.8333333, absoluteUsedCapacity=0.8333333, numApps=1, numContainers=5 clusterResource=<memory:12288, vCores:4> type=OFF_SWITCH
2016-12-02 23:07:06,974 INFO org.apache.hadoop.yarn.server.resourcemanager.rmcontainer.RMContainerImpl: container_1480719777699_0003_01_000035 Container Transitioned from ACQUIRED to RUNNING
2016-12-02 23:07:07,171 INFO org.apache.hadoop.yarn.server.resourcemanager.rmcontainer.RMContainerImpl: container_1480719777699_0003_01_000028 Container Transitioned from ALLOCATED to ACQUIRED
2016-12-02 23:07:07,306 INFO org.apache.hadoop.yarn.server.resourcemanager.scheduler.capacity.CapacityScheduler: Trying to fulfill reservation for application application_1480719777699_0003 on node: datanode3:60932
2016-12-02 23:07:07,306 INFO org.apache.hadoop.yarn.server.resourcemanager.scheduler.capacity.LeafQueue: Reserved container  application=application_1480719777699_0003 resource=<memory:2048, vCores:1> queue=default: capacity=1.0, absoluteCapacity=1.0, usedResources=<memory:10240, vCores:5>, usedCapacity=0.8333333, absoluteUsedCapacity=0.8333333, numApps=1, numContainers=5 usedCapacity=0.8333333 absoluteUsedCapacity=0.8333333 used=<memory:10240, vCores:5> cluster=<memory:12288, vCores:4>
2016-12-02 23:07:07,306 INFO org.apache.hadoop.yarn.server.resourcemanager.scheduler.capacity.CapacityScheduler: Skipping scheduling since node datanode3:60932 is reserved by application appattempt_1480719777699_0003_000001
2016-12-02 23:07:07,529 INFO org.apache.hadoop.yarn.server.resourcemanager.rmcontainer.RMContainerImpl: container_1480719777699_0003_01_000028 Container Transitioned from ACQUIRED to RUNNING
2016-12-02 23:07:07,530 INFO org.apache.hadoop.yarn.server.resourcemanager.rmcontainer.RMContainerImpl: container_1480719777699_0003_01_000040 Container Transitioned from NEW to RESERVED
2016-12-02 23:07:07,530 INFO org.apache.hadoop.yarn.server.resourcemanager.scheduler.capacity.LeafQueue: Reserved container  application=application_1480719777699_0003 resource=<memory:2048, vCores:1> queue=default: capacity=1.0, absoluteCapacity=1.0, usedResources=<memory:10240, vCores:5>, usedCapacity=0.8333333, absoluteUsedCapacity=0.8333333, numApps=1, numContainers=5 usedCapacity=0.8333333 absoluteUsedCapacity=0.8333333 used=<memory:10240, vCores:5> cluster=<memory:12288, vCores:4>
2016-12-02 23:07:07,530 INFO org.apache.hadoop.yarn.server.resourcemanager.scheduler.capacity.ParentQueue: Re-sorting assigned queue: root.default stats: default: capacity=1.0, absoluteCapacity=1.0, usedResources=<memory:12288, vCores:6>, usedCapacity=1.0, absoluteUsedCapacity=1.0, numApps=1, numContainers=6
2016-12-02 23:07:07,530 INFO org.apache.hadoop.yarn.server.resourcemanager.scheduler.capacity.ParentQueue: assignedContainer queue=root usedCapacity=1.0 absoluteUsedCapacity=1.0 used=<memory:12288, vCores:6> cluster=<memory:12288, vCores:4>
2016-12-02 23:07:08,195 INFO org.apache.hadoop.yarn.server.resourcemanager.rmcontainer.RMContainerImpl: container_1480719777699_0003_01_000026 Container Transitioned from RUNNING to COMPLETED
2016-12-02 23:07:08,195 INFO org.apache.hadoop.yarn.server.resourcemanager.scheduler.common.fica.FiCaSchedulerApp: Completed container: container_1480719777699_0003_01_000026 in state: COMPLETED event:FINISHED
2016-12-02 23:07:08,195 INFO org.apache.hadoop.yarn.server.resourcemanager.RMAuditLogger: USER=hdmaster	OPERATION=AM Released Container	TARGET=SchedulerApp	RESULT=SUCCESS	APPID=application_1480719777699_0003	CONTAINERID=container_1480719777699_0003_01_000026
2016-12-02 23:07:08,195 INFO org.apache.hadoop.yarn.server.resourcemanager.scheduler.SchedulerNode: Released container container_1480719777699_0003_01_000026 of capacity <memory:2048, vCores:1> on host datanode2:60334, which currently has 0 containers, <memory:0, vCores:0> used and <memory:3072, vCores:1> available, release resources=true
2016-12-02 23:07:08,195 INFO org.apache.hadoop.yarn.server.resourcemanager.scheduler.capacity.LeafQueue: default used=<memory:10240, vCores:5> numContainers=5 user=hdmaster user-resources=<memory:10240, vCores:5>
2016-12-02 23:07:08,196 INFO org.apache.hadoop.yarn.server.resourcemanager.scheduler.capacity.LeafQueue: completedContainer container=Container: [ContainerId: container_1480719777699_0003_01_000026, NodeId: datanode2:60334, NodeHttpAddress: datanode2:8042, Resource: <memory:2048, vCores:1>, Priority: 5, Token: Token { kind: ContainerToken, service: 10.0.0.7:60334 }, ] queue=default: capacity=1.0, absoluteCapacity=1.0, usedResources=<memory:10240, vCores:5>, usedCapacity=0.8333333, absoluteUsedCapacity=0.8333333, numApps=1, numContainers=5 cluster=<memory:12288, vCores:4>
2016-12-02 23:07:08,196 INFO org.apache.hadoop.yarn.server.resourcemanager.scheduler.capacity.ParentQueue: completedContainer queue=root usedCapacity=0.8333333 absoluteUsedCapacity=0.8333333 used=<memory:10240, vCores:5> cluster=<memory:12288, vCores:4>
2016-12-02 23:07:08,196 INFO org.apache.hadoop.yarn.server.resourcemanager.scheduler.capacity.ParentQueue: Re-sorting completed queue: root.default stats: default: capacity=1.0, absoluteCapacity=1.0, usedResources=<memory:10240, vCores:5>, usedCapacity=0.8333333, absoluteUsedCapacity=0.8333333, numApps=1, numContainers=5
2016-12-02 23:07:08,196 INFO org.apache.hadoop.yarn.server.resourcemanager.scheduler.capacity.CapacityScheduler: Application attempt appattempt_1480719777699_0003_000001 released container container_1480719777699_0003_01_000026 on node: host: datanode2:60334 #containers=0 available=<memory:3072, vCores:1> used=<memory:0, vCores:0> with event: FINISHED
2016-12-02 23:07:08,196 INFO org.apache.hadoop.yarn.server.resourcemanager.scheduler.common.fica.FiCaSchedulerApp: Application application_1480719777699_0003 unreserved  on node host: datanode3:60932 #containers=1 available=<memory:1024, vCores:0> used=<memory:2048, vCores:1>, currently has 1 at priority 5; currentReservation <memory:2048, vCores:1>
2016-12-02 23:07:08,196 INFO org.apache.hadoop.yarn.server.resourcemanager.scheduler.capacity.LeafQueue: default used=<memory:8192, vCores:4> numContainers=4 user=hdmaster user-resources=<memory:8192, vCores:4>
2016-12-02 23:07:08,196 INFO org.apache.hadoop.yarn.server.resourcemanager.scheduler.capacity.LeafQueue: completedContainer container=Container: [ContainerId: container_1480719777699_0003_01_000036, NodeId: datanode3:60932, NodeHttpAddress: datanode3:8042, Resource: <memory:2048, vCores:1>, Priority: 5, Token: null, ] queue=default: capacity=1.0, absoluteCapacity=1.0, usedResources=<memory:8192, vCores:4>, usedCapacity=0.6666667, absoluteUsedCapacity=0.6666667, numApps=1, numContainers=4 cluster=<memory:12288, vCores:4>
2016-12-02 23:07:08,196 INFO org.apache.hadoop.yarn.server.resourcemanager.scheduler.capacity.ParentQueue: completedContainer queue=root usedCapacity=0.6666667 absoluteUsedCapacity=0.6666667 used=<memory:8192, vCores:4> cluster=<memory:12288, vCores:4>
2016-12-02 23:07:08,196 INFO org.apache.hadoop.yarn.server.resourcemanager.rmcontainer.RMContainerImpl: container_1480719777699_0003_01_000043 Container Transitioned from NEW to ALLOCATED
2016-12-02 23:07:08,196 INFO org.apache.hadoop.yarn.server.resourcemanager.RMAuditLogger: USER=hdmaster	OPERATION=AM Allocated Container	TARGET=SchedulerApp	RESULT=SUCCESS	APPID=application_1480719777699_0003	CONTAINERID=container_1480719777699_0003_01_000043
2016-12-02 23:07:08,196 INFO org.apache.hadoop.yarn.server.resourcemanager.scheduler.SchedulerNode: Assigned container container_1480719777699_0003_01_000043 of capacity <memory:2048, vCores:1> on host datanode2:60334, which has 1 containers, <memory:2048, vCores:1> used and <memory:1024, vCores:0> available after allocation
2016-12-02 23:07:08,196 INFO org.apache.hadoop.yarn.server.resourcemanager.scheduler.capacity.LeafQueue: assignedContainer application attempt=appattempt_1480719777699_0003_000001 container=Container: [ContainerId: container_1480719777699_0003_01_000043, NodeId: datanode2:60334, NodeHttpAddress: datanode2:8042, Resource: <memory:2048, vCores:1>, Priority: 5, Token: null, ] queue=default: capacity=1.0, absoluteCapacity=1.0, usedResources=<memory:8192, vCores:4>, usedCapacity=0.6666667, absoluteUsedCapacity=0.6666667, numApps=1, numContainers=4 clusterResource=<memory:12288, vCores:4> type=OFF_SWITCH
2016-12-02 23:07:08,196 INFO org.apache.hadoop.yarn.server.resourcemanager.scheduler.capacity.ParentQueue: Re-sorting assigned queue: root.default stats: default: capacity=1.0, absoluteCapacity=1.0, usedResources=<memory:10240, vCores:5>, usedCapacity=0.8333333, absoluteUsedCapacity=0.8333333, numApps=1, numContainers=5
2016-12-02 23:07:08,196 INFO org.apache.hadoop.yarn.server.resourcemanager.scheduler.capacity.ParentQueue: assignedContainer queue=root usedCapacity=0.8333333 absoluteUsedCapacity=0.8333333 used=<memory:10240, vCores:5> cluster=<memory:12288, vCores:4>
2016-12-02 23:07:08,533 INFO org.apache.hadoop.yarn.server.resourcemanager.scheduler.capacity.CapacityScheduler: Trying to fulfill reservation for application application_1480719777699_0003 on node: datanode4:45290
2016-12-02 23:07:08,533 INFO org.apache.hadoop.yarn.server.resourcemanager.scheduler.capacity.LeafQueue: Reserved container  application=application_1480719777699_0003 resource=<memory:2048, vCores:1> queue=default: capacity=1.0, absoluteCapacity=1.0, usedResources=<memory:10240, vCores:5>, usedCapacity=0.8333333, absoluteUsedCapacity=0.8333333, numApps=1, numContainers=5 usedCapacity=0.8333333 absoluteUsedCapacity=0.8333333 used=<memory:10240, vCores:5> cluster=<memory:12288, vCores:4>
2016-12-02 23:07:08,533 INFO org.apache.hadoop.yarn.server.resourcemanager.scheduler.capacity.CapacityScheduler: Skipping scheduling since node datanode4:45290 is reserved by application appattempt_1480719777699_0003_000001
2016-12-02 23:07:09,186 INFO org.apache.hadoop.yarn.server.resourcemanager.rmcontainer.RMContainerImpl: container_1480719777699_0003_01_000043 Container Transitioned from ALLOCATED to ACQUIRED
2016-12-02 23:07:09,538 INFO org.apache.hadoop.yarn.server.resourcemanager.scheduler.capacity.CapacityScheduler: Trying to fulfill reservation for application application_1480719777699_0003 on node: datanode4:45290
2016-12-02 23:07:09,539 INFO org.apache.hadoop.yarn.server.resourcemanager.scheduler.capacity.LeafQueue: Reserved container  application=application_1480719777699_0003 resource=<memory:2048, vCores:1> queue=default: capacity=1.0, absoluteCapacity=1.0, usedResources=<memory:10240, vCores:5>, usedCapacity=0.8333333, absoluteUsedCapacity=0.8333333, numApps=1, numContainers=5 usedCapacity=0.8333333 absoluteUsedCapacity=0.8333333 used=<memory:10240, vCores:5> cluster=<memory:12288, vCores:4>
2016-12-02 23:07:09,539 INFO org.apache.hadoop.yarn.server.resourcemanager.scheduler.capacity.CapacityScheduler: Skipping scheduling since node datanode4:45290 is reserved by application appattempt_1480719777699_0003_000001
2016-12-02 23:07:10,203 INFO org.apache.hadoop.yarn.server.resourcemanager.rmcontainer.RMContainerImpl: container_1480719777699_0003_01_000043 Container Transitioned from ACQUIRED to RUNNING
2016-12-02 23:07:10,540 INFO org.apache.hadoop.yarn.server.resourcemanager.scheduler.capacity.CapacityScheduler: Trying to fulfill reservation for application application_1480719777699_0003 on node: datanode4:45290
2016-12-02 23:07:10,541 INFO org.apache.hadoop.yarn.server.resourcemanager.scheduler.capacity.LeafQueue: Reserved container  application=application_1480719777699_0003 resource=<memory:2048, vCores:1> queue=default: capacity=1.0, absoluteCapacity=1.0, usedResources=<memory:10240, vCores:5>, usedCapacity=0.8333333, absoluteUsedCapacity=0.8333333, numApps=1, numContainers=5 usedCapacity=0.8333333 absoluteUsedCapacity=0.8333333 used=<memory:10240, vCores:5> cluster=<memory:12288, vCores:4>
2016-12-02 23:07:10,541 INFO org.apache.hadoop.yarn.server.resourcemanager.scheduler.capacity.CapacityScheduler: Skipping scheduling since node datanode4:45290 is reserved by application appattempt_1480719777699_0003_000001
2016-12-02 23:07:11,543 INFO org.apache.hadoop.yarn.server.resourcemanager.scheduler.capacity.CapacityScheduler: Trying to fulfill reservation for application application_1480719777699_0003 on node: datanode4:45290
2016-12-02 23:07:11,543 INFO org.apache.hadoop.yarn.server.resourcemanager.scheduler.capacity.LeafQueue: Reserved container  application=application_1480719777699_0003 resource=<memory:2048, vCores:1> queue=default: capacity=1.0, absoluteCapacity=1.0, usedResources=<memory:10240, vCores:5>, usedCapacity=0.8333333, absoluteUsedCapacity=0.8333333, numApps=1, numContainers=5 usedCapacity=0.8333333 absoluteUsedCapacity=0.8333333 used=<memory:10240, vCores:5> cluster=<memory:12288, vCores:4>
2016-12-02 23:07:11,543 INFO org.apache.hadoop.yarn.server.resourcemanager.scheduler.capacity.CapacityScheduler: Skipping scheduling since node datanode4:45290 is reserved by application appattempt_1480719777699_0003_000001
2016-12-02 23:07:11,938 INFO org.apache.hadoop.yarn.server.resourcemanager.rmcontainer.RMContainerImpl: container_1480719777699_0003_01_000028 Container Transitioned from RUNNING to COMPLETED
2016-12-02 23:07:11,939 INFO org.apache.hadoop.yarn.server.resourcemanager.scheduler.common.fica.FiCaSchedulerApp: Completed container: container_1480719777699_0003_01_000028 in state: COMPLETED event:FINISHED
2016-12-02 23:07:11,939 INFO org.apache.hadoop.yarn.server.resourcemanager.RMAuditLogger: USER=hdmaster	OPERATION=AM Released Container	TARGET=SchedulerApp	RESULT=SUCCESS	APPID=application_1480719777699_0003	CONTAINERID=container_1480719777699_0003_01_000028
2016-12-02 23:07:11,939 INFO org.apache.hadoop.yarn.server.resourcemanager.scheduler.SchedulerNode: Released container container_1480719777699_0003_01_000028 of capacity <memory:2048, vCores:1> on host datanode4:45290, which currently has 0 containers, <memory:0, vCores:0> used and <memory:3072, vCores:1> available, release resources=true
2016-12-02 23:07:11,939 INFO org.apache.hadoop.yarn.server.resourcemanager.scheduler.capacity.LeafQueue: default used=<memory:8192, vCores:4> numContainers=4 user=hdmaster user-resources=<memory:8192, vCores:4>
2016-12-02 23:07:11,939 INFO org.apache.hadoop.yarn.server.resourcemanager.scheduler.capacity.LeafQueue: completedContainer container=Container: [ContainerId: container_1480719777699_0003_01_000028, NodeId: datanode4:45290, NodeHttpAddress: datanode4:8042, Resource: <memory:2048, vCores:1>, Priority: 5, Token: Token { kind: ContainerToken, service: 10.0.0.9:45290 }, ] queue=default: capacity=1.0, absoluteCapacity=1.0, usedResources=<memory:8192, vCores:4>, usedCapacity=0.6666667, absoluteUsedCapacity=0.6666667, numApps=1, numContainers=4 cluster=<memory:12288, vCores:4>
2016-12-02 23:07:11,939 INFO org.apache.hadoop.yarn.server.resourcemanager.scheduler.capacity.ParentQueue: completedContainer queue=root usedCapacity=0.6666667 absoluteUsedCapacity=0.6666667 used=<memory:8192, vCores:4> cluster=<memory:12288, vCores:4>
2016-12-02 23:07:11,939 INFO org.apache.hadoop.yarn.server.resourcemanager.scheduler.capacity.ParentQueue: Re-sorting completed queue: root.default stats: default: capacity=1.0, absoluteCapacity=1.0, usedResources=<memory:8192, vCores:4>, usedCapacity=0.6666667, absoluteUsedCapacity=0.6666667, numApps=1, numContainers=4
2016-12-02 23:07:11,939 INFO org.apache.hadoop.yarn.server.resourcemanager.scheduler.capacity.CapacityScheduler: Application attempt appattempt_1480719777699_0003_000001 released container container_1480719777699_0003_01_000028 on node: host: datanode4:45290 #containers=0 available=<memory:3072, vCores:1> used=<memory:0, vCores:0> with event: FINISHED
2016-12-02 23:07:11,939 INFO org.apache.hadoop.yarn.server.resourcemanager.scheduler.capacity.CapacityScheduler: Trying to fulfill reservation for application application_1480719777699_0003 on node: datanode4:45290
2016-12-02 23:07:11,939 INFO org.apache.hadoop.yarn.server.resourcemanager.scheduler.common.fica.FiCaSchedulerApp: Application application_1480719777699_0003 unreserved  on node host: datanode4:45290 #containers=0 available=<memory:3072, vCores:1> used=<memory:0, vCores:0>, currently has 0 at priority 5; currentReservation <memory:0, vCores:0>
2016-12-02 23:07:11,939 INFO org.apache.hadoop.yarn.server.resourcemanager.rmcontainer.RMContainerImpl: container_1480719777699_0003_01_000040 Container Transitioned from NEW to ALLOCATED
2016-12-02 23:07:11,939 INFO org.apache.hadoop.yarn.server.resourcemanager.RMAuditLogger: USER=hdmaster	OPERATION=AM Allocated Container	TARGET=SchedulerApp	RESULT=SUCCESS	APPID=application_1480719777699_0003	CONTAINERID=container_1480719777699_0003_01_000040
2016-12-02 23:07:11,939 INFO org.apache.hadoop.yarn.server.resourcemanager.scheduler.SchedulerNode: Assigned container container_1480719777699_0003_01_000040 of capacity <memory:2048, vCores:1> on host datanode4:45290, which has 1 containers, <memory:2048, vCores:1> used and <memory:1024, vCores:0> available after allocation
2016-12-02 23:07:11,939 INFO org.apache.hadoop.yarn.server.resourcemanager.scheduler.capacity.LeafQueue: assignedContainer application attempt=appattempt_1480719777699_0003_000001 container=Container: [ContainerId: container_1480719777699_0003_01_000040, NodeId: datanode4:45290, NodeHttpAddress: datanode4:8042, Resource: <memory:2048, vCores:1>, Priority: 5, Token: null, ] queue=default: capacity=1.0, absoluteCapacity=1.0, usedResources=<memory:8192, vCores:4>, usedCapacity=0.6666667, absoluteUsedCapacity=0.6666667, numApps=1, numContainers=4 clusterResource=<memory:12288, vCores:4> type=OFF_SWITCH
2016-12-02 23:07:12,198 INFO org.apache.hadoop.yarn.server.resourcemanager.rmcontainer.RMContainerImpl: container_1480719777699_0003_01_000040 Container Transitioned from ALLOCATED to ACQUIRED
2016-12-02 23:07:12,198 INFO org.apache.hadoop.yarn.server.resourcemanager.ApplicationMasterService: blacklist are updated in Scheduler.blacklistAdditions: [datanode4], blacklistRemovals: []
2016-12-02 23:07:12,209 INFO org.apache.hadoop.yarn.server.resourcemanager.rmcontainer.RMContainerImpl: container_1480719777699_0003_01_000054 Container Transitioned from NEW to RESERVED
2016-12-02 23:07:12,209 INFO org.apache.hadoop.yarn.server.resourcemanager.scheduler.capacity.LeafQueue: Reserved container  application=application_1480719777699_0003 resource=<memory:2048, vCores:1> queue=default: capacity=1.0, absoluteCapacity=1.0, usedResources=<memory:8192, vCores:4>, usedCapacity=0.6666667, absoluteUsedCapacity=0.6666667, numApps=1, numContainers=4 usedCapacity=0.6666667 absoluteUsedCapacity=0.6666667 used=<memory:8192, vCores:4> cluster=<memory:12288, vCores:4>
2016-12-02 23:07:12,209 INFO org.apache.hadoop.yarn.server.resourcemanager.scheduler.capacity.ParentQueue: Re-sorting assigned queue: root.default stats: default: capacity=1.0, absoluteCapacity=1.0, usedResources=<memory:10240, vCores:5>, usedCapacity=0.8333333, absoluteUsedCapacity=0.8333333, numApps=1, numContainers=5
2016-12-02 23:07:12,209 INFO org.apache.hadoop.yarn.server.resourcemanager.scheduler.capacity.ParentQueue: assignedContainer queue=root usedCapacity=0.8333333 absoluteUsedCapacity=0.8333333 used=<memory:10240, vCores:5> cluster=<memory:12288, vCores:4>
2016-12-02 23:07:12,315 INFO org.apache.hadoop.yarn.server.resourcemanager.rmcontainer.RMContainerImpl: container_1480719777699_0003_01_000055 Container Transitioned from NEW to RESERVED
2016-12-02 23:07:12,315 INFO org.apache.hadoop.yarn.server.resourcemanager.scheduler.capacity.LeafQueue: Reserved container  application=application_1480719777699_0003 resource=<memory:2048, vCores:1> queue=default: capacity=1.0, absoluteCapacity=1.0, usedResources=<memory:10240, vCores:5>, usedCapacity=0.8333333, absoluteUsedCapacity=0.8333333, numApps=1, numContainers=5 usedCapacity=0.8333333 absoluteUsedCapacity=0.8333333 used=<memory:10240, vCores:5> cluster=<memory:12288, vCores:4>
2016-12-02 23:07:12,316 INFO org.apache.hadoop.yarn.server.resourcemanager.scheduler.capacity.ParentQueue: Re-sorting assigned queue: root.default stats: default: capacity=1.0, absoluteCapacity=1.0, usedResources=<memory:12288, vCores:6>, usedCapacity=1.0, absoluteUsedCapacity=1.0, numApps=1, numContainers=6
2016-12-02 23:07:12,316 INFO org.apache.hadoop.yarn.server.resourcemanager.scheduler.capacity.ParentQueue: assignedContainer queue=root usedCapacity=1.0 absoluteUsedCapacity=1.0 used=<memory:12288, vCores:6> cluster=<memory:12288, vCores:4>
2016-12-02 23:07:13,205 INFO org.apache.hadoop.yarn.server.resourcemanager.rmcontainer.RMContainerImpl: container_1480719777699_0003_01_000040 Container Transitioned from ACQUIRED to RELEASED
2016-12-02 23:07:13,205 INFO org.apache.hadoop.yarn.server.resourcemanager.scheduler.common.fica.FiCaSchedulerApp: Completed container: container_1480719777699_0003_01_000040 in state: RELEASED event:RELEASED
2016-12-02 23:07:13,206 INFO org.apache.hadoop.yarn.server.resourcemanager.RMAuditLogger: USER=hdmaster	IP=10.0.0.8	OPERATION=AM Released Container	TARGET=SchedulerApp	RESULT=SUCCESS	APPID=application_1480719777699_0003	CONTAINERID=container_1480719777699_0003_01_000040
2016-12-02 23:07:13,206 INFO org.apache.hadoop.yarn.server.resourcemanager.scheduler.SchedulerNode: Released container container_1480719777699_0003_01_000040 of capacity <memory:2048, vCores:1> on host datanode4:45290, which currently has 0 containers, <memory:0, vCores:0> used and <memory:3072, vCores:1> available, release resources=true
2016-12-02 23:07:13,206 INFO org.apache.hadoop.yarn.server.resourcemanager.scheduler.capacity.LeafQueue: default used=<memory:10240, vCores:5> numContainers=5 user=hdmaster user-resources=<memory:10240, vCores:5>
2016-12-02 23:07:13,207 INFO org.apache.hadoop.yarn.server.resourcemanager.scheduler.capacity.LeafQueue: completedContainer container=Container: [ContainerId: container_1480719777699_0003_01_000040, NodeId: datanode4:45290, NodeHttpAddress: datanode4:8042, Resource: <memory:2048, vCores:1>, Priority: 5, Token: Token { kind: ContainerToken, service: 10.0.0.9:45290 }, ] queue=default: capacity=1.0, absoluteCapacity=1.0, usedResources=<memory:10240, vCores:5>, usedCapacity=0.8333333, absoluteUsedCapacity=0.8333333, numApps=1, numContainers=5 cluster=<memory:12288, vCores:4>
2016-12-02 23:07:13,207 INFO org.apache.hadoop.yarn.server.resourcemanager.scheduler.capacity.ParentQueue: completedContainer queue=root usedCapacity=0.8333333 absoluteUsedCapacity=0.8333333 used=<memory:10240, vCores:5> cluster=<memory:12288, vCores:4>
2016-12-02 23:07:13,207 INFO org.apache.hadoop.yarn.server.resourcemanager.scheduler.capacity.ParentQueue: Re-sorting completed queue: root.default stats: default: capacity=1.0, absoluteCapacity=1.0, usedResources=<memory:10240, vCores:5>, usedCapacity=0.8333333, absoluteUsedCapacity=0.8333333, numApps=1, numContainers=5
2016-12-02 23:07:13,207 INFO org.apache.hadoop.yarn.server.resourcemanager.scheduler.capacity.CapacityScheduler: Application attempt appattempt_1480719777699_0003_000001 released container container_1480719777699_0003_01_000040 on node: host: datanode4:45290 #containers=0 available=<memory:3072, vCores:1> used=<memory:0, vCores:0> with event: RELEASED
2016-12-02 23:07:13,212 INFO org.apache.hadoop.yarn.server.resourcemanager.scheduler.capacity.CapacityScheduler: Trying to fulfill reservation for application application_1480719777699_0003 on node: datanode2:60334
2016-12-02 23:07:13,212 INFO org.apache.hadoop.yarn.server.resourcemanager.scheduler.capacity.LeafQueue: Reserved container  application=application_1480719777699_0003 resource=<memory:2048, vCores:1> queue=default: capacity=1.0, absoluteCapacity=1.0, usedResources=<memory:10240, vCores:5>, usedCapacity=0.8333333, absoluteUsedCapacity=0.8333333, numApps=1, numContainers=5 usedCapacity=0.8333333 absoluteUsedCapacity=0.8333333 used=<memory:10240, vCores:5> cluster=<memory:12288, vCores:4>
2016-12-02 23:07:13,212 INFO org.apache.hadoop.yarn.server.resourcemanager.scheduler.capacity.CapacityScheduler: Skipping scheduling since node datanode2:60334 is reserved by application appattempt_1480719777699_0003_000001
2016-12-02 23:07:13,318 INFO org.apache.hadoop.yarn.server.resourcemanager.scheduler.capacity.CapacityScheduler: Trying to fulfill reservation for application application_1480719777699_0003 on node: datanode3:60932
2016-12-02 23:07:13,318 INFO org.apache.hadoop.yarn.server.resourcemanager.scheduler.capacity.LeafQueue: Reserved container  application=application_1480719777699_0003 resource=<memory:2048, vCores:1> queue=default: capacity=1.0, absoluteCapacity=1.0, usedResources=<memory:10240, vCores:5>, usedCapacity=0.8333333, absoluteUsedCapacity=0.8333333, numApps=1, numContainers=5 usedCapacity=0.8333333 absoluteUsedCapacity=0.8333333 used=<memory:10240, vCores:5> cluster=<memory:12288, vCores:4>
2016-12-02 23:07:13,318 INFO org.apache.hadoop.yarn.server.resourcemanager.scheduler.capacity.CapacityScheduler: Skipping scheduling since node datanode3:60932 is reserved by application appattempt_1480719777699_0003_000001
2016-12-02 23:07:13,746 INFO org.apache.hadoop.yarn.server.resourcemanager.rmcontainer.RMContainerImpl: container_1480719777699_0003_01_000035 Container Transitioned from RUNNING to COMPLETED
2016-12-02 23:07:13,746 INFO org.apache.hadoop.yarn.server.resourcemanager.scheduler.common.fica.FiCaSchedulerApp: Completed container: container_1480719777699_0003_01_000035 in state: COMPLETED event:FINISHED
2016-12-02 23:07:13,747 INFO org.apache.hadoop.yarn.server.resourcemanager.RMAuditLogger: USER=hdmaster	OPERATION=AM Released Container	TARGET=SchedulerApp	RESULT=SUCCESS	APPID=application_1480719777699_0003	CONTAINERID=container_1480719777699_0003_01_000035
2016-12-02 23:07:13,747 INFO org.apache.hadoop.yarn.server.resourcemanager.scheduler.SchedulerNode: Released container container_1480719777699_0003_01_000035 of capacity <memory:2048, vCores:1> on host datanode1:50178, which currently has 0 containers, <memory:0, vCores:0> used and <memory:3072, vCores:1> available, release resources=true
2016-12-02 23:07:13,747 INFO org.apache.hadoop.yarn.server.resourcemanager.scheduler.capacity.LeafQueue: default used=<memory:8192, vCores:4> numContainers=4 user=hdmaster user-resources=<memory:8192, vCores:4>
2016-12-02 23:07:13,749 INFO org.apache.hadoop.yarn.server.resourcemanager.scheduler.capacity.LeafQueue: completedContainer container=Container: [ContainerId: container_1480719777699_0003_01_000035, NodeId: datanode1:50178, NodeHttpAddress: datanode1:8042, Resource: <memory:2048, vCores:1>, Priority: 5, Token: Token { kind: ContainerToken, service: 10.0.0.6:50178 }, ] queue=default: capacity=1.0, absoluteCapacity=1.0, usedResources=<memory:8192, vCores:4>, usedCapacity=0.6666667, absoluteUsedCapacity=0.6666667, numApps=1, numContainers=4 cluster=<memory:12288, vCores:4>
2016-12-02 23:07:13,749 INFO org.apache.hadoop.yarn.server.resourcemanager.scheduler.capacity.ParentQueue: completedContainer queue=root usedCapacity=0.6666667 absoluteUsedCapacity=0.6666667 used=<memory:8192, vCores:4> cluster=<memory:12288, vCores:4>
2016-12-02 23:07:13,749 INFO org.apache.hadoop.yarn.server.resourcemanager.scheduler.capacity.ParentQueue: Re-sorting completed queue: root.default stats: default: capacity=1.0, absoluteCapacity=1.0, usedResources=<memory:8192, vCores:4>, usedCapacity=0.6666667, absoluteUsedCapacity=0.6666667, numApps=1, numContainers=4
2016-12-02 23:07:13,749 INFO org.apache.hadoop.yarn.server.resourcemanager.scheduler.capacity.CapacityScheduler: Application attempt appattempt_1480719777699_0003_000001 released container container_1480719777699_0003_01_000035 on node: host: datanode1:50178 #containers=0 available=<memory:3072, vCores:1> used=<memory:0, vCores:0> with event: FINISHED
2016-12-02 23:07:13,749 INFO org.apache.hadoop.yarn.server.resourcemanager.scheduler.common.fica.FiCaSchedulerApp: Application application_1480719777699_0003 unreserved  on node host: datanode2:60334 #containers=1 available=<memory:1024, vCores:0> used=<memory:2048, vCores:1>, currently has 1 at priority 5; currentReservation <memory:2048, vCores:1>
2016-12-02 23:07:13,749 INFO org.apache.hadoop.yarn.server.resourcemanager.scheduler.capacity.LeafQueue: default used=<memory:6144, vCores:3> numContainers=3 user=hdmaster user-resources=<memory:6144, vCores:3>
2016-12-02 23:07:13,749 INFO org.apache.hadoop.yarn.server.resourcemanager.scheduler.capacity.LeafQueue: completedContainer container=Container: [ContainerId: container_1480719777699_0003_01_000054, NodeId: datanode2:60334, NodeHttpAddress: datanode2:8042, Resource: <memory:2048, vCores:1>, Priority: 5, Token: null, ] queue=default: capacity=1.0, absoluteCapacity=1.0, usedResources=<memory:6144, vCores:3>, usedCapacity=0.5, absoluteUsedCapacity=0.5, numApps=1, numContainers=3 cluster=<memory:12288, vCores:4>
2016-12-02 23:07:13,749 INFO org.apache.hadoop.yarn.server.resourcemanager.scheduler.capacity.ParentQueue: completedContainer queue=root usedCapacity=0.5 absoluteUsedCapacity=0.5 used=<memory:6144, vCores:3> cluster=<memory:12288, vCores:4>
2016-12-02 23:07:13,749 INFO org.apache.hadoop.yarn.server.resourcemanager.rmcontainer.RMContainerImpl: container_1480719777699_0003_01_000057 Container Transitioned from NEW to ALLOCATED
2016-12-02 23:07:13,749 INFO org.apache.hadoop.yarn.server.resourcemanager.RMAuditLogger: USER=hdmaster	OPERATION=AM Allocated Container	TARGET=SchedulerApp	RESULT=SUCCESS	APPID=application_1480719777699_0003	CONTAINERID=container_1480719777699_0003_01_000057
2016-12-02 23:07:13,749 INFO org.apache.hadoop.yarn.server.resourcemanager.scheduler.SchedulerNode: Assigned container container_1480719777699_0003_01_000057 of capacity <memory:2048, vCores:1> on host datanode1:50178, which has 1 containers, <memory:2048, vCores:1> used and <memory:1024, vCores:0> available after allocation
2016-12-02 23:07:13,750 INFO org.apache.hadoop.yarn.server.resourcemanager.scheduler.capacity.LeafQueue: assignedContainer application attempt=appattempt_1480719777699_0003_000001 container=Container: [ContainerId: container_1480719777699_0003_01_000057, NodeId: datanode1:50178, NodeHttpAddress: datanode1:8042, Resource: <memory:2048, vCores:1>, Priority: 5, Token: null, ] queue=default: capacity=1.0, absoluteCapacity=1.0, usedResources=<memory:6144, vCores:3>, usedCapacity=0.5, absoluteUsedCapacity=0.5, numApps=1, numContainers=3 clusterResource=<memory:12288, vCores:4> type=OFF_SWITCH
2016-12-02 23:07:13,750 INFO org.apache.hadoop.yarn.server.resourcemanager.scheduler.capacity.ParentQueue: Re-sorting assigned queue: root.default stats: default: capacity=1.0, absoluteCapacity=1.0, usedResources=<memory:8192, vCores:4>, usedCapacity=0.6666667, absoluteUsedCapacity=0.6666667, numApps=1, numContainers=4
2016-12-02 23:07:13,750 INFO org.apache.hadoop.yarn.server.resourcemanager.scheduler.capacity.ParentQueue: assignedContainer queue=root usedCapacity=0.6666667 absoluteUsedCapacity=0.6666667 used=<memory:8192, vCores:4> cluster=<memory:12288, vCores:4>
2016-12-02 23:07:14,213 INFO org.apache.hadoop.yarn.server.resourcemanager.rmcontainer.RMContainerImpl: container_1480719777699_0003_01_000057 Container Transitioned from ALLOCATED to ACQUIRED
2016-12-02 23:07:14,215 INFO org.apache.hadoop.yarn.server.resourcemanager.rmcontainer.RMContainerImpl: container_1480719777699_0003_01_000058 Container Transitioned from NEW to RESERVED
2016-12-02 23:07:14,215 INFO org.apache.hadoop.yarn.server.resourcemanager.scheduler.capacity.LeafQueue: Reserved container  application=application_1480719777699_0003 resource=<memory:2048, vCores:1> queue=default: capacity=1.0, absoluteCapacity=1.0, usedResources=<memory:8192, vCores:4>, usedCapacity=0.6666667, absoluteUsedCapacity=0.6666667, numApps=1, numContainers=4 usedCapacity=0.6666667 absoluteUsedCapacity=0.6666667 used=<memory:8192, vCores:4> cluster=<memory:12288, vCores:4>
2016-12-02 23:07:14,216 INFO org.apache.hadoop.yarn.server.resourcemanager.scheduler.capacity.ParentQueue: Re-sorting assigned queue: root.default stats: default: capacity=1.0, absoluteCapacity=1.0, usedResources=<memory:10240, vCores:5>, usedCapacity=0.8333333, absoluteUsedCapacity=0.8333333, numApps=1, numContainers=5
2016-12-02 23:07:14,216 INFO org.apache.hadoop.yarn.server.resourcemanager.scheduler.capacity.ParentQueue: assignedContainer queue=root usedCapacity=0.8333333 absoluteUsedCapacity=0.8333333 used=<memory:10240, vCores:5> cluster=<memory:12288, vCores:4>
2016-12-02 23:07:14,321 INFO org.apache.hadoop.yarn.server.resourcemanager.scheduler.capacity.CapacityScheduler: Trying to fulfill reservation for application application_1480719777699_0003 on node: datanode3:60932
2016-12-02 23:07:14,321 INFO org.apache.hadoop.yarn.server.resourcemanager.scheduler.capacity.LeafQueue: Reserved container  application=application_1480719777699_0003 resource=<memory:2048, vCores:1> queue=default: capacity=1.0, absoluteCapacity=1.0, usedResources=<memory:10240, vCores:5>, usedCapacity=0.8333333, absoluteUsedCapacity=0.8333333, numApps=1, numContainers=5 usedCapacity=0.8333333 absoluteUsedCapacity=0.8333333 used=<memory:10240, vCores:5> cluster=<memory:12288, vCores:4>
2016-12-02 23:07:14,321 INFO org.apache.hadoop.yarn.server.resourcemanager.scheduler.capacity.CapacityScheduler: Skipping scheduling since node datanode3:60932 is reserved by application appattempt_1480719777699_0003_000001
2016-12-02 23:07:14,566 INFO org.apache.hadoop.yarn.server.resourcemanager.rmcontainer.RMContainerImpl: container_1480719777699_0003_01_000043 Container Transitioned from RUNNING to COMPLETED
2016-12-02 23:07:14,566 INFO org.apache.hadoop.yarn.server.resourcemanager.scheduler.common.fica.FiCaSchedulerApp: Completed container: container_1480719777699_0003_01_000043 in state: COMPLETED event:FINISHED
2016-12-02 23:07:14,566 INFO org.apache.hadoop.yarn.server.resourcemanager.RMAuditLogger: USER=hdmaster	OPERATION=AM Released Container	TARGET=SchedulerApp	RESULT=SUCCESS	APPID=application_1480719777699_0003	CONTAINERID=container_1480719777699_0003_01_000043
2016-12-02 23:07:14,566 INFO org.apache.hadoop.yarn.server.resourcemanager.scheduler.SchedulerNode: Released container container_1480719777699_0003_01_000043 of capacity <memory:2048, vCores:1> on host datanode2:60334, which currently has 0 containers, <memory:0, vCores:0> used and <memory:3072, vCores:1> available, release resources=true
2016-12-02 23:07:14,566 INFO org.apache.hadoop.yarn.server.resourcemanager.scheduler.capacity.LeafQueue: default used=<memory:8192, vCores:4> numContainers=4 user=hdmaster user-resources=<memory:8192, vCores:4>
2016-12-02 23:07:14,567 INFO org.apache.hadoop.yarn.server.resourcemanager.scheduler.capacity.LeafQueue: completedContainer container=Container: [ContainerId: container_1480719777699_0003_01_000043, NodeId: datanode2:60334, NodeHttpAddress: datanode2:8042, Resource: <memory:2048, vCores:1>, Priority: 5, Token: Token { kind: ContainerToken, service: 10.0.0.7:60334 }, ] queue=default: capacity=1.0, absoluteCapacity=1.0, usedResources=<memory:8192, vCores:4>, usedCapacity=0.6666667, absoluteUsedCapacity=0.6666667, numApps=1, numContainers=4 cluster=<memory:12288, vCores:4>
2016-12-02 23:07:14,567 INFO org.apache.hadoop.yarn.server.resourcemanager.scheduler.capacity.ParentQueue: completedContainer queue=root usedCapacity=0.6666667 absoluteUsedCapacity=0.6666667 used=<memory:8192, vCores:4> cluster=<memory:12288, vCores:4>
2016-12-02 23:07:14,567 INFO org.apache.hadoop.yarn.server.resourcemanager.scheduler.capacity.ParentQueue: Re-sorting completed queue: root.default stats: default: capacity=1.0, absoluteCapacity=1.0, usedResources=<memory:8192, vCores:4>, usedCapacity=0.6666667, absoluteUsedCapacity=0.6666667, numApps=1, numContainers=4
2016-12-02 23:07:14,567 INFO org.apache.hadoop.yarn.server.resourcemanager.scheduler.capacity.CapacityScheduler: Application attempt appattempt_1480719777699_0003_000001 released container container_1480719777699_0003_01_000043 on node: host: datanode2:60334 #containers=0 available=<memory:3072, vCores:1> used=<memory:0, vCores:0> with event: FINISHED
2016-12-02 23:07:14,567 INFO org.apache.hadoop.yarn.server.resourcemanager.scheduler.capacity.CapacityScheduler: Trying to fulfill reservation for application application_1480719777699_0003 on node: datanode2:60334
2016-12-02 23:07:14,567 INFO org.apache.hadoop.yarn.server.resourcemanager.scheduler.common.fica.FiCaSchedulerApp: Application application_1480719777699_0003 unreserved  on node host: datanode2:60334 #containers=0 available=<memory:3072, vCores:1> used=<memory:0, vCores:0>, currently has 1 at priority 5; currentReservation <memory:2048, vCores:1>
2016-12-02 23:07:14,567 INFO org.apache.hadoop.yarn.server.resourcemanager.rmcontainer.RMContainerImpl: container_1480719777699_0003_01_000058 Container Transitioned from NEW to ALLOCATED
2016-12-02 23:07:14,567 INFO org.apache.hadoop.yarn.server.resourcemanager.RMAuditLogger: USER=hdmaster	OPERATION=AM Allocated Container	TARGET=SchedulerApp	RESULT=SUCCESS	APPID=application_1480719777699_0003	CONTAINERID=container_1480719777699_0003_01_000058
2016-12-02 23:07:14,567 INFO org.apache.hadoop.yarn.server.resourcemanager.scheduler.SchedulerNode: Assigned container container_1480719777699_0003_01_000058 of capacity <memory:2048, vCores:1> on host datanode2:60334, which has 1 containers, <memory:2048, vCores:1> used and <memory:1024, vCores:0> available after allocation
2016-12-02 23:07:14,567 INFO org.apache.hadoop.yarn.server.resourcemanager.scheduler.capacity.LeafQueue: assignedContainer application attempt=appattempt_1480719777699_0003_000001 container=Container: [ContainerId: container_1480719777699_0003_01_000058, NodeId: datanode2:60334, NodeHttpAddress: datanode2:8042, Resource: <memory:2048, vCores:1>, Priority: 5, Token: null, ] queue=default: capacity=1.0, absoluteCapacity=1.0, usedResources=<memory:8192, vCores:4>, usedCapacity=0.6666667, absoluteUsedCapacity=0.6666667, numApps=1, numContainers=4 clusterResource=<memory:12288, vCores:4> type=OFF_SWITCH
2016-12-02 23:07:14,567 INFO org.apache.hadoop.yarn.server.resourcemanager.rmcontainer.RMContainerImpl: container_1480719777699_0003_01_000059 Container Transitioned from NEW to RESERVED
2016-12-02 23:07:14,567 INFO org.apache.hadoop.yarn.server.resourcemanager.scheduler.capacity.LeafQueue: Reserved container  application=application_1480719777699_0003 resource=<memory:2048, vCores:1> queue=default: capacity=1.0, absoluteCapacity=1.0, usedResources=<memory:8192, vCores:4>, usedCapacity=0.6666667, absoluteUsedCapacity=0.6666667, numApps=1, numContainers=4 usedCapacity=0.6666667 absoluteUsedCapacity=0.6666667 used=<memory:8192, vCores:4> cluster=<memory:12288, vCores:4>
2016-12-02 23:07:14,567 INFO org.apache.hadoop.yarn.server.resourcemanager.scheduler.capacity.ParentQueue: Re-sorting assigned queue: root.default stats: default: capacity=1.0, absoluteCapacity=1.0, usedResources=<memory:10240, vCores:5>, usedCapacity=0.8333333, absoluteUsedCapacity=0.8333333, numApps=1, numContainers=5
2016-12-02 23:07:14,567 INFO org.apache.hadoop.yarn.server.resourcemanager.scheduler.capacity.ParentQueue: assignedContainer queue=root usedCapacity=0.8333333 absoluteUsedCapacity=0.8333333 used=<memory:10240, vCores:5> cluster=<memory:12288, vCores:4>
2016-12-02 23:07:14,752 INFO org.apache.hadoop.yarn.server.resourcemanager.rmcontainer.RMContainerImpl: container_1480719777699_0003_01_000057 Container Transitioned from ACQUIRED to RUNNING
2016-12-02 23:07:15,219 INFO org.apache.hadoop.yarn.server.resourcemanager.rmcontainer.RMContainerImpl: container_1480719777699_0003_01_000058 Container Transitioned from ALLOCATED to ACQUIRED
2016-12-02 23:07:15,220 INFO org.apache.hadoop.yarn.server.resourcemanager.ApplicationMasterService: blacklist are updated in Scheduler.blacklistAdditions: [datanode2], blacklistRemovals: []
2016-12-02 23:07:15,324 INFO org.apache.hadoop.yarn.server.resourcemanager.scheduler.capacity.CapacityScheduler: Trying to fulfill reservation for application application_1480719777699_0003 on node: datanode3:60932
2016-12-02 23:07:15,324 INFO org.apache.hadoop.yarn.server.resourcemanager.scheduler.capacity.LeafQueue: Reserved container  application=application_1480719777699_0003 resource=<memory:2048, vCores:1> queue=default: capacity=1.0, absoluteCapacity=1.0, usedResources=<memory:10240, vCores:5>, usedCapacity=0.8333333, absoluteUsedCapacity=0.8333333, numApps=1, numContainers=5 usedCapacity=0.8333333 absoluteUsedCapacity=0.8333333 used=<memory:10240, vCores:5> cluster=<memory:12288, vCores:4>
2016-12-02 23:07:15,324 INFO org.apache.hadoop.yarn.server.resourcemanager.scheduler.capacity.CapacityScheduler: Skipping scheduling since node datanode3:60932 is reserved by application appattempt_1480719777699_0003_000001
2016-12-02 23:07:15,569 INFO org.apache.hadoop.yarn.server.resourcemanager.rmcontainer.RMContainerImpl: container_1480719777699_0003_01_000058 Container Transitioned from ACQUIRED to RUNNING
2016-12-02 23:07:15,569 INFO org.apache.hadoop.yarn.server.resourcemanager.scheduler.capacity.CapacityScheduler: Trying to fulfill reservation for application application_1480719777699_0003 on node: datanode2:60334
2016-12-02 23:07:15,569 INFO org.apache.hadoop.yarn.server.resourcemanager.scheduler.capacity.LeafQueue: Reserved container  application=application_1480719777699_0003 resource=<memory:2048, vCores:1> queue=default: capacity=1.0, absoluteCapacity=1.0, usedResources=<memory:10240, vCores:5>, usedCapacity=0.8333333, absoluteUsedCapacity=0.8333333, numApps=1, numContainers=5 usedCapacity=0.8333333 absoluteUsedCapacity=0.8333333 used=<memory:10240, vCores:5> cluster=<memory:12288, vCores:4>
2016-12-02 23:07:15,569 INFO org.apache.hadoop.yarn.server.resourcemanager.scheduler.capacity.CapacityScheduler: Skipping scheduling since node datanode2:60334 is reserved by application appattempt_1480719777699_0003_000001
2016-12-02 23:07:15,762 INFO org.apache.hadoop.yarn.server.resourcemanager.rmcontainer.RMContainerImpl: container_1480719777699_0003_01_000061 Container Transitioned from NEW to RESERVED
2016-12-02 23:07:15,762 INFO org.apache.hadoop.yarn.server.resourcemanager.scheduler.capacity.LeafQueue: Reserved container  application=application_1480719777699_0003 resource=<memory:2048, vCores:1> queue=default: capacity=1.0, absoluteCapacity=1.0, usedResources=<memory:10240, vCores:5>, usedCapacity=0.8333333, absoluteUsedCapacity=0.8333333, numApps=1, numContainers=5 usedCapacity=0.8333333 absoluteUsedCapacity=0.8333333 used=<memory:10240, vCores:5> cluster=<memory:12288, vCores:4>
2016-12-02 23:07:15,762 INFO org.apache.hadoop.yarn.server.resourcemanager.scheduler.capacity.ParentQueue: Re-sorting assigned queue: root.default stats: default: capacity=1.0, absoluteCapacity=1.0, usedResources=<memory:12288, vCores:6>, usedCapacity=1.0, absoluteUsedCapacity=1.0, numApps=1, numContainers=6
2016-12-02 23:07:15,763 INFO org.apache.hadoop.yarn.server.resourcemanager.scheduler.capacity.ParentQueue: assignedContainer queue=root usedCapacity=1.0 absoluteUsedCapacity=1.0 used=<memory:12288, vCores:6> cluster=<memory:12288, vCores:4>
2016-12-02 23:07:16,224 INFO org.apache.hadoop.yarn.server.resourcemanager.ApplicationMasterService: blacklist are updated in Scheduler.blacklistAdditions: [], blacklistRemovals: [datanode4, datanode2]
2016-12-02 23:07:16,326 INFO org.apache.hadoop.yarn.server.resourcemanager.scheduler.capacity.CapacityScheduler: Trying to fulfill reservation for application application_1480719777699_0003 on node: datanode3:60932
2016-12-02 23:07:16,326 INFO org.apache.hadoop.yarn.server.resourcemanager.scheduler.capacity.LeafQueue: Reserved container  application=application_1480719777699_0003 resource=<memory:2048, vCores:1> queue=default: capacity=1.0, absoluteCapacity=1.0, usedResources=<memory:12288, vCores:6>, usedCapacity=1.0, absoluteUsedCapacity=1.0, numApps=1, numContainers=6 usedCapacity=1.0 absoluteUsedCapacity=1.0 used=<memory:12288, vCores:6> cluster=<memory:12288, vCores:4>
2016-12-02 23:07:16,327 INFO org.apache.hadoop.yarn.server.resourcemanager.scheduler.capacity.CapacityScheduler: Skipping scheduling since node datanode3:60932 is reserved by application appattempt_1480719777699_0003_000001
2016-12-02 23:07:16,572 INFO org.apache.hadoop.yarn.server.resourcemanager.scheduler.capacity.CapacityScheduler: Trying to fulfill reservation for application application_1480719777699_0003 on node: datanode2:60334
2016-12-02 23:07:16,572 INFO org.apache.hadoop.yarn.server.resourcemanager.scheduler.capacity.LeafQueue: Reserved container  application=application_1480719777699_0003 resource=<memory:2048, vCores:1> queue=default: capacity=1.0, absoluteCapacity=1.0, usedResources=<memory:12288, vCores:6>, usedCapacity=1.0, absoluteUsedCapacity=1.0, numApps=1, numContainers=6 usedCapacity=1.0 absoluteUsedCapacity=1.0 used=<memory:12288, vCores:6> cluster=<memory:12288, vCores:4>
2016-12-02 23:07:16,572 INFO org.apache.hadoop.yarn.server.resourcemanager.scheduler.capacity.CapacityScheduler: Skipping scheduling since node datanode2:60334 is reserved by application appattempt_1480719777699_0003_000001
2016-12-02 23:07:16,766 INFO org.apache.hadoop.yarn.server.resourcemanager.scheduler.capacity.CapacityScheduler: Trying to fulfill reservation for application application_1480719777699_0003 on node: datanode1:50178
2016-12-02 23:07:16,767 INFO org.apache.hadoop.yarn.server.resourcemanager.scheduler.capacity.LeafQueue: Reserved container  application=application_1480719777699_0003 resource=<memory:2048, vCores:1> queue=default: capacity=1.0, absoluteCapacity=1.0, usedResources=<memory:12288, vCores:6>, usedCapacity=1.0, absoluteUsedCapacity=1.0, numApps=1, numContainers=6 usedCapacity=1.0 absoluteUsedCapacity=1.0 used=<memory:12288, vCores:6> cluster=<memory:12288, vCores:4>
2016-12-02 23:07:16,767 INFO org.apache.hadoop.yarn.server.resourcemanager.scheduler.capacity.CapacityScheduler: Skipping scheduling since node datanode1:50178 is reserved by application appattempt_1480719777699_0003_000001
2016-12-02 23:07:16,954 INFO org.apache.hadoop.yarn.server.resourcemanager.scheduler.common.fica.FiCaSchedulerApp: Application application_1480719777699_0003 unreserved  on node host: datanode2:60334 #containers=1 available=<memory:1024, vCores:0> used=<memory:2048, vCores:1>, currently has 2 at priority 5; currentReservation <memory:4096, vCores:2>
2016-12-02 23:07:16,954 INFO org.apache.hadoop.yarn.server.resourcemanager.scheduler.capacity.LeafQueue: default used=<memory:10240, vCores:5> numContainers=5 user=hdmaster user-resources=<memory:10240, vCores:5>
2016-12-02 23:07:16,954 INFO org.apache.hadoop.yarn.server.resourcemanager.scheduler.capacity.LeafQueue: completedContainer container=Container: [ContainerId: container_1480719777699_0003_01_000059, NodeId: datanode2:60334, NodeHttpAddress: datanode2:8042, Resource: <memory:2048, vCores:1>, Priority: 5, Token: null, ] queue=default: capacity=1.0, absoluteCapacity=1.0, usedResources=<memory:10240, vCores:5>, usedCapacity=0.8333333, absoluteUsedCapacity=0.8333333, numApps=1, numContainers=5 cluster=<memory:12288, vCores:4>
2016-12-02 23:07:16,954 INFO org.apache.hadoop.yarn.server.resourcemanager.scheduler.capacity.ParentQueue: completedContainer queue=root usedCapacity=0.8333333 absoluteUsedCapacity=0.8333333 used=<memory:10240, vCores:5> cluster=<memory:12288, vCores:4>
2016-12-02 23:07:16,954 INFO org.apache.hadoop.yarn.server.resourcemanager.rmcontainer.RMContainerImpl: container_1480719777699_0003_01_000062 Container Transitioned from NEW to ALLOCATED
2016-12-02 23:07:16,955 INFO org.apache.hadoop.yarn.server.resourcemanager.RMAuditLogger: USER=hdmaster	OPERATION=AM Allocated Container	TARGET=SchedulerApp	RESULT=SUCCESS	APPID=application_1480719777699_0003	CONTAINERID=container_1480719777699_0003_01_000062
2016-12-02 23:07:16,955 INFO org.apache.hadoop.yarn.server.resourcemanager.scheduler.SchedulerNode: Assigned container container_1480719777699_0003_01_000062 of capacity <memory:2048, vCores:1> on host datanode4:45290, which has 1 containers, <memory:2048, vCores:1> used and <memory:1024, vCores:0> available after allocation
2016-12-02 23:07:16,955 INFO org.apache.hadoop.yarn.server.resourcemanager.scheduler.capacity.LeafQueue: assignedContainer application attempt=appattempt_1480719777699_0003_000001 container=Container: [ContainerId: container_1480719777699_0003_01_000062, NodeId: datanode4:45290, NodeHttpAddress: datanode4:8042, Resource: <memory:2048, vCores:1>, Priority: 5, Token: null, ] queue=default: capacity=1.0, absoluteCapacity=1.0, usedResources=<memory:10240, vCores:5>, usedCapacity=0.8333333, absoluteUsedCapacity=0.8333333, numApps=1, numContainers=5 clusterResource=<memory:12288, vCores:4> type=OFF_SWITCH
2016-12-02 23:07:16,955 INFO org.apache.hadoop.yarn.server.resourcemanager.scheduler.capacity.ParentQueue: Re-sorting assigned queue: root.default stats: default: capacity=1.0, absoluteCapacity=1.0, usedResources=<memory:12288, vCores:6>, usedCapacity=1.0, absoluteUsedCapacity=1.0, numApps=1, numContainers=6
2016-12-02 23:07:16,955 INFO org.apache.hadoop.yarn.server.resourcemanager.scheduler.capacity.ParentQueue: assignedContainer queue=root usedCapacity=1.0 absoluteUsedCapacity=1.0 used=<memory:12288, vCores:6> cluster=<memory:12288, vCores:4>
2016-12-02 23:07:17,228 INFO org.apache.hadoop.yarn.server.resourcemanager.rmcontainer.RMContainerImpl: container_1480719777699_0003_01_000062 Container Transitioned from ALLOCATED to ACQUIRED
2016-12-02 23:07:17,328 INFO org.apache.hadoop.yarn.server.resourcemanager.scheduler.capacity.CapacityScheduler: Trying to fulfill reservation for application application_1480719777699_0003 on node: datanode3:60932
2016-12-02 23:07:17,328 INFO org.apache.hadoop.yarn.server.resourcemanager.scheduler.capacity.LeafQueue: Reserved container  application=application_1480719777699_0003 resource=<memory:2048, vCores:1> queue=default: capacity=1.0, absoluteCapacity=1.0, usedResources=<memory:12288, vCores:6>, usedCapacity=1.0, absoluteUsedCapacity=1.0, numApps=1, numContainers=6 usedCapacity=1.0 absoluteUsedCapacity=1.0 used=<memory:12288, vCores:6> cluster=<memory:12288, vCores:4>
2016-12-02 23:07:17,328 INFO org.apache.hadoop.yarn.server.resourcemanager.scheduler.capacity.CapacityScheduler: Skipping scheduling since node datanode3:60932 is reserved by application appattempt_1480719777699_0003_000001
2016-12-02 23:07:17,769 INFO org.apache.hadoop.yarn.server.resourcemanager.scheduler.capacity.CapacityScheduler: Trying to fulfill reservation for application application_1480719777699_0003 on node: datanode1:50178
2016-12-02 23:07:17,770 INFO org.apache.hadoop.yarn.server.resourcemanager.scheduler.capacity.LeafQueue: Reserved container  application=application_1480719777699_0003 resource=<memory:2048, vCores:1> queue=default: capacity=1.0, absoluteCapacity=1.0, usedResources=<memory:12288, vCores:6>, usedCapacity=1.0, absoluteUsedCapacity=1.0, numApps=1, numContainers=6 usedCapacity=1.0 absoluteUsedCapacity=1.0 used=<memory:12288, vCores:6> cluster=<memory:12288, vCores:4>
2016-12-02 23:07:17,770 INFO org.apache.hadoop.yarn.server.resourcemanager.scheduler.capacity.CapacityScheduler: Skipping scheduling since node datanode1:50178 is reserved by application appattempt_1480719777699_0003_000001
2016-12-02 23:07:17,958 INFO org.apache.hadoop.yarn.server.resourcemanager.rmcontainer.RMContainerImpl: container_1480719777699_0003_01_000062 Container Transitioned from ACQUIRED to RUNNING
2016-12-02 23:07:18,330 INFO org.apache.hadoop.yarn.server.resourcemanager.scheduler.capacity.CapacityScheduler: Trying to fulfill reservation for application application_1480719777699_0003 on node: datanode3:60932
2016-12-02 23:07:18,330 INFO org.apache.hadoop.yarn.server.resourcemanager.scheduler.capacity.LeafQueue: Reserved container  application=application_1480719777699_0003 resource=<memory:2048, vCores:1> queue=default: capacity=1.0, absoluteCapacity=1.0, usedResources=<memory:12288, vCores:6>, usedCapacity=1.0, absoluteUsedCapacity=1.0, numApps=1, numContainers=6 usedCapacity=1.0 absoluteUsedCapacity=1.0 used=<memory:12288, vCores:6> cluster=<memory:12288, vCores:4>
2016-12-02 23:07:18,331 INFO org.apache.hadoop.yarn.server.resourcemanager.scheduler.capacity.CapacityScheduler: Skipping scheduling since node datanode3:60932 is reserved by application appattempt_1480719777699_0003_000001
2016-12-02 23:07:18,773 INFO org.apache.hadoop.yarn.server.resourcemanager.scheduler.capacity.CapacityScheduler: Trying to fulfill reservation for application application_1480719777699_0003 on node: datanode1:50178
2016-12-02 23:07:18,773 INFO org.apache.hadoop.yarn.server.resourcemanager.scheduler.capacity.LeafQueue: Reserved container  application=application_1480719777699_0003 resource=<memory:2048, vCores:1> queue=default: capacity=1.0, absoluteCapacity=1.0, usedResources=<memory:12288, vCores:6>, usedCapacity=1.0, absoluteUsedCapacity=1.0, numApps=1, numContainers=6 usedCapacity=1.0 absoluteUsedCapacity=1.0 used=<memory:12288, vCores:6> cluster=<memory:12288, vCores:4>
2016-12-02 23:07:18,773 INFO org.apache.hadoop.yarn.server.resourcemanager.scheduler.capacity.CapacityScheduler: Skipping scheduling since node datanode1:50178 is reserved by application appattempt_1480719777699_0003_000001
2016-12-02 23:07:19,332 INFO org.apache.hadoop.yarn.server.resourcemanager.scheduler.capacity.CapacityScheduler: Trying to fulfill reservation for application application_1480719777699_0003 on node: datanode3:60932
2016-12-02 23:07:19,333 INFO org.apache.hadoop.yarn.server.resourcemanager.scheduler.capacity.LeafQueue: Reserved container  application=application_1480719777699_0003 resource=<memory:2048, vCores:1> queue=default: capacity=1.0, absoluteCapacity=1.0, usedResources=<memory:12288, vCores:6>, usedCapacity=1.0, absoluteUsedCapacity=1.0, numApps=1, numContainers=6 usedCapacity=1.0 absoluteUsedCapacity=1.0 used=<memory:12288, vCores:6> cluster=<memory:12288, vCores:4>
2016-12-02 23:07:19,333 INFO org.apache.hadoop.yarn.server.resourcemanager.scheduler.capacity.CapacityScheduler: Skipping scheduling since node datanode3:60932 is reserved by application appattempt_1480719777699_0003_000001
2016-12-02 23:07:19,776 INFO org.apache.hadoop.yarn.server.resourcemanager.scheduler.capacity.CapacityScheduler: Trying to fulfill reservation for application application_1480719777699_0003 on node: datanode1:50178
2016-12-02 23:07:19,776 INFO org.apache.hadoop.yarn.server.resourcemanager.scheduler.capacity.LeafQueue: Reserved container  application=application_1480719777699_0003 resource=<memory:2048, vCores:1> queue=default: capacity=1.0, absoluteCapacity=1.0, usedResources=<memory:12288, vCores:6>, usedCapacity=1.0, absoluteUsedCapacity=1.0, numApps=1, numContainers=6 usedCapacity=1.0 absoluteUsedCapacity=1.0 used=<memory:12288, vCores:6> cluster=<memory:12288, vCores:4>
2016-12-02 23:07:19,776 INFO org.apache.hadoop.yarn.server.resourcemanager.scheduler.capacity.CapacityScheduler: Skipping scheduling since node datanode1:50178 is reserved by application appattempt_1480719777699_0003_000001
2016-12-02 23:07:20,334 INFO org.apache.hadoop.yarn.server.resourcemanager.scheduler.capacity.CapacityScheduler: Trying to fulfill reservation for application application_1480719777699_0003 on node: datanode3:60932
2016-12-02 23:07:20,334 INFO org.apache.hadoop.yarn.server.resourcemanager.scheduler.capacity.LeafQueue: Reserved container  application=application_1480719777699_0003 resource=<memory:2048, vCores:1> queue=default: capacity=1.0, absoluteCapacity=1.0, usedResources=<memory:12288, vCores:6>, usedCapacity=1.0, absoluteUsedCapacity=1.0, numApps=1, numContainers=6 usedCapacity=1.0 absoluteUsedCapacity=1.0 used=<memory:12288, vCores:6> cluster=<memory:12288, vCores:4>
2016-12-02 23:07:20,334 INFO org.apache.hadoop.yarn.server.resourcemanager.scheduler.capacity.CapacityScheduler: Skipping scheduling since node datanode3:60932 is reserved by application appattempt_1480719777699_0003_000001
2016-12-02 23:07:20,557 INFO org.apache.hadoop.yarn.server.resourcemanager.rmcontainer.RMContainerImpl: container_1480719777699_0003_01_000058 Container Transitioned from RUNNING to COMPLETED
2016-12-02 23:07:20,557 INFO org.apache.hadoop.yarn.server.resourcemanager.scheduler.common.fica.FiCaSchedulerApp: Completed container: container_1480719777699_0003_01_000058 in state: COMPLETED event:FINISHED
2016-12-02 23:07:20,557 INFO org.apache.hadoop.yarn.server.resourcemanager.RMAuditLogger: USER=hdmaster	OPERATION=AM Released Container	TARGET=SchedulerApp	RESULT=SUCCESS	APPID=application_1480719777699_0003	CONTAINERID=container_1480719777699_0003_01_000058
2016-12-02 23:07:20,557 INFO org.apache.hadoop.yarn.server.resourcemanager.scheduler.SchedulerNode: Released container container_1480719777699_0003_01_000058 of capacity <memory:2048, vCores:1> on host datanode2:60334, which currently has 0 containers, <memory:0, vCores:0> used and <memory:3072, vCores:1> available, release resources=true
2016-12-02 23:07:20,557 INFO org.apache.hadoop.yarn.server.resourcemanager.scheduler.capacity.LeafQueue: default used=<memory:10240, vCores:5> numContainers=5 user=hdmaster user-resources=<memory:10240, vCores:5>
2016-12-02 23:07:20,557 INFO org.apache.hadoop.yarn.server.resourcemanager.scheduler.capacity.LeafQueue: completedContainer container=Container: [ContainerId: container_1480719777699_0003_01_000058, NodeId: datanode2:60334, NodeHttpAddress: datanode2:8042, Resource: <memory:2048, vCores:1>, Priority: 5, Token: Token { kind: ContainerToken, service: 10.0.0.7:60334 }, ] queue=default: capacity=1.0, absoluteCapacity=1.0, usedResources=<memory:10240, vCores:5>, usedCapacity=0.8333333, absoluteUsedCapacity=0.8333333, numApps=1, numContainers=5 cluster=<memory:12288, vCores:4>
2016-12-02 23:07:20,557 INFO org.apache.hadoop.yarn.server.resourcemanager.scheduler.capacity.ParentQueue: completedContainer queue=root usedCapacity=0.8333333 absoluteUsedCapacity=0.8333333 used=<memory:10240, vCores:5> cluster=<memory:12288, vCores:4>
2016-12-02 23:07:20,557 INFO org.apache.hadoop.yarn.server.resourcemanager.scheduler.capacity.ParentQueue: Re-sorting completed queue: root.default stats: default: capacity=1.0, absoluteCapacity=1.0, usedResources=<memory:10240, vCores:5>, usedCapacity=0.8333333, absoluteUsedCapacity=0.8333333, numApps=1, numContainers=5
2016-12-02 23:07:20,557 INFO org.apache.hadoop.yarn.server.resourcemanager.scheduler.capacity.CapacityScheduler: Application attempt appattempt_1480719777699_0003_000001 released container container_1480719777699_0003_01_000058 on node: host: datanode2:60334 #containers=0 available=<memory:3072, vCores:1> used=<memory:0, vCores:0> with event: FINISHED
2016-12-02 23:07:20,558 INFO org.apache.hadoop.yarn.server.resourcemanager.scheduler.common.fica.FiCaSchedulerApp: Application application_1480719777699_0003 unreserved  on node host: datanode3:60932 #containers=1 available=<memory:1024, vCores:0> used=<memory:2048, vCores:1>, currently has 1 at priority 5; currentReservation <memory:2048, vCores:1>
2016-12-02 23:07:20,558 INFO org.apache.hadoop.yarn.server.resourcemanager.scheduler.capacity.LeafQueue: default used=<memory:8192, vCores:4> numContainers=4 user=hdmaster user-resources=<memory:8192, vCores:4>
2016-12-02 23:07:20,558 INFO org.apache.hadoop.yarn.server.resourcemanager.scheduler.capacity.LeafQueue: completedContainer container=Container: [ContainerId: container_1480719777699_0003_01_000055, NodeId: datanode3:60932, NodeHttpAddress: datanode3:8042, Resource: <memory:2048, vCores:1>, Priority: 5, Token: null, ] queue=default: capacity=1.0, absoluteCapacity=1.0, usedResources=<memory:8192, vCores:4>, usedCapacity=0.6666667, absoluteUsedCapacity=0.6666667, numApps=1, numContainers=4 cluster=<memory:12288, vCores:4>
2016-12-02 23:07:20,558 INFO org.apache.hadoop.yarn.server.resourcemanager.scheduler.capacity.ParentQueue: completedContainer queue=root usedCapacity=0.6666667 absoluteUsedCapacity=0.6666667 used=<memory:8192, vCores:4> cluster=<memory:12288, vCores:4>
2016-12-02 23:07:20,558 INFO org.apache.hadoop.yarn.server.resourcemanager.rmcontainer.RMContainerImpl: container_1480719777699_0003_01_000069 Container Transitioned from NEW to ALLOCATED
2016-12-02 23:07:20,558 INFO org.apache.hadoop.yarn.server.resourcemanager.RMAuditLogger: USER=hdmaster	OPERATION=AM Allocated Container	TARGET=SchedulerApp	RESULT=SUCCESS	APPID=application_1480719777699_0003	CONTAINERID=container_1480719777699_0003_01_000069
2016-12-02 23:07:20,558 INFO org.apache.hadoop.yarn.server.resourcemanager.scheduler.SchedulerNode: Assigned container container_1480719777699_0003_01_000069 of capacity <memory:2048, vCores:1> on host datanode2:60334, which has 1 containers, <memory:2048, vCores:1> used and <memory:1024, vCores:0> available after allocation
2016-12-02 23:07:20,558 INFO org.apache.hadoop.yarn.server.resourcemanager.scheduler.capacity.LeafQueue: assignedContainer application attempt=appattempt_1480719777699_0003_000001 container=Container: [ContainerId: container_1480719777699_0003_01_000069, NodeId: datanode2:60334, NodeHttpAddress: datanode2:8042, Resource: <memory:2048, vCores:1>, Priority: 5, Token: null, ] queue=default: capacity=1.0, absoluteCapacity=1.0, usedResources=<memory:8192, vCores:4>, usedCapacity=0.6666667, absoluteUsedCapacity=0.6666667, numApps=1, numContainers=4 clusterResource=<memory:12288, vCores:4> type=OFF_SWITCH
2016-12-02 23:07:20,558 INFO org.apache.hadoop.yarn.server.resourcemanager.scheduler.capacity.ParentQueue: Re-sorting assigned queue: root.default stats: default: capacity=1.0, absoluteCapacity=1.0, usedResources=<memory:10240, vCores:5>, usedCapacity=0.8333333, absoluteUsedCapacity=0.8333333, numApps=1, numContainers=5
2016-12-02 23:07:20,558 INFO org.apache.hadoop.yarn.server.resourcemanager.scheduler.capacity.ParentQueue: assignedContainer queue=root usedCapacity=0.8333333 absoluteUsedCapacity=0.8333333 used=<memory:10240, vCores:5> cluster=<memory:12288, vCores:4>
2016-12-02 23:07:20,778 INFO org.apache.hadoop.yarn.server.resourcemanager.scheduler.capacity.CapacityScheduler: Trying to fulfill reservation for application application_1480719777699_0003 on node: datanode1:50178
2016-12-02 23:07:20,778 INFO org.apache.hadoop.yarn.server.resourcemanager.scheduler.common.fica.FiCaSchedulerApp: Application application_1480719777699_0003 unreserved  on node host: datanode1:50178 #containers=1 available=<memory:1024, vCores:0> used=<memory:2048, vCores:1>, currently has 0 at priority 5; currentReservation <memory:0, vCores:0>
2016-12-02 23:07:20,778 INFO org.apache.hadoop.yarn.server.resourcemanager.scheduler.capacity.LeafQueue: default used=<memory:8192, vCores:4> numContainers=4 user=hdmaster user-resources=<memory:8192, vCores:4>
2016-12-02 23:07:20,778 INFO org.apache.hadoop.yarn.server.resourcemanager.scheduler.capacity.LeafQueue: completedContainer container=Container: [ContainerId: container_1480719777699_0003_01_000061, NodeId: datanode1:50178, NodeHttpAddress: datanode1:8042, Resource: <memory:2048, vCores:1>, Priority: 5, Token: null, ] queue=default: capacity=1.0, absoluteCapacity=1.0, usedResources=<memory:8192, vCores:4>, usedCapacity=0.6666667, absoluteUsedCapacity=0.6666667, numApps=1, numContainers=4 cluster=<memory:12288, vCores:4>
2016-12-02 23:07:20,778 INFO org.apache.hadoop.yarn.server.resourcemanager.scheduler.capacity.ParentQueue: completedContainer queue=root usedCapacity=0.6666667 absoluteUsedCapacity=0.6666667 used=<memory:8192, vCores:4> cluster=<memory:12288, vCores:4>
2016-12-02 23:07:20,778 INFO org.apache.hadoop.yarn.server.resourcemanager.scheduler.capacity.ParentQueue: Re-sorting completed queue: root.default stats: default: capacity=1.0, absoluteCapacity=1.0, usedResources=<memory:8192, vCores:4>, usedCapacity=0.6666667, absoluteUsedCapacity=0.6666667, numApps=1, numContainers=4
2016-12-02 23:07:21,004 INFO org.apache.hadoop.yarn.server.resourcemanager.rmcontainer.RMContainerImpl: container_1480719777699_0003_01_000062 Container Transitioned from RUNNING to COMPLETED
2016-12-02 23:07:21,004 INFO org.apache.hadoop.yarn.server.resourcemanager.scheduler.common.fica.FiCaSchedulerApp: Completed container: container_1480719777699_0003_01_000062 in state: COMPLETED event:FINISHED
2016-12-02 23:07:21,004 INFO org.apache.hadoop.yarn.server.resourcemanager.RMAuditLogger: USER=hdmaster	OPERATION=AM Released Container	TARGET=SchedulerApp	RESULT=SUCCESS	APPID=application_1480719777699_0003	CONTAINERID=container_1480719777699_0003_01_000062
2016-12-02 23:07:21,004 INFO org.apache.hadoop.yarn.server.resourcemanager.scheduler.SchedulerNode: Released container container_1480719777699_0003_01_000062 of capacity <memory:2048, vCores:1> on host datanode4:45290, which currently has 0 containers, <memory:0, vCores:0> used and <memory:3072, vCores:1> available, release resources=true
2016-12-02 23:07:21,004 INFO org.apache.hadoop.yarn.server.resourcemanager.scheduler.capacity.LeafQueue: default used=<memory:6144, vCores:3> numContainers=3 user=hdmaster user-resources=<memory:6144, vCores:3>
2016-12-02 23:07:21,005 INFO org.apache.hadoop.yarn.server.resourcemanager.scheduler.capacity.LeafQueue: completedContainer container=Container: [ContainerId: container_1480719777699_0003_01_000062, NodeId: datanode4:45290, NodeHttpAddress: datanode4:8042, Resource: <memory:2048, vCores:1>, Priority: 5, Token: Token { kind: ContainerToken, service: 10.0.0.9:45290 }, ] queue=default: capacity=1.0, absoluteCapacity=1.0, usedResources=<memory:6144, vCores:3>, usedCapacity=0.5, absoluteUsedCapacity=0.5, numApps=1, numContainers=3 cluster=<memory:12288, vCores:4>
2016-12-02 23:07:21,005 INFO org.apache.hadoop.yarn.server.resourcemanager.scheduler.capacity.ParentQueue: completedContainer queue=root usedCapacity=0.5 absoluteUsedCapacity=0.5 used=<memory:6144, vCores:3> cluster=<memory:12288, vCores:4>
2016-12-02 23:07:21,005 INFO org.apache.hadoop.yarn.server.resourcemanager.scheduler.capacity.ParentQueue: Re-sorting completed queue: root.default stats: default: capacity=1.0, absoluteCapacity=1.0, usedResources=<memory:6144, vCores:3>, usedCapacity=0.5, absoluteUsedCapacity=0.5, numApps=1, numContainers=3
2016-12-02 23:07:21,005 INFO org.apache.hadoop.yarn.server.resourcemanager.scheduler.capacity.CapacityScheduler: Application attempt appattempt_1480719777699_0003_000001 released container container_1480719777699_0003_01_000062 on node: host: datanode4:45290 #containers=0 available=<memory:3072, vCores:1> used=<memory:0, vCores:0> with event: FINISHED
2016-12-02 23:07:21,243 INFO org.apache.hadoop.yarn.server.resourcemanager.rmcontainer.RMContainerImpl: container_1480719777699_0003_01_000069 Container Transitioned from ALLOCATED to ACQUIRED
2016-12-02 23:07:21,337 INFO org.apache.hadoop.yarn.server.resourcemanager.rmcontainer.RMContainerImpl: container_1480719777699_0003_01_000070 Container Transitioned from NEW to RESERVED
2016-12-02 23:07:21,337 INFO org.apache.hadoop.yarn.server.resourcemanager.scheduler.capacity.LeafQueue: Reserved container  application=application_1480719777699_0003 resource=<memory:2048, vCores:1> queue=default: capacity=1.0, absoluteCapacity=1.0, usedResources=<memory:6144, vCores:3>, usedCapacity=0.5, absoluteUsedCapacity=0.5, numApps=1, numContainers=3 usedCapacity=0.5 absoluteUsedCapacity=0.5 used=<memory:6144, vCores:3> cluster=<memory:12288, vCores:4>
2016-12-02 23:07:21,337 INFO org.apache.hadoop.yarn.server.resourcemanager.scheduler.capacity.ParentQueue: Re-sorting assigned queue: root.default stats: default: capacity=1.0, absoluteCapacity=1.0, usedResources=<memory:8192, vCores:4>, usedCapacity=0.6666667, absoluteUsedCapacity=0.6666667, numApps=1, numContainers=4
2016-12-02 23:07:21,338 INFO org.apache.hadoop.yarn.server.resourcemanager.scheduler.capacity.ParentQueue: assignedContainer queue=root usedCapacity=0.6666667 absoluteUsedCapacity=0.6666667 used=<memory:8192, vCores:4> cluster=<memory:12288, vCores:4>
2016-12-02 23:07:21,559 INFO org.apache.hadoop.yarn.server.resourcemanager.rmcontainer.RMContainerImpl: container_1480719777699_0003_01_000069 Container Transitioned from ACQUIRED to RUNNING
2016-12-02 23:07:21,559 INFO org.apache.hadoop.yarn.server.resourcemanager.rmcontainer.RMContainerImpl: container_1480719777699_0003_01_000071 Container Transitioned from NEW to RESERVED
2016-12-02 23:07:21,559 INFO org.apache.hadoop.yarn.server.resourcemanager.scheduler.capacity.LeafQueue: Reserved container  application=application_1480719777699_0003 resource=<memory:2048, vCores:1> queue=default: capacity=1.0, absoluteCapacity=1.0, usedResources=<memory:8192, vCores:4>, usedCapacity=0.6666667, absoluteUsedCapacity=0.6666667, numApps=1, numContainers=4 usedCapacity=0.6666667 absoluteUsedCapacity=0.6666667 used=<memory:8192, vCores:4> cluster=<memory:12288, vCores:4>
2016-12-02 23:07:21,559 INFO org.apache.hadoop.yarn.server.resourcemanager.scheduler.capacity.ParentQueue: Re-sorting assigned queue: root.default stats: default: capacity=1.0, absoluteCapacity=1.0, usedResources=<memory:10240, vCores:5>, usedCapacity=0.8333333, absoluteUsedCapacity=0.8333333, numApps=1, numContainers=5
2016-12-02 23:07:21,559 INFO org.apache.hadoop.yarn.server.resourcemanager.scheduler.capacity.ParentQueue: assignedContainer queue=root usedCapacity=0.8333333 absoluteUsedCapacity=0.8333333 used=<memory:10240, vCores:5> cluster=<memory:12288, vCores:4>
2016-12-02 23:07:21,782 INFO org.apache.hadoop.yarn.server.resourcemanager.rmcontainer.RMContainerImpl: container_1480719777699_0003_01_000072 Container Transitioned from NEW to RESERVED
2016-12-02 23:07:21,782 INFO org.apache.hadoop.yarn.server.resourcemanager.scheduler.capacity.LeafQueue: Reserved container  application=application_1480719777699_0003 resource=<memory:2048, vCores:1> queue=default: capacity=1.0, absoluteCapacity=1.0, usedResources=<memory:10240, vCores:5>, usedCapacity=0.8333333, absoluteUsedCapacity=0.8333333, numApps=1, numContainers=5 usedCapacity=0.8333333 absoluteUsedCapacity=0.8333333 used=<memory:10240, vCores:5> cluster=<memory:12288, vCores:4>
2016-12-02 23:07:21,782 INFO org.apache.hadoop.yarn.server.resourcemanager.scheduler.capacity.ParentQueue: Re-sorting assigned queue: root.default stats: default: capacity=1.0, absoluteCapacity=1.0, usedResources=<memory:12288, vCores:6>, usedCapacity=1.0, absoluteUsedCapacity=1.0, numApps=1, numContainers=6
2016-12-02 23:07:21,782 INFO org.apache.hadoop.yarn.server.resourcemanager.scheduler.capacity.ParentQueue: assignedContainer queue=root usedCapacity=1.0 absoluteUsedCapacity=1.0 used=<memory:12288, vCores:6> cluster=<memory:12288, vCores:4>
2016-12-02 23:07:22,006 INFO org.apache.hadoop.yarn.server.resourcemanager.scheduler.common.fica.FiCaSchedulerApp: Application application_1480719777699_0003 unreserved  on node host: datanode2:60334 #containers=1 available=<memory:1024, vCores:0> used=<memory:2048, vCores:1>, currently has 2 at priority 5; currentReservation <memory:4096, vCores:2>
2016-12-02 23:07:22,006 INFO org.apache.hadoop.yarn.server.resourcemanager.scheduler.capacity.LeafQueue: default used=<memory:10240, vCores:5> numContainers=5 user=hdmaster user-resources=<memory:10240, vCores:5>
2016-12-02 23:07:22,006 INFO org.apache.hadoop.yarn.server.resourcemanager.scheduler.capacity.LeafQueue: completedContainer container=Container: [ContainerId: container_1480719777699_0003_01_000071, NodeId: datanode2:60334, NodeHttpAddress: datanode2:8042, Resource: <memory:2048, vCores:1>, Priority: 5, Token: null, ] queue=default: capacity=1.0, absoluteCapacity=1.0, usedResources=<memory:10240, vCores:5>, usedCapacity=0.8333333, absoluteUsedCapacity=0.8333333, numApps=1, numContainers=5 cluster=<memory:12288, vCores:4>
2016-12-02 23:07:22,006 INFO org.apache.hadoop.yarn.server.resourcemanager.scheduler.capacity.ParentQueue: completedContainer queue=root usedCapacity=0.8333333 absoluteUsedCapacity=0.8333333 used=<memory:10240, vCores:5> cluster=<memory:12288, vCores:4>
2016-12-02 23:07:22,006 INFO org.apache.hadoop.yarn.server.resourcemanager.rmcontainer.RMContainerImpl: container_1480719777699_0003_01_000073 Container Transitioned from NEW to ALLOCATED
2016-12-02 23:07:22,006 INFO org.apache.hadoop.yarn.server.resourcemanager.RMAuditLogger: USER=hdmaster	OPERATION=AM Allocated Container	TARGET=SchedulerApp	RESULT=SUCCESS	APPID=application_1480719777699_0003	CONTAINERID=container_1480719777699_0003_01_000073
2016-12-02 23:07:22,006 INFO org.apache.hadoop.yarn.server.resourcemanager.scheduler.SchedulerNode: Assigned container container_1480719777699_0003_01_000073 of capacity <memory:2048, vCores:1> on host datanode4:45290, which has 1 containers, <memory:2048, vCores:1> used and <memory:1024, vCores:0> available after allocation
2016-12-02 23:07:22,006 INFO org.apache.hadoop.yarn.server.resourcemanager.scheduler.capacity.LeafQueue: assignedContainer application attempt=appattempt_1480719777699_0003_000001 container=Container: [ContainerId: container_1480719777699_0003_01_000073, NodeId: datanode4:45290, NodeHttpAddress: datanode4:8042, Resource: <memory:2048, vCores:1>, Priority: 5, Token: null, ] queue=default: capacity=1.0, absoluteCapacity=1.0, usedResources=<memory:10240, vCores:5>, usedCapacity=0.8333333, absoluteUsedCapacity=0.8333333, numApps=1, numContainers=5 clusterResource=<memory:12288, vCores:4> type=OFF_SWITCH
2016-12-02 23:07:22,006 INFO org.apache.hadoop.yarn.server.resourcemanager.scheduler.capacity.ParentQueue: Re-sorting assigned queue: root.default stats: default: capacity=1.0, absoluteCapacity=1.0, usedResources=<memory:12288, vCores:6>, usedCapacity=1.0, absoluteUsedCapacity=1.0, numApps=1, numContainers=6
2016-12-02 23:07:22,006 INFO org.apache.hadoop.yarn.server.resourcemanager.scheduler.capacity.ParentQueue: assignedContainer queue=root usedCapacity=1.0 absoluteUsedCapacity=1.0 used=<memory:12288, vCores:6> cluster=<memory:12288, vCores:4>
2016-12-02 23:07:22,086 INFO org.apache.hadoop.yarn.server.resourcemanager.rmcontainer.RMContainerImpl: container_1480719777699_0003_01_000057 Container Transitioned from RUNNING to COMPLETED
2016-12-02 23:07:22,086 INFO org.apache.hadoop.yarn.server.resourcemanager.scheduler.common.fica.FiCaSchedulerApp: Completed container: container_1480719777699_0003_01_000057 in state: COMPLETED event:FINISHED
2016-12-02 23:07:22,086 INFO org.apache.hadoop.yarn.server.resourcemanager.RMAuditLogger: USER=hdmaster	OPERATION=AM Released Container	TARGET=SchedulerApp	RESULT=SUCCESS	APPID=application_1480719777699_0003	CONTAINERID=container_1480719777699_0003_01_000057
2016-12-02 23:07:22,086 INFO org.apache.hadoop.yarn.server.resourcemanager.scheduler.SchedulerNode: Released container container_1480719777699_0003_01_000057 of capacity <memory:2048, vCores:1> on host datanode1:50178, which currently has 0 containers, <memory:0, vCores:0> used and <memory:3072, vCores:1> available, release resources=true
2016-12-02 23:07:22,086 INFO org.apache.hadoop.yarn.server.resourcemanager.scheduler.capacity.LeafQueue: default used=<memory:10240, vCores:5> numContainers=5 user=hdmaster user-resources=<memory:10240, vCores:5>
2016-12-02 23:07:22,086 INFO org.apache.hadoop.yarn.server.resourcemanager.scheduler.capacity.LeafQueue: completedContainer container=Container: [ContainerId: container_1480719777699_0003_01_000057, NodeId: datanode1:50178, NodeHttpAddress: datanode1:8042, Resource: <memory:2048, vCores:1>, Priority: 5, Token: Token { kind: ContainerToken, service: 10.0.0.6:50178 }, ] queue=default: capacity=1.0, absoluteCapacity=1.0, usedResources=<memory:10240, vCores:5>, usedCapacity=0.8333333, absoluteUsedCapacity=0.8333333, numApps=1, numContainers=5 cluster=<memory:12288, vCores:4>
2016-12-02 23:07:22,087 INFO org.apache.hadoop.yarn.server.resourcemanager.scheduler.capacity.ParentQueue: completedContainer queue=root usedCapacity=0.8333333 absoluteUsedCapacity=0.8333333 used=<memory:10240, vCores:5> cluster=<memory:12288, vCores:4>
2016-12-02 23:07:22,087 INFO org.apache.hadoop.yarn.server.resourcemanager.scheduler.capacity.ParentQueue: Re-sorting completed queue: root.default stats: default: capacity=1.0, absoluteCapacity=1.0, usedResources=<memory:10240, vCores:5>, usedCapacity=0.8333333, absoluteUsedCapacity=0.8333333, numApps=1, numContainers=5
2016-12-02 23:07:22,087 INFO org.apache.hadoop.yarn.server.resourcemanager.scheduler.capacity.CapacityScheduler: Application attempt appattempt_1480719777699_0003_000001 released container container_1480719777699_0003_01_000057 on node: host: datanode1:50178 #containers=0 available=<memory:3072, vCores:1> used=<memory:0, vCores:0> with event: FINISHED
2016-12-02 23:07:22,087 INFO org.apache.hadoop.yarn.server.resourcemanager.scheduler.capacity.CapacityScheduler: Trying to fulfill reservation for application application_1480719777699_0003 on node: datanode1:50178
2016-12-02 23:07:22,087 INFO org.apache.hadoop.yarn.server.resourcemanager.scheduler.common.fica.FiCaSchedulerApp: Application application_1480719777699_0003 unreserved  on node host: datanode1:50178 #containers=0 available=<memory:3072, vCores:1> used=<memory:0, vCores:0>, currently has 1 at priority 5; currentReservation <memory:2048, vCores:1>
2016-12-02 23:07:22,087 INFO org.apache.hadoop.yarn.server.resourcemanager.rmcontainer.RMContainerImpl: container_1480719777699_0003_01_000072 Container Transitioned from NEW to ALLOCATED
2016-12-02 23:07:22,087 INFO org.apache.hadoop.yarn.server.resourcemanager.RMAuditLogger: USER=hdmaster	OPERATION=AM Allocated Container	TARGET=SchedulerApp	RESULT=SUCCESS	APPID=application_1480719777699_0003	CONTAINERID=container_1480719777699_0003_01_000072
2016-12-02 23:07:22,087 INFO org.apache.hadoop.yarn.server.resourcemanager.scheduler.SchedulerNode: Assigned container container_1480719777699_0003_01_000072 of capacity <memory:2048, vCores:1> on host datanode1:50178, which has 1 containers, <memory:2048, vCores:1> used and <memory:1024, vCores:0> available after allocation
2016-12-02 23:07:22,087 INFO org.apache.hadoop.yarn.server.resourcemanager.scheduler.capacity.LeafQueue: assignedContainer application attempt=appattempt_1480719777699_0003_000001 container=Container: [ContainerId: container_1480719777699_0003_01_000072, NodeId: datanode1:50178, NodeHttpAddress: datanode1:8042, Resource: <memory:2048, vCores:1>, Priority: 5, Token: null, ] queue=default: capacity=1.0, absoluteCapacity=1.0, usedResources=<memory:10240, vCores:5>, usedCapacity=0.8333333, absoluteUsedCapacity=0.8333333, numApps=1, numContainers=5 clusterResource=<memory:12288, vCores:4> type=OFF_SWITCH
2016-12-02 23:07:22,248 INFO org.apache.hadoop.yarn.server.resourcemanager.rmcontainer.RMContainerImpl: container_1480719777699_0003_01_000073 Container Transitioned from ALLOCATED to ACQUIRED
2016-12-02 23:07:22,249 INFO org.apache.hadoop.yarn.server.resourcemanager.rmcontainer.RMContainerImpl: container_1480719777699_0003_01_000072 Container Transitioned from ALLOCATED to ACQUIRED
2016-12-02 23:07:22,339 INFO org.apache.hadoop.yarn.server.resourcemanager.scheduler.capacity.CapacityScheduler: Trying to fulfill reservation for application application_1480719777699_0003 on node: datanode3:60932
2016-12-02 23:07:22,339 INFO org.apache.hadoop.yarn.server.resourcemanager.scheduler.capacity.LeafQueue: Reserved container  application=application_1480719777699_0003 resource=<memory:2048, vCores:1> queue=default: capacity=1.0, absoluteCapacity=1.0, usedResources=<memory:10240, vCores:5>, usedCapacity=0.8333333, absoluteUsedCapacity=0.8333333, numApps=1, numContainers=5 usedCapacity=0.8333333 absoluteUsedCapacity=0.8333333 used=<memory:10240, vCores:5> cluster=<memory:12288, vCores:4>
2016-12-02 23:07:22,339 INFO org.apache.hadoop.yarn.server.resourcemanager.scheduler.capacity.CapacityScheduler: Skipping scheduling since node datanode3:60932 is reserved by application appattempt_1480719777699_0003_000001
2016-12-02 23:07:22,561 INFO org.apache.hadoop.yarn.server.resourcemanager.rmcontainer.RMContainerImpl: container_1480719777699_0003_01_000075 Container Transitioned from NEW to RESERVED
2016-12-02 23:07:22,561 INFO org.apache.hadoop.yarn.server.resourcemanager.scheduler.capacity.LeafQueue: Reserved container  application=application_1480719777699_0003 resource=<memory:2048, vCores:1> queue=default: capacity=1.0, absoluteCapacity=1.0, usedResources=<memory:10240, vCores:5>, usedCapacity=0.8333333, absoluteUsedCapacity=0.8333333, numApps=1, numContainers=5 usedCapacity=0.8333333 absoluteUsedCapacity=0.8333333 used=<memory:10240, vCores:5> cluster=<memory:12288, vCores:4>
2016-12-02 23:07:22,561 INFO org.apache.hadoop.yarn.server.resourcemanager.scheduler.capacity.ParentQueue: Re-sorting assigned queue: root.default stats: default: capacity=1.0, absoluteCapacity=1.0, usedResources=<memory:12288, vCores:6>, usedCapacity=1.0, absoluteUsedCapacity=1.0, numApps=1, numContainers=6
2016-12-02 23:07:22,561 INFO org.apache.hadoop.yarn.server.resourcemanager.scheduler.capacity.ParentQueue: assignedContainer queue=root usedCapacity=1.0 absoluteUsedCapacity=1.0 used=<memory:12288, vCores:6> cluster=<memory:12288, vCores:4>
2016-12-02 23:07:23,008 INFO org.apache.hadoop.yarn.server.resourcemanager.rmcontainer.RMContainerImpl: container_1480719777699_0003_01_000073 Container Transitioned from ACQUIRED to RUNNING
2016-12-02 23:07:23,097 INFO org.apache.hadoop.yarn.server.resourcemanager.rmcontainer.RMContainerImpl: container_1480719777699_0003_01_000072 Container Transitioned from ACQUIRED to RUNNING
2016-12-02 23:07:23,341 INFO org.apache.hadoop.yarn.server.resourcemanager.scheduler.capacity.CapacityScheduler: Trying to fulfill reservation for application application_1480719777699_0003 on node: datanode3:60932
2016-12-02 23:07:23,342 INFO org.apache.hadoop.yarn.server.resourcemanager.scheduler.capacity.LeafQueue: Reserved container  application=application_1480719777699_0003 resource=<memory:2048, vCores:1> queue=default: capacity=1.0, absoluteCapacity=1.0, usedResources=<memory:12288, vCores:6>, usedCapacity=1.0, absoluteUsedCapacity=1.0, numApps=1, numContainers=6 usedCapacity=1.0 absoluteUsedCapacity=1.0 used=<memory:12288, vCores:6> cluster=<memory:12288, vCores:4>
2016-12-02 23:07:23,342 INFO org.apache.hadoop.yarn.server.resourcemanager.scheduler.capacity.CapacityScheduler: Skipping scheduling since node datanode3:60932 is reserved by application appattempt_1480719777699_0003_000001
2016-12-02 23:07:23,564 INFO org.apache.hadoop.yarn.server.resourcemanager.scheduler.capacity.CapacityScheduler: Trying to fulfill reservation for application application_1480719777699_0003 on node: datanode2:60334
2016-12-02 23:07:23,565 INFO org.apache.hadoop.yarn.server.resourcemanager.scheduler.capacity.LeafQueue: Reserved container  application=application_1480719777699_0003 resource=<memory:2048, vCores:1> queue=default: capacity=1.0, absoluteCapacity=1.0, usedResources=<memory:12288, vCores:6>, usedCapacity=1.0, absoluteUsedCapacity=1.0, numApps=1, numContainers=6 usedCapacity=1.0 absoluteUsedCapacity=1.0 used=<memory:12288, vCores:6> cluster=<memory:12288, vCores:4>
2016-12-02 23:07:23,565 INFO org.apache.hadoop.yarn.server.resourcemanager.scheduler.capacity.CapacityScheduler: Skipping scheduling since node datanode2:60334 is reserved by application appattempt_1480719777699_0003_000001
2016-12-02 23:07:24,343 INFO org.apache.hadoop.yarn.server.resourcemanager.scheduler.capacity.CapacityScheduler: Trying to fulfill reservation for application application_1480719777699_0003 on node: datanode3:60932
2016-12-02 23:07:24,343 INFO org.apache.hadoop.yarn.server.resourcemanager.scheduler.capacity.LeafQueue: Reserved container  application=application_1480719777699_0003 resource=<memory:2048, vCores:1> queue=default: capacity=1.0, absoluteCapacity=1.0, usedResources=<memory:12288, vCores:6>, usedCapacity=1.0, absoluteUsedCapacity=1.0, numApps=1, numContainers=6 usedCapacity=1.0 absoluteUsedCapacity=1.0 used=<memory:12288, vCores:6> cluster=<memory:12288, vCores:4>
2016-12-02 23:07:24,344 INFO org.apache.hadoop.yarn.server.resourcemanager.scheduler.capacity.CapacityScheduler: Skipping scheduling since node datanode3:60932 is reserved by application appattempt_1480719777699_0003_000001
2016-12-02 23:07:24,572 INFO org.apache.hadoop.yarn.server.resourcemanager.scheduler.capacity.CapacityScheduler: Trying to fulfill reservation for application application_1480719777699_0003 on node: datanode2:60334
2016-12-02 23:07:24,572 INFO org.apache.hadoop.yarn.server.resourcemanager.scheduler.capacity.LeafQueue: Reserved container  application=application_1480719777699_0003 resource=<memory:2048, vCores:1> queue=default: capacity=1.0, absoluteCapacity=1.0, usedResources=<memory:12288, vCores:6>, usedCapacity=1.0, absoluteUsedCapacity=1.0, numApps=1, numContainers=6 usedCapacity=1.0 absoluteUsedCapacity=1.0 used=<memory:12288, vCores:6> cluster=<memory:12288, vCores:4>
2016-12-02 23:07:24,572 INFO org.apache.hadoop.yarn.server.resourcemanager.scheduler.capacity.CapacityScheduler: Skipping scheduling since node datanode2:60334 is reserved by application appattempt_1480719777699_0003_000001
2016-12-02 23:07:25,346 INFO org.apache.hadoop.yarn.server.resourcemanager.scheduler.capacity.CapacityScheduler: Trying to fulfill reservation for application application_1480719777699_0003 on node: datanode3:60932
2016-12-02 23:07:25,346 INFO org.apache.hadoop.yarn.server.resourcemanager.scheduler.capacity.LeafQueue: Reserved container  application=application_1480719777699_0003 resource=<memory:2048, vCores:1> queue=default: capacity=1.0, absoluteCapacity=1.0, usedResources=<memory:12288, vCores:6>, usedCapacity=1.0, absoluteUsedCapacity=1.0, numApps=1, numContainers=6 usedCapacity=1.0 absoluteUsedCapacity=1.0 used=<memory:12288, vCores:6> cluster=<memory:12288, vCores:4>
2016-12-02 23:07:25,346 INFO org.apache.hadoop.yarn.server.resourcemanager.scheduler.capacity.CapacityScheduler: Skipping scheduling since node datanode3:60932 is reserved by application appattempt_1480719777699_0003_000001
2016-12-02 23:07:25,582 INFO org.apache.hadoop.yarn.server.resourcemanager.scheduler.capacity.CapacityScheduler: Trying to fulfill reservation for application application_1480719777699_0003 on node: datanode2:60334
2016-12-02 23:07:25,583 INFO org.apache.hadoop.yarn.server.resourcemanager.scheduler.capacity.LeafQueue: Reserved container  application=application_1480719777699_0003 resource=<memory:2048, vCores:1> queue=default: capacity=1.0, absoluteCapacity=1.0, usedResources=<memory:12288, vCores:6>, usedCapacity=1.0, absoluteUsedCapacity=1.0, numApps=1, numContainers=6 usedCapacity=1.0 absoluteUsedCapacity=1.0 used=<memory:12288, vCores:6> cluster=<memory:12288, vCores:4>
2016-12-02 23:07:25,583 INFO org.apache.hadoop.yarn.server.resourcemanager.scheduler.capacity.CapacityScheduler: Skipping scheduling since node datanode2:60334 is reserved by application appattempt_1480719777699_0003_000001
2016-12-02 23:07:26,324 INFO org.apache.hadoop.yarn.server.resourcemanager.rmcontainer.RMContainerImpl: container_1480719777699_0003_01_000069 Container Transitioned from RUNNING to COMPLETED
2016-12-02 23:07:26,324 INFO org.apache.hadoop.yarn.server.resourcemanager.scheduler.common.fica.FiCaSchedulerApp: Completed container: container_1480719777699_0003_01_000069 in state: COMPLETED event:FINISHED
2016-12-02 23:07:26,324 INFO org.apache.hadoop.yarn.server.resourcemanager.RMAuditLogger: USER=hdmaster	OPERATION=AM Released Container	TARGET=SchedulerApp	RESULT=SUCCESS	APPID=application_1480719777699_0003	CONTAINERID=container_1480719777699_0003_01_000069
2016-12-02 23:07:26,324 INFO org.apache.hadoop.yarn.server.resourcemanager.scheduler.SchedulerNode: Released container container_1480719777699_0003_01_000069 of capacity <memory:2048, vCores:1> on host datanode2:60334, which currently has 0 containers, <memory:0, vCores:0> used and <memory:3072, vCores:1> available, release resources=true
2016-12-02 23:07:26,324 INFO org.apache.hadoop.yarn.server.resourcemanager.scheduler.capacity.LeafQueue: default used=<memory:10240, vCores:5> numContainers=5 user=hdmaster user-resources=<memory:10240, vCores:5>
2016-12-02 23:07:26,325 INFO org.apache.hadoop.yarn.server.resourcemanager.scheduler.capacity.LeafQueue: completedContainer container=Container: [ContainerId: container_1480719777699_0003_01_000069, NodeId: datanode2:60334, NodeHttpAddress: datanode2:8042, Resource: <memory:2048, vCores:1>, Priority: 5, Token: Token { kind: ContainerToken, service: 10.0.0.7:60334 }, ] queue=default: capacity=1.0, absoluteCapacity=1.0, usedResources=<memory:10240, vCores:5>, usedCapacity=0.8333333, absoluteUsedCapacity=0.8333333, numApps=1, numContainers=5 cluster=<memory:12288, vCores:4>
2016-12-02 23:07:26,325 INFO org.apache.hadoop.yarn.server.resourcemanager.scheduler.capacity.ParentQueue: completedContainer queue=root usedCapacity=0.8333333 absoluteUsedCapacity=0.8333333 used=<memory:10240, vCores:5> cluster=<memory:12288, vCores:4>
2016-12-02 23:07:26,325 INFO org.apache.hadoop.yarn.server.resourcemanager.scheduler.capacity.ParentQueue: Re-sorting completed queue: root.default stats: default: capacity=1.0, absoluteCapacity=1.0, usedResources=<memory:10240, vCores:5>, usedCapacity=0.8333333, absoluteUsedCapacity=0.8333333, numApps=1, numContainers=5
2016-12-02 23:07:26,325 INFO org.apache.hadoop.yarn.server.resourcemanager.scheduler.capacity.CapacityScheduler: Application attempt appattempt_1480719777699_0003_000001 released container container_1480719777699_0003_01_000069 on node: host: datanode2:60334 #containers=0 available=<memory:3072, vCores:1> used=<memory:0, vCores:0> with event: FINISHED
2016-12-02 23:07:26,325 INFO org.apache.hadoop.yarn.server.resourcemanager.scheduler.capacity.CapacityScheduler: Trying to fulfill reservation for application application_1480719777699_0003 on node: datanode2:60334
2016-12-02 23:07:26,325 INFO org.apache.hadoop.yarn.server.resourcemanager.scheduler.common.fica.FiCaSchedulerApp: Application application_1480719777699_0003 unreserved  on node host: datanode2:60334 #containers=0 available=<memory:3072, vCores:1> used=<memory:0, vCores:0>, currently has 1 at priority 5; currentReservation <memory:2048, vCores:1>
2016-12-02 23:07:26,325 INFO org.apache.hadoop.yarn.server.resourcemanager.rmcontainer.RMContainerImpl: container_1480719777699_0003_01_000075 Container Transitioned from NEW to ALLOCATED
2016-12-02 23:07:26,325 INFO org.apache.hadoop.yarn.server.resourcemanager.RMAuditLogger: USER=hdmaster	OPERATION=AM Allocated Container	TARGET=SchedulerApp	RESULT=SUCCESS	APPID=application_1480719777699_0003	CONTAINERID=container_1480719777699_0003_01_000075
2016-12-02 23:07:26,325 INFO org.apache.hadoop.yarn.server.resourcemanager.scheduler.SchedulerNode: Assigned container container_1480719777699_0003_01_000075 of capacity <memory:2048, vCores:1> on host datanode2:60334, which has 1 containers, <memory:2048, vCores:1> used and <memory:1024, vCores:0> available after allocation
2016-12-02 23:07:26,326 INFO org.apache.hadoop.yarn.server.resourcemanager.scheduler.capacity.LeafQueue: assignedContainer application attempt=appattempt_1480719777699_0003_000001 container=Container: [ContainerId: container_1480719777699_0003_01_000075, NodeId: datanode2:60334, NodeHttpAddress: datanode2:8042, Resource: <memory:2048, vCores:1>, Priority: 5, Token: null, ] queue=default: capacity=1.0, absoluteCapacity=1.0, usedResources=<memory:10240, vCores:5>, usedCapacity=0.8333333, absoluteUsedCapacity=0.8333333, numApps=1, numContainers=5 clusterResource=<memory:12288, vCores:4> type=OFF_SWITCH
2016-12-02 23:07:26,350 INFO org.apache.hadoop.yarn.server.resourcemanager.scheduler.capacity.CapacityScheduler: Trying to fulfill reservation for application application_1480719777699_0003 on node: datanode3:60932
2016-12-02 23:07:26,350 INFO org.apache.hadoop.yarn.server.resourcemanager.scheduler.capacity.LeafQueue: Reserved container  application=application_1480719777699_0003 resource=<memory:2048, vCores:1> queue=default: capacity=1.0, absoluteCapacity=1.0, usedResources=<memory:10240, vCores:5>, usedCapacity=0.8333333, absoluteUsedCapacity=0.8333333, numApps=1, numContainers=5 usedCapacity=0.8333333 absoluteUsedCapacity=0.8333333 used=<memory:10240, vCores:5> cluster=<memory:12288, vCores:4>
2016-12-02 23:07:26,350 INFO org.apache.hadoop.yarn.server.resourcemanager.scheduler.capacity.CapacityScheduler: Skipping scheduling since node datanode3:60932 is reserved by application appattempt_1480719777699_0003_000001
2016-12-02 23:07:26,651 INFO org.apache.hadoop.yarn.server.resourcemanager.rmcontainer.RMContainerImpl: container_1480719777699_0003_01_000073 Container Transitioned from RUNNING to COMPLETED
2016-12-02 23:07:26,651 INFO org.apache.hadoop.yarn.server.resourcemanager.scheduler.common.fica.FiCaSchedulerApp: Completed container: container_1480719777699_0003_01_000073 in state: COMPLETED event:FINISHED
2016-12-02 23:07:26,651 INFO org.apache.hadoop.yarn.server.resourcemanager.RMAuditLogger: USER=hdmaster	OPERATION=AM Released Container	TARGET=SchedulerApp	RESULT=SUCCESS	APPID=application_1480719777699_0003	CONTAINERID=container_1480719777699_0003_01_000073
2016-12-02 23:07:26,651 INFO org.apache.hadoop.yarn.server.resourcemanager.scheduler.SchedulerNode: Released container container_1480719777699_0003_01_000073 of capacity <memory:2048, vCores:1> on host datanode4:45290, which currently has 0 containers, <memory:0, vCores:0> used and <memory:3072, vCores:1> available, release resources=true
2016-12-02 23:07:26,651 INFO org.apache.hadoop.yarn.server.resourcemanager.scheduler.capacity.LeafQueue: default used=<memory:8192, vCores:4> numContainers=4 user=hdmaster user-resources=<memory:8192, vCores:4>
2016-12-02 23:07:26,651 INFO org.apache.hadoop.yarn.server.resourcemanager.scheduler.capacity.LeafQueue: completedContainer container=Container: [ContainerId: container_1480719777699_0003_01_000073, NodeId: datanode4:45290, NodeHttpAddress: datanode4:8042, Resource: <memory:2048, vCores:1>, Priority: 5, Token: Token { kind: ContainerToken, service: 10.0.0.9:45290 }, ] queue=default: capacity=1.0, absoluteCapacity=1.0, usedResources=<memory:8192, vCores:4>, usedCapacity=0.6666667, absoluteUsedCapacity=0.6666667, numApps=1, numContainers=4 cluster=<memory:12288, vCores:4>
2016-12-02 23:07:26,651 INFO org.apache.hadoop.yarn.server.resourcemanager.scheduler.capacity.ParentQueue: completedContainer queue=root usedCapacity=0.6666667 absoluteUsedCapacity=0.6666667 used=<memory:8192, vCores:4> cluster=<memory:12288, vCores:4>
2016-12-02 23:07:26,651 INFO org.apache.hadoop.yarn.server.resourcemanager.scheduler.capacity.ParentQueue: Re-sorting completed queue: root.default stats: default: capacity=1.0, absoluteCapacity=1.0, usedResources=<memory:8192, vCores:4>, usedCapacity=0.6666667, absoluteUsedCapacity=0.6666667, numApps=1, numContainers=4
2016-12-02 23:07:26,651 INFO org.apache.hadoop.yarn.server.resourcemanager.scheduler.capacity.CapacityScheduler: Application attempt appattempt_1480719777699_0003_000001 released container container_1480719777699_0003_01_000073 on node: host: datanode4:45290 #containers=0 available=<memory:3072, vCores:1> used=<memory:0, vCores:0> with event: FINISHED
2016-12-02 23:07:26,652 INFO org.apache.hadoop.yarn.server.resourcemanager.scheduler.common.fica.FiCaSchedulerApp: Application application_1480719777699_0003 unreserved  on node host: datanode3:60932 #containers=1 available=<memory:1024, vCores:0> used=<memory:2048, vCores:1>, currently has 0 at priority 5; currentReservation <memory:0, vCores:0>
2016-12-02 23:07:26,652 INFO org.apache.hadoop.yarn.server.resourcemanager.scheduler.capacity.LeafQueue: default used=<memory:6144, vCores:3> numContainers=3 user=hdmaster user-resources=<memory:6144, vCores:3>
2016-12-02 23:07:26,652 INFO org.apache.hadoop.yarn.server.resourcemanager.scheduler.capacity.LeafQueue: completedContainer container=Container: [ContainerId: container_1480719777699_0003_01_000070, NodeId: datanode3:60932, NodeHttpAddress: datanode3:8042, Resource: <memory:2048, vCores:1>, Priority: 5, Token: null, ] queue=default: capacity=1.0, absoluteCapacity=1.0, usedResources=<memory:6144, vCores:3>, usedCapacity=0.5, absoluteUsedCapacity=0.5, numApps=1, numContainers=3 cluster=<memory:12288, vCores:4>
2016-12-02 23:07:26,652 INFO org.apache.hadoop.yarn.server.resourcemanager.scheduler.capacity.ParentQueue: completedContainer queue=root usedCapacity=0.5 absoluteUsedCapacity=0.5 used=<memory:6144, vCores:3> cluster=<memory:12288, vCores:4>
2016-12-02 23:07:26,652 INFO org.apache.hadoop.yarn.server.resourcemanager.rmcontainer.RMContainerImpl: container_1480719777699_0003_01_000085 Container Transitioned from NEW to ALLOCATED
2016-12-02 23:07:26,652 INFO org.apache.hadoop.yarn.server.resourcemanager.RMAuditLogger: USER=hdmaster	OPERATION=AM Allocated Container	TARGET=SchedulerApp	RESULT=SUCCESS	APPID=application_1480719777699_0003	CONTAINERID=container_1480719777699_0003_01_000085
2016-12-02 23:07:26,652 INFO org.apache.hadoop.yarn.server.resourcemanager.scheduler.SchedulerNode: Assigned container container_1480719777699_0003_01_000085 of capacity <memory:2048, vCores:1> on host datanode4:45290, which has 1 containers, <memory:2048, vCores:1> used and <memory:1024, vCores:0> available after allocation
2016-12-02 23:07:26,652 INFO org.apache.hadoop.yarn.server.resourcemanager.scheduler.capacity.LeafQueue: assignedContainer application attempt=appattempt_1480719777699_0003_000001 container=Container: [ContainerId: container_1480719777699_0003_01_000085, NodeId: datanode4:45290, NodeHttpAddress: datanode4:8042, Resource: <memory:2048, vCores:1>, Priority: 5, Token: null, ] queue=default: capacity=1.0, absoluteCapacity=1.0, usedResources=<memory:6144, vCores:3>, usedCapacity=0.5, absoluteUsedCapacity=0.5, numApps=1, numContainers=3 clusterResource=<memory:12288, vCores:4> type=OFF_SWITCH
2016-12-02 23:07:26,652 INFO org.apache.hadoop.yarn.server.resourcemanager.scheduler.capacity.ParentQueue: Re-sorting assigned queue: root.default stats: default: capacity=1.0, absoluteCapacity=1.0, usedResources=<memory:8192, vCores:4>, usedCapacity=0.6666667, absoluteUsedCapacity=0.6666667, numApps=1, numContainers=4
2016-12-02 23:07:26,652 INFO org.apache.hadoop.yarn.server.resourcemanager.scheduler.capacity.ParentQueue: assignedContainer queue=root usedCapacity=0.6666667 absoluteUsedCapacity=0.6666667 used=<memory:8192, vCores:4> cluster=<memory:12288, vCores:4>
2016-12-02 23:07:26,772 INFO org.apache.hadoop.yarn.server.resourcemanager.rmcontainer.RMContainerImpl: container_1480719777699_0003_01_000072 Container Transitioned from RUNNING to COMPLETED
2016-12-02 23:07:26,772 INFO org.apache.hadoop.yarn.server.resourcemanager.scheduler.common.fica.FiCaSchedulerApp: Completed container: container_1480719777699_0003_01_000072 in state: COMPLETED event:FINISHED
2016-12-02 23:07:26,772 INFO org.apache.hadoop.yarn.server.resourcemanager.RMAuditLogger: USER=hdmaster	OPERATION=AM Released Container	TARGET=SchedulerApp	RESULT=SUCCESS	APPID=application_1480719777699_0003	CONTAINERID=container_1480719777699_0003_01_000072
2016-12-02 23:07:26,772 INFO org.apache.hadoop.yarn.server.resourcemanager.scheduler.SchedulerNode: Released container container_1480719777699_0003_01_000072 of capacity <memory:2048, vCores:1> on host datanode1:50178, which currently has 0 containers, <memory:0, vCores:0> used and <memory:3072, vCores:1> available, release resources=true
2016-12-02 23:07:26,772 INFO org.apache.hadoop.yarn.server.resourcemanager.scheduler.capacity.LeafQueue: default used=<memory:6144, vCores:3> numContainers=3 user=hdmaster user-resources=<memory:6144, vCores:3>
2016-12-02 23:07:26,772 INFO org.apache.hadoop.yarn.server.resourcemanager.scheduler.capacity.LeafQueue: completedContainer container=Container: [ContainerId: container_1480719777699_0003_01_000072, NodeId: datanode1:50178, NodeHttpAddress: datanode1:8042, Resource: <memory:2048, vCores:1>, Priority: 5, Token: Token { kind: ContainerToken, service: 10.0.0.6:50178 }, ] queue=default: capacity=1.0, absoluteCapacity=1.0, usedResources=<memory:6144, vCores:3>, usedCapacity=0.5, absoluteUsedCapacity=0.5, numApps=1, numContainers=3 cluster=<memory:12288, vCores:4>
2016-12-02 23:07:26,772 INFO org.apache.hadoop.yarn.server.resourcemanager.scheduler.capacity.ParentQueue: completedContainer queue=root usedCapacity=0.5 absoluteUsedCapacity=0.5 used=<memory:6144, vCores:3> cluster=<memory:12288, vCores:4>
2016-12-02 23:07:26,772 INFO org.apache.hadoop.yarn.server.resourcemanager.scheduler.capacity.ParentQueue: Re-sorting completed queue: root.default stats: default: capacity=1.0, absoluteCapacity=1.0, usedResources=<memory:6144, vCores:3>, usedCapacity=0.5, absoluteUsedCapacity=0.5, numApps=1, numContainers=3
2016-12-02 23:07:26,772 INFO org.apache.hadoop.yarn.server.resourcemanager.scheduler.capacity.CapacityScheduler: Application attempt appattempt_1480719777699_0003_000001 released container container_1480719777699_0003_01_000072 on node: host: datanode1:50178 #containers=0 available=<memory:3072, vCores:1> used=<memory:0, vCores:0> with event: FINISHED
2016-12-02 23:07:27,235 INFO org.apache.hadoop.yarn.server.resourcemanager.rmapp.attempt.RMAppAttemptImpl: Updating application attempt appattempt_1480719777699_0003_000001 with final state: FINISHING, and exit status: -1000
2016-12-02 23:07:27,237 INFO org.apache.hadoop.yarn.server.resourcemanager.rmapp.attempt.RMAppAttemptImpl: appattempt_1480719777699_0003_000001 State change from RUNNING to FINAL_SAVING
2016-12-02 23:07:27,237 INFO org.apache.hadoop.yarn.server.resourcemanager.rmapp.attempt.RMAppAttemptImpl: appattempt_1480719777699_0003_000001 State change from FINAL_SAVING to FINISHING
2016-12-02 23:07:27,237 INFO org.apache.hadoop.yarn.server.resourcemanager.rmapp.RMAppImpl: Updating application application_1480719777699_0003 with final state: FINISHING
2016-12-02 23:07:27,237 INFO org.apache.hadoop.yarn.server.resourcemanager.recovery.RMStateStore: Updating info for app: application_1480719777699_0003
2016-12-02 23:07:27,237 INFO org.apache.hadoop.yarn.server.resourcemanager.rmapp.RMAppImpl: application_1480719777699_0003 State change from RUNNING to FINAL_SAVING
2016-12-02 23:07:27,237 INFO org.apache.hadoop.yarn.server.resourcemanager.rmapp.RMAppImpl: application_1480719777699_0003 State change from FINAL_SAVING to FINISHING
2016-12-02 23:07:28,247 INFO org.apache.hadoop.yarn.server.resourcemanager.ApplicationMasterService: application_1480719777699_0003 unregistered successfully. 
2016-12-02 23:07:33,867 INFO org.apache.hadoop.yarn.server.resourcemanager.rmcontainer.RMContainerImpl: container_1480719777699_0003_01_000001 Container Transitioned from RUNNING to COMPLETED
2016-12-02 23:07:33,867 INFO org.apache.hadoop.yarn.server.resourcemanager.scheduler.common.fica.FiCaSchedulerApp: Completed container: container_1480719777699_0003_01_000001 in state: COMPLETED event:FINISHED
2016-12-02 23:07:33,867 INFO org.apache.hadoop.yarn.server.resourcemanager.ApplicationMasterService: Unregistering app attempt : appattempt_1480719777699_0003_000001
2016-12-02 23:07:33,867 INFO org.apache.hadoop.yarn.server.resourcemanager.RMAuditLogger: USER=hdmaster	OPERATION=AM Released Container	TARGET=SchedulerApp	RESULT=SUCCESS	APPID=application_1480719777699_0003	CONTAINERID=container_1480719777699_0003_01_000001
2016-12-02 23:07:33,867 INFO org.apache.hadoop.yarn.server.resourcemanager.scheduler.SchedulerNode: Released container container_1480719777699_0003_01_000001 of capacity <memory:2048, vCores:1> on host datanode3:60932, which currently has 0 containers, <memory:0, vCores:0> used and <memory:3072, vCores:1> available, release resources=true
2016-12-02 23:07:33,867 INFO org.apache.hadoop.yarn.server.resourcemanager.scheduler.capacity.LeafQueue: default used=<memory:4096, vCores:2> numContainers=2 user=hdmaster user-resources=<memory:4096, vCores:2>
2016-12-02 23:07:33,867 INFO org.apache.hadoop.yarn.server.resourcemanager.scheduler.capacity.LeafQueue: completedContainer container=Container: [ContainerId: container_1480719777699_0003_01_000001, NodeId: datanode3:60932, NodeHttpAddress: datanode3:8042, Resource: <memory:2048, vCores:1>, Priority: 0, Token: Token { kind: ContainerToken, service: 10.0.0.8:60932 }, ] queue=default: capacity=1.0, absoluteCapacity=1.0, usedResources=<memory:4096, vCores:2>, usedCapacity=0.33333334, absoluteUsedCapacity=0.33333334, numApps=1, numContainers=2 cluster=<memory:12288, vCores:4>
2016-12-02 23:07:33,868 INFO org.apache.hadoop.yarn.server.resourcemanager.scheduler.capacity.ParentQueue: completedContainer queue=root usedCapacity=0.33333334 absoluteUsedCapacity=0.33333334 used=<memory:4096, vCores:2> cluster=<memory:12288, vCores:4>
2016-12-02 23:07:33,868 INFO org.apache.hadoop.yarn.server.resourcemanager.scheduler.capacity.ParentQueue: Re-sorting completed queue: root.default stats: default: capacity=1.0, absoluteCapacity=1.0, usedResources=<memory:4096, vCores:2>, usedCapacity=0.33333334, absoluteUsedCapacity=0.33333334, numApps=1, numContainers=2
2016-12-02 23:07:33,868 INFO org.apache.hadoop.yarn.server.resourcemanager.scheduler.capacity.CapacityScheduler: Application attempt appattempt_1480719777699_0003_000001 released container container_1480719777699_0003_01_000001 on node: host: datanode3:60932 #containers=0 available=<memory:3072, vCores:1> used=<memory:0, vCores:0> with event: FINISHED
2016-12-02 23:07:33,868 INFO org.apache.hadoop.yarn.server.resourcemanager.security.AMRMTokenSecretManager: Application finished, removing password for appattempt_1480719777699_0003_000001
2016-12-02 23:07:33,869 INFO org.apache.hadoop.yarn.server.resourcemanager.rmapp.attempt.RMAppAttemptImpl: appattempt_1480719777699_0003_000001 State change from FINISHING to FINISHED
2016-12-02 23:07:33,870 INFO org.apache.hadoop.yarn.server.resourcemanager.rmapp.RMAppImpl: application_1480719777699_0003 State change from FINISHING to FINISHED
2016-12-02 23:07:33,870 INFO org.apache.hadoop.yarn.server.resourcemanager.scheduler.capacity.CapacityScheduler: Application Attempt appattempt_1480719777699_0003_000001 is done. finalState=FINISHED
2016-12-02 23:07:33,877 INFO org.apache.hadoop.yarn.server.resourcemanager.rmcontainer.RMContainerImpl: container_1480719777699_0003_01_000075 Container Transitioned from ALLOCATED to KILLED
2016-12-02 23:07:33,877 INFO org.apache.hadoop.yarn.server.resourcemanager.scheduler.common.fica.FiCaSchedulerApp: Completed container: container_1480719777699_0003_01_000075 in state: KILLED event:KILL
2016-12-02 23:07:33,877 INFO org.apache.hadoop.yarn.server.resourcemanager.RMAuditLogger: USER=hdmaster	OPERATION=AM Released Container	TARGET=SchedulerApp	RESULT=SUCCESS	APPID=application_1480719777699_0003	CONTAINERID=container_1480719777699_0003_01_000075
2016-12-02 23:07:33,877 INFO org.apache.hadoop.yarn.server.resourcemanager.scheduler.SchedulerNode: Released container container_1480719777699_0003_01_000075 of capacity <memory:2048, vCores:1> on host datanode2:60334, which currently has 0 containers, <memory:0, vCores:0> used and <memory:3072, vCores:1> available, release resources=true
2016-12-02 23:07:33,877 INFO org.apache.hadoop.yarn.server.resourcemanager.scheduler.capacity.LeafQueue: default used=<memory:2048, vCores:1> numContainers=1 user=hdmaster user-resources=<memory:2048, vCores:1>
2016-12-02 23:07:33,877 INFO org.apache.hadoop.yarn.server.resourcemanager.scheduler.capacity.LeafQueue: completedContainer container=Container: [ContainerId: container_1480719777699_0003_01_000075, NodeId: datanode2:60334, NodeHttpAddress: datanode2:8042, Resource: <memory:2048, vCores:1>, Priority: 5, Token: null, ] queue=default: capacity=1.0, absoluteCapacity=1.0, usedResources=<memory:2048, vCores:1>, usedCapacity=0.16666667, absoluteUsedCapacity=0.16666667, numApps=1, numContainers=1 cluster=<memory:12288, vCores:4>
2016-12-02 23:07:33,877 INFO org.apache.hadoop.yarn.server.resourcemanager.scheduler.capacity.ParentQueue: completedContainer queue=root usedCapacity=0.16666667 absoluteUsedCapacity=0.16666667 used=<memory:2048, vCores:1> cluster=<memory:12288, vCores:4>
2016-12-02 23:07:33,877 INFO org.apache.hadoop.yarn.server.resourcemanager.scheduler.capacity.ParentQueue: Re-sorting completed queue: root.default stats: default: capacity=1.0, absoluteCapacity=1.0, usedResources=<memory:2048, vCores:1>, usedCapacity=0.16666667, absoluteUsedCapacity=0.16666667, numApps=1, numContainers=1
2016-12-02 23:07:33,877 INFO org.apache.hadoop.yarn.server.resourcemanager.scheduler.capacity.CapacityScheduler: Application attempt appattempt_1480719777699_0003_000001 released container container_1480719777699_0003_01_000075 on node: host: datanode2:60334 #containers=0 available=<memory:3072, vCores:1> used=<memory:0, vCores:0> with event: KILL
2016-12-02 23:07:33,877 INFO org.apache.hadoop.yarn.server.resourcemanager.rmcontainer.RMContainerImpl: container_1480719777699_0003_01_000085 Container Transitioned from ALLOCATED to KILLED
2016-12-02 23:07:33,877 INFO org.apache.hadoop.yarn.server.resourcemanager.scheduler.common.fica.FiCaSchedulerApp: Completed container: container_1480719777699_0003_01_000085 in state: KILLED event:KILL
2016-12-02 23:07:33,877 INFO org.apache.hadoop.yarn.server.resourcemanager.RMAuditLogger: USER=hdmaster	OPERATION=AM Released Container	TARGET=SchedulerApp	RESULT=SUCCESS	APPID=application_1480719777699_0003	CONTAINERID=container_1480719777699_0003_01_000085
2016-12-02 23:07:33,877 INFO org.apache.hadoop.yarn.server.resourcemanager.scheduler.SchedulerNode: Released container container_1480719777699_0003_01_000085 of capacity <memory:2048, vCores:1> on host datanode4:45290, which currently has 0 containers, <memory:0, vCores:0> used and <memory:3072, vCores:1> available, release resources=true
2016-12-02 23:07:33,877 INFO org.apache.hadoop.yarn.server.resourcemanager.scheduler.capacity.LeafQueue: default used=<memory:0, vCores:0> numContainers=0 user=hdmaster user-resources=<memory:0, vCores:0>
2016-12-02 23:07:33,877 INFO org.apache.hadoop.yarn.server.resourcemanager.scheduler.capacity.LeafQueue: completedContainer container=Container: [ContainerId: container_1480719777699_0003_01_000085, NodeId: datanode4:45290, NodeHttpAddress: datanode4:8042, Resource: <memory:2048, vCores:1>, Priority: 5, Token: null, ] queue=default: capacity=1.0, absoluteCapacity=1.0, usedResources=<memory:0, vCores:0>, usedCapacity=0.0, absoluteUsedCapacity=0.0, numApps=1, numContainers=0 cluster=<memory:12288, vCores:4>
2016-12-02 23:07:33,877 INFO org.apache.hadoop.yarn.server.resourcemanager.scheduler.capacity.ParentQueue: completedContainer queue=root usedCapacity=0.0 absoluteUsedCapacity=0.0 used=<memory:0, vCores:0> cluster=<memory:12288, vCores:4>
2016-12-02 23:07:33,877 INFO org.apache.hadoop.yarn.server.resourcemanager.scheduler.capacity.ParentQueue: Re-sorting completed queue: root.default stats: default: capacity=1.0, absoluteCapacity=1.0, usedResources=<memory:0, vCores:0>, usedCapacity=0.0, absoluteUsedCapacity=0.0, numApps=1, numContainers=0
2016-12-02 23:07:33,877 INFO org.apache.hadoop.yarn.server.resourcemanager.scheduler.capacity.CapacityScheduler: Application attempt appattempt_1480719777699_0003_000001 released container container_1480719777699_0003_01_000085 on node: host: datanode4:45290 #containers=0 available=<memory:3072, vCores:1> used=<memory:0, vCores:0> with event: KILL
2016-12-02 23:07:33,877 INFO org.apache.hadoop.yarn.server.resourcemanager.scheduler.AppSchedulingInfo: Application application_1480719777699_0003 requests cleared
2016-12-02 23:07:33,878 INFO org.apache.hadoop.yarn.server.resourcemanager.scheduler.capacity.LeafQueue: Application removed - appId: application_1480719777699_0003 user: hdmaster queue: default #user-pending-applications: 0 #user-active-applications: 0 #queue-pending-applications: 0 #queue-active-applications: 0
2016-12-02 23:07:33,878 INFO org.apache.hadoop.yarn.server.resourcemanager.scheduler.capacity.ParentQueue: Application removed - appId: application_1480719777699_0003 user: hdmaster leaf-queue of parent: root #applications: 0
2016-12-02 23:07:33,879 INFO org.apache.hadoop.yarn.server.resourcemanager.RMAuditLogger: USER=hdmaster	OPERATION=Application Finished - Succeeded	TARGET=RMAppManager	RESULT=SUCCESS	APPID=application_1480719777699_0003
2016-12-02 23:07:33,890 INFO org.apache.hadoop.yarn.server.resourcemanager.RMAppManager$ApplicationSummary: appId=application_1480719777699_0003,name=streamjob7631880745345958807.jar,user=hdmaster,queue=default,state=FINISHED,trackingUrl=http://resourcemanager:8088/proxy/application_1480719777699_0003/,appMasterHost=DataNode3,startTime=1480719992911,finishTime=1480720047237,finalStatus=FAILED,memorySeconds=346380,vcoreSeconds=160,preemptedAMContainers=0,preemptedNonAMContainers=0,preemptedResources=<memory:0\, vCores:0>,applicationType=MAPREDUCE
2016-12-02 23:07:33,895 INFO org.apache.hadoop.yarn.server.resourcemanager.amlauncher.AMLauncher: Cleaning master appattempt_1480719777699_0003_000001
2016-12-02 23:07:35,358 INFO org.apache.hadoop.yarn.server.resourcemanager.scheduler.capacity.CapacityScheduler: Null container completed...
2016-12-02 23:07:35,674 INFO org.apache.hadoop.yarn.server.resourcemanager.scheduler.capacity.CapacityScheduler: Null container completed...
2016-12-02 23:07:35,806 INFO org.apache.hadoop.yarn.server.resourcemanager.scheduler.capacity.CapacityScheduler: Null container completed...
2016-12-02 23:11:31,725 INFO org.apache.hadoop.yarn.server.resourcemanager.ClientRMService: Allocated new applicationId: 4
2016-12-02 23:11:33,230 INFO org.apache.hadoop.yarn.server.resourcemanager.ClientRMService: Application with id 4 submitted by user hdmaster
2016-12-02 23:11:33,230 INFO org.apache.hadoop.yarn.server.resourcemanager.rmapp.RMAppImpl: Storing application with id application_1480719777699_0004
2016-12-02 23:11:33,230 INFO org.apache.hadoop.yarn.server.resourcemanager.rmapp.RMAppImpl: application_1480719777699_0004 State change from NEW to NEW_SAVING
2016-12-02 23:11:33,230 INFO org.apache.hadoop.yarn.server.resourcemanager.RMAuditLogger: USER=hdmaster	IP=10.0.0.4	OPERATION=Submit Application Request	TARGET=ClientRMService	RESULT=SUCCESS	APPID=application_1480719777699_0004
2016-12-02 23:11:33,230 INFO org.apache.hadoop.yarn.server.resourcemanager.recovery.RMStateStore: Storing info for app: application_1480719777699_0004
2016-12-02 23:11:33,230 INFO org.apache.hadoop.yarn.server.resourcemanager.rmapp.RMAppImpl: application_1480719777699_0004 State change from NEW_SAVING to SUBMITTED
2016-12-02 23:11:33,231 INFO org.apache.hadoop.yarn.server.resourcemanager.scheduler.capacity.ParentQueue: Application added - appId: application_1480719777699_0004 user: hdmaster leaf-queue of parent: root #applications: 1
2016-12-02 23:11:33,231 INFO org.apache.hadoop.yarn.server.resourcemanager.scheduler.capacity.CapacityScheduler: Accepted application application_1480719777699_0004 from user: hdmaster, in queue: default
2016-12-02 23:11:33,231 INFO org.apache.hadoop.yarn.server.resourcemanager.rmapp.RMAppImpl: application_1480719777699_0004 State change from SUBMITTED to ACCEPTED
2016-12-02 23:11:33,231 INFO org.apache.hadoop.yarn.server.resourcemanager.ApplicationMasterService: Registering app attempt : appattempt_1480719777699_0004_000001
2016-12-02 23:11:33,231 INFO org.apache.hadoop.yarn.server.resourcemanager.rmapp.attempt.RMAppAttemptImpl: appattempt_1480719777699_0004_000001 State change from NEW to SUBMITTED
2016-12-02 23:11:33,231 INFO org.apache.hadoop.yarn.server.resourcemanager.scheduler.capacity.LeafQueue: Application application_1480719777699_0004 from user: hdmaster activated in queue: default
2016-12-02 23:11:33,231 INFO org.apache.hadoop.yarn.server.resourcemanager.scheduler.capacity.LeafQueue: Application added - appId: application_1480719777699_0004 user: org.apache.hadoop.yarn.server.resourcemanager.scheduler.capacity.LeafQueue$User@1285bdab, leaf-queue: default #user-pending-applications: 0 #user-active-applications: 1 #queue-pending-applications: 0 #queue-active-applications: 1
2016-12-02 23:11:33,231 INFO org.apache.hadoop.yarn.server.resourcemanager.scheduler.capacity.CapacityScheduler: Added Application Attempt appattempt_1480719777699_0004_000001 to scheduler from user hdmaster in queue default
2016-12-02 23:11:33,232 INFO org.apache.hadoop.yarn.server.resourcemanager.rmapp.attempt.RMAppAttemptImpl: appattempt_1480719777699_0004_000001 State change from SUBMITTED to SCHEDULED
2016-12-02 23:11:33,310 INFO org.apache.hadoop.yarn.server.resourcemanager.rmcontainer.RMContainerImpl: container_1480719777699_0004_01_000001 Container Transitioned from NEW to ALLOCATED
2016-12-02 23:11:33,311 INFO org.apache.hadoop.yarn.server.resourcemanager.RMAuditLogger: USER=hdmaster	OPERATION=AM Allocated Container	TARGET=SchedulerApp	RESULT=SUCCESS	APPID=application_1480719777699_0004	CONTAINERID=container_1480719777699_0004_01_000001
2016-12-02 23:11:33,311 INFO org.apache.hadoop.yarn.server.resourcemanager.scheduler.SchedulerNode: Assigned container container_1480719777699_0004_01_000001 of capacity <memory:2048, vCores:1> on host datanode1:50178, which has 1 containers, <memory:2048, vCores:1> used and <memory:1024, vCores:0> available after allocation
2016-12-02 23:11:33,311 INFO org.apache.hadoop.yarn.server.resourcemanager.scheduler.capacity.LeafQueue: assignedContainer application attempt=appattempt_1480719777699_0004_000001 container=Container: [ContainerId: container_1480719777699_0004_01_000001, NodeId: datanode1:50178, NodeHttpAddress: datanode1:8042, Resource: <memory:2048, vCores:1>, Priority: 0, Token: null, ] queue=default: capacity=1.0, absoluteCapacity=1.0, usedResources=<memory:0, vCores:0>, usedCapacity=0.0, absoluteUsedCapacity=0.0, numApps=1, numContainers=0 clusterResource=<memory:12288, vCores:4> type=OFF_SWITCH
2016-12-02 23:11:33,311 INFO org.apache.hadoop.yarn.server.resourcemanager.scheduler.capacity.ParentQueue: Re-sorting assigned queue: root.default stats: default: capacity=1.0, absoluteCapacity=1.0, usedResources=<memory:2048, vCores:1>, usedCapacity=0.16666667, absoluteUsedCapacity=0.16666667, numApps=1, numContainers=1
2016-12-02 23:11:33,311 INFO org.apache.hadoop.yarn.server.resourcemanager.scheduler.capacity.ParentQueue: assignedContainer queue=root usedCapacity=0.16666667 absoluteUsedCapacity=0.16666667 used=<memory:2048, vCores:1> cluster=<memory:12288, vCores:4>
2016-12-02 23:11:33,314 INFO org.apache.hadoop.yarn.server.resourcemanager.security.NMTokenSecretManagerInRM: Sending NMToken for nodeId : datanode1:50178 for container : container_1480719777699_0004_01_000001
2016-12-02 23:11:33,315 INFO org.apache.hadoop.yarn.server.resourcemanager.rmcontainer.RMContainerImpl: container_1480719777699_0004_01_000001 Container Transitioned from ALLOCATED to ACQUIRED
2016-12-02 23:11:33,315 INFO org.apache.hadoop.yarn.server.resourcemanager.security.NMTokenSecretManagerInRM: Clear node set for appattempt_1480719777699_0004_000001
2016-12-02 23:11:33,315 INFO org.apache.hadoop.yarn.server.resourcemanager.rmapp.attempt.RMAppAttemptImpl: Storing attempt: AppId: application_1480719777699_0004 AttemptId: appattempt_1480719777699_0004_000001 MasterContainer: Container: [ContainerId: container_1480719777699_0004_01_000001, NodeId: datanode1:50178, NodeHttpAddress: datanode1:8042, Resource: <memory:2048, vCores:1>, Priority: 0, Token: Token { kind: ContainerToken, service: 10.0.0.6:50178 }, ]
2016-12-02 23:11:33,315 INFO org.apache.hadoop.yarn.server.resourcemanager.rmapp.attempt.RMAppAttemptImpl: appattempt_1480719777699_0004_000001 State change from SCHEDULED to ALLOCATED_SAVING
2016-12-02 23:11:33,315 INFO org.apache.hadoop.yarn.server.resourcemanager.rmapp.attempt.RMAppAttemptImpl: appattempt_1480719777699_0004_000001 State change from ALLOCATED_SAVING to ALLOCATED
2016-12-02 23:11:33,320 INFO org.apache.hadoop.yarn.server.resourcemanager.amlauncher.AMLauncher: Launching masterappattempt_1480719777699_0004_000001
2016-12-02 23:11:33,329 INFO org.apache.hadoop.yarn.server.resourcemanager.amlauncher.AMLauncher: Setting up container Container: [ContainerId: container_1480719777699_0004_01_000001, NodeId: datanode1:50178, NodeHttpAddress: datanode1:8042, Resource: <memory:2048, vCores:1>, Priority: 0, Token: Token { kind: ContainerToken, service: 10.0.0.6:50178 }, ] for AM appattempt_1480719777699_0004_000001
2016-12-02 23:11:33,329 INFO org.apache.hadoop.yarn.server.resourcemanager.amlauncher.AMLauncher: Command to launch container container_1480719777699_0004_01_000001 : $JAVA_HOME/bin/java -Djava.io.tmpdir=$PWD/tmp -Dlog4j.configuration=container-log4j.properties -Dyarn.app.container.log.dir=<LOG_DIR> -Dyarn.app.container.log.filesize=0 -Dhadoop.root.logger=INFO,CLA -Dhadoop.root.logfile=syslog  -Xmx1024m org.apache.hadoop.mapreduce.v2.app.MRAppMaster 1><LOG_DIR>/stdout 2><LOG_DIR>/stderr 
2016-12-02 23:11:33,329 INFO org.apache.hadoop.yarn.server.resourcemanager.security.AMRMTokenSecretManager: Create AMRMToken for ApplicationAttempt: appattempt_1480719777699_0004_000001
2016-12-02 23:11:33,329 INFO org.apache.hadoop.yarn.server.resourcemanager.security.AMRMTokenSecretManager: Creating password for appattempt_1480719777699_0004_000001
2016-12-02 23:11:33,366 INFO org.apache.hadoop.yarn.server.resourcemanager.amlauncher.AMLauncher: Done launching container Container: [ContainerId: container_1480719777699_0004_01_000001, NodeId: datanode1:50178, NodeHttpAddress: datanode1:8042, Resource: <memory:2048, vCores:1>, Priority: 0, Token: Token { kind: ContainerToken, service: 10.0.0.6:50178 }, ] for AM appattempt_1480719777699_0004_000001
2016-12-02 23:11:33,366 INFO org.apache.hadoop.yarn.server.resourcemanager.rmapp.attempt.RMAppAttemptImpl: appattempt_1480719777699_0004_000001 State change from ALLOCATED to LAUNCHED
2016-12-02 23:11:34,322 INFO org.apache.hadoop.yarn.server.resourcemanager.rmcontainer.RMContainerImpl: container_1480719777699_0004_01_000001 Container Transitioned from ACQUIRED to RUNNING
2016-12-02 23:11:46,330 INFO SecurityLogger.org.apache.hadoop.ipc.Server: Auth successful for appattempt_1480719777699_0004_000001 (auth:SIMPLE)
2016-12-02 23:11:46,345 INFO org.apache.hadoop.yarn.server.resourcemanager.ApplicationMasterService: AM registration appattempt_1480719777699_0004_000001
2016-12-02 23:11:46,345 INFO org.apache.hadoop.yarn.server.resourcemanager.RMAuditLogger: USER=hdmaster	IP=10.0.0.6	OPERATION=Register App Master	TARGET=ApplicationMasterService	RESULT=SUCCESS	APPID=application_1480719777699_0004	APPATTEMPTID=appattempt_1480719777699_0004_000001
2016-12-02 23:11:46,345 INFO org.apache.hadoop.yarn.server.resourcemanager.rmapp.attempt.RMAppAttemptImpl: appattempt_1480719777699_0004_000001 State change from LAUNCHED to RUNNING
2016-12-02 23:11:46,345 INFO org.apache.hadoop.yarn.server.resourcemanager.rmapp.RMAppImpl: application_1480719777699_0004 State change from ACCEPTED to RUNNING
2016-12-02 23:11:48,908 INFO org.apache.hadoop.yarn.server.resourcemanager.rmcontainer.RMContainerImpl: container_1480719777699_0004_01_000002 Container Transitioned from NEW to ALLOCATED
2016-12-02 23:11:48,908 INFO org.apache.hadoop.yarn.server.resourcemanager.RMAuditLogger: USER=hdmaster	OPERATION=AM Allocated Container	TARGET=SchedulerApp	RESULT=SUCCESS	APPID=application_1480719777699_0004	CONTAINERID=container_1480719777699_0004_01_000002
2016-12-02 23:11:48,908 INFO org.apache.hadoop.yarn.server.resourcemanager.scheduler.SchedulerNode: Assigned container container_1480719777699_0004_01_000002 of capacity <memory:2048, vCores:1> on host datanode2:60334, which has 1 containers, <memory:2048, vCores:1> used and <memory:1024, vCores:0> available after allocation
2016-12-02 23:11:48,908 INFO org.apache.hadoop.yarn.server.resourcemanager.scheduler.capacity.LeafQueue: assignedContainer application attempt=appattempt_1480719777699_0004_000001 container=Container: [ContainerId: container_1480719777699_0004_01_000002, NodeId: datanode2:60334, NodeHttpAddress: datanode2:8042, Resource: <memory:2048, vCores:1>, Priority: 20, Token: null, ] queue=default: capacity=1.0, absoluteCapacity=1.0, usedResources=<memory:2048, vCores:1>, usedCapacity=0.16666667, absoluteUsedCapacity=0.16666667, numApps=1, numContainers=1 clusterResource=<memory:12288, vCores:4> type=OFF_SWITCH
2016-12-02 23:11:48,908 INFO org.apache.hadoop.yarn.server.resourcemanager.scheduler.capacity.ParentQueue: Re-sorting assigned queue: root.default stats: default: capacity=1.0, absoluteCapacity=1.0, usedResources=<memory:4096, vCores:2>, usedCapacity=0.33333334, absoluteUsedCapacity=0.33333334, numApps=1, numContainers=2
2016-12-02 23:11:48,908 INFO org.apache.hadoop.yarn.server.resourcemanager.scheduler.capacity.ParentQueue: assignedContainer queue=root usedCapacity=0.33333334 absoluteUsedCapacity=0.33333334 used=<memory:4096, vCores:2> cluster=<memory:12288, vCores:4>
2016-12-02 23:11:49,223 INFO org.apache.hadoop.yarn.server.resourcemanager.rmcontainer.RMContainerImpl: container_1480719777699_0004_01_000003 Container Transitioned from NEW to ALLOCATED
2016-12-02 23:11:49,223 INFO org.apache.hadoop.yarn.server.resourcemanager.RMAuditLogger: USER=hdmaster	OPERATION=AM Allocated Container	TARGET=SchedulerApp	RESULT=SUCCESS	APPID=application_1480719777699_0004	CONTAINERID=container_1480719777699_0004_01_000003
2016-12-02 23:11:49,223 INFO org.apache.hadoop.yarn.server.resourcemanager.scheduler.SchedulerNode: Assigned container container_1480719777699_0004_01_000003 of capacity <memory:2048, vCores:1> on host datanode4:45290, which has 1 containers, <memory:2048, vCores:1> used and <memory:1024, vCores:0> available after allocation
2016-12-02 23:11:49,224 INFO org.apache.hadoop.yarn.server.resourcemanager.scheduler.capacity.LeafQueue: assignedContainer application attempt=appattempt_1480719777699_0004_000001 container=Container: [ContainerId: container_1480719777699_0004_01_000003, NodeId: datanode4:45290, NodeHttpAddress: datanode4:8042, Resource: <memory:2048, vCores:1>, Priority: 20, Token: null, ] queue=default: capacity=1.0, absoluteCapacity=1.0, usedResources=<memory:4096, vCores:2>, usedCapacity=0.33333334, absoluteUsedCapacity=0.33333334, numApps=1, numContainers=2 clusterResource=<memory:12288, vCores:4> type=OFF_SWITCH
2016-12-02 23:11:49,224 INFO org.apache.hadoop.yarn.server.resourcemanager.scheduler.capacity.ParentQueue: Re-sorting assigned queue: root.default stats: default: capacity=1.0, absoluteCapacity=1.0, usedResources=<memory:6144, vCores:3>, usedCapacity=0.5, absoluteUsedCapacity=0.5, numApps=1, numContainers=3
2016-12-02 23:11:49,224 INFO org.apache.hadoop.yarn.server.resourcemanager.scheduler.capacity.ParentQueue: assignedContainer queue=root usedCapacity=0.5 absoluteUsedCapacity=0.5 used=<memory:6144, vCores:3> cluster=<memory:12288, vCores:4>
2016-12-02 23:11:49,377 INFO org.apache.hadoop.yarn.server.resourcemanager.rmcontainer.RMContainerImpl: container_1480719777699_0004_01_000004 Container Transitioned from NEW to RESERVED
2016-12-02 23:11:49,377 INFO org.apache.hadoop.yarn.server.resourcemanager.scheduler.capacity.LeafQueue: Reserved container  application=application_1480719777699_0004 resource=<memory:2048, vCores:1> queue=default: capacity=1.0, absoluteCapacity=1.0, usedResources=<memory:6144, vCores:3>, usedCapacity=0.5, absoluteUsedCapacity=0.5, numApps=1, numContainers=3 usedCapacity=0.5 absoluteUsedCapacity=0.5 used=<memory:6144, vCores:3> cluster=<memory:12288, vCores:4>
2016-12-02 23:11:49,377 INFO org.apache.hadoop.yarn.server.resourcemanager.scheduler.capacity.ParentQueue: Re-sorting assigned queue: root.default stats: default: capacity=1.0, absoluteCapacity=1.0, usedResources=<memory:8192, vCores:4>, usedCapacity=0.6666667, absoluteUsedCapacity=0.6666667, numApps=1, numContainers=4
2016-12-02 23:11:49,377 INFO org.apache.hadoop.yarn.server.resourcemanager.scheduler.capacity.ParentQueue: assignedContainer queue=root usedCapacity=0.6666667 absoluteUsedCapacity=0.6666667 used=<memory:8192, vCores:4> cluster=<memory:12288, vCores:4>
2016-12-02 23:11:49,408 INFO org.apache.hadoop.yarn.server.resourcemanager.rmcontainer.RMContainerImpl: container_1480719777699_0004_01_000005 Container Transitioned from NEW to ALLOCATED
2016-12-02 23:11:49,408 INFO org.apache.hadoop.yarn.server.resourcemanager.RMAuditLogger: USER=hdmaster	OPERATION=AM Allocated Container	TARGET=SchedulerApp	RESULT=SUCCESS	APPID=application_1480719777699_0004	CONTAINERID=container_1480719777699_0004_01_000005
2016-12-02 23:11:49,408 INFO org.apache.hadoop.yarn.server.resourcemanager.scheduler.SchedulerNode: Assigned container container_1480719777699_0004_01_000005 of capacity <memory:2048, vCores:1> on host datanode3:60932, which has 1 containers, <memory:2048, vCores:1> used and <memory:1024, vCores:0> available after allocation
2016-12-02 23:11:49,408 INFO org.apache.hadoop.yarn.server.resourcemanager.scheduler.capacity.LeafQueue: assignedContainer application attempt=appattempt_1480719777699_0004_000001 container=Container: [ContainerId: container_1480719777699_0004_01_000005, NodeId: datanode3:60932, NodeHttpAddress: datanode3:8042, Resource: <memory:2048, vCores:1>, Priority: 20, Token: null, ] queue=default: capacity=1.0, absoluteCapacity=1.0, usedResources=<memory:8192, vCores:4>, usedCapacity=0.6666667, absoluteUsedCapacity=0.6666667, numApps=1, numContainers=4 clusterResource=<memory:12288, vCores:4> type=OFF_SWITCH
2016-12-02 23:11:49,408 INFO org.apache.hadoop.yarn.server.resourcemanager.scheduler.capacity.ParentQueue: Re-sorting assigned queue: root.default stats: default: capacity=1.0, absoluteCapacity=1.0, usedResources=<memory:10240, vCores:5>, usedCapacity=0.8333333, absoluteUsedCapacity=0.8333333, numApps=1, numContainers=5
2016-12-02 23:11:49,408 INFO org.apache.hadoop.yarn.server.resourcemanager.scheduler.capacity.ParentQueue: assignedContainer queue=root usedCapacity=0.8333333 absoluteUsedCapacity=0.8333333 used=<memory:10240, vCores:5> cluster=<memory:12288, vCores:4>
2016-12-02 23:11:49,628 INFO org.apache.hadoop.yarn.server.resourcemanager.security.NMTokenSecretManagerInRM: Sending NMToken for nodeId : datanode2:60334 for container : container_1480719777699_0004_01_000002
2016-12-02 23:11:49,631 INFO org.apache.hadoop.yarn.server.resourcemanager.rmcontainer.RMContainerImpl: container_1480719777699_0004_01_000002 Container Transitioned from ALLOCATED to ACQUIRED
2016-12-02 23:11:49,631 INFO org.apache.hadoop.yarn.server.resourcemanager.security.NMTokenSecretManagerInRM: Sending NMToken for nodeId : datanode4:45290 for container : container_1480719777699_0004_01_000003
2016-12-02 23:11:49,631 INFO org.apache.hadoop.yarn.server.resourcemanager.rmcontainer.RMContainerImpl: container_1480719777699_0004_01_000003 Container Transitioned from ALLOCATED to ACQUIRED
2016-12-02 23:11:49,632 INFO org.apache.hadoop.yarn.server.resourcemanager.security.NMTokenSecretManagerInRM: Sending NMToken for nodeId : datanode3:60932 for container : container_1480719777699_0004_01_000005
2016-12-02 23:11:49,632 INFO org.apache.hadoop.yarn.server.resourcemanager.rmcontainer.RMContainerImpl: container_1480719777699_0004_01_000005 Container Transitioned from ALLOCATED to ACQUIRED
2016-12-02 23:11:50,225 INFO org.apache.hadoop.yarn.server.resourcemanager.rmcontainer.RMContainerImpl: container_1480719777699_0004_01_000003 Container Transitioned from ACQUIRED to RUNNING
2016-12-02 23:11:50,379 INFO org.apache.hadoop.yarn.server.resourcemanager.scheduler.capacity.CapacityScheduler: Trying to fulfill reservation for application application_1480719777699_0004 on node: datanode1:50178
2016-12-02 23:11:50,379 INFO org.apache.hadoop.yarn.server.resourcemanager.scheduler.capacity.LeafQueue: Reserved container  application=application_1480719777699_0004 resource=<memory:2048, vCores:1> queue=default: capacity=1.0, absoluteCapacity=1.0, usedResources=<memory:10240, vCores:5>, usedCapacity=0.8333333, absoluteUsedCapacity=0.8333333, numApps=1, numContainers=5 usedCapacity=0.8333333 absoluteUsedCapacity=0.8333333 used=<memory:10240, vCores:5> cluster=<memory:12288, vCores:4>
2016-12-02 23:11:50,379 INFO org.apache.hadoop.yarn.server.resourcemanager.scheduler.capacity.CapacityScheduler: Skipping scheduling since node datanode1:50178 is reserved by application appattempt_1480719777699_0004_000001
2016-12-02 23:11:50,410 INFO org.apache.hadoop.yarn.server.resourcemanager.rmcontainer.RMContainerImpl: container_1480719777699_0004_01_000005 Container Transitioned from ACQUIRED to RUNNING
2016-12-02 23:11:50,912 INFO org.apache.hadoop.yarn.server.resourcemanager.rmcontainer.RMContainerImpl: container_1480719777699_0004_01_000002 Container Transitioned from ACQUIRED to RUNNING
2016-12-02 23:11:51,381 INFO org.apache.hadoop.yarn.server.resourcemanager.scheduler.capacity.CapacityScheduler: Trying to fulfill reservation for application application_1480719777699_0004 on node: datanode1:50178
2016-12-02 23:11:51,381 INFO org.apache.hadoop.yarn.server.resourcemanager.scheduler.capacity.LeafQueue: Reserved container  application=application_1480719777699_0004 resource=<memory:2048, vCores:1> queue=default: capacity=1.0, absoluteCapacity=1.0, usedResources=<memory:10240, vCores:5>, usedCapacity=0.8333333, absoluteUsedCapacity=0.8333333, numApps=1, numContainers=5 usedCapacity=0.8333333 absoluteUsedCapacity=0.8333333 used=<memory:10240, vCores:5> cluster=<memory:12288, vCores:4>
2016-12-02 23:11:51,381 INFO org.apache.hadoop.yarn.server.resourcemanager.scheduler.capacity.CapacityScheduler: Skipping scheduling since node datanode1:50178 is reserved by application appattempt_1480719777699_0004_000001
2016-12-02 23:11:52,383 INFO org.apache.hadoop.yarn.server.resourcemanager.scheduler.capacity.CapacityScheduler: Trying to fulfill reservation for application application_1480719777699_0004 on node: datanode1:50178
2016-12-02 23:11:52,383 INFO org.apache.hadoop.yarn.server.resourcemanager.scheduler.capacity.LeafQueue: Reserved container  application=application_1480719777699_0004 resource=<memory:2048, vCores:1> queue=default: capacity=1.0, absoluteCapacity=1.0, usedResources=<memory:10240, vCores:5>, usedCapacity=0.8333333, absoluteUsedCapacity=0.8333333, numApps=1, numContainers=5 usedCapacity=0.8333333 absoluteUsedCapacity=0.8333333 used=<memory:10240, vCores:5> cluster=<memory:12288, vCores:4>
2016-12-02 23:11:52,383 INFO org.apache.hadoop.yarn.server.resourcemanager.scheduler.capacity.CapacityScheduler: Skipping scheduling since node datanode1:50178 is reserved by application appattempt_1480719777699_0004_000001
2016-12-02 23:11:53,385 INFO org.apache.hadoop.yarn.server.resourcemanager.scheduler.capacity.CapacityScheduler: Trying to fulfill reservation for application application_1480719777699_0004 on node: datanode1:50178
2016-12-02 23:11:53,385 INFO org.apache.hadoop.yarn.server.resourcemanager.scheduler.capacity.LeafQueue: Reserved container  application=application_1480719777699_0004 resource=<memory:2048, vCores:1> queue=default: capacity=1.0, absoluteCapacity=1.0, usedResources=<memory:10240, vCores:5>, usedCapacity=0.8333333, absoluteUsedCapacity=0.8333333, numApps=1, numContainers=5 usedCapacity=0.8333333 absoluteUsedCapacity=0.8333333 used=<memory:10240, vCores:5> cluster=<memory:12288, vCores:4>
2016-12-02 23:11:53,385 INFO org.apache.hadoop.yarn.server.resourcemanager.scheduler.capacity.CapacityScheduler: Skipping scheduling since node datanode1:50178 is reserved by application appattempt_1480719777699_0004_000001
2016-12-02 23:11:53,416 INFO org.apache.hadoop.yarn.server.resourcemanager.rmcontainer.RMContainerImpl: container_1480719777699_0004_01_000017 Container Transitioned from NEW to RESERVED
2016-12-02 23:11:53,416 INFO org.apache.hadoop.yarn.server.resourcemanager.scheduler.capacity.LeafQueue: Reserved container  application=application_1480719777699_0004 resource=<memory:2048, vCores:1> queue=default: capacity=1.0, absoluteCapacity=1.0, usedResources=<memory:10240, vCores:5>, usedCapacity=0.8333333, absoluteUsedCapacity=0.8333333, numApps=1, numContainers=5 usedCapacity=0.8333333 absoluteUsedCapacity=0.8333333 used=<memory:10240, vCores:5> cluster=<memory:12288, vCores:4>
2016-12-02 23:11:53,416 INFO org.apache.hadoop.yarn.server.resourcemanager.scheduler.capacity.ParentQueue: Re-sorting assigned queue: root.default stats: default: capacity=1.0, absoluteCapacity=1.0, usedResources=<memory:12288, vCores:6>, usedCapacity=1.0, absoluteUsedCapacity=1.0, numApps=1, numContainers=6
2016-12-02 23:11:53,416 INFO org.apache.hadoop.yarn.server.resourcemanager.scheduler.capacity.ParentQueue: assignedContainer queue=root usedCapacity=1.0 absoluteUsedCapacity=1.0 used=<memory:12288, vCores:6> cluster=<memory:12288, vCores:4>
2016-12-02 23:11:54,133 INFO org.apache.hadoop.yarn.server.resourcemanager.rmcontainer.RMContainerImpl: container_1480719777699_0004_01_000005 Container Transitioned from RUNNING to COMPLETED
2016-12-02 23:11:54,133 INFO org.apache.hadoop.yarn.server.resourcemanager.scheduler.common.fica.FiCaSchedulerApp: Completed container: container_1480719777699_0004_01_000005 in state: COMPLETED event:FINISHED
2016-12-02 23:11:54,133 INFO org.apache.hadoop.yarn.server.resourcemanager.RMAuditLogger: USER=hdmaster	OPERATION=AM Released Container	TARGET=SchedulerApp	RESULT=SUCCESS	APPID=application_1480719777699_0004	CONTAINERID=container_1480719777699_0004_01_000005
2016-12-02 23:11:54,133 INFO org.apache.hadoop.yarn.server.resourcemanager.scheduler.SchedulerNode: Released container container_1480719777699_0004_01_000005 of capacity <memory:2048, vCores:1> on host datanode3:60932, which currently has 0 containers, <memory:0, vCores:0> used and <memory:3072, vCores:1> available, release resources=true
2016-12-02 23:11:54,134 INFO org.apache.hadoop.yarn.server.resourcemanager.scheduler.capacity.LeafQueue: default used=<memory:10240, vCores:5> numContainers=5 user=hdmaster user-resources=<memory:10240, vCores:5>
2016-12-02 23:11:54,134 INFO org.apache.hadoop.yarn.server.resourcemanager.scheduler.capacity.LeafQueue: completedContainer container=Container: [ContainerId: container_1480719777699_0004_01_000005, NodeId: datanode3:60932, NodeHttpAddress: datanode3:8042, Resource: <memory:2048, vCores:1>, Priority: 20, Token: Token { kind: ContainerToken, service: 10.0.0.8:60932 }, ] queue=default: capacity=1.0, absoluteCapacity=1.0, usedResources=<memory:10240, vCores:5>, usedCapacity=0.8333333, absoluteUsedCapacity=0.8333333, numApps=1, numContainers=5 cluster=<memory:12288, vCores:4>
2016-12-02 23:11:54,134 INFO org.apache.hadoop.yarn.server.resourcemanager.scheduler.capacity.ParentQueue: completedContainer queue=root usedCapacity=0.8333333 absoluteUsedCapacity=0.8333333 used=<memory:10240, vCores:5> cluster=<memory:12288, vCores:4>
2016-12-02 23:11:54,134 INFO org.apache.hadoop.yarn.server.resourcemanager.scheduler.capacity.ParentQueue: Re-sorting completed queue: root.default stats: default: capacity=1.0, absoluteCapacity=1.0, usedResources=<memory:10240, vCores:5>, usedCapacity=0.8333333, absoluteUsedCapacity=0.8333333, numApps=1, numContainers=5
2016-12-02 23:11:54,134 INFO org.apache.hadoop.yarn.server.resourcemanager.scheduler.capacity.CapacityScheduler: Application attempt appattempt_1480719777699_0004_000001 released container container_1480719777699_0004_01_000005 on node: host: datanode3:60932 #containers=0 available=<memory:3072, vCores:1> used=<memory:0, vCores:0> with event: FINISHED
2016-12-02 23:11:54,134 INFO org.apache.hadoop.yarn.server.resourcemanager.scheduler.capacity.CapacityScheduler: Trying to fulfill reservation for application application_1480719777699_0004 on node: datanode3:60932
2016-12-02 23:11:54,134 INFO org.apache.hadoop.yarn.server.resourcemanager.scheduler.common.fica.FiCaSchedulerApp: Application application_1480719777699_0004 unreserved  on node host: datanode3:60932 #containers=0 available=<memory:3072, vCores:1> used=<memory:0, vCores:0>, currently has 1 at priority 20; currentReservation <memory:2048, vCores:1>
2016-12-02 23:11:54,134 INFO org.apache.hadoop.yarn.server.resourcemanager.rmcontainer.RMContainerImpl: container_1480719777699_0004_01_000017 Container Transitioned from NEW to ALLOCATED
2016-12-02 23:11:54,134 INFO org.apache.hadoop.yarn.server.resourcemanager.RMAuditLogger: USER=hdmaster	OPERATION=AM Allocated Container	TARGET=SchedulerApp	RESULT=SUCCESS	APPID=application_1480719777699_0004	CONTAINERID=container_1480719777699_0004_01_000017
2016-12-02 23:11:54,134 INFO org.apache.hadoop.yarn.server.resourcemanager.scheduler.SchedulerNode: Assigned container container_1480719777699_0004_01_000017 of capacity <memory:2048, vCores:1> on host datanode3:60932, which has 1 containers, <memory:2048, vCores:1> used and <memory:1024, vCores:0> available after allocation
2016-12-02 23:11:54,134 INFO org.apache.hadoop.yarn.server.resourcemanager.scheduler.capacity.LeafQueue: assignedContainer application attempt=appattempt_1480719777699_0004_000001 container=Container: [ContainerId: container_1480719777699_0004_01_000017, NodeId: datanode3:60932, NodeHttpAddress: datanode3:8042, Resource: <memory:2048, vCores:1>, Priority: 20, Token: null, ] queue=default: capacity=1.0, absoluteCapacity=1.0, usedResources=<memory:10240, vCores:5>, usedCapacity=0.8333333, absoluteUsedCapacity=0.8333333, numApps=1, numContainers=5 clusterResource=<memory:12288, vCores:4> type=OFF_SWITCH
2016-12-02 23:11:54,386 INFO org.apache.hadoop.yarn.server.resourcemanager.scheduler.capacity.CapacityScheduler: Trying to fulfill reservation for application application_1480719777699_0004 on node: datanode1:50178
2016-12-02 23:11:54,386 INFO org.apache.hadoop.yarn.server.resourcemanager.scheduler.common.fica.FiCaSchedulerApp: Application application_1480719777699_0004 unreserved  on node host: datanode1:50178 #containers=1 available=<memory:1024, vCores:0> used=<memory:2048, vCores:1>, currently has 0 at priority 20; currentReservation <memory:0, vCores:0>
2016-12-02 23:11:54,386 INFO org.apache.hadoop.yarn.server.resourcemanager.scheduler.capacity.LeafQueue: default used=<memory:8192, vCores:4> numContainers=4 user=hdmaster user-resources=<memory:8192, vCores:4>
2016-12-02 23:11:54,386 INFO org.apache.hadoop.yarn.server.resourcemanager.scheduler.capacity.LeafQueue: completedContainer container=Container: [ContainerId: container_1480719777699_0004_01_000004, NodeId: datanode1:50178, NodeHttpAddress: datanode1:8042, Resource: <memory:2048, vCores:1>, Priority: 20, Token: null, ] queue=default: capacity=1.0, absoluteCapacity=1.0, usedResources=<memory:8192, vCores:4>, usedCapacity=0.6666667, absoluteUsedCapacity=0.6666667, numApps=1, numContainers=4 cluster=<memory:12288, vCores:4>
2016-12-02 23:11:54,386 INFO org.apache.hadoop.yarn.server.resourcemanager.scheduler.capacity.ParentQueue: completedContainer queue=root usedCapacity=0.6666667 absoluteUsedCapacity=0.6666667 used=<memory:8192, vCores:4> cluster=<memory:12288, vCores:4>
2016-12-02 23:11:54,386 INFO org.apache.hadoop.yarn.server.resourcemanager.scheduler.capacity.ParentQueue: Re-sorting completed queue: root.default stats: default: capacity=1.0, absoluteCapacity=1.0, usedResources=<memory:8192, vCores:4>, usedCapacity=0.6666667, absoluteUsedCapacity=0.6666667, numApps=1, numContainers=4
2016-12-02 23:11:54,693 INFO org.apache.hadoop.yarn.server.resourcemanager.rmcontainer.RMContainerImpl: container_1480719777699_0004_01_000003 Container Transitioned from RUNNING to COMPLETED
2016-12-02 23:11:54,693 INFO org.apache.hadoop.yarn.server.resourcemanager.scheduler.common.fica.FiCaSchedulerApp: Completed container: container_1480719777699_0004_01_000003 in state: COMPLETED event:FINISHED
2016-12-02 23:11:54,693 INFO org.apache.hadoop.yarn.server.resourcemanager.RMAuditLogger: USER=hdmaster	OPERATION=AM Released Container	TARGET=SchedulerApp	RESULT=SUCCESS	APPID=application_1480719777699_0004	CONTAINERID=container_1480719777699_0004_01_000003
2016-12-02 23:11:54,693 INFO org.apache.hadoop.yarn.server.resourcemanager.scheduler.SchedulerNode: Released container container_1480719777699_0004_01_000003 of capacity <memory:2048, vCores:1> on host datanode4:45290, which currently has 0 containers, <memory:0, vCores:0> used and <memory:3072, vCores:1> available, release resources=true
2016-12-02 23:11:54,693 INFO org.apache.hadoop.yarn.server.resourcemanager.scheduler.capacity.LeafQueue: default used=<memory:6144, vCores:3> numContainers=3 user=hdmaster user-resources=<memory:6144, vCores:3>
2016-12-02 23:11:54,693 INFO org.apache.hadoop.yarn.server.resourcemanager.scheduler.capacity.LeafQueue: completedContainer container=Container: [ContainerId: container_1480719777699_0004_01_000003, NodeId: datanode4:45290, NodeHttpAddress: datanode4:8042, Resource: <memory:2048, vCores:1>, Priority: 20, Token: Token { kind: ContainerToken, service: 10.0.0.9:45290 }, ] queue=default: capacity=1.0, absoluteCapacity=1.0, usedResources=<memory:6144, vCores:3>, usedCapacity=0.5, absoluteUsedCapacity=0.5, numApps=1, numContainers=3 cluster=<memory:12288, vCores:4>
2016-12-02 23:11:54,693 INFO org.apache.hadoop.yarn.server.resourcemanager.scheduler.capacity.ParentQueue: completedContainer queue=root usedCapacity=0.5 absoluteUsedCapacity=0.5 used=<memory:6144, vCores:3> cluster=<memory:12288, vCores:4>
2016-12-02 23:11:54,693 INFO org.apache.hadoop.yarn.server.resourcemanager.scheduler.capacity.ParentQueue: Re-sorting completed queue: root.default stats: default: capacity=1.0, absoluteCapacity=1.0, usedResources=<memory:6144, vCores:3>, usedCapacity=0.5, absoluteUsedCapacity=0.5, numApps=1, numContainers=3
2016-12-02 23:11:54,693 INFO org.apache.hadoop.yarn.server.resourcemanager.scheduler.capacity.CapacityScheduler: Application attempt appattempt_1480719777699_0004_000001 released container container_1480719777699_0004_01_000003 on node: host: datanode4:45290 #containers=0 available=<memory:3072, vCores:1> used=<memory:0, vCores:0> with event: FINISHED
2016-12-02 23:11:54,698 INFO org.apache.hadoop.yarn.server.resourcemanager.rmcontainer.RMContainerImpl: container_1480719777699_0004_01_000017 Container Transitioned from ALLOCATED to ACQUIRED
2016-12-02 23:11:54,819 INFO org.apache.hadoop.yarn.server.resourcemanager.rmcontainer.RMContainerImpl: container_1480719777699_0004_01_000002 Container Transitioned from RUNNING to COMPLETED
2016-12-02 23:11:54,819 INFO org.apache.hadoop.yarn.server.resourcemanager.scheduler.common.fica.FiCaSchedulerApp: Completed container: container_1480719777699_0004_01_000002 in state: COMPLETED event:FINISHED
2016-12-02 23:11:54,819 INFO org.apache.hadoop.yarn.server.resourcemanager.RMAuditLogger: USER=hdmaster	OPERATION=AM Released Container	TARGET=SchedulerApp	RESULT=SUCCESS	APPID=application_1480719777699_0004	CONTAINERID=container_1480719777699_0004_01_000002
2016-12-02 23:11:54,819 INFO org.apache.hadoop.yarn.server.resourcemanager.scheduler.SchedulerNode: Released container container_1480719777699_0004_01_000002 of capacity <memory:2048, vCores:1> on host datanode2:60334, which currently has 0 containers, <memory:0, vCores:0> used and <memory:3072, vCores:1> available, release resources=true
2016-12-02 23:11:54,819 INFO org.apache.hadoop.yarn.server.resourcemanager.scheduler.capacity.LeafQueue: default used=<memory:4096, vCores:2> numContainers=2 user=hdmaster user-resources=<memory:4096, vCores:2>
2016-12-02 23:11:54,820 INFO org.apache.hadoop.yarn.server.resourcemanager.scheduler.capacity.LeafQueue: completedContainer container=Container: [ContainerId: container_1480719777699_0004_01_000002, NodeId: datanode2:60334, NodeHttpAddress: datanode2:8042, Resource: <memory:2048, vCores:1>, Priority: 20, Token: Token { kind: ContainerToken, service: 10.0.0.7:60334 }, ] queue=default: capacity=1.0, absoluteCapacity=1.0, usedResources=<memory:4096, vCores:2>, usedCapacity=0.33333334, absoluteUsedCapacity=0.33333334, numApps=1, numContainers=2 cluster=<memory:12288, vCores:4>
2016-12-02 23:11:54,820 INFO org.apache.hadoop.yarn.server.resourcemanager.scheduler.capacity.ParentQueue: completedContainer queue=root usedCapacity=0.33333334 absoluteUsedCapacity=0.33333334 used=<memory:4096, vCores:2> cluster=<memory:12288, vCores:4>
2016-12-02 23:11:54,820 INFO org.apache.hadoop.yarn.server.resourcemanager.scheduler.capacity.ParentQueue: Re-sorting completed queue: root.default stats: default: capacity=1.0, absoluteCapacity=1.0, usedResources=<memory:4096, vCores:2>, usedCapacity=0.33333334, absoluteUsedCapacity=0.33333334, numApps=1, numContainers=2
2016-12-02 23:11:54,820 INFO org.apache.hadoop.yarn.server.resourcemanager.scheduler.capacity.CapacityScheduler: Application attempt appattempt_1480719777699_0004_000001 released container container_1480719777699_0004_01_000002 on node: host: datanode2:60334 #containers=0 available=<memory:3072, vCores:1> used=<memory:0, vCores:0> with event: FINISHED
2016-12-02 23:11:54,820 INFO org.apache.hadoop.yarn.server.resourcemanager.rmcontainer.RMContainerImpl: container_1480719777699_0004_01_000019 Container Transitioned from NEW to ALLOCATED
2016-12-02 23:11:54,820 INFO org.apache.hadoop.yarn.server.resourcemanager.RMAuditLogger: USER=hdmaster	OPERATION=AM Allocated Container	TARGET=SchedulerApp	RESULT=SUCCESS	APPID=application_1480719777699_0004	CONTAINERID=container_1480719777699_0004_01_000019
2016-12-02 23:11:54,820 INFO org.apache.hadoop.yarn.server.resourcemanager.scheduler.SchedulerNode: Assigned container container_1480719777699_0004_01_000019 of capacity <memory:2048, vCores:1> on host datanode2:60334, which has 1 containers, <memory:2048, vCores:1> used and <memory:1024, vCores:0> available after allocation
2016-12-02 23:11:54,821 INFO org.apache.hadoop.yarn.server.resourcemanager.scheduler.capacity.LeafQueue: assignedContainer application attempt=appattempt_1480719777699_0004_000001 container=Container: [ContainerId: container_1480719777699_0004_01_000019, NodeId: datanode2:60334, NodeHttpAddress: datanode2:8042, Resource: <memory:2048, vCores:1>, Priority: 5, Token: null, ] queue=default: capacity=1.0, absoluteCapacity=1.0, usedResources=<memory:4096, vCores:2>, usedCapacity=0.33333334, absoluteUsedCapacity=0.33333334, numApps=1, numContainers=2 clusterResource=<memory:12288, vCores:4> type=OFF_SWITCH
2016-12-02 23:11:54,821 INFO org.apache.hadoop.yarn.server.resourcemanager.scheduler.capacity.ParentQueue: Re-sorting assigned queue: root.default stats: default: capacity=1.0, absoluteCapacity=1.0, usedResources=<memory:6144, vCores:3>, usedCapacity=0.5, absoluteUsedCapacity=0.5, numApps=1, numContainers=3
2016-12-02 23:11:54,821 INFO org.apache.hadoop.yarn.server.resourcemanager.scheduler.capacity.ParentQueue: assignedContainer queue=root usedCapacity=0.5 absoluteUsedCapacity=0.5 used=<memory:6144, vCores:3> cluster=<memory:12288, vCores:4>
2016-12-02 23:11:55,135 INFO org.apache.hadoop.yarn.server.resourcemanager.rmcontainer.RMContainerImpl: container_1480719777699_0004_01_000017 Container Transitioned from ACQUIRED to RUNNING
2016-12-02 23:11:55,136 INFO org.apache.hadoop.yarn.server.resourcemanager.rmcontainer.RMContainerImpl: container_1480719777699_0004_01_000020 Container Transitioned from NEW to RESERVED
2016-12-02 23:11:55,136 INFO org.apache.hadoop.yarn.server.resourcemanager.scheduler.capacity.LeafQueue: Reserved container  application=application_1480719777699_0004 resource=<memory:2048, vCores:1> queue=default: capacity=1.0, absoluteCapacity=1.0, usedResources=<memory:6144, vCores:3>, usedCapacity=0.5, absoluteUsedCapacity=0.5, numApps=1, numContainers=3 usedCapacity=0.5 absoluteUsedCapacity=0.5 used=<memory:6144, vCores:3> cluster=<memory:12288, vCores:4>
2016-12-02 23:11:55,136 INFO org.apache.hadoop.yarn.server.resourcemanager.scheduler.capacity.ParentQueue: Re-sorting assigned queue: root.default stats: default: capacity=1.0, absoluteCapacity=1.0, usedResources=<memory:8192, vCores:4>, usedCapacity=0.6666667, absoluteUsedCapacity=0.6666667, numApps=1, numContainers=4
2016-12-02 23:11:55,136 INFO org.apache.hadoop.yarn.server.resourcemanager.scheduler.capacity.ParentQueue: assignedContainer queue=root usedCapacity=0.6666667 absoluteUsedCapacity=0.6666667 used=<memory:8192, vCores:4> cluster=<memory:12288, vCores:4>
2016-12-02 23:11:55,696 INFO org.apache.hadoop.yarn.server.resourcemanager.scheduler.common.fica.FiCaSchedulerApp: Application application_1480719777699_0004 unreserved  on node host: datanode3:60932 #containers=1 available=<memory:1024, vCores:0> used=<memory:2048, vCores:1>, currently has 0 at priority 5; currentReservation <memory:0, vCores:0>
2016-12-02 23:11:55,696 INFO org.apache.hadoop.yarn.server.resourcemanager.scheduler.capacity.LeafQueue: default used=<memory:6144, vCores:3> numContainers=3 user=hdmaster user-resources=<memory:6144, vCores:3>
2016-12-02 23:11:55,696 INFO org.apache.hadoop.yarn.server.resourcemanager.scheduler.capacity.LeafQueue: completedContainer container=Container: [ContainerId: container_1480719777699_0004_01_000020, NodeId: datanode3:60932, NodeHttpAddress: datanode3:8042, Resource: <memory:2048, vCores:1>, Priority: 5, Token: null, ] queue=default: capacity=1.0, absoluteCapacity=1.0, usedResources=<memory:6144, vCores:3>, usedCapacity=0.5, absoluteUsedCapacity=0.5, numApps=1, numContainers=3 cluster=<memory:12288, vCores:4>
2016-12-02 23:11:55,696 INFO org.apache.hadoop.yarn.server.resourcemanager.scheduler.capacity.ParentQueue: completedContainer queue=root usedCapacity=0.5 absoluteUsedCapacity=0.5 used=<memory:6144, vCores:3> cluster=<memory:12288, vCores:4>
2016-12-02 23:11:55,697 INFO org.apache.hadoop.yarn.server.resourcemanager.rmcontainer.RMContainerImpl: container_1480719777699_0004_01_000022 Container Transitioned from NEW to ALLOCATED
2016-12-02 23:11:55,697 INFO org.apache.hadoop.yarn.server.resourcemanager.RMAuditLogger: USER=hdmaster	OPERATION=AM Allocated Container	TARGET=SchedulerApp	RESULT=SUCCESS	APPID=application_1480719777699_0004	CONTAINERID=container_1480719777699_0004_01_000022
2016-12-02 23:11:55,697 INFO org.apache.hadoop.yarn.server.resourcemanager.scheduler.SchedulerNode: Assigned container container_1480719777699_0004_01_000022 of capacity <memory:2048, vCores:1> on host datanode4:45290, which has 1 containers, <memory:2048, vCores:1> used and <memory:1024, vCores:0> available after allocation
2016-12-02 23:11:55,697 INFO org.apache.hadoop.yarn.server.resourcemanager.scheduler.capacity.LeafQueue: assignedContainer application attempt=appattempt_1480719777699_0004_000001 container=Container: [ContainerId: container_1480719777699_0004_01_000022, NodeId: datanode4:45290, NodeHttpAddress: datanode4:8042, Resource: <memory:2048, vCores:1>, Priority: 5, Token: null, ] queue=default: capacity=1.0, absoluteCapacity=1.0, usedResources=<memory:6144, vCores:3>, usedCapacity=0.5, absoluteUsedCapacity=0.5, numApps=1, numContainers=3 clusterResource=<memory:12288, vCores:4> type=OFF_SWITCH
2016-12-02 23:11:55,697 INFO org.apache.hadoop.yarn.server.resourcemanager.scheduler.capacity.ParentQueue: Re-sorting assigned queue: root.default stats: default: capacity=1.0, absoluteCapacity=1.0, usedResources=<memory:8192, vCores:4>, usedCapacity=0.6666667, absoluteUsedCapacity=0.6666667, numApps=1, numContainers=4
2016-12-02 23:11:55,697 INFO org.apache.hadoop.yarn.server.resourcemanager.scheduler.capacity.ParentQueue: assignedContainer queue=root usedCapacity=0.6666667 absoluteUsedCapacity=0.6666667 used=<memory:8192, vCores:4> cluster=<memory:12288, vCores:4>
2016-12-02 23:11:55,717 INFO org.apache.hadoop.yarn.server.resourcemanager.scheduler.AppSchedulingInfo: checking for deactivate of application :application_1480719777699_0004
2016-12-02 23:11:55,718 INFO org.apache.hadoop.yarn.server.resourcemanager.rmcontainer.RMContainerImpl: container_1480719777699_0004_01_000019 Container Transitioned from ALLOCATED to ACQUIRED
2016-12-02 23:11:55,719 INFO org.apache.hadoop.yarn.server.resourcemanager.rmcontainer.RMContainerImpl: container_1480719777699_0004_01_000022 Container Transitioned from ALLOCATED to ACQUIRED
2016-12-02 23:11:55,826 INFO org.apache.hadoop.yarn.server.resourcemanager.rmcontainer.RMContainerImpl: container_1480719777699_0004_01_000019 Container Transitioned from ACQUIRED to RUNNING
2016-12-02 23:11:55,826 INFO org.apache.hadoop.yarn.server.resourcemanager.rmcontainer.RMContainerImpl: container_1480719777699_0004_01_000023 Container Transitioned from NEW to RESERVED
2016-12-02 23:11:55,826 INFO org.apache.hadoop.yarn.server.resourcemanager.scheduler.capacity.LeafQueue: Reserved container  application=application_1480719777699_0004 resource=<memory:2048, vCores:1> queue=default: capacity=1.0, absoluteCapacity=1.0, usedResources=<memory:8192, vCores:4>, usedCapacity=0.6666667, absoluteUsedCapacity=0.6666667, numApps=1, numContainers=4 usedCapacity=0.6666667 absoluteUsedCapacity=0.6666667 used=<memory:8192, vCores:4> cluster=<memory:12288, vCores:4>
2016-12-02 23:11:55,826 INFO org.apache.hadoop.yarn.server.resourcemanager.scheduler.capacity.ParentQueue: Re-sorting assigned queue: root.default stats: default: capacity=1.0, absoluteCapacity=1.0, usedResources=<memory:10240, vCores:5>, usedCapacity=0.8333333, absoluteUsedCapacity=0.8333333, numApps=1, numContainers=5
2016-12-02 23:11:55,826 INFO org.apache.hadoop.yarn.server.resourcemanager.scheduler.capacity.ParentQueue: assignedContainer queue=root usedCapacity=0.8333333 absoluteUsedCapacity=0.8333333 used=<memory:10240, vCores:5> cluster=<memory:12288, vCores:4>
2016-12-02 23:11:56,143 INFO org.apache.hadoop.yarn.server.resourcemanager.rmcontainer.RMContainerImpl: container_1480719777699_0004_01_000024 Container Transitioned from NEW to RESERVED
2016-12-02 23:11:56,143 INFO org.apache.hadoop.yarn.server.resourcemanager.scheduler.capacity.LeafQueue: Reserved container  application=application_1480719777699_0004 resource=<memory:2048, vCores:1> queue=default: capacity=1.0, absoluteCapacity=1.0, usedResources=<memory:10240, vCores:5>, usedCapacity=0.8333333, absoluteUsedCapacity=0.8333333, numApps=1, numContainers=5 usedCapacity=0.8333333 absoluteUsedCapacity=0.8333333 used=<memory:10240, vCores:5> cluster=<memory:12288, vCores:4>
2016-12-02 23:11:56,143 INFO org.apache.hadoop.yarn.server.resourcemanager.scheduler.capacity.ParentQueue: Re-sorting assigned queue: root.default stats: default: capacity=1.0, absoluteCapacity=1.0, usedResources=<memory:12288, vCores:6>, usedCapacity=1.0, absoluteUsedCapacity=1.0, numApps=1, numContainers=6
2016-12-02 23:11:56,144 INFO org.apache.hadoop.yarn.server.resourcemanager.scheduler.capacity.ParentQueue: assignedContainer queue=root usedCapacity=1.0 absoluteUsedCapacity=1.0 used=<memory:12288, vCores:6> cluster=<memory:12288, vCores:4>
2016-12-02 23:11:56,699 INFO org.apache.hadoop.yarn.server.resourcemanager.rmcontainer.RMContainerImpl: container_1480719777699_0004_01_000022 Container Transitioned from ACQUIRED to RUNNING
2016-12-02 23:11:56,829 INFO org.apache.hadoop.yarn.server.resourcemanager.scheduler.capacity.CapacityScheduler: Trying to fulfill reservation for application application_1480719777699_0004 on node: datanode2:60334
2016-12-02 23:11:56,830 INFO org.apache.hadoop.yarn.server.resourcemanager.scheduler.capacity.LeafQueue: Reserved container  application=application_1480719777699_0004 resource=<memory:2048, vCores:1> queue=default: capacity=1.0, absoluteCapacity=1.0, usedResources=<memory:12288, vCores:6>, usedCapacity=1.0, absoluteUsedCapacity=1.0, numApps=1, numContainers=6 usedCapacity=1.0 absoluteUsedCapacity=1.0 used=<memory:12288, vCores:6> cluster=<memory:12288, vCores:4>
2016-12-02 23:11:56,830 INFO org.apache.hadoop.yarn.server.resourcemanager.scheduler.capacity.CapacityScheduler: Skipping scheduling since node datanode2:60334 is reserved by application appattempt_1480719777699_0004_000001
2016-12-02 23:11:57,151 INFO org.apache.hadoop.yarn.server.resourcemanager.scheduler.capacity.CapacityScheduler: Trying to fulfill reservation for application application_1480719777699_0004 on node: datanode3:60932
2016-12-02 23:11:57,151 INFO org.apache.hadoop.yarn.server.resourcemanager.scheduler.capacity.LeafQueue: Reserved container  application=application_1480719777699_0004 resource=<memory:2048, vCores:1> queue=default: capacity=1.0, absoluteCapacity=1.0, usedResources=<memory:12288, vCores:6>, usedCapacity=1.0, absoluteUsedCapacity=1.0, numApps=1, numContainers=6 usedCapacity=1.0 absoluteUsedCapacity=1.0 used=<memory:12288, vCores:6> cluster=<memory:12288, vCores:4>
2016-12-02 23:11:57,151 INFO org.apache.hadoop.yarn.server.resourcemanager.scheduler.capacity.CapacityScheduler: Skipping scheduling since node datanode3:60932 is reserved by application appattempt_1480719777699_0004_000001
2016-12-02 23:11:57,832 INFO org.apache.hadoop.yarn.server.resourcemanager.scheduler.capacity.CapacityScheduler: Trying to fulfill reservation for application application_1480719777699_0004 on node: datanode2:60334
2016-12-02 23:11:57,832 INFO org.apache.hadoop.yarn.server.resourcemanager.scheduler.capacity.LeafQueue: Reserved container  application=application_1480719777699_0004 resource=<memory:2048, vCores:1> queue=default: capacity=1.0, absoluteCapacity=1.0, usedResources=<memory:12288, vCores:6>, usedCapacity=1.0, absoluteUsedCapacity=1.0, numApps=1, numContainers=6 usedCapacity=1.0 absoluteUsedCapacity=1.0 used=<memory:12288, vCores:6> cluster=<memory:12288, vCores:4>
2016-12-02 23:11:57,832 INFO org.apache.hadoop.yarn.server.resourcemanager.scheduler.capacity.CapacityScheduler: Skipping scheduling since node datanode2:60334 is reserved by application appattempt_1480719777699_0004_000001
2016-12-02 23:11:58,153 INFO org.apache.hadoop.yarn.server.resourcemanager.scheduler.capacity.CapacityScheduler: Trying to fulfill reservation for application application_1480719777699_0004 on node: datanode3:60932
2016-12-02 23:11:58,153 INFO org.apache.hadoop.yarn.server.resourcemanager.scheduler.capacity.LeafQueue: Reserved container  application=application_1480719777699_0004 resource=<memory:2048, vCores:1> queue=default: capacity=1.0, absoluteCapacity=1.0, usedResources=<memory:12288, vCores:6>, usedCapacity=1.0, absoluteUsedCapacity=1.0, numApps=1, numContainers=6 usedCapacity=1.0 absoluteUsedCapacity=1.0 used=<memory:12288, vCores:6> cluster=<memory:12288, vCores:4>
2016-12-02 23:11:58,153 INFO org.apache.hadoop.yarn.server.resourcemanager.scheduler.capacity.CapacityScheduler: Skipping scheduling since node datanode3:60932 is reserved by application appattempt_1480719777699_0004_000001
2016-12-02 23:11:58,457 INFO org.apache.hadoop.yarn.server.resourcemanager.rmcontainer.RMContainerImpl: container_1480719777699_0004_01_000017 Container Transitioned from RUNNING to COMPLETED
2016-12-02 23:11:58,457 INFO org.apache.hadoop.yarn.server.resourcemanager.scheduler.common.fica.FiCaSchedulerApp: Completed container: container_1480719777699_0004_01_000017 in state: COMPLETED event:FINISHED
2016-12-02 23:11:58,457 INFO org.apache.hadoop.yarn.server.resourcemanager.RMAuditLogger: USER=hdmaster	OPERATION=AM Released Container	TARGET=SchedulerApp	RESULT=SUCCESS	APPID=application_1480719777699_0004	CONTAINERID=container_1480719777699_0004_01_000017
2016-12-02 23:11:58,457 INFO org.apache.hadoop.yarn.server.resourcemanager.scheduler.SchedulerNode: Released container container_1480719777699_0004_01_000017 of capacity <memory:2048, vCores:1> on host datanode3:60932, which currently has 0 containers, <memory:0, vCores:0> used and <memory:3072, vCores:1> available, release resources=true
2016-12-02 23:11:58,457 INFO org.apache.hadoop.yarn.server.resourcemanager.scheduler.capacity.LeafQueue: default used=<memory:10240, vCores:5> numContainers=5 user=hdmaster user-resources=<memory:10240, vCores:5>
2016-12-02 23:11:58,457 INFO org.apache.hadoop.yarn.server.resourcemanager.scheduler.capacity.LeafQueue: completedContainer container=Container: [ContainerId: container_1480719777699_0004_01_000017, NodeId: datanode3:60932, NodeHttpAddress: datanode3:8042, Resource: <memory:2048, vCores:1>, Priority: 20, Token: Token { kind: ContainerToken, service: 10.0.0.8:60932 }, ] queue=default: capacity=1.0, absoluteCapacity=1.0, usedResources=<memory:10240, vCores:5>, usedCapacity=0.8333333, absoluteUsedCapacity=0.8333333, numApps=1, numContainers=5 cluster=<memory:12288, vCores:4>
2016-12-02 23:11:58,457 INFO org.apache.hadoop.yarn.server.resourcemanager.scheduler.capacity.ParentQueue: completedContainer queue=root usedCapacity=0.8333333 absoluteUsedCapacity=0.8333333 used=<memory:10240, vCores:5> cluster=<memory:12288, vCores:4>
2016-12-02 23:11:58,457 INFO org.apache.hadoop.yarn.server.resourcemanager.scheduler.capacity.ParentQueue: Re-sorting completed queue: root.default stats: default: capacity=1.0, absoluteCapacity=1.0, usedResources=<memory:10240, vCores:5>, usedCapacity=0.8333333, absoluteUsedCapacity=0.8333333, numApps=1, numContainers=5
2016-12-02 23:11:58,457 INFO org.apache.hadoop.yarn.server.resourcemanager.scheduler.capacity.CapacityScheduler: Application attempt appattempt_1480719777699_0004_000001 released container container_1480719777699_0004_01_000017 on node: host: datanode3:60932 #containers=0 available=<memory:3072, vCores:1> used=<memory:0, vCores:0> with event: FINISHED
2016-12-02 23:11:58,457 INFO org.apache.hadoop.yarn.server.resourcemanager.scheduler.capacity.CapacityScheduler: Trying to fulfill reservation for application application_1480719777699_0004 on node: datanode3:60932
2016-12-02 23:11:58,457 INFO org.apache.hadoop.yarn.server.resourcemanager.scheduler.common.fica.FiCaSchedulerApp: Application application_1480719777699_0004 unreserved  on node host: datanode3:60932 #containers=0 available=<memory:3072, vCores:1> used=<memory:0, vCores:0>, currently has 1 at priority 5; currentReservation <memory:2048, vCores:1>
2016-12-02 23:11:58,458 INFO org.apache.hadoop.yarn.server.resourcemanager.rmcontainer.RMContainerImpl: container_1480719777699_0004_01_000024 Container Transitioned from NEW to ALLOCATED
2016-12-02 23:11:58,458 INFO org.apache.hadoop.yarn.server.resourcemanager.RMAuditLogger: USER=hdmaster	OPERATION=AM Allocated Container	TARGET=SchedulerApp	RESULT=SUCCESS	APPID=application_1480719777699_0004	CONTAINERID=container_1480719777699_0004_01_000024
2016-12-02 23:11:58,458 INFO org.apache.hadoop.yarn.server.resourcemanager.scheduler.SchedulerNode: Assigned container container_1480719777699_0004_01_000024 of capacity <memory:2048, vCores:1> on host datanode3:60932, which has 1 containers, <memory:2048, vCores:1> used and <memory:1024, vCores:0> available after allocation
2016-12-02 23:11:58,458 INFO org.apache.hadoop.yarn.server.resourcemanager.scheduler.capacity.LeafQueue: assignedContainer application attempt=appattempt_1480719777699_0004_000001 container=Container: [ContainerId: container_1480719777699_0004_01_000024, NodeId: datanode3:60932, NodeHttpAddress: datanode3:8042, Resource: <memory:2048, vCores:1>, Priority: 5, Token: null, ] queue=default: capacity=1.0, absoluteCapacity=1.0, usedResources=<memory:10240, vCores:5>, usedCapacity=0.8333333, absoluteUsedCapacity=0.8333333, numApps=1, numContainers=5 clusterResource=<memory:12288, vCores:4> type=OFF_SWITCH
2016-12-02 23:11:58,743 INFO org.apache.hadoop.yarn.server.resourcemanager.rmcontainer.RMContainerImpl: container_1480719777699_0004_01_000024 Container Transitioned from ALLOCATED to ACQUIRED
2016-12-02 23:11:58,834 INFO org.apache.hadoop.yarn.server.resourcemanager.scheduler.capacity.CapacityScheduler: Trying to fulfill reservation for application application_1480719777699_0004 on node: datanode2:60334
2016-12-02 23:11:58,835 INFO org.apache.hadoop.yarn.server.resourcemanager.scheduler.capacity.LeafQueue: Reserved container  application=application_1480719777699_0004 resource=<memory:2048, vCores:1> queue=default: capacity=1.0, absoluteCapacity=1.0, usedResources=<memory:10240, vCores:5>, usedCapacity=0.8333333, absoluteUsedCapacity=0.8333333, numApps=1, numContainers=5 usedCapacity=0.8333333 absoluteUsedCapacity=0.8333333 used=<memory:10240, vCores:5> cluster=<memory:12288, vCores:4>
2016-12-02 23:11:58,835 INFO org.apache.hadoop.yarn.server.resourcemanager.scheduler.capacity.CapacityScheduler: Skipping scheduling since node datanode2:60334 is reserved by application appattempt_1480719777699_0004_000001
2016-12-02 23:11:59,396 INFO org.apache.hadoop.yarn.server.resourcemanager.rmcontainer.RMContainerImpl: container_1480719777699_0004_01_000030 Container Transitioned from NEW to RESERVED
2016-12-02 23:11:59,396 INFO org.apache.hadoop.yarn.server.resourcemanager.scheduler.capacity.LeafQueue: Reserved container  application=application_1480719777699_0004 resource=<memory:2048, vCores:1> queue=default: capacity=1.0, absoluteCapacity=1.0, usedResources=<memory:10240, vCores:5>, usedCapacity=0.8333333, absoluteUsedCapacity=0.8333333, numApps=1, numContainers=5 usedCapacity=0.8333333 absoluteUsedCapacity=0.8333333 used=<memory:10240, vCores:5> cluster=<memory:12288, vCores:4>
2016-12-02 23:11:59,396 INFO org.apache.hadoop.yarn.server.resourcemanager.scheduler.capacity.ParentQueue: Re-sorting assigned queue: root.default stats: default: capacity=1.0, absoluteCapacity=1.0, usedResources=<memory:12288, vCores:6>, usedCapacity=1.0, absoluteUsedCapacity=1.0, numApps=1, numContainers=6
2016-12-02 23:11:59,396 INFO org.apache.hadoop.yarn.server.resourcemanager.scheduler.capacity.ParentQueue: assignedContainer queue=root usedCapacity=1.0 absoluteUsedCapacity=1.0 used=<memory:12288, vCores:6> cluster=<memory:12288, vCores:4>
2016-12-02 23:11:59,459 INFO org.apache.hadoop.yarn.server.resourcemanager.rmcontainer.RMContainerImpl: container_1480719777699_0004_01_000024 Container Transitioned from ACQUIRED to RUNNING
2016-12-02 23:11:59,697 INFO org.apache.hadoop.yarn.server.resourcemanager.rmcontainer.RMContainerImpl: container_1480719777699_0004_01_000022 Container Transitioned from RUNNING to COMPLETED
2016-12-02 23:11:59,697 INFO org.apache.hadoop.yarn.server.resourcemanager.scheduler.common.fica.FiCaSchedulerApp: Completed container: container_1480719777699_0004_01_000022 in state: COMPLETED event:FINISHED
2016-12-02 23:11:59,697 INFO org.apache.hadoop.yarn.server.resourcemanager.RMAuditLogger: USER=hdmaster	OPERATION=AM Released Container	TARGET=SchedulerApp	RESULT=SUCCESS	APPID=application_1480719777699_0004	CONTAINERID=container_1480719777699_0004_01_000022
2016-12-02 23:11:59,697 INFO org.apache.hadoop.yarn.server.resourcemanager.scheduler.SchedulerNode: Released container container_1480719777699_0004_01_000022 of capacity <memory:2048, vCores:1> on host datanode4:45290, which currently has 0 containers, <memory:0, vCores:0> used and <memory:3072, vCores:1> available, release resources=true
2016-12-02 23:11:59,697 INFO org.apache.hadoop.yarn.server.resourcemanager.scheduler.capacity.LeafQueue: default used=<memory:10240, vCores:5> numContainers=5 user=hdmaster user-resources=<memory:10240, vCores:5>
2016-12-02 23:11:59,698 INFO org.apache.hadoop.yarn.server.resourcemanager.scheduler.capacity.LeafQueue: completedContainer container=Container: [ContainerId: container_1480719777699_0004_01_000022, NodeId: datanode4:45290, NodeHttpAddress: datanode4:8042, Resource: <memory:2048, vCores:1>, Priority: 5, Token: Token { kind: ContainerToken, service: 10.0.0.9:45290 }, ] queue=default: capacity=1.0, absoluteCapacity=1.0, usedResources=<memory:10240, vCores:5>, usedCapacity=0.8333333, absoluteUsedCapacity=0.8333333, numApps=1, numContainers=5 cluster=<memory:12288, vCores:4>
2016-12-02 23:11:59,698 INFO org.apache.hadoop.yarn.server.resourcemanager.scheduler.capacity.ParentQueue: completedContainer queue=root usedCapacity=0.8333333 absoluteUsedCapacity=0.8333333 used=<memory:10240, vCores:5> cluster=<memory:12288, vCores:4>
2016-12-02 23:11:59,698 INFO org.apache.hadoop.yarn.server.resourcemanager.scheduler.capacity.ParentQueue: Re-sorting completed queue: root.default stats: default: capacity=1.0, absoluteCapacity=1.0, usedResources=<memory:10240, vCores:5>, usedCapacity=0.8333333, absoluteUsedCapacity=0.8333333, numApps=1, numContainers=5
2016-12-02 23:11:59,698 INFO org.apache.hadoop.yarn.server.resourcemanager.scheduler.capacity.CapacityScheduler: Application attempt appattempt_1480719777699_0004_000001 released container container_1480719777699_0004_01_000022 on node: host: datanode4:45290 #containers=0 available=<memory:3072, vCores:1> used=<memory:0, vCores:0> with event: FINISHED
2016-12-02 23:11:59,698 INFO org.apache.hadoop.yarn.server.resourcemanager.scheduler.common.fica.FiCaSchedulerApp: Application application_1480719777699_0004 unreserved  on node host: datanode2:60334 #containers=1 available=<memory:1024, vCores:0> used=<memory:2048, vCores:1>, currently has 1 at priority 5; currentReservation <memory:2048, vCores:1>
2016-12-02 23:11:59,698 INFO org.apache.hadoop.yarn.server.resourcemanager.scheduler.capacity.LeafQueue: default used=<memory:8192, vCores:4> numContainers=4 user=hdmaster user-resources=<memory:8192, vCores:4>
2016-12-02 23:11:59,698 INFO org.apache.hadoop.yarn.server.resourcemanager.scheduler.capacity.LeafQueue: completedContainer container=Container: [ContainerId: container_1480719777699_0004_01_000023, NodeId: datanode2:60334, NodeHttpAddress: datanode2:8042, Resource: <memory:2048, vCores:1>, Priority: 5, Token: null, ] queue=default: capacity=1.0, absoluteCapacity=1.0, usedResources=<memory:8192, vCores:4>, usedCapacity=0.6666667, absoluteUsedCapacity=0.6666667, numApps=1, numContainers=4 cluster=<memory:12288, vCores:4>
2016-12-02 23:11:59,698 INFO org.apache.hadoop.yarn.server.resourcemanager.scheduler.capacity.ParentQueue: completedContainer queue=root usedCapacity=0.6666667 absoluteUsedCapacity=0.6666667 used=<memory:8192, vCores:4> cluster=<memory:12288, vCores:4>
2016-12-02 23:11:59,698 INFO org.apache.hadoop.yarn.server.resourcemanager.rmcontainer.RMContainerImpl: container_1480719777699_0004_01_000032 Container Transitioned from NEW to ALLOCATED
2016-12-02 23:11:59,698 INFO org.apache.hadoop.yarn.server.resourcemanager.RMAuditLogger: USER=hdmaster	OPERATION=AM Allocated Container	TARGET=SchedulerApp	RESULT=SUCCESS	APPID=application_1480719777699_0004	CONTAINERID=container_1480719777699_0004_01_000032
2016-12-02 23:11:59,698 INFO org.apache.hadoop.yarn.server.resourcemanager.scheduler.SchedulerNode: Assigned container container_1480719777699_0004_01_000032 of capacity <memory:2048, vCores:1> on host datanode4:45290, which has 1 containers, <memory:2048, vCores:1> used and <memory:1024, vCores:0> available after allocation
2016-12-02 23:11:59,698 INFO org.apache.hadoop.yarn.server.resourcemanager.scheduler.capacity.LeafQueue: assignedContainer application attempt=appattempt_1480719777699_0004_000001 container=Container: [ContainerId: container_1480719777699_0004_01_000032, NodeId: datanode4:45290, NodeHttpAddress: datanode4:8042, Resource: <memory:2048, vCores:1>, Priority: 5, Token: null, ] queue=default: capacity=1.0, absoluteCapacity=1.0, usedResources=<memory:8192, vCores:4>, usedCapacity=0.6666667, absoluteUsedCapacity=0.6666667, numApps=1, numContainers=4 clusterResource=<memory:12288, vCores:4> type=OFF_SWITCH
2016-12-02 23:11:59,699 INFO org.apache.hadoop.yarn.server.resourcemanager.scheduler.capacity.ParentQueue: Re-sorting assigned queue: root.default stats: default: capacity=1.0, absoluteCapacity=1.0, usedResources=<memory:10240, vCores:5>, usedCapacity=0.8333333, absoluteUsedCapacity=0.8333333, numApps=1, numContainers=5
2016-12-02 23:11:59,699 INFO org.apache.hadoop.yarn.server.resourcemanager.scheduler.capacity.ParentQueue: assignedContainer queue=root usedCapacity=0.8333333 absoluteUsedCapacity=0.8333333 used=<memory:10240, vCores:5> cluster=<memory:12288, vCores:4>
2016-12-02 23:11:59,750 INFO org.apache.hadoop.yarn.server.resourcemanager.rmcontainer.RMContainerImpl: container_1480719777699_0004_01_000032 Container Transitioned from ALLOCATED to ACQUIRED
2016-12-02 23:11:59,840 INFO org.apache.hadoop.yarn.server.resourcemanager.rmcontainer.RMContainerImpl: container_1480719777699_0004_01_000033 Container Transitioned from NEW to RESERVED
2016-12-02 23:11:59,840 INFO org.apache.hadoop.yarn.server.resourcemanager.scheduler.capacity.LeafQueue: Reserved container  application=application_1480719777699_0004 resource=<memory:2048, vCores:1> queue=default: capacity=1.0, absoluteCapacity=1.0, usedResources=<memory:10240, vCores:5>, usedCapacity=0.8333333, absoluteUsedCapacity=0.8333333, numApps=1, numContainers=5 usedCapacity=0.8333333 absoluteUsedCapacity=0.8333333 used=<memory:10240, vCores:5> cluster=<memory:12288, vCores:4>
2016-12-02 23:11:59,840 INFO org.apache.hadoop.yarn.server.resourcemanager.scheduler.capacity.ParentQueue: Re-sorting assigned queue: root.default stats: default: capacity=1.0, absoluteCapacity=1.0, usedResources=<memory:12288, vCores:6>, usedCapacity=1.0, absoluteUsedCapacity=1.0, numApps=1, numContainers=6
2016-12-02 23:11:59,840 INFO org.apache.hadoop.yarn.server.resourcemanager.scheduler.capacity.ParentQueue: assignedContainer queue=root usedCapacity=1.0 absoluteUsedCapacity=1.0 used=<memory:12288, vCores:6> cluster=<memory:12288, vCores:4>
2016-12-02 23:12:00,263 INFO org.apache.hadoop.yarn.server.resourcemanager.rmcontainer.RMContainerImpl: container_1480719777699_0004_01_000019 Container Transitioned from RUNNING to COMPLETED
2016-12-02 23:12:00,263 INFO org.apache.hadoop.yarn.server.resourcemanager.scheduler.common.fica.FiCaSchedulerApp: Completed container: container_1480719777699_0004_01_000019 in state: COMPLETED event:FINISHED
2016-12-02 23:12:00,263 INFO org.apache.hadoop.yarn.server.resourcemanager.RMAuditLogger: USER=hdmaster	OPERATION=AM Released Container	TARGET=SchedulerApp	RESULT=SUCCESS	APPID=application_1480719777699_0004	CONTAINERID=container_1480719777699_0004_01_000019
2016-12-02 23:12:00,263 INFO org.apache.hadoop.yarn.server.resourcemanager.scheduler.SchedulerNode: Released container container_1480719777699_0004_01_000019 of capacity <memory:2048, vCores:1> on host datanode2:60334, which currently has 0 containers, <memory:0, vCores:0> used and <memory:3072, vCores:1> available, release resources=true
2016-12-02 23:12:00,263 INFO org.apache.hadoop.yarn.server.resourcemanager.scheduler.capacity.LeafQueue: default used=<memory:10240, vCores:5> numContainers=5 user=hdmaster user-resources=<memory:10240, vCores:5>
2016-12-02 23:12:00,264 INFO org.apache.hadoop.yarn.server.resourcemanager.scheduler.capacity.LeafQueue: completedContainer container=Container: [ContainerId: container_1480719777699_0004_01_000019, NodeId: datanode2:60334, NodeHttpAddress: datanode2:8042, Resource: <memory:2048, vCores:1>, Priority: 5, Token: Token { kind: ContainerToken, service: 10.0.0.7:60334 }, ] queue=default: capacity=1.0, absoluteCapacity=1.0, usedResources=<memory:10240, vCores:5>, usedCapacity=0.8333333, absoluteUsedCapacity=0.8333333, numApps=1, numContainers=5 cluster=<memory:12288, vCores:4>
2016-12-02 23:12:00,264 INFO org.apache.hadoop.yarn.server.resourcemanager.scheduler.capacity.ParentQueue: completedContainer queue=root usedCapacity=0.8333333 absoluteUsedCapacity=0.8333333 used=<memory:10240, vCores:5> cluster=<memory:12288, vCores:4>
2016-12-02 23:12:00,264 INFO org.apache.hadoop.yarn.server.resourcemanager.scheduler.capacity.ParentQueue: Re-sorting completed queue: root.default stats: default: capacity=1.0, absoluteCapacity=1.0, usedResources=<memory:10240, vCores:5>, usedCapacity=0.8333333, absoluteUsedCapacity=0.8333333, numApps=1, numContainers=5
2016-12-02 23:12:00,264 INFO org.apache.hadoop.yarn.server.resourcemanager.scheduler.capacity.CapacityScheduler: Application attempt appattempt_1480719777699_0004_000001 released container container_1480719777699_0004_01_000019 on node: host: datanode2:60334 #containers=0 available=<memory:3072, vCores:1> used=<memory:0, vCores:0> with event: FINISHED
2016-12-02 23:12:00,264 INFO org.apache.hadoop.yarn.server.resourcemanager.scheduler.capacity.CapacityScheduler: Trying to fulfill reservation for application application_1480719777699_0004 on node: datanode2:60334
2016-12-02 23:12:00,264 INFO org.apache.hadoop.yarn.server.resourcemanager.scheduler.common.fica.FiCaSchedulerApp: Application application_1480719777699_0004 unreserved  on node host: datanode2:60334 #containers=0 available=<memory:3072, vCores:1> used=<memory:0, vCores:0>, currently has 1 at priority 5; currentReservation <memory:2048, vCores:1>
2016-12-02 23:12:00,264 INFO org.apache.hadoop.yarn.server.resourcemanager.rmcontainer.RMContainerImpl: container_1480719777699_0004_01_000033 Container Transitioned from NEW to ALLOCATED
2016-12-02 23:12:00,264 INFO org.apache.hadoop.yarn.server.resourcemanager.RMAuditLogger: USER=hdmaster	OPERATION=AM Allocated Container	TARGET=SchedulerApp	RESULT=SUCCESS	APPID=application_1480719777699_0004	CONTAINERID=container_1480719777699_0004_01_000033
2016-12-02 23:12:00,264 INFO org.apache.hadoop.yarn.server.resourcemanager.scheduler.SchedulerNode: Assigned container container_1480719777699_0004_01_000033 of capacity <memory:2048, vCores:1> on host datanode2:60334, which has 1 containers, <memory:2048, vCores:1> used and <memory:1024, vCores:0> available after allocation
2016-12-02 23:12:00,264 INFO org.apache.hadoop.yarn.server.resourcemanager.scheduler.capacity.LeafQueue: assignedContainer application attempt=appattempt_1480719777699_0004_000001 container=Container: [ContainerId: container_1480719777699_0004_01_000033, NodeId: datanode2:60334, NodeHttpAddress: datanode2:8042, Resource: <memory:2048, vCores:1>, Priority: 5, Token: null, ] queue=default: capacity=1.0, absoluteCapacity=1.0, usedResources=<memory:10240, vCores:5>, usedCapacity=0.8333333, absoluteUsedCapacity=0.8333333, numApps=1, numContainers=5 clusterResource=<memory:12288, vCores:4> type=OFF_SWITCH
2016-12-02 23:12:00,401 INFO org.apache.hadoop.yarn.server.resourcemanager.scheduler.capacity.CapacityScheduler: Trying to fulfill reservation for application application_1480719777699_0004 on node: datanode1:50178
2016-12-02 23:12:00,401 INFO org.apache.hadoop.yarn.server.resourcemanager.scheduler.capacity.LeafQueue: Reserved container  application=application_1480719777699_0004 resource=<memory:2048, vCores:1> queue=default: capacity=1.0, absoluteCapacity=1.0, usedResources=<memory:10240, vCores:5>, usedCapacity=0.8333333, absoluteUsedCapacity=0.8333333, numApps=1, numContainers=5 usedCapacity=0.8333333 absoluteUsedCapacity=0.8333333 used=<memory:10240, vCores:5> cluster=<memory:12288, vCores:4>
2016-12-02 23:12:00,401 INFO org.apache.hadoop.yarn.server.resourcemanager.scheduler.capacity.CapacityScheduler: Skipping scheduling since node datanode1:50178 is reserved by application appattempt_1480719777699_0004_000001
2016-12-02 23:12:00,699 INFO org.apache.hadoop.yarn.server.resourcemanager.rmcontainer.RMContainerImpl: container_1480719777699_0004_01_000032 Container Transitioned from ACQUIRED to RUNNING
2016-12-02 23:12:00,756 INFO org.apache.hadoop.yarn.server.resourcemanager.rmcontainer.RMContainerImpl: container_1480719777699_0004_01_000033 Container Transitioned from ALLOCATED to ACQUIRED
2016-12-02 23:12:01,264 INFO org.apache.hadoop.yarn.server.resourcemanager.rmcontainer.RMContainerImpl: container_1480719777699_0004_01_000033 Container Transitioned from ACQUIRED to RUNNING
2016-12-02 23:12:01,264 INFO org.apache.hadoop.yarn.server.resourcemanager.rmcontainer.RMContainerImpl: container_1480719777699_0004_01_000037 Container Transitioned from NEW to RESERVED
2016-12-02 23:12:01,264 INFO org.apache.hadoop.yarn.server.resourcemanager.scheduler.capacity.LeafQueue: Reserved container  application=application_1480719777699_0004 resource=<memory:2048, vCores:1> queue=default: capacity=1.0, absoluteCapacity=1.0, usedResources=<memory:10240, vCores:5>, usedCapacity=0.8333333, absoluteUsedCapacity=0.8333333, numApps=1, numContainers=5 usedCapacity=0.8333333 absoluteUsedCapacity=0.8333333 used=<memory:10240, vCores:5> cluster=<memory:12288, vCores:4>
2016-12-02 23:12:01,265 INFO org.apache.hadoop.yarn.server.resourcemanager.scheduler.capacity.ParentQueue: Re-sorting assigned queue: root.default stats: default: capacity=1.0, absoluteCapacity=1.0, usedResources=<memory:12288, vCores:6>, usedCapacity=1.0, absoluteUsedCapacity=1.0, numApps=1, numContainers=6
2016-12-02 23:12:01,265 INFO org.apache.hadoop.yarn.server.resourcemanager.scheduler.capacity.ParentQueue: assignedContainer queue=root usedCapacity=1.0 absoluteUsedCapacity=1.0 used=<memory:12288, vCores:6> cluster=<memory:12288, vCores:4>
2016-12-02 23:12:01,403 INFO org.apache.hadoop.yarn.server.resourcemanager.scheduler.capacity.CapacityScheduler: Trying to fulfill reservation for application application_1480719777699_0004 on node: datanode1:50178
2016-12-02 23:12:01,403 INFO org.apache.hadoop.yarn.server.resourcemanager.scheduler.capacity.LeafQueue: Reserved container  application=application_1480719777699_0004 resource=<memory:2048, vCores:1> queue=default: capacity=1.0, absoluteCapacity=1.0, usedResources=<memory:12288, vCores:6>, usedCapacity=1.0, absoluteUsedCapacity=1.0, numApps=1, numContainers=6 usedCapacity=1.0 absoluteUsedCapacity=1.0 used=<memory:12288, vCores:6> cluster=<memory:12288, vCores:4>
2016-12-02 23:12:01,403 INFO org.apache.hadoop.yarn.server.resourcemanager.scheduler.capacity.CapacityScheduler: Skipping scheduling since node datanode1:50178 is reserved by application appattempt_1480719777699_0004_000001
2016-12-02 23:12:01,912 INFO org.apache.hadoop.yarn.server.resourcemanager.rmcontainer.RMContainerImpl: container_1480719777699_0004_01_000024 Container Transitioned from RUNNING to COMPLETED
2016-12-02 23:12:01,912 INFO org.apache.hadoop.yarn.server.resourcemanager.scheduler.common.fica.FiCaSchedulerApp: Completed container: container_1480719777699_0004_01_000024 in state: COMPLETED event:FINISHED
2016-12-02 23:12:01,912 INFO org.apache.hadoop.yarn.server.resourcemanager.RMAuditLogger: USER=hdmaster	OPERATION=AM Released Container	TARGET=SchedulerApp	RESULT=SUCCESS	APPID=application_1480719777699_0004	CONTAINERID=container_1480719777699_0004_01_000024
2016-12-02 23:12:01,912 INFO org.apache.hadoop.yarn.server.resourcemanager.scheduler.SchedulerNode: Released container container_1480719777699_0004_01_000024 of capacity <memory:2048, vCores:1> on host datanode3:60932, which currently has 0 containers, <memory:0, vCores:0> used and <memory:3072, vCores:1> available, release resources=true
2016-12-02 23:12:01,912 INFO org.apache.hadoop.yarn.server.resourcemanager.scheduler.capacity.LeafQueue: default used=<memory:10240, vCores:5> numContainers=5 user=hdmaster user-resources=<memory:10240, vCores:5>
2016-12-02 23:12:01,915 INFO org.apache.hadoop.yarn.server.resourcemanager.scheduler.capacity.LeafQueue: completedContainer container=Container: [ContainerId: container_1480719777699_0004_01_000024, NodeId: datanode3:60932, NodeHttpAddress: datanode3:8042, Resource: <memory:2048, vCores:1>, Priority: 5, Token: Token { kind: ContainerToken, service: 10.0.0.8:60932 }, ] queue=default: capacity=1.0, absoluteCapacity=1.0, usedResources=<memory:10240, vCores:5>, usedCapacity=0.8333333, absoluteUsedCapacity=0.8333333, numApps=1, numContainers=5 cluster=<memory:12288, vCores:4>
2016-12-02 23:12:01,915 INFO org.apache.hadoop.yarn.server.resourcemanager.scheduler.capacity.ParentQueue: completedContainer queue=root usedCapacity=0.8333333 absoluteUsedCapacity=0.8333333 used=<memory:10240, vCores:5> cluster=<memory:12288, vCores:4>
2016-12-02 23:12:01,915 INFO org.apache.hadoop.yarn.server.resourcemanager.scheduler.capacity.ParentQueue: Re-sorting completed queue: root.default stats: default: capacity=1.0, absoluteCapacity=1.0, usedResources=<memory:10240, vCores:5>, usedCapacity=0.8333333, absoluteUsedCapacity=0.8333333, numApps=1, numContainers=5
2016-12-02 23:12:01,915 INFO org.apache.hadoop.yarn.server.resourcemanager.scheduler.capacity.CapacityScheduler: Application attempt appattempt_1480719777699_0004_000001 released container container_1480719777699_0004_01_000024 on node: host: datanode3:60932 #containers=0 available=<memory:3072, vCores:1> used=<memory:0, vCores:0> with event: FINISHED
2016-12-02 23:12:01,915 INFO org.apache.hadoop.yarn.server.resourcemanager.scheduler.common.fica.FiCaSchedulerApp: Application application_1480719777699_0004 unreserved  on node host: datanode2:60334 #containers=1 available=<memory:1024, vCores:0> used=<memory:2048, vCores:1>, currently has 1 at priority 5; currentReservation <memory:2048, vCores:1>
2016-12-02 23:12:01,915 INFO org.apache.hadoop.yarn.server.resourcemanager.scheduler.capacity.LeafQueue: default used=<memory:8192, vCores:4> numContainers=4 user=hdmaster user-resources=<memory:8192, vCores:4>
2016-12-02 23:12:01,916 INFO org.apache.hadoop.yarn.server.resourcemanager.scheduler.capacity.LeafQueue: completedContainer container=Container: [ContainerId: container_1480719777699_0004_01_000037, NodeId: datanode2:60334, NodeHttpAddress: datanode2:8042, Resource: <memory:2048, vCores:1>, Priority: 5, Token: null, ] queue=default: capacity=1.0, absoluteCapacity=1.0, usedResources=<memory:8192, vCores:4>, usedCapacity=0.6666667, absoluteUsedCapacity=0.6666667, numApps=1, numContainers=4 cluster=<memory:12288, vCores:4>
2016-12-02 23:12:01,916 INFO org.apache.hadoop.yarn.server.resourcemanager.scheduler.capacity.ParentQueue: completedContainer queue=root usedCapacity=0.6666667 absoluteUsedCapacity=0.6666667 used=<memory:8192, vCores:4> cluster=<memory:12288, vCores:4>
2016-12-02 23:12:01,916 INFO org.apache.hadoop.yarn.server.resourcemanager.rmcontainer.RMContainerImpl: container_1480719777699_0004_01_000040 Container Transitioned from NEW to ALLOCATED
2016-12-02 23:12:01,916 INFO org.apache.hadoop.yarn.server.resourcemanager.RMAuditLogger: USER=hdmaster	OPERATION=AM Allocated Container	TARGET=SchedulerApp	RESULT=SUCCESS	APPID=application_1480719777699_0004	CONTAINERID=container_1480719777699_0004_01_000040
2016-12-02 23:12:01,916 INFO org.apache.hadoop.yarn.server.resourcemanager.scheduler.SchedulerNode: Assigned container container_1480719777699_0004_01_000040 of capacity <memory:2048, vCores:1> on host datanode3:60932, which has 1 containers, <memory:2048, vCores:1> used and <memory:1024, vCores:0> available after allocation
2016-12-02 23:12:01,916 INFO org.apache.hadoop.yarn.server.resourcemanager.scheduler.capacity.LeafQueue: assignedContainer application attempt=appattempt_1480719777699_0004_000001 container=Container: [ContainerId: container_1480719777699_0004_01_000040, NodeId: datanode3:60932, NodeHttpAddress: datanode3:8042, Resource: <memory:2048, vCores:1>, Priority: 5, Token: null, ] queue=default: capacity=1.0, absoluteCapacity=1.0, usedResources=<memory:8192, vCores:4>, usedCapacity=0.6666667, absoluteUsedCapacity=0.6666667, numApps=1, numContainers=4 clusterResource=<memory:12288, vCores:4> type=OFF_SWITCH
2016-12-02 23:12:01,916 INFO org.apache.hadoop.yarn.server.resourcemanager.scheduler.capacity.ParentQueue: Re-sorting assigned queue: root.default stats: default: capacity=1.0, absoluteCapacity=1.0, usedResources=<memory:10240, vCores:5>, usedCapacity=0.8333333, absoluteUsedCapacity=0.8333333, numApps=1, numContainers=5
2016-12-02 23:12:01,916 INFO org.apache.hadoop.yarn.server.resourcemanager.scheduler.capacity.ParentQueue: assignedContainer queue=root usedCapacity=0.8333333 absoluteUsedCapacity=0.8333333 used=<memory:10240, vCores:5> cluster=<memory:12288, vCores:4>
2016-12-02 23:12:02,405 INFO org.apache.hadoop.yarn.server.resourcemanager.scheduler.capacity.CapacityScheduler: Trying to fulfill reservation for application application_1480719777699_0004 on node: datanode1:50178
2016-12-02 23:12:02,405 INFO org.apache.hadoop.yarn.server.resourcemanager.scheduler.common.fica.FiCaSchedulerApp: Application application_1480719777699_0004 unreserved  on node host: datanode1:50178 #containers=1 available=<memory:1024, vCores:0> used=<memory:2048, vCores:1>, currently has 0 at priority 5; currentReservation <memory:0, vCores:0>
2016-12-02 23:12:02,405 INFO org.apache.hadoop.yarn.server.resourcemanager.scheduler.capacity.LeafQueue: default used=<memory:8192, vCores:4> numContainers=4 user=hdmaster user-resources=<memory:8192, vCores:4>
2016-12-02 23:12:02,405 INFO org.apache.hadoop.yarn.server.resourcemanager.scheduler.capacity.LeafQueue: completedContainer container=Container: [ContainerId: container_1480719777699_0004_01_000030, NodeId: datanode1:50178, NodeHttpAddress: datanode1:8042, Resource: <memory:2048, vCores:1>, Priority: 5, Token: null, ] queue=default: capacity=1.0, absoluteCapacity=1.0, usedResources=<memory:8192, vCores:4>, usedCapacity=0.6666667, absoluteUsedCapacity=0.6666667, numApps=1, numContainers=4 cluster=<memory:12288, vCores:4>
2016-12-02 23:12:02,405 INFO org.apache.hadoop.yarn.server.resourcemanager.scheduler.capacity.ParentQueue: completedContainer queue=root usedCapacity=0.6666667 absoluteUsedCapacity=0.6666667 used=<memory:8192, vCores:4> cluster=<memory:12288, vCores:4>
2016-12-02 23:12:02,405 INFO org.apache.hadoop.yarn.server.resourcemanager.scheduler.capacity.ParentQueue: Re-sorting completed queue: root.default stats: default: capacity=1.0, absoluteCapacity=1.0, usedResources=<memory:8192, vCores:4>, usedCapacity=0.6666667, absoluteUsedCapacity=0.6666667, numApps=1, numContainers=4
2016-12-02 23:12:02,767 INFO org.apache.hadoop.yarn.server.resourcemanager.rmcontainer.RMContainerImpl: container_1480719777699_0004_01_000040 Container Transitioned from ALLOCATED to ACQUIRED
2016-12-02 23:12:02,767 INFO org.apache.hadoop.yarn.server.resourcemanager.ApplicationMasterService: blacklist are updated in Scheduler.blacklistAdditions: [datanode3], blacklistRemovals: []
2016-12-02 23:12:03,268 INFO org.apache.hadoop.yarn.server.resourcemanager.rmcontainer.RMContainerImpl: container_1480719777699_0004_01_000041 Container Transitioned from NEW to RESERVED
2016-12-02 23:12:03,268 INFO org.apache.hadoop.yarn.server.resourcemanager.scheduler.capacity.LeafQueue: Reserved container  application=application_1480719777699_0004 resource=<memory:2048, vCores:1> queue=default: capacity=1.0, absoluteCapacity=1.0, usedResources=<memory:8192, vCores:4>, usedCapacity=0.6666667, absoluteUsedCapacity=0.6666667, numApps=1, numContainers=4 usedCapacity=0.6666667 absoluteUsedCapacity=0.6666667 used=<memory:8192, vCores:4> cluster=<memory:12288, vCores:4>
2016-12-02 23:12:03,268 INFO org.apache.hadoop.yarn.server.resourcemanager.scheduler.capacity.ParentQueue: Re-sorting assigned queue: root.default stats: default: capacity=1.0, absoluteCapacity=1.0, usedResources=<memory:10240, vCores:5>, usedCapacity=0.8333333, absoluteUsedCapacity=0.8333333, numApps=1, numContainers=5
2016-12-02 23:12:03,268 INFO org.apache.hadoop.yarn.server.resourcemanager.scheduler.capacity.ParentQueue: assignedContainer queue=root usedCapacity=0.8333333 absoluteUsedCapacity=0.8333333 used=<memory:10240, vCores:5> cluster=<memory:12288, vCores:4>
2016-12-02 23:12:03,368 INFO org.apache.hadoop.yarn.server.resourcemanager.rmcontainer.RMContainerImpl: container_1480719777699_0004_01_000032 Container Transitioned from RUNNING to COMPLETED
2016-12-02 23:12:03,368 INFO org.apache.hadoop.yarn.server.resourcemanager.scheduler.common.fica.FiCaSchedulerApp: Completed container: container_1480719777699_0004_01_000032 in state: COMPLETED event:FINISHED
2016-12-02 23:12:03,368 INFO org.apache.hadoop.yarn.server.resourcemanager.RMAuditLogger: USER=hdmaster	OPERATION=AM Released Container	TARGET=SchedulerApp	RESULT=SUCCESS	APPID=application_1480719777699_0004	CONTAINERID=container_1480719777699_0004_01_000032
2016-12-02 23:12:03,368 INFO org.apache.hadoop.yarn.server.resourcemanager.scheduler.SchedulerNode: Released container container_1480719777699_0004_01_000032 of capacity <memory:2048, vCores:1> on host datanode4:45290, which currently has 0 containers, <memory:0, vCores:0> used and <memory:3072, vCores:1> available, release resources=true
2016-12-02 23:12:03,368 INFO org.apache.hadoop.yarn.server.resourcemanager.scheduler.capacity.LeafQueue: default used=<memory:8192, vCores:4> numContainers=4 user=hdmaster user-resources=<memory:8192, vCores:4>
2016-12-02 23:12:03,368 INFO org.apache.hadoop.yarn.server.resourcemanager.scheduler.capacity.LeafQueue: completedContainer container=Container: [ContainerId: container_1480719777699_0004_01_000032, NodeId: datanode4:45290, NodeHttpAddress: datanode4:8042, Resource: <memory:2048, vCores:1>, Priority: 5, Token: Token { kind: ContainerToken, service: 10.0.0.9:45290 }, ] queue=default: capacity=1.0, absoluteCapacity=1.0, usedResources=<memory:8192, vCores:4>, usedCapacity=0.6666667, absoluteUsedCapacity=0.6666667, numApps=1, numContainers=4 cluster=<memory:12288, vCores:4>
2016-12-02 23:12:03,368 INFO org.apache.hadoop.yarn.server.resourcemanager.scheduler.capacity.ParentQueue: completedContainer queue=root usedCapacity=0.6666667 absoluteUsedCapacity=0.6666667 used=<memory:8192, vCores:4> cluster=<memory:12288, vCores:4>
2016-12-02 23:12:03,368 INFO org.apache.hadoop.yarn.server.resourcemanager.scheduler.capacity.ParentQueue: Re-sorting completed queue: root.default stats: default: capacity=1.0, absoluteCapacity=1.0, usedResources=<memory:8192, vCores:4>, usedCapacity=0.6666667, absoluteUsedCapacity=0.6666667, numApps=1, numContainers=4
2016-12-02 23:12:03,368 INFO org.apache.hadoop.yarn.server.resourcemanager.scheduler.capacity.CapacityScheduler: Application attempt appattempt_1480719777699_0004_000001 released container container_1480719777699_0004_01_000032 on node: host: datanode4:45290 #containers=0 available=<memory:3072, vCores:1> used=<memory:0, vCores:0> with event: FINISHED
2016-12-02 23:12:03,368 INFO org.apache.hadoop.yarn.server.resourcemanager.rmcontainer.RMContainerImpl: container_1480719777699_0004_01_000042 Container Transitioned from NEW to ALLOCATED
2016-12-02 23:12:03,368 INFO org.apache.hadoop.yarn.server.resourcemanager.RMAuditLogger: USER=hdmaster	OPERATION=AM Allocated Container	TARGET=SchedulerApp	RESULT=SUCCESS	APPID=application_1480719777699_0004	CONTAINERID=container_1480719777699_0004_01_000042
2016-12-02 23:12:03,368 INFO org.apache.hadoop.yarn.server.resourcemanager.scheduler.SchedulerNode: Assigned container container_1480719777699_0004_01_000042 of capacity <memory:2048, vCores:1> on host datanode4:45290, which has 1 containers, <memory:2048, vCores:1> used and <memory:1024, vCores:0> available after allocation
2016-12-02 23:12:03,368 INFO org.apache.hadoop.yarn.server.resourcemanager.scheduler.capacity.LeafQueue: assignedContainer application attempt=appattempt_1480719777699_0004_000001 container=Container: [ContainerId: container_1480719777699_0004_01_000042, NodeId: datanode4:45290, NodeHttpAddress: datanode4:8042, Resource: <memory:2048, vCores:1>, Priority: 5, Token: null, ] queue=default: capacity=1.0, absoluteCapacity=1.0, usedResources=<memory:8192, vCores:4>, usedCapacity=0.6666667, absoluteUsedCapacity=0.6666667, numApps=1, numContainers=4 clusterResource=<memory:12288, vCores:4> type=OFF_SWITCH
2016-12-02 23:12:03,368 INFO org.apache.hadoop.yarn.server.resourcemanager.scheduler.capacity.ParentQueue: Re-sorting assigned queue: root.default stats: default: capacity=1.0, absoluteCapacity=1.0, usedResources=<memory:10240, vCores:5>, usedCapacity=0.8333333, absoluteUsedCapacity=0.8333333, numApps=1, numContainers=5
2016-12-02 23:12:03,369 INFO org.apache.hadoop.yarn.server.resourcemanager.scheduler.capacity.ParentQueue: assignedContainer queue=root usedCapacity=0.8333333 absoluteUsedCapacity=0.8333333 used=<memory:10240, vCores:5> cluster=<memory:12288, vCores:4>
2016-12-02 23:12:03,773 INFO org.apache.hadoop.yarn.server.resourcemanager.rmcontainer.RMContainerImpl: container_1480719777699_0004_01_000040 Container Transitioned from ACQUIRED to RELEASED
2016-12-02 23:12:03,773 INFO org.apache.hadoop.yarn.server.resourcemanager.scheduler.common.fica.FiCaSchedulerApp: Completed container: container_1480719777699_0004_01_000040 in state: RELEASED event:RELEASED
2016-12-02 23:12:03,773 INFO org.apache.hadoop.yarn.server.resourcemanager.RMAuditLogger: USER=hdmaster	IP=10.0.0.6	OPERATION=AM Released Container	TARGET=SchedulerApp	RESULT=SUCCESS	APPID=application_1480719777699_0004	CONTAINERID=container_1480719777699_0004_01_000040
2016-12-02 23:12:03,774 INFO org.apache.hadoop.yarn.server.resourcemanager.scheduler.SchedulerNode: Released container container_1480719777699_0004_01_000040 of capacity <memory:2048, vCores:1> on host datanode3:60932, which currently has 0 containers, <memory:0, vCores:0> used and <memory:3072, vCores:1> available, release resources=true
2016-12-02 23:12:03,774 INFO org.apache.hadoop.yarn.server.resourcemanager.scheduler.capacity.LeafQueue: default used=<memory:8192, vCores:4> numContainers=4 user=hdmaster user-resources=<memory:8192, vCores:4>
2016-12-02 23:12:03,775 INFO org.apache.hadoop.yarn.server.resourcemanager.scheduler.capacity.LeafQueue: completedContainer container=Container: [ContainerId: container_1480719777699_0004_01_000040, NodeId: datanode3:60932, NodeHttpAddress: datanode3:8042, Resource: <memory:2048, vCores:1>, Priority: 5, Token: Token { kind: ContainerToken, service: 10.0.0.8:60932 }, ] queue=default: capacity=1.0, absoluteCapacity=1.0, usedResources=<memory:8192, vCores:4>, usedCapacity=0.6666667, absoluteUsedCapacity=0.6666667, numApps=1, numContainers=4 cluster=<memory:12288, vCores:4>
2016-12-02 23:12:03,775 INFO org.apache.hadoop.yarn.server.resourcemanager.scheduler.capacity.ParentQueue: completedContainer queue=root usedCapacity=0.6666667 absoluteUsedCapacity=0.6666667 used=<memory:8192, vCores:4> cluster=<memory:12288, vCores:4>
2016-12-02 23:12:03,775 INFO org.apache.hadoop.yarn.server.resourcemanager.scheduler.capacity.ParentQueue: Re-sorting completed queue: root.default stats: default: capacity=1.0, absoluteCapacity=1.0, usedResources=<memory:8192, vCores:4>, usedCapacity=0.6666667, absoluteUsedCapacity=0.6666667, numApps=1, numContainers=4
2016-12-02 23:12:03,775 INFO org.apache.hadoop.yarn.server.resourcemanager.scheduler.capacity.CapacityScheduler: Application attempt appattempt_1480719777699_0004_000001 released container container_1480719777699_0004_01_000040 on node: host: datanode3:60932 #containers=0 available=<memory:3072, vCores:1> used=<memory:0, vCores:0> with event: RELEASED
2016-12-02 23:12:03,777 INFO org.apache.hadoop.yarn.server.resourcemanager.rmcontainer.RMContainerImpl: container_1480719777699_0004_01_000042 Container Transitioned from ALLOCATED to ACQUIRED
2016-12-02 23:12:03,777 INFO org.apache.hadoop.yarn.server.resourcemanager.ApplicationMasterService: blacklist are updated in Scheduler.blacklistAdditions: [datanode4], blacklistRemovals: []
2016-12-02 23:12:04,269 INFO org.apache.hadoop.yarn.server.resourcemanager.scheduler.capacity.CapacityScheduler: Trying to fulfill reservation for application application_1480719777699_0004 on node: datanode2:60334
2016-12-02 23:12:04,270 INFO org.apache.hadoop.yarn.server.resourcemanager.scheduler.capacity.LeafQueue: Reserved container  application=application_1480719777699_0004 resource=<memory:2048, vCores:1> queue=default: capacity=1.0, absoluteCapacity=1.0, usedResources=<memory:8192, vCores:4>, usedCapacity=0.6666667, absoluteUsedCapacity=0.6666667, numApps=1, numContainers=4 usedCapacity=0.6666667 absoluteUsedCapacity=0.6666667 used=<memory:8192, vCores:4> cluster=<memory:12288, vCores:4>
2016-12-02 23:12:04,270 INFO org.apache.hadoop.yarn.server.resourcemanager.scheduler.capacity.CapacityScheduler: Skipping scheduling since node datanode2:60334 is reserved by application appattempt_1480719777699_0004_000001
2016-12-02 23:12:04,370 INFO org.apache.hadoop.yarn.server.resourcemanager.rmcontainer.RMContainerImpl: container_1480719777699_0004_01_000042 Container Transitioned from ACQUIRED to RUNNING
2016-12-02 23:12:04,408 INFO org.apache.hadoop.yarn.server.resourcemanager.rmcontainer.RMContainerImpl: container_1480719777699_0004_01_000044 Container Transitioned from NEW to RESERVED
2016-12-02 23:12:04,408 INFO org.apache.hadoop.yarn.server.resourcemanager.scheduler.capacity.LeafQueue: Reserved container  application=application_1480719777699_0004 resource=<memory:2048, vCores:1> queue=default: capacity=1.0, absoluteCapacity=1.0, usedResources=<memory:8192, vCores:4>, usedCapacity=0.6666667, absoluteUsedCapacity=0.6666667, numApps=1, numContainers=4 usedCapacity=0.6666667 absoluteUsedCapacity=0.6666667 used=<memory:8192, vCores:4> cluster=<memory:12288, vCores:4>
2016-12-02 23:12:04,408 INFO org.apache.hadoop.yarn.server.resourcemanager.scheduler.capacity.ParentQueue: Re-sorting assigned queue: root.default stats: default: capacity=1.0, absoluteCapacity=1.0, usedResources=<memory:10240, vCores:5>, usedCapacity=0.8333333, absoluteUsedCapacity=0.8333333, numApps=1, numContainers=5
2016-12-02 23:12:04,408 INFO org.apache.hadoop.yarn.server.resourcemanager.scheduler.capacity.ParentQueue: assignedContainer queue=root usedCapacity=0.8333333 absoluteUsedCapacity=0.8333333 used=<memory:10240, vCores:5> cluster=<memory:12288, vCores:4>
2016-12-02 23:12:04,780 INFO org.apache.hadoop.yarn.server.resourcemanager.ApplicationMasterService: blacklist are updated in Scheduler.blacklistAdditions: [], blacklistRemovals: [datanode4, datanode3]
2016-12-02 23:12:04,917 INFO org.apache.hadoop.yarn.server.resourcemanager.scheduler.common.fica.FiCaSchedulerApp: Application application_1480719777699_0004 unreserved  on node host: datanode2:60334 #containers=1 available=<memory:1024, vCores:0> used=<memory:2048, vCores:1>, currently has 1 at priority 5; currentReservation <memory:2048, vCores:1>
2016-12-02 23:12:04,918 INFO org.apache.hadoop.yarn.server.resourcemanager.scheduler.capacity.LeafQueue: default used=<memory:8192, vCores:4> numContainers=4 user=hdmaster user-resources=<memory:8192, vCores:4>
2016-12-02 23:12:04,918 INFO org.apache.hadoop.yarn.server.resourcemanager.scheduler.capacity.LeafQueue: completedContainer container=Container: [ContainerId: container_1480719777699_0004_01_000041, NodeId: datanode2:60334, NodeHttpAddress: datanode2:8042, Resource: <memory:2048, vCores:1>, Priority: 5, Token: null, ] queue=default: capacity=1.0, absoluteCapacity=1.0, usedResources=<memory:8192, vCores:4>, usedCapacity=0.6666667, absoluteUsedCapacity=0.6666667, numApps=1, numContainers=4 cluster=<memory:12288, vCores:4>
2016-12-02 23:12:04,918 INFO org.apache.hadoop.yarn.server.resourcemanager.scheduler.capacity.ParentQueue: completedContainer queue=root usedCapacity=0.6666667 absoluteUsedCapacity=0.6666667 used=<memory:8192, vCores:4> cluster=<memory:12288, vCores:4>
2016-12-02 23:12:04,918 INFO org.apache.hadoop.yarn.server.resourcemanager.rmcontainer.RMContainerImpl: container_1480719777699_0004_01_000045 Container Transitioned from NEW to ALLOCATED
2016-12-02 23:12:04,918 INFO org.apache.hadoop.yarn.server.resourcemanager.RMAuditLogger: USER=hdmaster	OPERATION=AM Allocated Container	TARGET=SchedulerApp	RESULT=SUCCESS	APPID=application_1480719777699_0004	CONTAINERID=container_1480719777699_0004_01_000045
2016-12-02 23:12:04,918 INFO org.apache.hadoop.yarn.server.resourcemanager.scheduler.SchedulerNode: Assigned container container_1480719777699_0004_01_000045 of capacity <memory:2048, vCores:1> on host datanode3:60932, which has 1 containers, <memory:2048, vCores:1> used and <memory:1024, vCores:0> available after allocation
2016-12-02 23:12:04,918 INFO org.apache.hadoop.yarn.server.resourcemanager.scheduler.capacity.LeafQueue: assignedContainer application attempt=appattempt_1480719777699_0004_000001 container=Container: [ContainerId: container_1480719777699_0004_01_000045, NodeId: datanode3:60932, NodeHttpAddress: datanode3:8042, Resource: <memory:2048, vCores:1>, Priority: 5, Token: null, ] queue=default: capacity=1.0, absoluteCapacity=1.0, usedResources=<memory:8192, vCores:4>, usedCapacity=0.6666667, absoluteUsedCapacity=0.6666667, numApps=1, numContainers=4 clusterResource=<memory:12288, vCores:4> type=OFF_SWITCH
2016-12-02 23:12:04,918 INFO org.apache.hadoop.yarn.server.resourcemanager.scheduler.capacity.ParentQueue: Re-sorting assigned queue: root.default stats: default: capacity=1.0, absoluteCapacity=1.0, usedResources=<memory:10240, vCores:5>, usedCapacity=0.8333333, absoluteUsedCapacity=0.8333333, numApps=1, numContainers=5
2016-12-02 23:12:04,918 INFO org.apache.hadoop.yarn.server.resourcemanager.scheduler.capacity.ParentQueue: assignedContainer queue=root usedCapacity=0.8333333 absoluteUsedCapacity=0.8333333 used=<memory:10240, vCores:5> cluster=<memory:12288, vCores:4>
2016-12-02 23:12:05,175 INFO org.apache.hadoop.yarn.server.resourcemanager.rmcontainer.RMContainerImpl: container_1480719777699_0004_01_000033 Container Transitioned from RUNNING to COMPLETED
2016-12-02 23:12:05,175 INFO org.apache.hadoop.yarn.server.resourcemanager.scheduler.common.fica.FiCaSchedulerApp: Completed container: container_1480719777699_0004_01_000033 in state: COMPLETED event:FINISHED
2016-12-02 23:12:05,175 INFO org.apache.hadoop.yarn.server.resourcemanager.RMAuditLogger: USER=hdmaster	OPERATION=AM Released Container	TARGET=SchedulerApp	RESULT=SUCCESS	APPID=application_1480719777699_0004	CONTAINERID=container_1480719777699_0004_01_000033
2016-12-02 23:12:05,175 INFO org.apache.hadoop.yarn.server.resourcemanager.scheduler.SchedulerNode: Released container container_1480719777699_0004_01_000033 of capacity <memory:2048, vCores:1> on host datanode2:60334, which currently has 0 containers, <memory:0, vCores:0> used and <memory:3072, vCores:1> available, release resources=true
2016-12-02 23:12:05,175 INFO org.apache.hadoop.yarn.server.resourcemanager.scheduler.capacity.LeafQueue: default used=<memory:8192, vCores:4> numContainers=4 user=hdmaster user-resources=<memory:8192, vCores:4>
2016-12-02 23:12:05,175 INFO org.apache.hadoop.yarn.server.resourcemanager.scheduler.capacity.LeafQueue: completedContainer container=Container: [ContainerId: container_1480719777699_0004_01_000033, NodeId: datanode2:60334, NodeHttpAddress: datanode2:8042, Resource: <memory:2048, vCores:1>, Priority: 5, Token: Token { kind: ContainerToken, service: 10.0.0.7:60334 }, ] queue=default: capacity=1.0, absoluteCapacity=1.0, usedResources=<memory:8192, vCores:4>, usedCapacity=0.6666667, absoluteUsedCapacity=0.6666667, numApps=1, numContainers=4 cluster=<memory:12288, vCores:4>
2016-12-02 23:12:05,175 INFO org.apache.hadoop.yarn.server.resourcemanager.scheduler.capacity.ParentQueue: completedContainer queue=root usedCapacity=0.6666667 absoluteUsedCapacity=0.6666667 used=<memory:8192, vCores:4> cluster=<memory:12288, vCores:4>
2016-12-02 23:12:05,175 INFO org.apache.hadoop.yarn.server.resourcemanager.scheduler.capacity.ParentQueue: Re-sorting completed queue: root.default stats: default: capacity=1.0, absoluteCapacity=1.0, usedResources=<memory:8192, vCores:4>, usedCapacity=0.6666667, absoluteUsedCapacity=0.6666667, numApps=1, numContainers=4
2016-12-02 23:12:05,175 INFO org.apache.hadoop.yarn.server.resourcemanager.scheduler.capacity.CapacityScheduler: Application attempt appattempt_1480719777699_0004_000001 released container container_1480719777699_0004_01_000033 on node: host: datanode2:60334 #containers=0 available=<memory:3072, vCores:1> used=<memory:0, vCores:0> with event: FINISHED
2016-12-02 23:12:05,176 INFO org.apache.hadoop.yarn.server.resourcemanager.scheduler.common.fica.FiCaSchedulerApp: Application application_1480719777699_0004 unreserved  on node host: datanode1:50178 #containers=1 available=<memory:1024, vCores:0> used=<memory:2048, vCores:1>, currently has 0 at priority 5; currentReservation <memory:0, vCores:0>
2016-12-02 23:12:05,176 INFO org.apache.hadoop.yarn.server.resourcemanager.scheduler.capacity.LeafQueue: default used=<memory:6144, vCores:3> numContainers=3 user=hdmaster user-resources=<memory:6144, vCores:3>
2016-12-02 23:12:05,176 INFO org.apache.hadoop.yarn.server.resourcemanager.scheduler.capacity.LeafQueue: completedContainer container=Container: [ContainerId: container_1480719777699_0004_01_000044, NodeId: datanode1:50178, NodeHttpAddress: datanode1:8042, Resource: <memory:2048, vCores:1>, Priority: 5, Token: null, ] queue=default: capacity=1.0, absoluteCapacity=1.0, usedResources=<memory:6144, vCores:3>, usedCapacity=0.5, absoluteUsedCapacity=0.5, numApps=1, numContainers=3 cluster=<memory:12288, vCores:4>
2016-12-02 23:12:05,176 INFO org.apache.hadoop.yarn.server.resourcemanager.scheduler.capacity.ParentQueue: completedContainer queue=root usedCapacity=0.5 absoluteUsedCapacity=0.5 used=<memory:6144, vCores:3> cluster=<memory:12288, vCores:4>
2016-12-02 23:12:05,176 INFO org.apache.hadoop.yarn.server.resourcemanager.rmcontainer.RMContainerImpl: container_1480719777699_0004_01_000046 Container Transitioned from NEW to ALLOCATED
2016-12-02 23:12:05,176 INFO org.apache.hadoop.yarn.server.resourcemanager.RMAuditLogger: USER=hdmaster	OPERATION=AM Allocated Container	TARGET=SchedulerApp	RESULT=SUCCESS	APPID=application_1480719777699_0004	CONTAINERID=container_1480719777699_0004_01_000046
2016-12-02 23:12:05,176 INFO org.apache.hadoop.yarn.server.resourcemanager.scheduler.SchedulerNode: Assigned container container_1480719777699_0004_01_000046 of capacity <memory:2048, vCores:1> on host datanode2:60334, which has 1 containers, <memory:2048, vCores:1> used and <memory:1024, vCores:0> available after allocation
2016-12-02 23:12:05,176 INFO org.apache.hadoop.yarn.server.resourcemanager.scheduler.capacity.LeafQueue: assignedContainer application attempt=appattempt_1480719777699_0004_000001 container=Container: [ContainerId: container_1480719777699_0004_01_000046, NodeId: datanode2:60334, NodeHttpAddress: datanode2:8042, Resource: <memory:2048, vCores:1>, Priority: 5, Token: null, ] queue=default: capacity=1.0, absoluteCapacity=1.0, usedResources=<memory:6144, vCores:3>, usedCapacity=0.5, absoluteUsedCapacity=0.5, numApps=1, numContainers=3 clusterResource=<memory:12288, vCores:4> type=OFF_SWITCH
2016-12-02 23:12:05,176 INFO org.apache.hadoop.yarn.server.resourcemanager.scheduler.capacity.ParentQueue: Re-sorting assigned queue: root.default stats: default: capacity=1.0, absoluteCapacity=1.0, usedResources=<memory:8192, vCores:4>, usedCapacity=0.6666667, absoluteUsedCapacity=0.6666667, numApps=1, numContainers=4
2016-12-02 23:12:05,177 INFO org.apache.hadoop.yarn.server.resourcemanager.scheduler.capacity.ParentQueue: assignedContainer queue=root usedCapacity=0.6666667 absoluteUsedCapacity=0.6666667 used=<memory:8192, vCores:4> cluster=<memory:12288, vCores:4>
2016-12-02 23:12:05,785 INFO org.apache.hadoop.yarn.server.resourcemanager.rmcontainer.RMContainerImpl: container_1480719777699_0004_01_000045 Container Transitioned from ALLOCATED to ACQUIRED
2016-12-02 23:12:05,785 INFO org.apache.hadoop.yarn.server.resourcemanager.rmcontainer.RMContainerImpl: container_1480719777699_0004_01_000046 Container Transitioned from ALLOCATED to ACQUIRED
2016-12-02 23:12:05,919 INFO org.apache.hadoop.yarn.server.resourcemanager.rmcontainer.RMContainerImpl: container_1480719777699_0004_01_000045 Container Transitioned from ACQUIRED to RUNNING
2016-12-02 23:12:05,919 INFO org.apache.hadoop.yarn.server.resourcemanager.rmcontainer.RMContainerImpl: container_1480719777699_0004_01_000047 Container Transitioned from NEW to RESERVED
2016-12-02 23:12:05,919 INFO org.apache.hadoop.yarn.server.resourcemanager.scheduler.capacity.LeafQueue: Reserved container  application=application_1480719777699_0004 resource=<memory:2048, vCores:1> queue=default: capacity=1.0, absoluteCapacity=1.0, usedResources=<memory:8192, vCores:4>, usedCapacity=0.6666667, absoluteUsedCapacity=0.6666667, numApps=1, numContainers=4 usedCapacity=0.6666667 absoluteUsedCapacity=0.6666667 used=<memory:8192, vCores:4> cluster=<memory:12288, vCores:4>
2016-12-02 23:12:05,919 INFO org.apache.hadoop.yarn.server.resourcemanager.scheduler.capacity.ParentQueue: Re-sorting assigned queue: root.default stats: default: capacity=1.0, absoluteCapacity=1.0, usedResources=<memory:10240, vCores:5>, usedCapacity=0.8333333, absoluteUsedCapacity=0.8333333, numApps=1, numContainers=5
2016-12-02 23:12:05,919 INFO org.apache.hadoop.yarn.server.resourcemanager.scheduler.capacity.ParentQueue: assignedContainer queue=root usedCapacity=0.8333333 absoluteUsedCapacity=0.8333333 used=<memory:10240, vCores:5> cluster=<memory:12288, vCores:4>
2016-12-02 23:12:06,177 INFO org.apache.hadoop.yarn.server.resourcemanager.rmcontainer.RMContainerImpl: container_1480719777699_0004_01_000046 Container Transitioned from ACQUIRED to RUNNING
2016-12-02 23:12:06,177 INFO org.apache.hadoop.yarn.server.resourcemanager.rmcontainer.RMContainerImpl: container_1480719777699_0004_01_000048 Container Transitioned from NEW to RESERVED
2016-12-02 23:12:06,177 INFO org.apache.hadoop.yarn.server.resourcemanager.scheduler.capacity.LeafQueue: Reserved container  application=application_1480719777699_0004 resource=<memory:2048, vCores:1> queue=default: capacity=1.0, absoluteCapacity=1.0, usedResources=<memory:10240, vCores:5>, usedCapacity=0.8333333, absoluteUsedCapacity=0.8333333, numApps=1, numContainers=5 usedCapacity=0.8333333 absoluteUsedCapacity=0.8333333 used=<memory:10240, vCores:5> cluster=<memory:12288, vCores:4>
2016-12-02 23:12:06,177 INFO org.apache.hadoop.yarn.server.resourcemanager.scheduler.capacity.ParentQueue: Re-sorting assigned queue: root.default stats: default: capacity=1.0, absoluteCapacity=1.0, usedResources=<memory:12288, vCores:6>, usedCapacity=1.0, absoluteUsedCapacity=1.0, numApps=1, numContainers=6
2016-12-02 23:12:06,177 INFO org.apache.hadoop.yarn.server.resourcemanager.scheduler.capacity.ParentQueue: assignedContainer queue=root usedCapacity=1.0 absoluteUsedCapacity=1.0 used=<memory:12288, vCores:6> cluster=<memory:12288, vCores:4>
2016-12-02 23:12:06,923 INFO org.apache.hadoop.yarn.server.resourcemanager.scheduler.capacity.CapacityScheduler: Trying to fulfill reservation for application application_1480719777699_0004 on node: datanode3:60932
2016-12-02 23:12:06,924 INFO org.apache.hadoop.yarn.server.resourcemanager.scheduler.capacity.LeafQueue: Reserved container  application=application_1480719777699_0004 resource=<memory:2048, vCores:1> queue=default: capacity=1.0, absoluteCapacity=1.0, usedResources=<memory:12288, vCores:6>, usedCapacity=1.0, absoluteUsedCapacity=1.0, numApps=1, numContainers=6 usedCapacity=1.0 absoluteUsedCapacity=1.0 used=<memory:12288, vCores:6> cluster=<memory:12288, vCores:4>
2016-12-02 23:12:06,924 INFO org.apache.hadoop.yarn.server.resourcemanager.scheduler.capacity.CapacityScheduler: Skipping scheduling since node datanode3:60932 is reserved by application appattempt_1480719777699_0004_000001
2016-12-02 23:12:07,179 INFO org.apache.hadoop.yarn.server.resourcemanager.scheduler.capacity.CapacityScheduler: Trying to fulfill reservation for application application_1480719777699_0004 on node: datanode2:60334
2016-12-02 23:12:07,179 INFO org.apache.hadoop.yarn.server.resourcemanager.scheduler.capacity.LeafQueue: Reserved container  application=application_1480719777699_0004 resource=<memory:2048, vCores:1> queue=default: capacity=1.0, absoluteCapacity=1.0, usedResources=<memory:12288, vCores:6>, usedCapacity=1.0, absoluteUsedCapacity=1.0, numApps=1, numContainers=6 usedCapacity=1.0 absoluteUsedCapacity=1.0 used=<memory:12288, vCores:6> cluster=<memory:12288, vCores:4>
2016-12-02 23:12:07,179 INFO org.apache.hadoop.yarn.server.resourcemanager.scheduler.capacity.CapacityScheduler: Skipping scheduling since node datanode2:60334 is reserved by application appattempt_1480719777699_0004_000001
2016-12-02 23:12:07,674 INFO org.apache.hadoop.yarn.server.resourcemanager.rmcontainer.RMContainerImpl: container_1480719777699_0004_01_000042 Container Transitioned from RUNNING to COMPLETED
2016-12-02 23:12:07,674 INFO org.apache.hadoop.yarn.server.resourcemanager.scheduler.common.fica.FiCaSchedulerApp: Completed container: container_1480719777699_0004_01_000042 in state: COMPLETED event:FINISHED
2016-12-02 23:12:07,674 INFO org.apache.hadoop.yarn.server.resourcemanager.RMAuditLogger: USER=hdmaster	OPERATION=AM Released Container	TARGET=SchedulerApp	RESULT=SUCCESS	APPID=application_1480719777699_0004	CONTAINERID=container_1480719777699_0004_01_000042
2016-12-02 23:12:07,674 INFO org.apache.hadoop.yarn.server.resourcemanager.scheduler.SchedulerNode: Released container container_1480719777699_0004_01_000042 of capacity <memory:2048, vCores:1> on host datanode4:45290, which currently has 0 containers, <memory:0, vCores:0> used and <memory:3072, vCores:1> available, release resources=true
2016-12-02 23:12:07,674 INFO org.apache.hadoop.yarn.server.resourcemanager.scheduler.capacity.LeafQueue: default used=<memory:10240, vCores:5> numContainers=5 user=hdmaster user-resources=<memory:10240, vCores:5>
2016-12-02 23:12:07,674 INFO org.apache.hadoop.yarn.server.resourcemanager.scheduler.capacity.LeafQueue: completedContainer container=Container: [ContainerId: container_1480719777699_0004_01_000042, NodeId: datanode4:45290, NodeHttpAddress: datanode4:8042, Resource: <memory:2048, vCores:1>, Priority: 5, Token: Token { kind: ContainerToken, service: 10.0.0.9:45290 }, ] queue=default: capacity=1.0, absoluteCapacity=1.0, usedResources=<memory:10240, vCores:5>, usedCapacity=0.8333333, absoluteUsedCapacity=0.8333333, numApps=1, numContainers=5 cluster=<memory:12288, vCores:4>
2016-12-02 23:12:07,675 INFO org.apache.hadoop.yarn.server.resourcemanager.scheduler.capacity.ParentQueue: completedContainer queue=root usedCapacity=0.8333333 absoluteUsedCapacity=0.8333333 used=<memory:10240, vCores:5> cluster=<memory:12288, vCores:4>
2016-12-02 23:12:07,675 INFO org.apache.hadoop.yarn.server.resourcemanager.scheduler.capacity.ParentQueue: Re-sorting completed queue: root.default stats: default: capacity=1.0, absoluteCapacity=1.0, usedResources=<memory:10240, vCores:5>, usedCapacity=0.8333333, absoluteUsedCapacity=0.8333333, numApps=1, numContainers=5
2016-12-02 23:12:07,675 INFO org.apache.hadoop.yarn.server.resourcemanager.scheduler.capacity.CapacityScheduler: Application attempt appattempt_1480719777699_0004_000001 released container container_1480719777699_0004_01_000042 on node: host: datanode4:45290 #containers=0 available=<memory:3072, vCores:1> used=<memory:0, vCores:0> with event: FINISHED
2016-12-02 23:12:07,675 INFO org.apache.hadoop.yarn.server.resourcemanager.scheduler.common.fica.FiCaSchedulerApp: Application application_1480719777699_0004 unreserved  on node host: datanode2:60334 #containers=1 available=<memory:1024, vCores:0> used=<memory:2048, vCores:1>, currently has 1 at priority 5; currentReservation <memory:2048, vCores:1>
2016-12-02 23:12:07,675 INFO org.apache.hadoop.yarn.server.resourcemanager.scheduler.capacity.LeafQueue: default used=<memory:8192, vCores:4> numContainers=4 user=hdmaster user-resources=<memory:8192, vCores:4>
2016-12-02 23:12:07,675 INFO org.apache.hadoop.yarn.server.resourcemanager.scheduler.capacity.LeafQueue: completedContainer container=Container: [ContainerId: container_1480719777699_0004_01_000048, NodeId: datanode2:60334, NodeHttpAddress: datanode2:8042, Resource: <memory:2048, vCores:1>, Priority: 5, Token: null, ] queue=default: capacity=1.0, absoluteCapacity=1.0, usedResources=<memory:8192, vCores:4>, usedCapacity=0.6666667, absoluteUsedCapacity=0.6666667, numApps=1, numContainers=4 cluster=<memory:12288, vCores:4>
2016-12-02 23:12:07,675 INFO org.apache.hadoop.yarn.server.resourcemanager.scheduler.capacity.ParentQueue: completedContainer queue=root usedCapacity=0.6666667 absoluteUsedCapacity=0.6666667 used=<memory:8192, vCores:4> cluster=<memory:12288, vCores:4>
2016-12-02 23:12:07,676 INFO org.apache.hadoop.yarn.server.resourcemanager.rmcontainer.RMContainerImpl: container_1480719777699_0004_01_000053 Container Transitioned from NEW to ALLOCATED
2016-12-02 23:12:07,676 INFO org.apache.hadoop.yarn.server.resourcemanager.RMAuditLogger: USER=hdmaster	OPERATION=AM Allocated Container	TARGET=SchedulerApp	RESULT=SUCCESS	APPID=application_1480719777699_0004	CONTAINERID=container_1480719777699_0004_01_000053
2016-12-02 23:12:07,676 INFO org.apache.hadoop.yarn.server.resourcemanager.scheduler.SchedulerNode: Assigned container container_1480719777699_0004_01_000053 of capacity <memory:2048, vCores:1> on host datanode4:45290, which has 1 containers, <memory:2048, vCores:1> used and <memory:1024, vCores:0> available after allocation
2016-12-02 23:12:07,676 INFO org.apache.hadoop.yarn.server.resourcemanager.scheduler.capacity.LeafQueue: assignedContainer application attempt=appattempt_1480719777699_0004_000001 container=Container: [ContainerId: container_1480719777699_0004_01_000053, NodeId: datanode4:45290, NodeHttpAddress: datanode4:8042, Resource: <memory:2048, vCores:1>, Priority: 5, Token: null, ] queue=default: capacity=1.0, absoluteCapacity=1.0, usedResources=<memory:8192, vCores:4>, usedCapacity=0.6666667, absoluteUsedCapacity=0.6666667, numApps=1, numContainers=4 clusterResource=<memory:12288, vCores:4> type=OFF_SWITCH
2016-12-02 23:12:07,676 INFO org.apache.hadoop.yarn.server.resourcemanager.scheduler.capacity.ParentQueue: Re-sorting assigned queue: root.default stats: default: capacity=1.0, absoluteCapacity=1.0, usedResources=<memory:10240, vCores:5>, usedCapacity=0.8333333, absoluteUsedCapacity=0.8333333, numApps=1, numContainers=5
2016-12-02 23:12:07,676 INFO org.apache.hadoop.yarn.server.resourcemanager.scheduler.capacity.ParentQueue: assignedContainer queue=root usedCapacity=0.8333333 absoluteUsedCapacity=0.8333333 used=<memory:10240, vCores:5> cluster=<memory:12288, vCores:4>
2016-12-02 23:12:07,794 INFO org.apache.hadoop.yarn.server.resourcemanager.rmcontainer.RMContainerImpl: container_1480719777699_0004_01_000053 Container Transitioned from ALLOCATED to ACQUIRED
2016-12-02 23:12:07,925 INFO org.apache.hadoop.yarn.server.resourcemanager.scheduler.capacity.CapacityScheduler: Trying to fulfill reservation for application application_1480719777699_0004 on node: datanode3:60932
2016-12-02 23:12:07,926 INFO org.apache.hadoop.yarn.server.resourcemanager.scheduler.capacity.LeafQueue: Reserved container  application=application_1480719777699_0004 resource=<memory:2048, vCores:1> queue=default: capacity=1.0, absoluteCapacity=1.0, usedResources=<memory:10240, vCores:5>, usedCapacity=0.8333333, absoluteUsedCapacity=0.8333333, numApps=1, numContainers=5 usedCapacity=0.8333333 absoluteUsedCapacity=0.8333333 used=<memory:10240, vCores:5> cluster=<memory:12288, vCores:4>
2016-12-02 23:12:07,926 INFO org.apache.hadoop.yarn.server.resourcemanager.scheduler.capacity.CapacityScheduler: Skipping scheduling since node datanode3:60932 is reserved by application appattempt_1480719777699_0004_000001
2016-12-02 23:12:08,181 INFO org.apache.hadoop.yarn.server.resourcemanager.rmcontainer.RMContainerImpl: container_1480719777699_0004_01_000054 Container Transitioned from NEW to RESERVED
2016-12-02 23:12:08,181 INFO org.apache.hadoop.yarn.server.resourcemanager.scheduler.capacity.LeafQueue: Reserved container  application=application_1480719777699_0004 resource=<memory:2048, vCores:1> queue=default: capacity=1.0, absoluteCapacity=1.0, usedResources=<memory:10240, vCores:5>, usedCapacity=0.8333333, absoluteUsedCapacity=0.8333333, numApps=1, numContainers=5 usedCapacity=0.8333333 absoluteUsedCapacity=0.8333333 used=<memory:10240, vCores:5> cluster=<memory:12288, vCores:4>
2016-12-02 23:12:08,181 INFO org.apache.hadoop.yarn.server.resourcemanager.scheduler.capacity.ParentQueue: Re-sorting assigned queue: root.default stats: default: capacity=1.0, absoluteCapacity=1.0, usedResources=<memory:12288, vCores:6>, usedCapacity=1.0, absoluteUsedCapacity=1.0, numApps=1, numContainers=6
2016-12-02 23:12:08,181 INFO org.apache.hadoop.yarn.server.resourcemanager.scheduler.capacity.ParentQueue: assignedContainer queue=root usedCapacity=1.0 absoluteUsedCapacity=1.0 used=<memory:12288, vCores:6> cluster=<memory:12288, vCores:4>
2016-12-02 23:12:08,677 INFO org.apache.hadoop.yarn.server.resourcemanager.rmcontainer.RMContainerImpl: container_1480719777699_0004_01_000053 Container Transitioned from ACQUIRED to RUNNING
2016-12-02 23:12:08,926 INFO org.apache.hadoop.yarn.server.resourcemanager.scheduler.capacity.CapacityScheduler: Trying to fulfill reservation for application application_1480719777699_0004 on node: datanode3:60932
2016-12-02 23:12:08,927 INFO org.apache.hadoop.yarn.server.resourcemanager.scheduler.capacity.LeafQueue: Reserved container  application=application_1480719777699_0004 resource=<memory:2048, vCores:1> queue=default: capacity=1.0, absoluteCapacity=1.0, usedResources=<memory:12288, vCores:6>, usedCapacity=1.0, absoluteUsedCapacity=1.0, numApps=1, numContainers=6 usedCapacity=1.0 absoluteUsedCapacity=1.0 used=<memory:12288, vCores:6> cluster=<memory:12288, vCores:4>
2016-12-02 23:12:08,927 INFO org.apache.hadoop.yarn.server.resourcemanager.scheduler.capacity.CapacityScheduler: Skipping scheduling since node datanode3:60932 is reserved by application appattempt_1480719777699_0004_000001
2016-12-02 23:12:09,183 INFO org.apache.hadoop.yarn.server.resourcemanager.scheduler.capacity.CapacityScheduler: Trying to fulfill reservation for application application_1480719777699_0004 on node: datanode2:60334
2016-12-02 23:12:09,183 INFO org.apache.hadoop.yarn.server.resourcemanager.scheduler.capacity.LeafQueue: Reserved container  application=application_1480719777699_0004 resource=<memory:2048, vCores:1> queue=default: capacity=1.0, absoluteCapacity=1.0, usedResources=<memory:12288, vCores:6>, usedCapacity=1.0, absoluteUsedCapacity=1.0, numApps=1, numContainers=6 usedCapacity=1.0 absoluteUsedCapacity=1.0 used=<memory:12288, vCores:6> cluster=<memory:12288, vCores:4>
2016-12-02 23:12:09,183 INFO org.apache.hadoop.yarn.server.resourcemanager.scheduler.capacity.CapacityScheduler: Skipping scheduling since node datanode2:60334 is reserved by application appattempt_1480719777699_0004_000001
2016-12-02 23:12:09,320 INFO org.apache.hadoop.yarn.server.resourcemanager.rmcontainer.RMContainerImpl: container_1480719777699_0004_01_000045 Container Transitioned from RUNNING to COMPLETED
2016-12-02 23:12:09,320 INFO org.apache.hadoop.yarn.server.resourcemanager.scheduler.common.fica.FiCaSchedulerApp: Completed container: container_1480719777699_0004_01_000045 in state: COMPLETED event:FINISHED
2016-12-02 23:12:09,320 INFO org.apache.hadoop.yarn.server.resourcemanager.RMAuditLogger: USER=hdmaster	OPERATION=AM Released Container	TARGET=SchedulerApp	RESULT=SUCCESS	APPID=application_1480719777699_0004	CONTAINERID=container_1480719777699_0004_01_000045
2016-12-02 23:12:09,320 INFO org.apache.hadoop.yarn.server.resourcemanager.scheduler.SchedulerNode: Released container container_1480719777699_0004_01_000045 of capacity <memory:2048, vCores:1> on host datanode3:60932, which currently has 0 containers, <memory:0, vCores:0> used and <memory:3072, vCores:1> available, release resources=true
2016-12-02 23:12:09,320 INFO org.apache.hadoop.yarn.server.resourcemanager.scheduler.capacity.LeafQueue: default used=<memory:10240, vCores:5> numContainers=5 user=hdmaster user-resources=<memory:10240, vCores:5>
2016-12-02 23:12:09,320 INFO org.apache.hadoop.yarn.server.resourcemanager.scheduler.capacity.LeafQueue: completedContainer container=Container: [ContainerId: container_1480719777699_0004_01_000045, NodeId: datanode3:60932, NodeHttpAddress: datanode3:8042, Resource: <memory:2048, vCores:1>, Priority: 5, Token: Token { kind: ContainerToken, service: 10.0.0.8:60932 }, ] queue=default: capacity=1.0, absoluteCapacity=1.0, usedResources=<memory:10240, vCores:5>, usedCapacity=0.8333333, absoluteUsedCapacity=0.8333333, numApps=1, numContainers=5 cluster=<memory:12288, vCores:4>
2016-12-02 23:12:09,320 INFO org.apache.hadoop.yarn.server.resourcemanager.scheduler.capacity.ParentQueue: completedContainer queue=root usedCapacity=0.8333333 absoluteUsedCapacity=0.8333333 used=<memory:10240, vCores:5> cluster=<memory:12288, vCores:4>
2016-12-02 23:12:09,320 INFO org.apache.hadoop.yarn.server.resourcemanager.scheduler.capacity.ParentQueue: Re-sorting completed queue: root.default stats: default: capacity=1.0, absoluteCapacity=1.0, usedResources=<memory:10240, vCores:5>, usedCapacity=0.8333333, absoluteUsedCapacity=0.8333333, numApps=1, numContainers=5
2016-12-02 23:12:09,321 INFO org.apache.hadoop.yarn.server.resourcemanager.scheduler.capacity.CapacityScheduler: Application attempt appattempt_1480719777699_0004_000001 released container container_1480719777699_0004_01_000045 on node: host: datanode3:60932 #containers=0 available=<memory:3072, vCores:1> used=<memory:0, vCores:0> with event: FINISHED
2016-12-02 23:12:09,321 INFO org.apache.hadoop.yarn.server.resourcemanager.scheduler.capacity.CapacityScheduler: Trying to fulfill reservation for application application_1480719777699_0004 on node: datanode3:60932
2016-12-02 23:12:09,321 INFO org.apache.hadoop.yarn.server.resourcemanager.scheduler.common.fica.FiCaSchedulerApp: Application application_1480719777699_0004 unreserved  on node host: datanode3:60932 #containers=0 available=<memory:3072, vCores:1> used=<memory:0, vCores:0>, currently has 1 at priority 5; currentReservation <memory:2048, vCores:1>
2016-12-02 23:12:09,321 INFO org.apache.hadoop.yarn.server.resourcemanager.rmcontainer.RMContainerImpl: container_1480719777699_0004_01_000047 Container Transitioned from NEW to ALLOCATED
2016-12-02 23:12:09,321 INFO org.apache.hadoop.yarn.server.resourcemanager.RMAuditLogger: USER=hdmaster	OPERATION=AM Allocated Container	TARGET=SchedulerApp	RESULT=SUCCESS	APPID=application_1480719777699_0004	CONTAINERID=container_1480719777699_0004_01_000047
2016-12-02 23:12:09,321 INFO org.apache.hadoop.yarn.server.resourcemanager.scheduler.SchedulerNode: Assigned container container_1480719777699_0004_01_000047 of capacity <memory:2048, vCores:1> on host datanode3:60932, which has 1 containers, <memory:2048, vCores:1> used and <memory:1024, vCores:0> available after allocation
2016-12-02 23:12:09,321 INFO org.apache.hadoop.yarn.server.resourcemanager.scheduler.capacity.LeafQueue: assignedContainer application attempt=appattempt_1480719777699_0004_000001 container=Container: [ContainerId: container_1480719777699_0004_01_000047, NodeId: datanode3:60932, NodeHttpAddress: datanode3:8042, Resource: <memory:2048, vCores:1>, Priority: 5, Token: null, ] queue=default: capacity=1.0, absoluteCapacity=1.0, usedResources=<memory:10240, vCores:5>, usedCapacity=0.8333333, absoluteUsedCapacity=0.8333333, numApps=1, numContainers=5 clusterResource=<memory:12288, vCores:4> type=OFF_SWITCH
2016-12-02 23:12:09,804 INFO org.apache.hadoop.yarn.server.resourcemanager.rmcontainer.RMContainerImpl: container_1480719777699_0004_01_000047 Container Transitioned from ALLOCATED to ACQUIRED
2016-12-02 23:12:10,185 INFO org.apache.hadoop.yarn.server.resourcemanager.scheduler.capacity.CapacityScheduler: Trying to fulfill reservation for application application_1480719777699_0004 on node: datanode2:60334
2016-12-02 23:12:10,186 INFO org.apache.hadoop.yarn.server.resourcemanager.scheduler.capacity.LeafQueue: Reserved container  application=application_1480719777699_0004 resource=<memory:2048, vCores:1> queue=default: capacity=1.0, absoluteCapacity=1.0, usedResources=<memory:10240, vCores:5>, usedCapacity=0.8333333, absoluteUsedCapacity=0.8333333, numApps=1, numContainers=5 usedCapacity=0.8333333 absoluteUsedCapacity=0.8333333 used=<memory:10240, vCores:5> cluster=<memory:12288, vCores:4>
2016-12-02 23:12:10,186 INFO org.apache.hadoop.yarn.server.resourcemanager.scheduler.capacity.CapacityScheduler: Skipping scheduling since node datanode2:60334 is reserved by application appattempt_1480719777699_0004_000001
2016-12-02 23:12:10,322 INFO org.apache.hadoop.yarn.server.resourcemanager.rmcontainer.RMContainerImpl: container_1480719777699_0004_01_000047 Container Transitioned from ACQUIRED to RUNNING
2016-12-02 23:12:10,322 INFO org.apache.hadoop.yarn.server.resourcemanager.rmcontainer.RMContainerImpl: container_1480719777699_0004_01_000057 Container Transitioned from NEW to RESERVED
2016-12-02 23:12:10,322 INFO org.apache.hadoop.yarn.server.resourcemanager.scheduler.capacity.LeafQueue: Reserved container  application=application_1480719777699_0004 resource=<memory:2048, vCores:1> queue=default: capacity=1.0, absoluteCapacity=1.0, usedResources=<memory:10240, vCores:5>, usedCapacity=0.8333333, absoluteUsedCapacity=0.8333333, numApps=1, numContainers=5 usedCapacity=0.8333333 absoluteUsedCapacity=0.8333333 used=<memory:10240, vCores:5> cluster=<memory:12288, vCores:4>
2016-12-02 23:12:10,322 INFO org.apache.hadoop.yarn.server.resourcemanager.scheduler.capacity.ParentQueue: Re-sorting assigned queue: root.default stats: default: capacity=1.0, absoluteCapacity=1.0, usedResources=<memory:12288, vCores:6>, usedCapacity=1.0, absoluteUsedCapacity=1.0, numApps=1, numContainers=6
2016-12-02 23:12:10,322 INFO org.apache.hadoop.yarn.server.resourcemanager.scheduler.capacity.ParentQueue: assignedContainer queue=root usedCapacity=1.0 absoluteUsedCapacity=1.0 used=<memory:12288, vCores:6> cluster=<memory:12288, vCores:4>
2016-12-02 23:12:10,331 INFO org.apache.hadoop.yarn.server.resourcemanager.rmcontainer.RMContainerImpl: container_1480719777699_0004_01_000046 Container Transitioned from RUNNING to COMPLETED
2016-12-02 23:12:10,331 INFO org.apache.hadoop.yarn.server.resourcemanager.scheduler.common.fica.FiCaSchedulerApp: Completed container: container_1480719777699_0004_01_000046 in state: COMPLETED event:FINISHED
2016-12-02 23:12:10,331 INFO org.apache.hadoop.yarn.server.resourcemanager.RMAuditLogger: USER=hdmaster	OPERATION=AM Released Container	TARGET=SchedulerApp	RESULT=SUCCESS	APPID=application_1480719777699_0004	CONTAINERID=container_1480719777699_0004_01_000046
2016-12-02 23:12:10,331 INFO org.apache.hadoop.yarn.server.resourcemanager.scheduler.SchedulerNode: Released container container_1480719777699_0004_01_000046 of capacity <memory:2048, vCores:1> on host datanode2:60334, which currently has 0 containers, <memory:0, vCores:0> used and <memory:3072, vCores:1> available, release resources=true
2016-12-02 23:12:10,331 INFO org.apache.hadoop.yarn.server.resourcemanager.scheduler.capacity.LeafQueue: default used=<memory:10240, vCores:5> numContainers=5 user=hdmaster user-resources=<memory:10240, vCores:5>
2016-12-02 23:12:10,332 INFO org.apache.hadoop.yarn.server.resourcemanager.scheduler.capacity.LeafQueue: completedContainer container=Container: [ContainerId: container_1480719777699_0004_01_000046, NodeId: datanode2:60334, NodeHttpAddress: datanode2:8042, Resource: <memory:2048, vCores:1>, Priority: 5, Token: Token { kind: ContainerToken, service: 10.0.0.7:60334 }, ] queue=default: capacity=1.0, absoluteCapacity=1.0, usedResources=<memory:10240, vCores:5>, usedCapacity=0.8333333, absoluteUsedCapacity=0.8333333, numApps=1, numContainers=5 cluster=<memory:12288, vCores:4>
2016-12-02 23:12:10,332 INFO org.apache.hadoop.yarn.server.resourcemanager.scheduler.capacity.ParentQueue: completedContainer queue=root usedCapacity=0.8333333 absoluteUsedCapacity=0.8333333 used=<memory:10240, vCores:5> cluster=<memory:12288, vCores:4>
2016-12-02 23:12:10,332 INFO org.apache.hadoop.yarn.server.resourcemanager.scheduler.capacity.ParentQueue: Re-sorting completed queue: root.default stats: default: capacity=1.0, absoluteCapacity=1.0, usedResources=<memory:10240, vCores:5>, usedCapacity=0.8333333, absoluteUsedCapacity=0.8333333, numApps=1, numContainers=5
2016-12-02 23:12:10,333 INFO org.apache.hadoop.yarn.server.resourcemanager.scheduler.capacity.CapacityScheduler: Application attempt appattempt_1480719777699_0004_000001 released container container_1480719777699_0004_01_000046 on node: host: datanode2:60334 #containers=0 available=<memory:3072, vCores:1> used=<memory:0, vCores:0> with event: FINISHED
2016-12-02 23:12:10,333 INFO org.apache.hadoop.yarn.server.resourcemanager.scheduler.capacity.CapacityScheduler: Trying to fulfill reservation for application application_1480719777699_0004 on node: datanode2:60334
2016-12-02 23:12:10,333 INFO org.apache.hadoop.yarn.server.resourcemanager.scheduler.common.fica.FiCaSchedulerApp: Application application_1480719777699_0004 unreserved  on node host: datanode2:60334 #containers=0 available=<memory:3072, vCores:1> used=<memory:0, vCores:0>, currently has 1 at priority 5; currentReservation <memory:2048, vCores:1>
2016-12-02 23:12:10,333 INFO org.apache.hadoop.yarn.server.resourcemanager.rmcontainer.RMContainerImpl: container_1480719777699_0004_01_000054 Container Transitioned from NEW to ALLOCATED
2016-12-02 23:12:10,333 INFO org.apache.hadoop.yarn.server.resourcemanager.RMAuditLogger: USER=hdmaster	OPERATION=AM Allocated Container	TARGET=SchedulerApp	RESULT=SUCCESS	APPID=application_1480719777699_0004	CONTAINERID=container_1480719777699_0004_01_000054
2016-12-02 23:12:10,333 INFO org.apache.hadoop.yarn.server.resourcemanager.scheduler.SchedulerNode: Assigned container container_1480719777699_0004_01_000054 of capacity <memory:2048, vCores:1> on host datanode2:60334, which has 1 containers, <memory:2048, vCores:1> used and <memory:1024, vCores:0> available after allocation
2016-12-02 23:12:10,333 INFO org.apache.hadoop.yarn.server.resourcemanager.scheduler.capacity.LeafQueue: assignedContainer application attempt=appattempt_1480719777699_0004_000001 container=Container: [ContainerId: container_1480719777699_0004_01_000054, NodeId: datanode2:60334, NodeHttpAddress: datanode2:8042, Resource: <memory:2048, vCores:1>, Priority: 5, Token: null, ] queue=default: capacity=1.0, absoluteCapacity=1.0, usedResources=<memory:10240, vCores:5>, usedCapacity=0.8333333, absoluteUsedCapacity=0.8333333, numApps=1, numContainers=5 clusterResource=<memory:12288, vCores:4> type=OFF_SWITCH
2016-12-02 23:12:10,810 INFO org.apache.hadoop.yarn.server.resourcemanager.rmcontainer.RMContainerImpl: container_1480719777699_0004_01_000054 Container Transitioned from ALLOCATED to ACQUIRED
2016-12-02 23:12:11,324 INFO org.apache.hadoop.yarn.server.resourcemanager.scheduler.capacity.CapacityScheduler: Trying to fulfill reservation for application application_1480719777699_0004 on node: datanode3:60932
2016-12-02 23:12:11,325 INFO org.apache.hadoop.yarn.server.resourcemanager.scheduler.capacity.LeafQueue: Reserved container  application=application_1480719777699_0004 resource=<memory:2048, vCores:1> queue=default: capacity=1.0, absoluteCapacity=1.0, usedResources=<memory:10240, vCores:5>, usedCapacity=0.8333333, absoluteUsedCapacity=0.8333333, numApps=1, numContainers=5 usedCapacity=0.8333333 absoluteUsedCapacity=0.8333333 used=<memory:10240, vCores:5> cluster=<memory:12288, vCores:4>
2016-12-02 23:12:11,325 INFO org.apache.hadoop.yarn.server.resourcemanager.scheduler.capacity.CapacityScheduler: Skipping scheduling since node datanode3:60932 is reserved by application appattempt_1480719777699_0004_000001
2016-12-02 23:12:11,332 INFO org.apache.hadoop.yarn.server.resourcemanager.rmcontainer.RMContainerImpl: container_1480719777699_0004_01_000054 Container Transitioned from ACQUIRED to RUNNING
2016-12-02 23:12:11,333 INFO org.apache.hadoop.yarn.server.resourcemanager.rmcontainer.RMContainerImpl: container_1480719777699_0004_01_000061 Container Transitioned from NEW to RESERVED
2016-12-02 23:12:11,333 INFO org.apache.hadoop.yarn.server.resourcemanager.scheduler.capacity.LeafQueue: Reserved container  application=application_1480719777699_0004 resource=<memory:2048, vCores:1> queue=default: capacity=1.0, absoluteCapacity=1.0, usedResources=<memory:10240, vCores:5>, usedCapacity=0.8333333, absoluteUsedCapacity=0.8333333, numApps=1, numContainers=5 usedCapacity=0.8333333 absoluteUsedCapacity=0.8333333 used=<memory:10240, vCores:5> cluster=<memory:12288, vCores:4>
2016-12-02 23:12:11,333 INFO org.apache.hadoop.yarn.server.resourcemanager.scheduler.capacity.ParentQueue: Re-sorting assigned queue: root.default stats: default: capacity=1.0, absoluteCapacity=1.0, usedResources=<memory:12288, vCores:6>, usedCapacity=1.0, absoluteUsedCapacity=1.0, numApps=1, numContainers=6
2016-12-02 23:12:11,333 INFO org.apache.hadoop.yarn.server.resourcemanager.scheduler.capacity.ParentQueue: assignedContainer queue=root usedCapacity=1.0 absoluteUsedCapacity=1.0 used=<memory:12288, vCores:6> cluster=<memory:12288, vCores:4>
2016-12-02 23:12:11,918 INFO org.apache.hadoop.yarn.server.resourcemanager.rmcontainer.RMContainerImpl: container_1480719777699_0004_01_000053 Container Transitioned from RUNNING to COMPLETED
2016-12-02 23:12:11,918 INFO org.apache.hadoop.yarn.server.resourcemanager.scheduler.common.fica.FiCaSchedulerApp: Completed container: container_1480719777699_0004_01_000053 in state: COMPLETED event:FINISHED
2016-12-02 23:12:11,918 INFO org.apache.hadoop.yarn.server.resourcemanager.RMAuditLogger: USER=hdmaster	OPERATION=AM Released Container	TARGET=SchedulerApp	RESULT=SUCCESS	APPID=application_1480719777699_0004	CONTAINERID=container_1480719777699_0004_01_000053
2016-12-02 23:12:11,918 INFO org.apache.hadoop.yarn.server.resourcemanager.scheduler.SchedulerNode: Released container container_1480719777699_0004_01_000053 of capacity <memory:2048, vCores:1> on host datanode4:45290, which currently has 0 containers, <memory:0, vCores:0> used and <memory:3072, vCores:1> available, release resources=true
2016-12-02 23:12:11,918 INFO org.apache.hadoop.yarn.server.resourcemanager.scheduler.capacity.LeafQueue: default used=<memory:10240, vCores:5> numContainers=5 user=hdmaster user-resources=<memory:10240, vCores:5>
2016-12-02 23:12:11,918 INFO org.apache.hadoop.yarn.server.resourcemanager.scheduler.capacity.LeafQueue: completedContainer container=Container: [ContainerId: container_1480719777699_0004_01_000053, NodeId: datanode4:45290, NodeHttpAddress: datanode4:8042, Resource: <memory:2048, vCores:1>, Priority: 5, Token: Token { kind: ContainerToken, service: 10.0.0.9:45290 }, ] queue=default: capacity=1.0, absoluteCapacity=1.0, usedResources=<memory:10240, vCores:5>, usedCapacity=0.8333333, absoluteUsedCapacity=0.8333333, numApps=1, numContainers=5 cluster=<memory:12288, vCores:4>
2016-12-02 23:12:11,918 INFO org.apache.hadoop.yarn.server.resourcemanager.scheduler.capacity.ParentQueue: completedContainer queue=root usedCapacity=0.8333333 absoluteUsedCapacity=0.8333333 used=<memory:10240, vCores:5> cluster=<memory:12288, vCores:4>
2016-12-02 23:12:11,919 INFO org.apache.hadoop.yarn.server.resourcemanager.scheduler.capacity.ParentQueue: Re-sorting completed queue: root.default stats: default: capacity=1.0, absoluteCapacity=1.0, usedResources=<memory:10240, vCores:5>, usedCapacity=0.8333333, absoluteUsedCapacity=0.8333333, numApps=1, numContainers=5
2016-12-02 23:12:11,919 INFO org.apache.hadoop.yarn.server.resourcemanager.scheduler.capacity.CapacityScheduler: Application attempt appattempt_1480719777699_0004_000001 released container container_1480719777699_0004_01_000053 on node: host: datanode4:45290 #containers=0 available=<memory:3072, vCores:1> used=<memory:0, vCores:0> with event: FINISHED
2016-12-02 23:12:11,919 INFO org.apache.hadoop.yarn.server.resourcemanager.scheduler.common.fica.FiCaSchedulerApp: Application application_1480719777699_0004 unreserved  on node host: datanode2:60334 #containers=1 available=<memory:1024, vCores:0> used=<memory:2048, vCores:1>, currently has 1 at priority 5; currentReservation <memory:2048, vCores:1>
2016-12-02 23:12:11,919 INFO org.apache.hadoop.yarn.server.resourcemanager.scheduler.capacity.LeafQueue: default used=<memory:8192, vCores:4> numContainers=4 user=hdmaster user-resources=<memory:8192, vCores:4>
2016-12-02 23:12:11,919 INFO org.apache.hadoop.yarn.server.resourcemanager.scheduler.capacity.LeafQueue: completedContainer container=Container: [ContainerId: container_1480719777699_0004_01_000061, NodeId: datanode2:60334, NodeHttpAddress: datanode2:8042, Resource: <memory:2048, vCores:1>, Priority: 5, Token: null, ] queue=default: capacity=1.0, absoluteCapacity=1.0, usedResources=<memory:8192, vCores:4>, usedCapacity=0.6666667, absoluteUsedCapacity=0.6666667, numApps=1, numContainers=4 cluster=<memory:12288, vCores:4>
2016-12-02 23:12:11,919 INFO org.apache.hadoop.yarn.server.resourcemanager.scheduler.capacity.ParentQueue: completedContainer queue=root usedCapacity=0.6666667 absoluteUsedCapacity=0.6666667 used=<memory:8192, vCores:4> cluster=<memory:12288, vCores:4>
2016-12-02 23:12:11,919 INFO org.apache.hadoop.yarn.server.resourcemanager.rmcontainer.RMContainerImpl: container_1480719777699_0004_01_000064 Container Transitioned from NEW to ALLOCATED
2016-12-02 23:12:11,919 INFO org.apache.hadoop.yarn.server.resourcemanager.RMAuditLogger: USER=hdmaster	OPERATION=AM Allocated Container	TARGET=SchedulerApp	RESULT=SUCCESS	APPID=application_1480719777699_0004	CONTAINERID=container_1480719777699_0004_01_000064
2016-12-02 23:12:11,919 INFO org.apache.hadoop.yarn.server.resourcemanager.scheduler.SchedulerNode: Assigned container container_1480719777699_0004_01_000064 of capacity <memory:2048, vCores:1> on host datanode4:45290, which has 1 containers, <memory:2048, vCores:1> used and <memory:1024, vCores:0> available after allocation
2016-12-02 23:12:11,919 INFO org.apache.hadoop.yarn.server.resourcemanager.scheduler.capacity.LeafQueue: assignedContainer application attempt=appattempt_1480719777699_0004_000001 container=Container: [ContainerId: container_1480719777699_0004_01_000064, NodeId: datanode4:45290, NodeHttpAddress: datanode4:8042, Resource: <memory:2048, vCores:1>, Priority: 5, Token: null, ] queue=default: capacity=1.0, absoluteCapacity=1.0, usedResources=<memory:8192, vCores:4>, usedCapacity=0.6666667, absoluteUsedCapacity=0.6666667, numApps=1, numContainers=4 clusterResource=<memory:12288, vCores:4> type=OFF_SWITCH
2016-12-02 23:12:11,919 INFO org.apache.hadoop.yarn.server.resourcemanager.scheduler.capacity.ParentQueue: Re-sorting assigned queue: root.default stats: default: capacity=1.0, absoluteCapacity=1.0, usedResources=<memory:10240, vCores:5>, usedCapacity=0.8333333, absoluteUsedCapacity=0.8333333, numApps=1, numContainers=5
2016-12-02 23:12:11,919 INFO org.apache.hadoop.yarn.server.resourcemanager.scheduler.capacity.ParentQueue: assignedContainer queue=root usedCapacity=0.8333333 absoluteUsedCapacity=0.8333333 used=<memory:10240, vCores:5> cluster=<memory:12288, vCores:4>
2016-12-02 23:12:12,005 INFO org.apache.hadoop.yarn.server.resourcemanager.rmcontainer.RMContainerImpl: container_1480719777699_0004_01_000047 Container Transitioned from RUNNING to COMPLETED
2016-12-02 23:12:12,005 INFO org.apache.hadoop.yarn.server.resourcemanager.scheduler.common.fica.FiCaSchedulerApp: Completed container: container_1480719777699_0004_01_000047 in state: COMPLETED event:FINISHED
2016-12-02 23:12:12,005 INFO org.apache.hadoop.yarn.server.resourcemanager.RMAuditLogger: USER=hdmaster	OPERATION=AM Released Container	TARGET=SchedulerApp	RESULT=SUCCESS	APPID=application_1480719777699_0004	CONTAINERID=container_1480719777699_0004_01_000047
2016-12-02 23:12:12,005 INFO org.apache.hadoop.yarn.server.resourcemanager.scheduler.SchedulerNode: Released container container_1480719777699_0004_01_000047 of capacity <memory:2048, vCores:1> on host datanode3:60932, which currently has 0 containers, <memory:0, vCores:0> used and <memory:3072, vCores:1> available, release resources=true
2016-12-02 23:12:12,005 INFO org.apache.hadoop.yarn.server.resourcemanager.scheduler.capacity.LeafQueue: default used=<memory:8192, vCores:4> numContainers=4 user=hdmaster user-resources=<memory:8192, vCores:4>
2016-12-02 23:12:12,006 INFO org.apache.hadoop.yarn.server.resourcemanager.scheduler.capacity.LeafQueue: completedContainer container=Container: [ContainerId: container_1480719777699_0004_01_000047, NodeId: datanode3:60932, NodeHttpAddress: datanode3:8042, Resource: <memory:2048, vCores:1>, Priority: 5, Token: Token { kind: ContainerToken, service: 10.0.0.8:60932 }, ] queue=default: capacity=1.0, absoluteCapacity=1.0, usedResources=<memory:8192, vCores:4>, usedCapacity=0.6666667, absoluteUsedCapacity=0.6666667, numApps=1, numContainers=4 cluster=<memory:12288, vCores:4>
2016-12-02 23:12:12,006 INFO org.apache.hadoop.yarn.server.resourcemanager.scheduler.capacity.ParentQueue: completedContainer queue=root usedCapacity=0.6666667 absoluteUsedCapacity=0.6666667 used=<memory:8192, vCores:4> cluster=<memory:12288, vCores:4>
2016-12-02 23:12:12,006 INFO org.apache.hadoop.yarn.server.resourcemanager.scheduler.capacity.ParentQueue: Re-sorting completed queue: root.default stats: default: capacity=1.0, absoluteCapacity=1.0, usedResources=<memory:8192, vCores:4>, usedCapacity=0.6666667, absoluteUsedCapacity=0.6666667, numApps=1, numContainers=4
2016-12-02 23:12:12,006 INFO org.apache.hadoop.yarn.server.resourcemanager.scheduler.capacity.CapacityScheduler: Application attempt appattempt_1480719777699_0004_000001 released container container_1480719777699_0004_01_000047 on node: host: datanode3:60932 #containers=0 available=<memory:3072, vCores:1> used=<memory:0, vCores:0> with event: FINISHED
2016-12-02 23:12:12,006 INFO org.apache.hadoop.yarn.server.resourcemanager.scheduler.capacity.CapacityScheduler: Trying to fulfill reservation for application application_1480719777699_0004 on node: datanode3:60932
2016-12-02 23:12:12,006 INFO org.apache.hadoop.yarn.server.resourcemanager.scheduler.common.fica.FiCaSchedulerApp: Application application_1480719777699_0004 unreserved  on node host: datanode3:60932 #containers=0 available=<memory:3072, vCores:1> used=<memory:0, vCores:0>, currently has 0 at priority 5; currentReservation <memory:0, vCores:0>
2016-12-02 23:12:12,006 INFO org.apache.hadoop.yarn.server.resourcemanager.scheduler.capacity.LeafQueue: default used=<memory:6144, vCores:3> numContainers=3 user=hdmaster user-resources=<memory:6144, vCores:3>
2016-12-02 23:12:12,006 INFO org.apache.hadoop.yarn.server.resourcemanager.scheduler.capacity.LeafQueue: completedContainer container=Container: [ContainerId: container_1480719777699_0004_01_000057, NodeId: datanode3:60932, NodeHttpAddress: datanode3:8042, Resource: <memory:2048, vCores:1>, Priority: 5, Token: null, ] queue=default: capacity=1.0, absoluteCapacity=1.0, usedResources=<memory:6144, vCores:3>, usedCapacity=0.5, absoluteUsedCapacity=0.5, numApps=1, numContainers=3 cluster=<memory:12288, vCores:4>
2016-12-02 23:12:12,006 INFO org.apache.hadoop.yarn.server.resourcemanager.scheduler.capacity.ParentQueue: completedContainer queue=root usedCapacity=0.5 absoluteUsedCapacity=0.5 used=<memory:6144, vCores:3> cluster=<memory:12288, vCores:4>
2016-12-02 23:12:12,006 INFO org.apache.hadoop.yarn.server.resourcemanager.scheduler.capacity.ParentQueue: Re-sorting completed queue: root.default stats: default: capacity=1.0, absoluteCapacity=1.0, usedResources=<memory:6144, vCores:3>, usedCapacity=0.5, absoluteUsedCapacity=0.5, numApps=1, numContainers=3
2016-12-02 23:12:12,065 INFO org.apache.hadoop.yarn.server.resourcemanager.rmcontainer.RMContainerImpl: container_1480719777699_0004_01_000054 Container Transitioned from RUNNING to COMPLETED
2016-12-02 23:12:12,065 INFO org.apache.hadoop.yarn.server.resourcemanager.scheduler.common.fica.FiCaSchedulerApp: Completed container: container_1480719777699_0004_01_000054 in state: COMPLETED event:FINISHED
2016-12-02 23:12:12,065 INFO org.apache.hadoop.yarn.server.resourcemanager.RMAuditLogger: USER=hdmaster	OPERATION=AM Released Container	TARGET=SchedulerApp	RESULT=SUCCESS	APPID=application_1480719777699_0004	CONTAINERID=container_1480719777699_0004_01_000054
2016-12-02 23:12:12,065 INFO org.apache.hadoop.yarn.server.resourcemanager.scheduler.SchedulerNode: Released container container_1480719777699_0004_01_000054 of capacity <memory:2048, vCores:1> on host datanode2:60334, which currently has 0 containers, <memory:0, vCores:0> used and <memory:3072, vCores:1> available, release resources=true
2016-12-02 23:12:12,065 INFO org.apache.hadoop.yarn.server.resourcemanager.scheduler.capacity.LeafQueue: default used=<memory:4096, vCores:2> numContainers=2 user=hdmaster user-resources=<memory:4096, vCores:2>
2016-12-02 23:12:12,065 INFO org.apache.hadoop.yarn.server.resourcemanager.scheduler.capacity.LeafQueue: completedContainer container=Container: [ContainerId: container_1480719777699_0004_01_000054, NodeId: datanode2:60334, NodeHttpAddress: datanode2:8042, Resource: <memory:2048, vCores:1>, Priority: 5, Token: Token { kind: ContainerToken, service: 10.0.0.7:60334 }, ] queue=default: capacity=1.0, absoluteCapacity=1.0, usedResources=<memory:4096, vCores:2>, usedCapacity=0.33333334, absoluteUsedCapacity=0.33333334, numApps=1, numContainers=2 cluster=<memory:12288, vCores:4>
2016-12-02 23:12:12,065 INFO org.apache.hadoop.yarn.server.resourcemanager.scheduler.capacity.ParentQueue: completedContainer queue=root usedCapacity=0.33333334 absoluteUsedCapacity=0.33333334 used=<memory:4096, vCores:2> cluster=<memory:12288, vCores:4>
2016-12-02 23:12:12,065 INFO org.apache.hadoop.yarn.server.resourcemanager.scheduler.capacity.ParentQueue: Re-sorting completed queue: root.default stats: default: capacity=1.0, absoluteCapacity=1.0, usedResources=<memory:4096, vCores:2>, usedCapacity=0.33333334, absoluteUsedCapacity=0.33333334, numApps=1, numContainers=2
2016-12-02 23:12:12,065 INFO org.apache.hadoop.yarn.server.resourcemanager.scheduler.capacity.CapacityScheduler: Application attempt appattempt_1480719777699_0004_000001 released container container_1480719777699_0004_01_000054 on node: host: datanode2:60334 #containers=0 available=<memory:3072, vCores:1> used=<memory:0, vCores:0> with event: FINISHED
2016-12-02 23:12:12,514 INFO org.apache.hadoop.yarn.server.resourcemanager.rmapp.attempt.RMAppAttemptImpl: Updating application attempt appattempt_1480719777699_0004_000001 with final state: FINISHING, and exit status: -1000
2016-12-02 23:12:12,515 INFO org.apache.hadoop.yarn.server.resourcemanager.rmapp.attempt.RMAppAttemptImpl: appattempt_1480719777699_0004_000001 State change from RUNNING to FINAL_SAVING
2016-12-02 23:12:12,515 INFO org.apache.hadoop.yarn.server.resourcemanager.rmapp.RMAppImpl: Updating application application_1480719777699_0004 with final state: FINISHING
2016-12-02 23:12:12,515 INFO org.apache.hadoop.yarn.server.resourcemanager.rmapp.RMAppImpl: application_1480719777699_0004 State change from RUNNING to FINAL_SAVING
2016-12-02 23:12:12,515 INFO org.apache.hadoop.yarn.server.resourcemanager.recovery.RMStateStore: Updating info for app: application_1480719777699_0004
2016-12-02 23:12:12,515 INFO org.apache.hadoop.yarn.server.resourcemanager.rmapp.attempt.RMAppAttemptImpl: appattempt_1480719777699_0004_000001 State change from FINAL_SAVING to FINISHING
2016-12-02 23:12:12,515 INFO org.apache.hadoop.yarn.server.resourcemanager.rmapp.RMAppImpl: application_1480719777699_0004 State change from FINAL_SAVING to FINISHING
2016-12-02 23:12:13,518 INFO org.apache.hadoop.yarn.server.resourcemanager.ApplicationMasterService: application_1480719777699_0004 unregistered successfully. 
2016-12-02 23:12:19,053 INFO org.apache.hadoop.yarn.server.resourcemanager.rmcontainer.RMContainerImpl: container_1480719777699_0004_01_000001 Container Transitioned from RUNNING to COMPLETED
2016-12-02 23:12:19,053 INFO org.apache.hadoop.yarn.server.resourcemanager.scheduler.common.fica.FiCaSchedulerApp: Completed container: container_1480719777699_0004_01_000001 in state: COMPLETED event:FINISHED
2016-12-02 23:12:19,053 INFO org.apache.hadoop.yarn.server.resourcemanager.RMAuditLogger: USER=hdmaster	OPERATION=AM Released Container	TARGET=SchedulerApp	RESULT=SUCCESS	APPID=application_1480719777699_0004	CONTAINERID=container_1480719777699_0004_01_000001
2016-12-02 23:12:19,053 INFO org.apache.hadoop.yarn.server.resourcemanager.scheduler.SchedulerNode: Released container container_1480719777699_0004_01_000001 of capacity <memory:2048, vCores:1> on host datanode1:50178, which currently has 0 containers, <memory:0, vCores:0> used and <memory:3072, vCores:1> available, release resources=true
2016-12-02 23:12:19,053 INFO org.apache.hadoop.yarn.server.resourcemanager.scheduler.capacity.LeafQueue: default used=<memory:2048, vCores:1> numContainers=1 user=hdmaster user-resources=<memory:2048, vCores:1>
2016-12-02 23:12:19,053 INFO org.apache.hadoop.yarn.server.resourcemanager.scheduler.capacity.LeafQueue: completedContainer container=Container: [ContainerId: container_1480719777699_0004_01_000001, NodeId: datanode1:50178, NodeHttpAddress: datanode1:8042, Resource: <memory:2048, vCores:1>, Priority: 0, Token: Token { kind: ContainerToken, service: 10.0.0.6:50178 }, ] queue=default: capacity=1.0, absoluteCapacity=1.0, usedResources=<memory:2048, vCores:1>, usedCapacity=0.16666667, absoluteUsedCapacity=0.16666667, numApps=1, numContainers=1 cluster=<memory:12288, vCores:4>
2016-12-02 23:12:19,053 INFO org.apache.hadoop.yarn.server.resourcemanager.scheduler.capacity.ParentQueue: completedContainer queue=root usedCapacity=0.16666667 absoluteUsedCapacity=0.16666667 used=<memory:2048, vCores:1> cluster=<memory:12288, vCores:4>
2016-12-02 23:12:19,053 INFO org.apache.hadoop.yarn.server.resourcemanager.scheduler.capacity.ParentQueue: Re-sorting completed queue: root.default stats: default: capacity=1.0, absoluteCapacity=1.0, usedResources=<memory:2048, vCores:1>, usedCapacity=0.16666667, absoluteUsedCapacity=0.16666667, numApps=1, numContainers=1
2016-12-02 23:12:19,053 INFO org.apache.hadoop.yarn.server.resourcemanager.scheduler.capacity.CapacityScheduler: Application attempt appattempt_1480719777699_0004_000001 released container container_1480719777699_0004_01_000001 on node: host: datanode1:50178 #containers=0 available=<memory:3072, vCores:1> used=<memory:0, vCores:0> with event: FINISHED
2016-12-02 23:12:19,053 INFO org.apache.hadoop.yarn.server.resourcemanager.ApplicationMasterService: Unregistering app attempt : appattempt_1480719777699_0004_000001
2016-12-02 23:12:19,054 INFO org.apache.hadoop.yarn.server.resourcemanager.security.AMRMTokenSecretManager: Application finished, removing password for appattempt_1480719777699_0004_000001
2016-12-02 23:12:19,054 INFO org.apache.hadoop.yarn.server.resourcemanager.rmapp.attempt.RMAppAttemptImpl: appattempt_1480719777699_0004_000001 State change from FINISHING to FINISHED
2016-12-02 23:12:19,054 INFO org.apache.hadoop.yarn.server.resourcemanager.rmapp.RMAppImpl: application_1480719777699_0004 State change from FINISHING to FINISHED
2016-12-02 23:12:19,054 INFO org.apache.hadoop.yarn.server.resourcemanager.RMAuditLogger: USER=hdmaster	OPERATION=Application Finished - Succeeded	TARGET=RMAppManager	RESULT=SUCCESS	APPID=application_1480719777699_0004
2016-12-02 23:12:19,054 INFO org.apache.hadoop.yarn.server.resourcemanager.RMAppManager$ApplicationSummary: appId=application_1480719777699_0004,name=streamjob5973149531896437388.jar,user=hdmaster,queue=default,state=FINISHED,trackingUrl=http://resourcemanager:8088/proxy/application_1480719777699_0004/,appMasterHost=DataNode1,startTime=1480720293230,finishTime=1480720332515,finalStatus=FAILED,memorySeconds=244041,vcoreSeconds=110,preemptedAMContainers=0,preemptedNonAMContainers=0,preemptedResources=<memory:0\, vCores:0>,applicationType=MAPREDUCE
2016-12-02 23:12:19,054 INFO org.apache.hadoop.yarn.server.resourcemanager.scheduler.capacity.CapacityScheduler: Application Attempt appattempt_1480719777699_0004_000001 is done. finalState=FINISHED
2016-12-02 23:12:19,054 INFO org.apache.hadoop.yarn.server.resourcemanager.rmcontainer.RMContainerImpl: container_1480719777699_0004_01_000064 Container Transitioned from ALLOCATED to KILLED
2016-12-02 23:12:19,054 INFO org.apache.hadoop.yarn.server.resourcemanager.scheduler.common.fica.FiCaSchedulerApp: Completed container: container_1480719777699_0004_01_000064 in state: KILLED event:KILL
2016-12-02 23:12:19,054 INFO org.apache.hadoop.yarn.server.resourcemanager.RMAuditLogger: USER=hdmaster	OPERATION=AM Released Container	TARGET=SchedulerApp	RESULT=SUCCESS	APPID=application_1480719777699_0004	CONTAINERID=container_1480719777699_0004_01_000064
2016-12-02 23:12:19,054 INFO org.apache.hadoop.yarn.server.resourcemanager.scheduler.SchedulerNode: Released container container_1480719777699_0004_01_000064 of capacity <memory:2048, vCores:1> on host datanode4:45290, which currently has 0 containers, <memory:0, vCores:0> used and <memory:3072, vCores:1> available, release resources=true
2016-12-02 23:12:19,054 INFO org.apache.hadoop.yarn.server.resourcemanager.scheduler.capacity.LeafQueue: default used=<memory:0, vCores:0> numContainers=0 user=hdmaster user-resources=<memory:0, vCores:0>
2016-12-02 23:12:19,054 INFO org.apache.hadoop.yarn.server.resourcemanager.scheduler.capacity.LeafQueue: completedContainer container=Container: [ContainerId: container_1480719777699_0004_01_000064, NodeId: datanode4:45290, NodeHttpAddress: datanode4:8042, Resource: <memory:2048, vCores:1>, Priority: 5, Token: null, ] queue=default: capacity=1.0, absoluteCapacity=1.0, usedResources=<memory:0, vCores:0>, usedCapacity=0.0, absoluteUsedCapacity=0.0, numApps=1, numContainers=0 cluster=<memory:12288, vCores:4>
2016-12-02 23:12:19,054 INFO org.apache.hadoop.yarn.server.resourcemanager.scheduler.capacity.ParentQueue: completedContainer queue=root usedCapacity=0.0 absoluteUsedCapacity=0.0 used=<memory:0, vCores:0> cluster=<memory:12288, vCores:4>
2016-12-02 23:12:19,054 INFO org.apache.hadoop.yarn.server.resourcemanager.scheduler.capacity.ParentQueue: Re-sorting completed queue: root.default stats: default: capacity=1.0, absoluteCapacity=1.0, usedResources=<memory:0, vCores:0>, usedCapacity=0.0, absoluteUsedCapacity=0.0, numApps=1, numContainers=0
2016-12-02 23:12:19,054 INFO org.apache.hadoop.yarn.server.resourcemanager.scheduler.capacity.CapacityScheduler: Application attempt appattempt_1480719777699_0004_000001 released container container_1480719777699_0004_01_000064 on node: host: datanode4:45290 #containers=0 available=<memory:3072, vCores:1> used=<memory:0, vCores:0> with event: KILL
2016-12-02 23:12:19,054 INFO org.apache.hadoop.yarn.server.resourcemanager.scheduler.AppSchedulingInfo: Application application_1480719777699_0004 requests cleared
2016-12-02 23:12:19,054 INFO org.apache.hadoop.yarn.server.resourcemanager.scheduler.capacity.LeafQueue: Application removed - appId: application_1480719777699_0004 user: hdmaster queue: default #user-pending-applications: 0 #user-active-applications: 0 #queue-pending-applications: 0 #queue-active-applications: 0
2016-12-02 23:12:19,054 INFO org.apache.hadoop.yarn.server.resourcemanager.scheduler.capacity.ParentQueue: Application removed - appId: application_1480719777699_0004 user: hdmaster leaf-queue of parent: root #applications: 0
2016-12-02 23:12:19,055 INFO org.apache.hadoop.yarn.server.resourcemanager.amlauncher.AMLauncher: Cleaning master appattempt_1480719777699_0004_000001
2016-12-02 23:12:20,081 INFO org.apache.hadoop.yarn.server.resourcemanager.scheduler.capacity.CapacityScheduler: Null container completed...
2016-12-02 23:12:20,944 INFO org.apache.hadoop.yarn.server.resourcemanager.scheduler.capacity.CapacityScheduler: Null container completed...
2016-12-02 23:12:21,031 INFO org.apache.hadoop.yarn.server.resourcemanager.scheduler.capacity.CapacityScheduler: Null container completed...
2016-12-02 23:12:57,492 INFO org.apache.hadoop.yarn.server.resourcemanager.scheduler.AbstractYarnScheduler: Release request cache is cleaned up
2016-12-02 23:15:23,683 INFO org.apache.hadoop.yarn.server.resourcemanager.ClientRMService: Allocated new applicationId: 5
2016-12-02 23:15:25,190 INFO org.apache.hadoop.yarn.server.resourcemanager.ClientRMService: Application with id 5 submitted by user hdmaster
2016-12-02 23:15:25,191 INFO org.apache.hadoop.yarn.server.resourcemanager.RMAuditLogger: USER=hdmaster	IP=10.0.0.4	OPERATION=Submit Application Request	TARGET=ClientRMService	RESULT=SUCCESS	APPID=application_1480719777699_0005
2016-12-02 23:15:25,191 INFO org.apache.hadoop.yarn.server.resourcemanager.rmapp.RMAppImpl: Storing application with id application_1480719777699_0005
2016-12-02 23:15:25,191 INFO org.apache.hadoop.yarn.server.resourcemanager.rmapp.RMAppImpl: application_1480719777699_0005 State change from NEW to NEW_SAVING
2016-12-02 23:15:25,191 INFO org.apache.hadoop.yarn.server.resourcemanager.recovery.RMStateStore: Storing info for app: application_1480719777699_0005
2016-12-02 23:15:25,191 INFO org.apache.hadoop.yarn.server.resourcemanager.rmapp.RMAppImpl: application_1480719777699_0005 State change from NEW_SAVING to SUBMITTED
2016-12-02 23:15:25,191 INFO org.apache.hadoop.yarn.server.resourcemanager.scheduler.capacity.ParentQueue: Application added - appId: application_1480719777699_0005 user: hdmaster leaf-queue of parent: root #applications: 1
2016-12-02 23:15:25,191 INFO org.apache.hadoop.yarn.server.resourcemanager.scheduler.capacity.CapacityScheduler: Accepted application application_1480719777699_0005 from user: hdmaster, in queue: default
2016-12-02 23:15:25,191 INFO org.apache.hadoop.yarn.server.resourcemanager.rmapp.RMAppImpl: application_1480719777699_0005 State change from SUBMITTED to ACCEPTED
2016-12-02 23:15:25,191 INFO org.apache.hadoop.yarn.server.resourcemanager.ApplicationMasterService: Registering app attempt : appattempt_1480719777699_0005_000001
2016-12-02 23:15:25,191 INFO org.apache.hadoop.yarn.server.resourcemanager.rmapp.attempt.RMAppAttemptImpl: appattempt_1480719777699_0005_000001 State change from NEW to SUBMITTED
2016-12-02 23:15:25,192 INFO org.apache.hadoop.yarn.server.resourcemanager.scheduler.capacity.LeafQueue: Application application_1480719777699_0005 from user: hdmaster activated in queue: default
2016-12-02 23:15:25,192 INFO org.apache.hadoop.yarn.server.resourcemanager.scheduler.capacity.LeafQueue: Application added - appId: application_1480719777699_0005 user: org.apache.hadoop.yarn.server.resourcemanager.scheduler.capacity.LeafQueue$User@5e095e25, leaf-queue: default #user-pending-applications: 0 #user-active-applications: 1 #queue-pending-applications: 0 #queue-active-applications: 1
2016-12-02 23:15:25,192 INFO org.apache.hadoop.yarn.server.resourcemanager.scheduler.capacity.CapacityScheduler: Added Application Attempt appattempt_1480719777699_0005_000001 to scheduler from user hdmaster in queue default
2016-12-02 23:15:25,195 INFO org.apache.hadoop.yarn.server.resourcemanager.rmapp.attempt.RMAppAttemptImpl: appattempt_1480719777699_0005_000001 State change from SUBMITTED to SCHEDULED
2016-12-02 23:15:25,312 INFO org.apache.hadoop.yarn.server.resourcemanager.rmcontainer.RMContainerImpl: container_1480719777699_0005_01_000001 Container Transitioned from NEW to ALLOCATED
2016-12-02 23:15:25,313 INFO org.apache.hadoop.yarn.server.resourcemanager.RMAuditLogger: USER=hdmaster	OPERATION=AM Allocated Container	TARGET=SchedulerApp	RESULT=SUCCESS	APPID=application_1480719777699_0005	CONTAINERID=container_1480719777699_0005_01_000001
2016-12-02 23:15:25,313 INFO org.apache.hadoop.yarn.server.resourcemanager.scheduler.SchedulerNode: Assigned container container_1480719777699_0005_01_000001 of capacity <memory:2048, vCores:1> on host datanode4:45290, which has 1 containers, <memory:2048, vCores:1> used and <memory:1024, vCores:0> available after allocation
2016-12-02 23:15:25,313 INFO org.apache.hadoop.yarn.server.resourcemanager.scheduler.capacity.LeafQueue: assignedContainer application attempt=appattempt_1480719777699_0005_000001 container=Container: [ContainerId: container_1480719777699_0005_01_000001, NodeId: datanode4:45290, NodeHttpAddress: datanode4:8042, Resource: <memory:2048, vCores:1>, Priority: 0, Token: null, ] queue=default: capacity=1.0, absoluteCapacity=1.0, usedResources=<memory:0, vCores:0>, usedCapacity=0.0, absoluteUsedCapacity=0.0, numApps=1, numContainers=0 clusterResource=<memory:12288, vCores:4> type=OFF_SWITCH
2016-12-02 23:15:25,313 INFO org.apache.hadoop.yarn.server.resourcemanager.scheduler.capacity.ParentQueue: Re-sorting assigned queue: root.default stats: default: capacity=1.0, absoluteCapacity=1.0, usedResources=<memory:2048, vCores:1>, usedCapacity=0.16666667, absoluteUsedCapacity=0.16666667, numApps=1, numContainers=1
2016-12-02 23:15:25,313 INFO org.apache.hadoop.yarn.server.resourcemanager.scheduler.capacity.ParentQueue: assignedContainer queue=root usedCapacity=0.16666667 absoluteUsedCapacity=0.16666667 used=<memory:2048, vCores:1> cluster=<memory:12288, vCores:4>
2016-12-02 23:15:25,313 INFO org.apache.hadoop.yarn.server.resourcemanager.security.NMTokenSecretManagerInRM: Sending NMToken for nodeId : datanode4:45290 for container : container_1480719777699_0005_01_000001
2016-12-02 23:15:25,314 INFO org.apache.hadoop.yarn.server.resourcemanager.rmcontainer.RMContainerImpl: container_1480719777699_0005_01_000001 Container Transitioned from ALLOCATED to ACQUIRED
2016-12-02 23:15:25,314 INFO org.apache.hadoop.yarn.server.resourcemanager.security.NMTokenSecretManagerInRM: Clear node set for appattempt_1480719777699_0005_000001
2016-12-02 23:15:25,314 INFO org.apache.hadoop.yarn.server.resourcemanager.rmapp.attempt.RMAppAttemptImpl: Storing attempt: AppId: application_1480719777699_0005 AttemptId: appattempt_1480719777699_0005_000001 MasterContainer: Container: [ContainerId: container_1480719777699_0005_01_000001, NodeId: datanode4:45290, NodeHttpAddress: datanode4:8042, Resource: <memory:2048, vCores:1>, Priority: 0, Token: Token { kind: ContainerToken, service: 10.0.0.9:45290 }, ]
2016-12-02 23:15:25,314 INFO org.apache.hadoop.yarn.server.resourcemanager.rmapp.attempt.RMAppAttemptImpl: appattempt_1480719777699_0005_000001 State change from SCHEDULED to ALLOCATED_SAVING
2016-12-02 23:15:25,314 INFO org.apache.hadoop.yarn.server.resourcemanager.rmapp.attempt.RMAppAttemptImpl: appattempt_1480719777699_0005_000001 State change from ALLOCATED_SAVING to ALLOCATED
2016-12-02 23:15:25,315 INFO org.apache.hadoop.yarn.server.resourcemanager.amlauncher.AMLauncher: Launching masterappattempt_1480719777699_0005_000001
2016-12-02 23:15:25,321 INFO org.apache.hadoop.yarn.server.resourcemanager.amlauncher.AMLauncher: Setting up container Container: [ContainerId: container_1480719777699_0005_01_000001, NodeId: datanode4:45290, NodeHttpAddress: datanode4:8042, Resource: <memory:2048, vCores:1>, Priority: 0, Token: Token { kind: ContainerToken, service: 10.0.0.9:45290 }, ] for AM appattempt_1480719777699_0005_000001
2016-12-02 23:15:25,321 INFO org.apache.hadoop.yarn.server.resourcemanager.amlauncher.AMLauncher: Command to launch container container_1480719777699_0005_01_000001 : $JAVA_HOME/bin/java -Djava.io.tmpdir=$PWD/tmp -Dlog4j.configuration=container-log4j.properties -Dyarn.app.container.log.dir=<LOG_DIR> -Dyarn.app.container.log.filesize=0 -Dhadoop.root.logger=INFO,CLA -Dhadoop.root.logfile=syslog  -Xmx1024m org.apache.hadoop.mapreduce.v2.app.MRAppMaster 1><LOG_DIR>/stdout 2><LOG_DIR>/stderr 
2016-12-02 23:15:25,321 INFO org.apache.hadoop.yarn.server.resourcemanager.security.AMRMTokenSecretManager: Create AMRMToken for ApplicationAttempt: appattempt_1480719777699_0005_000001
2016-12-02 23:15:25,321 INFO org.apache.hadoop.yarn.server.resourcemanager.security.AMRMTokenSecretManager: Creating password for appattempt_1480719777699_0005_000001
2016-12-02 23:15:25,339 INFO org.apache.hadoop.yarn.server.resourcemanager.amlauncher.AMLauncher: Done launching container Container: [ContainerId: container_1480719777699_0005_01_000001, NodeId: datanode4:45290, NodeHttpAddress: datanode4:8042, Resource: <memory:2048, vCores:1>, Priority: 0, Token: Token { kind: ContainerToken, service: 10.0.0.9:45290 }, ] for AM appattempt_1480719777699_0005_000001
2016-12-02 23:15:25,339 INFO org.apache.hadoop.yarn.server.resourcemanager.rmapp.attempt.RMAppAttemptImpl: appattempt_1480719777699_0005_000001 State change from ALLOCATED to LAUNCHED
2016-12-02 23:15:26,314 INFO org.apache.hadoop.yarn.server.resourcemanager.rmcontainer.RMContainerImpl: container_1480719777699_0005_01_000001 Container Transitioned from ACQUIRED to RUNNING
2016-12-02 23:15:32,046 INFO SecurityLogger.org.apache.hadoop.ipc.Server: Auth successful for appattempt_1480719777699_0005_000001 (auth:SIMPLE)
2016-12-02 23:15:32,055 INFO org.apache.hadoop.yarn.server.resourcemanager.ApplicationMasterService: AM registration appattempt_1480719777699_0005_000001
2016-12-02 23:15:32,055 INFO org.apache.hadoop.yarn.server.resourcemanager.RMAuditLogger: USER=hdmaster	IP=10.0.0.9	OPERATION=Register App Master	TARGET=ApplicationMasterService	RESULT=SUCCESS	APPID=application_1480719777699_0005	APPATTEMPTID=appattempt_1480719777699_0005_000001
2016-12-02 23:15:32,055 INFO org.apache.hadoop.yarn.server.resourcemanager.rmapp.attempt.RMAppAttemptImpl: appattempt_1480719777699_0005_000001 State change from LAUNCHED to RUNNING
2016-12-02 23:15:32,055 INFO org.apache.hadoop.yarn.server.resourcemanager.rmapp.RMAppImpl: application_1480719777699_0005 State change from ACCEPTED to RUNNING
2016-12-02 23:15:34,333 INFO org.apache.hadoop.yarn.server.resourcemanager.rmcontainer.RMContainerImpl: container_1480719777699_0005_01_000002 Container Transitioned from NEW to RESERVED
2016-12-02 23:15:34,333 INFO org.apache.hadoop.yarn.server.resourcemanager.scheduler.capacity.LeafQueue: Reserved container  application=application_1480719777699_0005 resource=<memory:2048, vCores:1> queue=default: capacity=1.0, absoluteCapacity=1.0, usedResources=<memory:2048, vCores:1>, usedCapacity=0.16666667, absoluteUsedCapacity=0.16666667, numApps=1, numContainers=1 usedCapacity=0.16666667 absoluteUsedCapacity=0.16666667 used=<memory:2048, vCores:1> cluster=<memory:12288, vCores:4>
2016-12-02 23:15:34,333 INFO org.apache.hadoop.yarn.server.resourcemanager.scheduler.capacity.ParentQueue: Re-sorting assigned queue: root.default stats: default: capacity=1.0, absoluteCapacity=1.0, usedResources=<memory:4096, vCores:2>, usedCapacity=0.33333334, absoluteUsedCapacity=0.33333334, numApps=1, numContainers=2
2016-12-02 23:15:34,333 INFO org.apache.hadoop.yarn.server.resourcemanager.scheduler.capacity.ParentQueue: assignedContainer queue=root usedCapacity=0.33333334 absoluteUsedCapacity=0.33333334 used=<memory:4096, vCores:2> cluster=<memory:12288, vCores:4>
2016-12-02 23:15:34,417 INFO org.apache.hadoop.yarn.server.resourcemanager.rmcontainer.RMContainerImpl: container_1480719777699_0005_01_000003 Container Transitioned from NEW to ALLOCATED
2016-12-02 23:15:34,417 INFO org.apache.hadoop.yarn.server.resourcemanager.RMAuditLogger: USER=hdmaster	OPERATION=AM Allocated Container	TARGET=SchedulerApp	RESULT=SUCCESS	APPID=application_1480719777699_0005	CONTAINERID=container_1480719777699_0005_01_000003
2016-12-02 23:15:34,417 INFO org.apache.hadoop.yarn.server.resourcemanager.scheduler.SchedulerNode: Assigned container container_1480719777699_0005_01_000003 of capacity <memory:2048, vCores:1> on host datanode3:60932, which has 1 containers, <memory:2048, vCores:1> used and <memory:1024, vCores:0> available after allocation
2016-12-02 23:15:34,417 INFO org.apache.hadoop.yarn.server.resourcemanager.scheduler.capacity.LeafQueue: assignedContainer application attempt=appattempt_1480719777699_0005_000001 container=Container: [ContainerId: container_1480719777699_0005_01_000003, NodeId: datanode3:60932, NodeHttpAddress: datanode3:8042, Resource: <memory:2048, vCores:1>, Priority: 20, Token: null, ] queue=default: capacity=1.0, absoluteCapacity=1.0, usedResources=<memory:4096, vCores:2>, usedCapacity=0.33333334, absoluteUsedCapacity=0.33333334, numApps=1, numContainers=2 clusterResource=<memory:12288, vCores:4> type=OFF_SWITCH
2016-12-02 23:15:34,417 INFO org.apache.hadoop.yarn.server.resourcemanager.scheduler.capacity.ParentQueue: Re-sorting assigned queue: root.default stats: default: capacity=1.0, absoluteCapacity=1.0, usedResources=<memory:6144, vCores:3>, usedCapacity=0.5, absoluteUsedCapacity=0.5, numApps=1, numContainers=3
2016-12-02 23:15:34,417 INFO org.apache.hadoop.yarn.server.resourcemanager.scheduler.capacity.ParentQueue: assignedContainer queue=root usedCapacity=0.5 absoluteUsedCapacity=0.5 used=<memory:6144, vCores:3> cluster=<memory:12288, vCores:4>
2016-12-02 23:15:34,420 INFO org.apache.hadoop.yarn.server.resourcemanager.rmcontainer.RMContainerImpl: container_1480719777699_0005_01_000004 Container Transitioned from NEW to ALLOCATED
2016-12-02 23:15:34,420 INFO org.apache.hadoop.yarn.server.resourcemanager.RMAuditLogger: USER=hdmaster	OPERATION=AM Allocated Container	TARGET=SchedulerApp	RESULT=SUCCESS	APPID=application_1480719777699_0005	CONTAINERID=container_1480719777699_0005_01_000004
2016-12-02 23:15:34,420 INFO org.apache.hadoop.yarn.server.resourcemanager.scheduler.SchedulerNode: Assigned container container_1480719777699_0005_01_000004 of capacity <memory:2048, vCores:1> on host datanode1:50178, which has 1 containers, <memory:2048, vCores:1> used and <memory:1024, vCores:0> available after allocation
2016-12-02 23:15:34,420 INFO org.apache.hadoop.yarn.server.resourcemanager.scheduler.capacity.LeafQueue: assignedContainer application attempt=appattempt_1480719777699_0005_000001 container=Container: [ContainerId: container_1480719777699_0005_01_000004, NodeId: datanode1:50178, NodeHttpAddress: datanode1:8042, Resource: <memory:2048, vCores:1>, Priority: 20, Token: null, ] queue=default: capacity=1.0, absoluteCapacity=1.0, usedResources=<memory:6144, vCores:3>, usedCapacity=0.5, absoluteUsedCapacity=0.5, numApps=1, numContainers=3 clusterResource=<memory:12288, vCores:4> type=OFF_SWITCH
2016-12-02 23:15:34,420 INFO org.apache.hadoop.yarn.server.resourcemanager.scheduler.capacity.ParentQueue: Re-sorting assigned queue: root.default stats: default: capacity=1.0, absoluteCapacity=1.0, usedResources=<memory:8192, vCores:4>, usedCapacity=0.6666667, absoluteUsedCapacity=0.6666667, numApps=1, numContainers=4
2016-12-02 23:15:34,420 INFO org.apache.hadoop.yarn.server.resourcemanager.scheduler.capacity.ParentQueue: assignedContainer queue=root usedCapacity=0.6666667 absoluteUsedCapacity=0.6666667 used=<memory:8192, vCores:4> cluster=<memory:12288, vCores:4>
2016-12-02 23:15:34,475 INFO org.apache.hadoop.yarn.server.resourcemanager.rmcontainer.RMContainerImpl: container_1480719777699_0005_01_000005 Container Transitioned from NEW to ALLOCATED
2016-12-02 23:15:34,475 INFO org.apache.hadoop.yarn.server.resourcemanager.RMAuditLogger: USER=hdmaster	OPERATION=AM Allocated Container	TARGET=SchedulerApp	RESULT=SUCCESS	APPID=application_1480719777699_0005	CONTAINERID=container_1480719777699_0005_01_000005
2016-12-02 23:15:34,475 INFO org.apache.hadoop.yarn.server.resourcemanager.scheduler.SchedulerNode: Assigned container container_1480719777699_0005_01_000005 of capacity <memory:2048, vCores:1> on host datanode2:60334, which has 1 containers, <memory:2048, vCores:1> used and <memory:1024, vCores:0> available after allocation
2016-12-02 23:15:34,475 INFO org.apache.hadoop.yarn.server.resourcemanager.scheduler.capacity.LeafQueue: assignedContainer application attempt=appattempt_1480719777699_0005_000001 container=Container: [ContainerId: container_1480719777699_0005_01_000005, NodeId: datanode2:60334, NodeHttpAddress: datanode2:8042, Resource: <memory:2048, vCores:1>, Priority: 20, Token: null, ] queue=default: capacity=1.0, absoluteCapacity=1.0, usedResources=<memory:8192, vCores:4>, usedCapacity=0.6666667, absoluteUsedCapacity=0.6666667, numApps=1, numContainers=4 clusterResource=<memory:12288, vCores:4> type=OFF_SWITCH
2016-12-02 23:15:34,476 INFO org.apache.hadoop.yarn.server.resourcemanager.scheduler.capacity.ParentQueue: Re-sorting assigned queue: root.default stats: default: capacity=1.0, absoluteCapacity=1.0, usedResources=<memory:10240, vCores:5>, usedCapacity=0.8333333, absoluteUsedCapacity=0.8333333, numApps=1, numContainers=5
2016-12-02 23:15:34,476 INFO org.apache.hadoop.yarn.server.resourcemanager.scheduler.capacity.ParentQueue: assignedContainer queue=root usedCapacity=0.8333333 absoluteUsedCapacity=0.8333333 used=<memory:10240, vCores:5> cluster=<memory:12288, vCores:4>
2016-12-02 23:15:35,134 INFO org.apache.hadoop.yarn.server.resourcemanager.security.NMTokenSecretManagerInRM: Sending NMToken for nodeId : datanode3:60932 for container : container_1480719777699_0005_01_000003
2016-12-02 23:15:35,135 INFO org.apache.hadoop.yarn.server.resourcemanager.rmcontainer.RMContainerImpl: container_1480719777699_0005_01_000003 Container Transitioned from ALLOCATED to ACQUIRED
2016-12-02 23:15:35,135 INFO org.apache.hadoop.yarn.server.resourcemanager.security.NMTokenSecretManagerInRM: Sending NMToken for nodeId : datanode1:50178 for container : container_1480719777699_0005_01_000004
2016-12-02 23:15:35,136 INFO org.apache.hadoop.yarn.server.resourcemanager.rmcontainer.RMContainerImpl: container_1480719777699_0005_01_000004 Container Transitioned from ALLOCATED to ACQUIRED
2016-12-02 23:15:35,137 INFO org.apache.hadoop.yarn.server.resourcemanager.security.NMTokenSecretManagerInRM: Sending NMToken for nodeId : datanode2:60334 for container : container_1480719777699_0005_01_000005
2016-12-02 23:15:35,137 INFO org.apache.hadoop.yarn.server.resourcemanager.rmcontainer.RMContainerImpl: container_1480719777699_0005_01_000005 Container Transitioned from ALLOCATED to ACQUIRED
2016-12-02 23:15:35,335 INFO org.apache.hadoop.yarn.server.resourcemanager.scheduler.capacity.CapacityScheduler: Trying to fulfill reservation for application application_1480719777699_0005 on node: datanode4:45290
2016-12-02 23:15:35,336 INFO org.apache.hadoop.yarn.server.resourcemanager.scheduler.capacity.LeafQueue: Reserved container  application=application_1480719777699_0005 resource=<memory:2048, vCores:1> queue=default: capacity=1.0, absoluteCapacity=1.0, usedResources=<memory:10240, vCores:5>, usedCapacity=0.8333333, absoluteUsedCapacity=0.8333333, numApps=1, numContainers=5 usedCapacity=0.8333333 absoluteUsedCapacity=0.8333333 used=<memory:10240, vCores:5> cluster=<memory:12288, vCores:4>
2016-12-02 23:15:35,336 INFO org.apache.hadoop.yarn.server.resourcemanager.scheduler.capacity.CapacityScheduler: Skipping scheduling since node datanode4:45290 is reserved by application appattempt_1480719777699_0005_000001
2016-12-02 23:15:35,477 INFO org.apache.hadoop.yarn.server.resourcemanager.rmcontainer.RMContainerImpl: container_1480719777699_0005_01_000005 Container Transitioned from ACQUIRED to RUNNING
2016-12-02 23:15:36,337 INFO org.apache.hadoop.yarn.server.resourcemanager.scheduler.capacity.CapacityScheduler: Trying to fulfill reservation for application application_1480719777699_0005 on node: datanode4:45290
